Workbook

Sheet Folha de Pagamento
B1: Folha de Pagamento | G1: CNPJ da empresa: Referência da Folha de Pagamento: 09/2025 Quantidade de horas mensais usada: 160h Data de Construção: 06/10/2025
A3: Cod. do cargo | B3: Cod. do funcionário | C3: Cargo atual | D3: Novo Cargo | E3: Senioridade | F3: Nível Organizacional | G3: Área | H3: Carga Horária | I3: Salários | J3: Tipo de Contratação | K3: CBO | L3: Gênero | M3: Data de Admissão | N3: Observações
A4: 3 | B4: 15 | C4: Engenheiro de Software Full Stack | D4: Engenheiro de Software Full Stack Sr | E4: Sênior | F4: Tático | G4: DEV | H4: 160 | I4: 6458.4 | J4: CLT | K4: 81937 | L4: Masculino | M4: 45420
A5: 3 | B5: 50 | C5: Engenheiro de Software Full Stack | D5: Engenheiro de Software Full Stack Sr | E5: Sênior | F5: Tático | G5: DEV | H5: 160 | I5: 6458.4 | J5: CLT | K5: 81937 | L5: Masculino | M5: 45420
A6: 2 | B6: 14 | C6: Engenheiro de Software Full Stack | D6: Engenheiro de Software Full Stack Pl | E6: Pleno | F6: Operacional | G6: DEV | H6: 160 | I6: 4305.6 | J6: CLT | K6: 81937 | L6: Masculino | M6: 1/13/2025
A7: 2 | B7: 42 | C7: Engenheiro de Software Full Stack | D7: Engenheiro de Software Full Stack Pl | E7: Pleno | F7: Operacional | G7: DEV | H7: 160 | I7: 4305.6 | J7: CLT | K7: 81937 | L7: Feminino | M7: 45334
A8: 2 | B8: 36 | C8: Engenheiro de Software Full Stack | D8: Engenheiro de Software Full Stack Pl | E8: Pleno | F8: Operacional | G8: DEV | H8: 160 | I8: 4305.6 | J8: CLT | K8: 81937 | L8: Masculino | M8: 45809
A9: 2 | B9: 37 | C9: Engenheiro de Software Full Stack | D9: Engenheiro de Software Full Stack Pl | E9: Pleno | F9: Operacional | G9: DEV | H9: 160 | I9: 4305.6 | J9: CLT | K9: 81937 | L9: Masculino | M9: 45809
A10: 2 | B10: 38 | C10: Engenheiro de Software Full Stack | D10: Engenheiro de Software Full Stack Pl | E10: Pleno | F10: Operacional | G10: DEV | H10: 160 | I10: 4305.6 | J10: CLT | K10: 81937 | L10: Masculino | M10: 45635
A11: 1 | B11: 20 | C11: Engenheiro de Software Full Stack | D11: Engenheiro de Software Full Stack Jr | E11: Júnior | F11: Operacional | G11: DEV | H11: 160 | I11: 2489.18 | J11: CLT | K11: 81937 | L11: Masculino | M11: 45331
A12: 1 | B12: 54 | C12: Engenheiro de Software Full Stack | D12: Engenheiro de Software Full Stack Jr | E12: Júnior | F12: Operacional | G12: DEV | H12: 160 | I12: 2489.18 | J12: CLT | K12: 81937 | L12: Masculino | M12: 2/19/2024
A13: 1 | B13: 8 | C13: Engenheiro de Software Full Stack | D13: Engenheiro de Software Full Stack Jr | E13: Júnior | F13: Operacional | G13: DEV | H13: 160 | I13: 2489.18 | J13: CLT | K13: 81937 | L13: Masculino | M13: 1/13/2025
A14: 1 | B14: 41 | C14: Engenheiro de Software Full Stack | D14: Engenheiro de Software Full Stack Jr | E14: Júnior | F14: Operacional | G14: DEV | H14: 160 | I14: 2489.18 | J14: CLT | K14: 81937 | L14: Feminino | M14: 45809
A15: 1 | B15: 46 | C15: Engenheiro de Software Full Stack | D15: Engenheiro de Software Full Stack Jr | E15: Júnior | F15: Operacional | G15: DEV | H15: 160 | I15: 2489.18 | J15: CLT | K15: 81937 | L15: Masculino | M15: 1/13/2025
A16: 1 | B16: 40 | C16: Engenheiro de Software Full Stack | D16: Engenheiro de Software Full Stack Jr | E16: Júnior | F16: Operacional | G16: DEV | H16: 160 | I16: 2489.18 | J16: CLT | K16: 81937 | L16: Masculino | M16: 1/13/2025
A17: 1 | B17: 39 | C17: Engenheiro de Software Full Stack | D17: Engenheiro de Software Full Stack Jr | E17: Júnior | F17: Operacional | G17: DEV | H17: 160 | I17: 2489.18 | J17: CLT | K17: 81937 | L17: Masculino | M17: 45809
A18: 1 | B18: 19 | C18: Engenheiro de Software Full Stack | D18: Engenheiro de Software Full Stack Jr | E18: Júnior | F18: Operacional | G18: DEV | H18: 160 | I18: 2489.18 | J18: CLT | K18: 81937 | L18: Masculino | M18: 45421
A19: 1 | B19: 19 | C19: Engenheiro de Software Full Stack | D19: Engenheiro de Software Full Stack Jr | E19: Júnior | F19: Operacional | G19: DEV | H19: 160 | I19: 2489.18 | J19: CLT | K19: 81937 | L19: Masculino | M19: 45635
A20: 1 | B20: 21 | C20: Engenheiro de Software Full Stack | D20: Engenheiro de Software Full Stack Jr | E20: Júnior | F20: Operacional | G20: DEV | H20: 160 | I20: 2489.18 | J20: CLT | K20: 81937 | L20: Masculino | M20: 45809
A21: 1 | B21: 45 | C21: Engenheiro de Software Full Stack | D21: Engenheiro de Software Full Stack Jr | E21: Júnior | F21: Operacional | G21: DEV | H21: 160 | I21: 2489.18 | J21: CLT | K21: 81937 | L21: Masculino | M21: 45511
A22: 1 | B22: 13 | C22: Engenheiro de Software Full Stack | D22: Engenheiro de Software Full Stack Jr | E22: Júnior | F22: Operacional | G22: DEV | H22: 160 | I22: 2489.18 | J22: CLT | K22: 81937 | L22: Masculino | M22: 9/16/2024
A23: 1 | B23: 22 | C23: Engenheiro de Software Full Stack | D23: Engenheiro de Software Full Stack Jr | E23: Júnior | F23: Operacional | G23: DEV | H23: 160 | I23: 2489.18 | J23: CLT | K23: 81937 | L23: Feminino | M23: 44932
A24: 1 | B24: 1 | C24: Engenheiro de Software Full Stack | D24: Engenheiro de Software Full Stack Jr | E24: Júnior | F24: Operacional | G24: DEV | H24: 160 | I24: 2489.18 | J24: CLT | K24: 81937 | L24: Masculino | M24: 2/19/2024
A25: 1 | B25: 9 | C25: Engenheiro de Software Full Stack | D25: Engenheiro de Software Full Stack Jr | E25: Júnior | F25: Operacional | G25: DEV | H25: 160 | I25: 2489.18 | J25: CLT | K25: 81937 | L25: Masculino | M25: 44932
A26: 1 | B26: 2 | C26: Engenheiro de Software Full Stack | D26: Engenheiro de Software Full Stack Jr | E26: Júnior | F26: Operacional | G26: DEV | H26: 160 | I26: 2489.18 | J26: CLT | K26: 81937 | L26: Masculino | M26: 45809
A27: 1 | B27: 43 | C27: Engenheiro de Software Full Stack | D27: Engenheiro de Software Full Stack Jr | E27: Júnior | F27: Operacional | G27: DEV | H27: 160 | I27: 2489.18 | J27: CLT | K27: 81937 | L27: Masculino | M27: 45809
A28: 1 | B28: 44 | C28: Engenheiro de Software Full Stack | D28: Engenheiro de Software Full Stack Jr | E28: Júnior | F28: Operacional | G28: DEV | H28: 160 | I28: 2489.18 | J28: CLT | K28: 81937 | L28: Masculino | M28: 9/16/2024
A29: 1 | B29: 24 | C29: Engenheiro de Software Full Stack | D29: Engenheiro de Software Full Stack Jr | E29: Júnior | F29: Operacional | G29: DEV | H29: 160 | I29: 2489.18 | J29: CLT | K29: 81937 | L29: Masculino | M29: 44932
A30: 1 | B30: 4 | C30: Engenheiro de Software Full Stack | D30: Engenheiro de Software Full Stack Jr | E30: Júnior | F30: Operacional | G30: DEV | H30: 160 | I30: 2489.18 | J30: CLT | K30: 81937 | L30: Masculino | M30: 10/14/2024
A31: 1 | B31: 27 | C31: Engenheiro de Software Full Stack | D31: Engenheiro de Software Full Stack Jr | E31: Júnior | F31: Operacional | G31: DEV | H31: 160 | I31: 2489.18 | J31: CLT | K31: 81937 | L31: Feminino | M31: 44937
A32: 1 | B32: 381 | C32: Engenheiro de Software Full Stack | D32: Engenheiro de Software Full Stack Jr | E32: Júnior | F32: Operacional | G32: DEV | H32: 160 | I32: 2489.18 | J32: CLT | K32: 81937 | L32: Masculino | M32: 45628
A33: 1 | B33: 34 | C33: Engenheiro de Software Full Stack | D33: Engenheiro de Software Full Stack Jr | E33: Júnior | F33: Operacional | G33: DEV | H33: 160 | I33: 2489.18 | J33: CLT | K33: 81937 | L33: Masculino | M33: 45809
A34: 4 | B34: 33 | C34: Analista de Requisitos | E34: Júnior | F34: Operacional | G34: DEV | H34: 160 | I34: 2489.18 | J34: CLT | K34: 81937 | L34: Feminino | M34: 45607
A35: 4 | B35: 49 | C35: Analista de Requisitos | E35: Júnior | F35: Operacional | G35: DEV | H35: 160 | I35: 3229.2 | J35: CLT | K35: 81968 | L35: Masculino | M35: 45809
A36: 5 | B36: 3 | C36: Lider | E36: Sênior | F36: Estratégico | G36: DEV | H36: 160 | I36: 8611.2 | J36: CLT | K36: 464498 | L36: Masculino | M36: 45078

Sheet Jobmatch
A1: Jobmatch
A3: Cod. | B3: Cargos Empresa | C3: Área | D3: Nível Organizacional | E3: Cod. Pesquisa | F3: Cargos Pesquisa | G3: Senioridade | H3: Observações
A4: 1 | B4: Engenheiro de Software Full Stack Jr | C4: DEV | D4: Operacional | E4: 1 | F4: Desenvolvedor | G4: Júnior
A5: 2 | B5: Engenheiro de Software Full Stack Pl | C5: DEV | D5: Operacional | E5: 1 | F5: Desenvolvedor | G5: Pleno
A6: 3 | B6: Engenheiro de Software Full Stack Sr | C6: DEV | D6: Tático | E6: 1 | F6: Desenvolvedor | G6: Sênior
A7: 4 | B7: Analista de Requisitos | C7: DEV | D7: Operacional | E7: 796 | F7: Analista de Requisitos | G7: Júnior
A8: 5 | B8: Lider | C8: DEV | D8: Estratégico | E8: 1016 | F8: Líder Técnico | G8: Indiferente

Sheet Cálculos Comparativos
H1: DADOS PARA COMPARAÇÃO | M1: ='Informações Relevantes Cenários'!A1 -> Cenário 01: Pesquisa TI - Nacional | P1: Cenário 01: Pesquisa TI - Nacional | S1: ="% Distância da "&'Painel Geral'!B5 -> % Distância da Mediana | T1: Posicionamento | U1: ='Informações Relevantes Cenários'!C1 -> Cenário 02: Pesquisa TI - Corte por Santa Catarina | AA1: ="% Distância da "&'Painel Geral'!B5 -> % Distância da Mediana | AB1: Posicionamento
A3: Cod. | B3: Cargos Empresa | C3: Cargos Padronizados | D3: Média Empresa | E3: Cod. Área | F3: Área | G3: Nível Organizacional | H3: Cod. Pesquisa | I3: Cargos Pesquisa | J3: Senioridade | K3: Código+Senioridade | L3: Qtd de Colab | M3: Menor Salário | N3: 1º Quartil | O3: Média | P3: Mediana | Q3: 3º Quartil | R3: Maior Salário | S3: C-01 | T3: C-01 (Posicionamento) | U3: Menor Salário | V3: 1º Quartil | W3: Média | X3: Mediana | Y3: 3º Quartil | Z3: Maior Salário | AA3: C-02 | AB3: C-02 (Posicionamento)
A4: 1 | B4: =VLOOKUP(A4,Jobmatch!A:F,2,0) -> Engenheiro de Software Full Stack Jr | C4: Desenvolvedor Jr | D4: =IFERROR(AVERAGEIF('Folha de Pagamento'!A:A,A4,'Folha de Pagamento'!I:I),"") -> 2489.18 | E4: 1 | F4: =VLOOKUP(A4,Jobmatch!A:G,3,0) -> DEV | G4: =VLOOKUP(A4,Jobmatch!A:H,4,0) -> Operacional | H4: =VLOOKUP(A4,Jobmatch!A:H,5,0) -> 1 | I4: =VLOOKUP(A4,Jobmatch!A:H,6,0) -> Desenvolvedor | J4: =VLOOKUP(A4,Jobmatch!A:H,7,0) -> Júnior | K4: =H4&J4 -> 1Júnior | L4: =COUNTIF('Folha de Pagamento'!A:A,A4) -> 23 | M4: =IFERROR(VLOOKUP(K4,'C-01'!$D:$L,4,0),"") -> 2030.9 | N4: =IFERROR(VLOOKUP(K4,'C-01'!$D:$L,5,0),"") -> 2706.62 | O4: =IFERROR(VLOOKUP(K4,'C-01'!$D:$L,6,0),"") -> 3370.79 | P4: =IFERROR(VLOOKUP(K4,'C-01'!$D:$L,7,0),"") -> 3379.04 | Q4: =IFERROR(VLOOKUP(K4,'C-01'!$D:$L,8,0),"") -> 3870.49 | R4: =IFERROR(VLOOKUP(K4,'C-01'!$D:$L,9,0),"") -> 5268.74 | S4: =IFS('Painel Geral'!$B$5="Mediana",IFERROR(IF(OR(D4="",P4=0,P4=""),"",($D4/$P4)),""),'Painel Geral'!$B$5="Menor Salário",IFERROR(IF(OR(D4="",P4=0,P4=""),"",($D4/$M4)),""),'Painel Geral'!$B$5="1º Quartil",IFERROR(IF(OR(D4="",P4=0,P4=""),"",($D4/$N4)),""), 'Painel Geral'!$B$5="Média",IFERROR(IF(OR(D4="",P4=0,P4=""),"",($D4/$O4)),""),'Painel Geral'!$B$5="3º Quartil",IFERROR(IF(OR(D4="",P4=0,P4=""),"",($D4/$Q4)),""),'Painel Geral'!$B$5="Maior Salário",IFERROR(IF(OR(D4="",P4=0,P4=""),"",($D4/$R4)),"")) -> 0.73665301 | T4: =IFS(OR(M4="",M4=0,D4="", D4=0),"",S4<=80%,"Muito Defasado",S4<=90%,"Defasado",S4<=100%,"Na Média",S4<=110%,"Competitivo",S4<=120%,"Muito Competitivo",S4>120%,"Agressivo") -> Muito Defasado | U4: =IFERROR(VLOOKUP($K4,'C-02'!$D:$L,4,0),"") -> 2468.17 | V4: =IFERROR(VLOOKUP($K4,'C-02'!$D:$L,5,0),"") -> 2944.09 | W4: =IFERROR(VLOOKUP($K4,'C-02'!$D:$L,6,0),"") -> 3642.17 | X4: =IFERROR(VLOOKUP($K4,'C-02'!$D:$L,7,0),"") -> 3493.9 | Y4: =IFERROR(VLOOKUP($K4,'C-02'!$D:$L,8,0),"") -> 4224.13 | Z4: =IFERROR(VLOOKUP($K4,'C-02'!$D:$L,9,0),"") -> 5456.83 | AA4: =IFS('Painel Geral'!$B$5="Mediana",IFERROR(IF(OR(D4="",X4=0,X4=""),"",($D4/$X4)),""),'Painel Geral'!$B$5="Menor Salário",IFERROR(IF(OR(D4="",X4=0,X4=""),"",($D4/$U4)),""),'Painel Geral'!$B$5="1º Quartil",IFERROR(IF(OR(D4="",X4=0,X4=""),"",($D4/$V4)),""),'Painel Geral'!$B$5="Média",IFERROR(IF(OR(D4="",X4=0,X4=""),"",($D4/$W4)),""),'Painel Geral'!$B$5="3º Quartil",IFERROR(IF(OR(D4="",X4=0,X4=""),"",($D4/$Y4)),""), 'Painel Geral'!$B$5="Maior Salário",IFERROR(IF(OR(D4="",X4=0,X4=""),"",($D4/$Z4)),"")) -> 0.71243596 | AB4: =IFS(OR(U4="",U4=0,D4="", D4=0),"",AA4<=80%,"Muito Defasado",AA4<=90%,"Defasado",AA4<=100%,"Na Média",AA4<=110%,"Competitivo",AA4<=120%,"Muito Competitivo",AA4>120%,"Agressivo") -> Muito Defasado
A5: 2 | B5: =VLOOKUP(A5,Jobmatch!A:F,2,0) -> Engenheiro de Software Full Stack Pl | C5: Desenvolvedor Pl | D5: =IFERROR(AVERAGEIF('Folha de Pagamento'!A:A,A5,'Folha de Pagamento'!I:I),"") -> 4305.6 | E5: 1 | F5: =VLOOKUP(A5,Jobmatch!A:G,3,0) -> DEV | G5: =VLOOKUP(A5,Jobmatch!A:H,4,0) -> Operacional | H5: =VLOOKUP(A5,Jobmatch!A:H,5,0) -> 1 | I5: =VLOOKUP(A5,Jobmatch!A:H,6,0) -> Desenvolvedor | J5: =VLOOKUP(A5,Jobmatch!A:H,7,0) -> Pleno | K5: =H5&J5 -> 1Pleno | L5: =COUNTIF('Folha de Pagamento'!A:A,A5) -> 5 | M5: =IFERROR(VLOOKUP(K5,'C-01'!$D:$L,4,0),"") -> 3358.05 | N5: =IFERROR(VLOOKUP(K5,'C-01'!$D:$L,5,0),"") -> 4730.15 | O5: =IFERROR(VLOOKUP(K5,'C-01'!$D:$L,6,0),"") -> 5379.82 | P5: =IFERROR(VLOOKUP(K5,'C-01'!$D:$L,7,0),"") -> 5342.35 | Q5: =IFERROR(VLOOKUP(K5,'C-01'!$D:$L,8,0),"") -> 5995.34 | R5: =IFERROR(VLOOKUP(K5,'C-01'!$D:$L,9,0),"") -> 7790.91 | S5: =IFS('Painel Geral'!$B$5="Mediana",IFERROR(IF(OR(D5="",P5=0,P5=""),"",($D5/$P5)),""),'Painel Geral'!$B$5="Menor Salário",IFERROR(IF(OR(D5="",P5=0,P5=""),"",($D5/$M5)),""),'Painel Geral'!$B$5="1º Quartil",IFERROR(IF(OR(D5="",P5=0,P5=""),"",($D5/$N5)),""), 'Painel Geral'!$B$5="Média",IFERROR(IF(OR(D5="",P5=0,P5=""),"",($D5/$O5)),""),'Painel Geral'!$B$5="3º Quartil",IFERROR(IF(OR(D5="",P5=0,P5=""),"",($D5/$Q5)),""),'Painel Geral'!$B$5="Maior Salário",IFERROR(IF(OR(D5="",P5=0,P5=""),"",($D5/$R5)),"")) -> 0.80593746 | T5: =IFS(OR(M5="",M5=0,D5="", D5=0),"",S5<=80%,"Muito Defasado",S5<=90%,"Defasado",S5<=100%,"Na Média",S5<=110%,"Competitivo",S5<=120%,"Muito Competitivo",S5>120%,"Agressivo") -> Defasado | U5: =IFERROR(VLOOKUP($K5,'C-02'!$D:$L,4,0),"") -> 3480.14 | V5: =IFERROR(VLOOKUP($K5,'C-02'!$D:$L,5,0),"") -> 4665.99 | W5: =IFERROR(VLOOKUP($K5,'C-02'!$D:$L,6,0),"") -> 5399.83 | X5: =IFERROR(VLOOKUP($K5,'C-02'!$D:$L,7,0),"") -> 5248.63 | Y5: =IFERROR(VLOOKUP($K5,'C-02'!$D:$L,8,0),"") -> 6311.23 | Z5: =IFERROR(VLOOKUP($K5,'C-02'!$D:$L,9,0),"") -> 7135.86 | AA5: =IFS('Painel Geral'!$B$5="Mediana",IFERROR(IF(OR(D5="",X5=0,X5=""),"",($D5/$X5)),""),'Painel Geral'!$B$5="Menor Salário",IFERROR(IF(OR(D5="",X5=0,X5=""),"",($D5/$U5)),""),'Painel Geral'!$B$5="1º Quartil",IFERROR(IF(OR(D5="",X5=0,X5=""),"",($D5/$V5)),""),'Painel Geral'!$B$5="Média",IFERROR(IF(OR(D5="",X5=0,X5=""),"",($D5/$W5)),""),'Painel Geral'!$B$5="3º Quartil",IFERROR(IF(OR(D5="",X5=0,X5=""),"",($D5/$Y5)),""), 'Painel Geral'!$B$5="Maior Salário",IFERROR(IF(OR(D5="",X5=0,X5=""),"",($D5/$Z5)),"")) -> 0.82032835 | AB5: =IFS(OR(U5="",U5=0,D5="", D5=0),"",AA5<=80%,"Muito Defasado",AA5<=90%,"Defasado",AA5<=100%,"Na Média",AA5<=110%,"Competitivo",AA5<=120%,"Muito Competitivo",AA5>120%,"Agressivo") -> Defasado
A6: 3 | B6: =VLOOKUP(A6,Jobmatch!A:F,2,0) -> Engenheiro de Software Full Stack Sr | C6: Desenvolvedor Sr | D6: =IFERROR(AVERAGEIF('Folha de Pagamento'!A:A,A6,'Folha de Pagamento'!I:I),"") -> 6458.4 | E6: 1 | F6: =VLOOKUP(A6,Jobmatch!A:G,3,0) -> DEV | G6: =VLOOKUP(A6,Jobmatch!A:H,4,0) -> Tático | H6: =VLOOKUP(A6,Jobmatch!A:H,5,0) -> 1 | I6: =VLOOKUP(A6,Jobmatch!A:H,6,0) -> Desenvolvedor | J6: =VLOOKUP(A6,Jobmatch!A:H,7,0) -> Sênior | K6: =H6&J6 -> 1Sênior | L6: =COUNTIF('Folha de Pagamento'!A:A,A6) -> 2 | M6: =IFERROR(VLOOKUP(K6,'C-01'!$D:$L,4,0),"") -> 5873.21 | N6: =IFERROR(VLOOKUP(K6,'C-01'!$D:$L,5,0),"") -> 7005.56 | O6: =IFERROR(VLOOKUP(K6,'C-01'!$D:$L,6,0),"") -> 8047.78 | P6: =IFERROR(VLOOKUP(K6,'C-01'!$D:$L,7,0),"") -> 7999.87 | Q6: =IFERROR(VLOOKUP(K6,'C-01'!$D:$L,8,0),"") -> 9271.4 | R6: =IFERROR(VLOOKUP(K6,'C-01'!$D:$L,9,0),"") -> 10095.14 | S6: =IFS('Painel Geral'!$B$5="Mediana",IFERROR(IF(OR(D6="",P6=0,P6=""),"",($D6/$P6)),""),'Painel Geral'!$B$5="Menor Salário",IFERROR(IF(OR(D6="",P6=0,P6=""),"",($D6/$M6)),""),'Painel Geral'!$B$5="1º Quartil",IFERROR(IF(OR(D6="",P6=0,P6=""),"",($D6/$N6)),""), 'Painel Geral'!$B$5="Média",IFERROR(IF(OR(D6="",P6=0,P6=""),"",($D6/$O6)),""),'Painel Geral'!$B$5="3º Quartil",IFERROR(IF(OR(D6="",P6=0,P6=""),"",($D6/$Q6)),""),'Painel Geral'!$B$5="Maior Salário",IFERROR(IF(OR(D6="",P6=0,P6=""),"",($D6/$R6)),"")) -> 0.80731312 | T6: =IFS(OR(M6="",M6=0,D6="", D6=0),"",S6<=80%,"Muito Defasado",S6<=90%,"Defasado",S6<=100%,"Na Média",S6<=110%,"Competitivo",S6<=120%,"Muito Competitivo",S6>120%,"Agressivo") -> Defasado | U6: =IFERROR(VLOOKUP($K6,'C-02'!$D:$L,4,0),"") -> 5928.64 | V6: =IFERROR(VLOOKUP($K6,'C-02'!$D:$L,5,0),"") -> 6791.87 | W6: =IFERROR(VLOOKUP($K6,'C-02'!$D:$L,6,0),"") -> 7984.54 | X6: =IFERROR(VLOOKUP($K6,'C-02'!$D:$L,7,0),"") -> 7851.14 | Y6: =IFERROR(VLOOKUP($K6,'C-02'!$D:$L,8,0),"") -> 9534.06 | Z6: =IFERROR(VLOOKUP($K6,'C-02'!$D:$L,9,0),"") -> 9921.51 | AA6: =IFS('Painel Geral'!$B$5="Mediana",IFERROR(IF(OR(D6="",X6=0,X6=""),"",($D6/$X6)),""),'Painel Geral'!$B$5="Menor Salário",IFERROR(IF(OR(D6="",X6=0,X6=""),"",($D6/$U6)),""),'Painel Geral'!$B$5="1º Quartil",IFERROR(IF(OR(D6="",X6=0,X6=""),"",($D6/$V6)),""),'Painel Geral'!$B$5="Média",IFERROR(IF(OR(D6="",X6=0,X6=""),"",($D6/$W6)),""),'Painel Geral'!$B$5="3º Quartil",IFERROR(IF(OR(D6="",X6=0,X6=""),"",($D6/$Y6)),""), 'Painel Geral'!$B$5="Maior Salário",IFERROR(IF(OR(D6="",X6=0,X6=""),"",($D6/$Z6)),"")) -> 0.82260665 | AB6: =IFS(OR(U6="",U6=0,D6="", D6=0),"",AA6<=80%,"Muito Defasado",AA6<=90%,"Defasado",AA6<=100%,"Na Média",AA6<=110%,"Competitivo",AA6<=120%,"Muito Competitivo",AA6>120%,"Agressivo") -> Defasado
A7: 4 | B7: =VLOOKUP(A7,Jobmatch!A:F,2,0) -> Analista de Requisitos | C7: Analista Requisitos Jr | D7: =IFERROR(AVERAGEIF('Folha de Pagamento'!A:A,A7,'Folha de Pagamento'!I:I),"") -> 2859.19 | E7: 1 | F7: =VLOOKUP(A7,Jobmatch!A:G,3,0) -> DEV | G7: =VLOOKUP(A7,Jobmatch!A:H,4,0) -> Operacional | H7: =VLOOKUP(A7,Jobmatch!A:H,5,0) -> 796 | I7: =VLOOKUP(A7,Jobmatch!A:H,6,0) -> Analista de Requisitos | J7: =VLOOKUP(A7,Jobmatch!A:H,7,0) -> Júnior | K7: =H7&J7 -> 796Júnior | L7: =COUNTIF('Folha de Pagamento'!A:A,A7) -> 2 | M7: =IFERROR(VLOOKUP(K7,'C-01'!$D:$L,4,0),"") -> 2626.68 | N7: =IFERROR(VLOOKUP(K7,'C-01'!$D:$L,5,0),"") -> 3508.61 | O7: =IFERROR(VLOOKUP(K7,'C-01'!$D:$L,6,0),"") -> 4174.12 | P7: =IFERROR(VLOOKUP(K7,'C-01'!$D:$L,7,0),"") -> 3618.72 | Q7: =IFERROR(VLOOKUP(K7,'C-01'!$D:$L,8,0),"") -> 5081.15 | R7: =IFERROR(VLOOKUP(K7,'C-01'!$D:$L,9,0),"") -> 5977.75 | S7: =IFS('Painel Geral'!$B$5="Mediana",IFERROR(IF(OR(D7="",P7=0,P7=""),"",($D7/$P7)),""),'Painel Geral'!$B$5="Menor Salário",IFERROR(IF(OR(D7="",P7=0,P7=""),"",($D7/$M7)),""),'Painel Geral'!$B$5="1º Quartil",IFERROR(IF(OR(D7="",P7=0,P7=""),"",($D7/$N7)),""), 'Painel Geral'!$B$5="Média",IFERROR(IF(OR(D7="",P7=0,P7=""),"",($D7/$O7)),""),'Painel Geral'!$B$5="3º Quartil",IFERROR(IF(OR(D7="",P7=0,P7=""),"",($D7/$Q7)),""),'Painel Geral'!$B$5="Maior Salário",IFERROR(IF(OR(D7="",P7=0,P7=""),"",($D7/$R7)),"")) -> 0.79011087 | T7: =IFS(OR(M7="",M7=0,D7="", D7=0),"",S7<=80%,"Muito Defasado",S7<=90%,"Defasado",S7<=100%,"Na Média",S7<=110%,"Competitivo",S7<=120%,"Muito Competitivo",S7>120%,"Agressivo") -> Muito Defasado | U7: =IFERROR(VLOOKUP($K7,'C-02'!$D:$L,4,0),"") -> 0 | V7: =IFERROR(VLOOKUP($K7,'C-02'!$D:$L,5,0),"") -> 0 | W7: =IFERROR(VLOOKUP($K7,'C-02'!$D:$L,6,0),"") -> 0 | X7: =IFERROR(VLOOKUP($K7,'C-02'!$D:$L,7,0),"") -> 0 | Y7: =IFERROR(VLOOKUP($K7,'C-02'!$D:$L,8,0),"") -> 0 | Z7: =IFERROR(VLOOKUP($K7,'C-02'!$D:$L,9,0),"") -> 0 | AA7: =IFS('Painel Geral'!$B$5="Mediana",IFERROR(IF(OR(D7="",X7=0,X7=""),"",($D7/$X7)),""),'Painel Geral'!$B$5="Menor Salário",IFERROR(IF(OR(D7="",X7=0,X7=""),"",($D7/$U7)),""),'Painel Geral'!$B$5="1º Quartil",IFERROR(IF(OR(D7="",X7=0,X7=""),"",($D7/$V7)),""),'Painel Geral'!$B$5="Média",IFERROR(IF(OR(D7="",X7=0,X7=""),"",($D7/$W7)),""),'Painel Geral'!$B$5="3º Quartil",IFERROR(IF(OR(D7="",X7=0,X7=""),"",($D7/$Y7)),""), 'Painel Geral'!$B$5="Maior Salário",IFERROR(IF(OR(D7="",X7=0,X7=""),"",($D7/$Z7)),"")) | AB7: =IFS(OR(U7="",U7=0,D7="", D7=0),"",AA7<=80%,"Muito Defasado",AA7<=90%,"Defasado",AA7<=100%,"Na Média",AA7<=110%,"Competitivo",AA7<=120%,"Muito Competitivo",AA7>120%,"Agressivo")
C8: Analista Requisitos Pl | F8: DEV | H8: 796 | I8: Analista de Requisitos | J8: Pleno | K8: =H8&J8 -> 796Pleno | M8: =IFERROR(VLOOKUP(K8,'C-01'!$D:$L,4,0),"") -> 3810.77 | N8: =IFERROR(VLOOKUP(K8,'C-01'!$D:$L,5,0),"") -> 4192.12 | O8: =IFERROR(VLOOKUP(K8,'C-01'!$D:$L,6,0),"") -> 4717.97 | P8: =IFERROR(VLOOKUP(K8,'C-01'!$D:$L,7,0),"") -> 4465.27 | Q8: =IFERROR(VLOOKUP(K8,'C-01'!$D:$L,8,0),"") -> 5273.23 | R8: =IFERROR(VLOOKUP(K8,'C-01'!$D:$L,9,0),"") -> 6105.55 | S8: =IFS('Painel Geral'!$B$5="Mediana",IFERROR(IF(OR(D8="",P8=0,P8=""),"",($D8/$P8)),""),'Painel Geral'!$B$5="Menor Salário",IFERROR(IF(OR(D8="",P8=0,P8=""),"",($D8/$M8)),""),'Painel Geral'!$B$5="1º Quartil",IFERROR(IF(OR(D8="",P8=0,P8=""),"",($D8/$N8)),""), 'Painel Geral'!$B$5="Média",IFERROR(IF(OR(D8="",P8=0,P8=""),"",($D8/$O8)),""),'Painel Geral'!$B$5="3º Quartil",IFERROR(IF(OR(D8="",P8=0,P8=""),"",($D8/$Q8)),""),'Painel Geral'!$B$5="Maior Salário",IFERROR(IF(OR(D8="",P8=0,P8=""),"",($D8/$R8)),"")) | T8: =IFS(OR(M8="",M8=0,D8="", D8=0),"",S8<=80%,"Muito Defasado",S8<=90%,"Defasado",S8<=100%,"Na Média",S8<=110%,"Competitivo",S8<=120%,"Muito Competitivo",S8>120%,"Agressivo") | U8: =IFERROR(VLOOKUP($K8,'C-02'!$D:$L,4,0),"") -> 0 | V8: =IFERROR(VLOOKUP($K8,'C-02'!$D:$L,5,0),"") -> 0 | W8: =IFERROR(VLOOKUP($K8,'C-02'!$D:$L,6,0),"") -> 0 | X8: =IFERROR(VLOOKUP($K8,'C-02'!$D:$L,7,0),"") -> 0 | Y8: =IFERROR(VLOOKUP($K8,'C-02'!$D:$L,8,0),"") -> 0 | Z8: =IFERROR(VLOOKUP($K8,'C-02'!$D:$L,9,0),"") -> 0 | AA8: =IFS('Painel Geral'!$B$5="Mediana",IFERROR(IF(OR(D8="",X8=0,X8=""),"",($D8/$X8)),""),'Painel Geral'!$B$5="Menor Salário",IFERROR(IF(OR(D8="",X8=0,X8=""),"",($D8/$U8)),""),'Painel Geral'!$B$5="1º Quartil",IFERROR(IF(OR(D8="",X8=0,X8=""),"",($D8/$V8)),""),'Painel Geral'!$B$5="Média",IFERROR(IF(OR(D8="",X8=0,X8=""),"",($D8/$W8)),""),'Painel Geral'!$B$5="3º Quartil",IFERROR(IF(OR(D8="",X8=0,X8=""),"",($D8/$Y8)),""), 'Painel Geral'!$B$5="Maior Salário",IFERROR(IF(OR(D8="",X8=0,X8=""),"",($D8/$Z8)),"")) | AB8: =IFS(OR(U8="",U8=0,D8="", D8=0),"",AA8<=80%,"Muito Defasado",AA8<=90%,"Defasado",AA8<=100%,"Na Média",AA8<=110%,"Competitivo",AA8<=120%,"Muito Competitivo",AA8>120%,"Agressivo")
C9: Analista Requisitos Sr | F9: DEV | H9: 796 | I9: Analista de Requisitos | J9: Sênior | K9: =H9&J9 -> 796Sênior | M9: =IFERROR(VLOOKUP(K9,'C-01'!$D:$L,4,0),"") -> 6472.04 | N9: =IFERROR(VLOOKUP(K9,'C-01'!$D:$L,5,0),"") -> 7185.89 | O9: =IFERROR(VLOOKUP(K9,'C-01'!$D:$L,6,0),"") -> 7572.48 | P9: =IFERROR(VLOOKUP(K9,'C-01'!$D:$L,7,0),"") -> 7264.21 | Q9: =IFERROR(VLOOKUP(K9,'C-01'!$D:$L,8,0),"") -> 8100.12 | R9: =IFERROR(VLOOKUP(K9,'C-01'!$D:$L,9,0),"") -> 8614.28 | S9: =IFS('Painel Geral'!$B$5="Mediana",IFERROR(IF(OR(D9="",P9=0,P9=""),"",($D9/$P9)),""),'Painel Geral'!$B$5="Menor Salário",IFERROR(IF(OR(D9="",P9=0,P9=""),"",($D9/$M9)),""),'Painel Geral'!$B$5="1º Quartil",IFERROR(IF(OR(D9="",P9=0,P9=""),"",($D9/$N9)),""), 'Painel Geral'!$B$5="Média",IFERROR(IF(OR(D9="",P9=0,P9=""),"",($D9/$O9)),""),'Painel Geral'!$B$5="3º Quartil",IFERROR(IF(OR(D9="",P9=0,P9=""),"",($D9/$Q9)),""),'Painel Geral'!$B$5="Maior Salário",IFERROR(IF(OR(D9="",P9=0,P9=""),"",($D9/$R9)),"")) | T9: =IFS(OR(M9="",M9=0,D9="", D9=0),"",S9<=80%,"Muito Defasado",S9<=90%,"Defasado",S9<=100%,"Na Média",S9<=110%,"Competitivo",S9<=120%,"Muito Competitivo",S9>120%,"Agressivo") | U9: =IFERROR(VLOOKUP($K9,'C-02'!$D:$L,4,0),"") -> 0 | V9: =IFERROR(VLOOKUP($K9,'C-02'!$D:$L,5,0),"") -> 0 | W9: =IFERROR(VLOOKUP($K9,'C-02'!$D:$L,6,0),"") -> 0 | X9: =IFERROR(VLOOKUP($K9,'C-02'!$D:$L,7,0),"") -> 0 | Y9: =IFERROR(VLOOKUP($K9,'C-02'!$D:$L,8,0),"") -> 0 | Z9: =IFERROR(VLOOKUP($K9,'C-02'!$D:$L,9,0),"") -> 0 | AA9: =IFS('Painel Geral'!$B$5="Mediana",IFERROR(IF(OR(D9="",X9=0,X9=""),"",($D9/$X9)),""),'Painel Geral'!$B$5="Menor Salário",IFERROR(IF(OR(D9="",X9=0,X9=""),"",($D9/$U9)),""),'Painel Geral'!$B$5="1º Quartil",IFERROR(IF(OR(D9="",X9=0,X9=""),"",($D9/$V9)),""),'Painel Geral'!$B$5="Média",IFERROR(IF(OR(D9="",X9=0,X9=""),"",($D9/$W9)),""),'Painel Geral'!$B$5="3º Quartil",IFERROR(IF(OR(D9="",X9=0,X9=""),"",($D9/$Y9)),""), 'Painel Geral'!$B$5="Maior Salário",IFERROR(IF(OR(D9="",X9=0,X9=""),"",($D9/$Z9)),"")) | AB9: =IFS(OR(U9="",U9=0,D9="", D9=0),"",AA9<=80%,"Muito Defasado",AA9<=90%,"Defasado",AA9<=100%,"Na Média",AA9<=110%,"Competitivo",AA9<=120%,"Muito Competitivo",AA9>120%,"Agressivo")
A10: 5 | B10: =VLOOKUP(A10,Jobmatch!A:F,2,0) -> Lider | C10: Líder Técnico | D10: =IFERROR(AVERAGEIF('Folha de Pagamento'!A:A,A10,'Folha de Pagamento'!I:I),"") -> 8611.2 | E10: 1 | F10: =VLOOKUP(A10,Jobmatch!A:G,3,0) -> DEV | G10: =VLOOKUP(A10,Jobmatch!A:H,4,0) -> Estratégico | H10: =VLOOKUP(A10,Jobmatch!A:H,5,0) -> 1016 | I10: =VLOOKUP(A10,Jobmatch!A:H,6,0) -> Líder Técnico | J10: =VLOOKUP(A10,Jobmatch!A:H,7,0) -> Indiferente | K10: =H10&J10 -> 1016Indiferente | L10: =COUNTIF('Folha de Pagamento'!A:A,A10) -> 1 | M10: =IFERROR(VLOOKUP(K10,'C-01'!$D:$L,4,0),"") -> 5639.53 | N10: =IFERROR(VLOOKUP(K10,'C-01'!$D:$L,5,0),"") -> 7452.03 | O10: =IFERROR(VLOOKUP(K10,'C-01'!$D:$L,6,0),"") -> 8919.44 | P10: =IFERROR(VLOOKUP(K10,'C-01'!$D:$L,7,0),"") -> 8929.22 | Q10: =IFERROR(VLOOKUP(K10,'C-01'!$D:$L,8,0),"") -> 10057.47 | R10: =IFERROR(VLOOKUP(K10,'C-01'!$D:$L,9,0),"") -> 12817.68 | S10: =IFS('Painel Geral'!$B$5="Mediana",IFERROR(IF(OR(D10="",P10=0,P10=""),"",($D10/$P10)),""),'Painel Geral'!$B$5="Menor Salário",IFERROR(IF(OR(D10="",P10=0,P10=""),"",($D10/$M10)),""),'Painel Geral'!$B$5="1º Quartil",IFERROR(IF(OR(D10="",P10=0,P10=""),"",($D10/$N10)),""), 'Painel Geral'!$B$5="Média",IFERROR(IF(OR(D10="",P10=0,P10=""),"",($D10/$O10)),""),'Painel Geral'!$B$5="3º Quartil",IFERROR(IF(OR(D10="",P10=0,P10=""),"",($D10/$Q10)),""),'Painel Geral'!$B$5="Maior Salário",IFERROR(IF(OR(D10="",P10=0,P10=""),"",($D10/$R10)),"")) -> 0.96438435 | T10: =IFS(OR(M10="",M10=0,D10="", D10=0),"",S10<=80%,"Muito Defasado",S10<=90%,"Defasado",S10<=100%,"Na Média",S10<=110%,"Competitivo",S10<=120%,"Muito Competitivo",S10>120%,"Agressivo") -> Na Média | U10: =IFERROR(VLOOKUP($K10,'C-02'!$D:$L,4,0),"") -> 5288.93 | V10: =IFERROR(VLOOKUP($K10,'C-02'!$D:$L,5,0),"") -> 7107.92 | W10: =IFERROR(VLOOKUP($K10,'C-02'!$D:$L,6,0),"") -> 8904.46 | X10: =IFERROR(VLOOKUP($K10,'C-02'!$D:$L,7,0),"") -> 9047.66 | Y10: =IFERROR(VLOOKUP($K10,'C-02'!$D:$L,8,0),"") -> 10074.15 | Z10: =IFERROR(VLOOKUP($K10,'C-02'!$D:$L,9,0),"") -> 12817.68 | AA10: =IFS('Painel Geral'!$B$5="Mediana",IFERROR(IF(OR(D10="",X10=0,X10=""),"",($D10/$X10)),""),'Painel Geral'!$B$5="Menor Salário",IFERROR(IF(OR(D10="",X10=0,X10=""),"",($D10/$U10)),""),'Painel Geral'!$B$5="1º Quartil",IFERROR(IF(OR(D10="",X10=0,X10=""),"",($D10/$V10)),""),'Painel Geral'!$B$5="Média",IFERROR(IF(OR(D10="",X10=0,X10=""),"",($D10/$W10)),""),'Painel Geral'!$B$5="3º Quartil",IFERROR(IF(OR(D10="",X10=0,X10=""),"",($D10/$Y10)),""), 'Painel Geral'!$B$5="Maior Salário",IFERROR(IF(OR(D10="",X10=0,X10=""),"",($D10/$Z10)),"")) -> 0.9517599 | AB10: =IFS(OR(U10="",U10=0,D10="", D10=0),"",AA10<=80%,"Muito Defasado",AA10<=90%,"Defasado",AA10<=100%,"Na Média",AA10<=110%,"Competitivo",AA10<=120%,"Muito Competitivo",AA10>120%,"Agressivo") -> Na Média
C11: Técnico Infraestrutura | F11: DEV | H11: 69 | I11: Assistente de Infraestrutura de TI | J11: Indiferente | K11: =H11&J11 -> 69Indiferente | M11: =IFERROR(VLOOKUP(K11,'C-01'!$D:$L,4,0),"") -> 1782.06 | N11: =IFERROR(VLOOKUP(K11,'C-01'!$D:$L,5,0),"") -> 2143.44 | O11: =IFERROR(VLOOKUP(K11,'C-01'!$D:$L,6,0),"") -> 2238.54 | P11: =IFERROR(VLOOKUP(K11,'C-01'!$D:$L,7,0),"") -> 2220.51 | Q11: =IFERROR(VLOOKUP(K11,'C-01'!$D:$L,8,0),"") -> 2220.51 | R11: =IFERROR(VLOOKUP(K11,'C-01'!$D:$L,9,0),"") -> 2726.11 | S11: =IFS('Painel Geral'!$B$5="Mediana",IFERROR(IF(OR(D11="",P11=0,P11=""),"",($D11/$P11)),""),'Painel Geral'!$B$5="Menor Salário",IFERROR(IF(OR(D11="",P11=0,P11=""),"",($D11/$M11)),""),'Painel Geral'!$B$5="1º Quartil",IFERROR(IF(OR(D11="",P11=0,P11=""),"",($D11/$N11)),""), 'Painel Geral'!$B$5="Média",IFERROR(IF(OR(D11="",P11=0,P11=""),"",($D11/$O11)),""),'Painel Geral'!$B$5="3º Quartil",IFERROR(IF(OR(D11="",P11=0,P11=""),"",($D11/$Q11)),""),'Painel Geral'!$B$5="Maior Salário",IFERROR(IF(OR(D11="",P11=0,P11=""),"",($D11/$R11)),"")) | T11: =IFS(OR(M11="",M11=0,D11="", D11=0),"",S11<=80%,"Muito Defasado",S11<=90%,"Defasado",S11<=100%,"Na Média",S11<=110%,"Competitivo",S11<=120%,"Muito Competitivo",S11>120%,"Agressivo") | U11: =IFERROR(VLOOKUP($K11,'C-02'!$D:$L,4,0),"") | V11: =IFERROR(VLOOKUP($K11,'C-02'!$D:$L,5,0),"") | W11: =IFERROR(VLOOKUP($K11,'C-02'!$D:$L,6,0),"") | X11: =IFERROR(VLOOKUP($K11,'C-02'!$D:$L,7,0),"") | Y11: =IFERROR(VLOOKUP($K11,'C-02'!$D:$L,8,0),"") | Z11: =IFERROR(VLOOKUP($K11,'C-02'!$D:$L,9,0),"") | AA11: =IFS('Painel Geral'!$B$5="Mediana",IFERROR(IF(OR(D11="",X11=0,X11=""),"",($D11/$X11)),""),'Painel Geral'!$B$5="Menor Salário",IFERROR(IF(OR(D11="",X11=0,X11=""),"",($D11/$U11)),""),'Painel Geral'!$B$5="1º Quartil",IFERROR(IF(OR(D11="",X11=0,X11=""),"",($D11/$V11)),""),'Painel Geral'!$B$5="Média",IFERROR(IF(OR(D11="",X11=0,X11=""),"",($D11/$W11)),""),'Painel Geral'!$B$5="3º Quartil",IFERROR(IF(OR(D11="",X11=0,X11=""),"",($D11/$Y11)),""), 'Painel Geral'!$B$5="Maior Salário",IFERROR(IF(OR(D11="",X11=0,X11=""),"",($D11/$Z11)),"")) | AB11: =IFS(OR(U11="",U11=0,D11="", D11=0),"",AA11<=80%,"Muito Defasado",AA11<=90%,"Defasado",AA11<=100%,"Na Média",AA11<=110%,"Competitivo",AA11<=120%,"Muito Competitivo",AA11>120%,"Agressivo")
C12: Analista Infraestrutura Jr | F12: DEV | H12: 15 | I12: Analista de Infraestrutura de TI | J12: Júnior | K12: =H12&J12 -> 15Júnior | M12: =IFERROR(VLOOKUP(K12,'C-01'!$D:$L,4,0),"") -> 2093.28 | N12: =IFERROR(VLOOKUP(K12,'C-01'!$D:$L,5,0),"") -> 2289.58 | O12: =IFERROR(VLOOKUP(K12,'C-01'!$D:$L,6,0),"") -> 2653.62 | P12: =IFERROR(VLOOKUP(K12,'C-01'!$D:$L,7,0),"") -> 2644.46 | Q12: =IFERROR(VLOOKUP(K12,'C-01'!$D:$L,8,0),"") -> 2908.53 | R12: =IFERROR(VLOOKUP(K12,'C-01'!$D:$L,9,0),"") -> 3400.19 | S12: =IFS('Painel Geral'!$B$5="Mediana",IFERROR(IF(OR(D12="",P12=0,P12=""),"",($D12/$P12)),""),'Painel Geral'!$B$5="Menor Salário",IFERROR(IF(OR(D12="",P12=0,P12=""),"",($D12/$M12)),""),'Painel Geral'!$B$5="1º Quartil",IFERROR(IF(OR(D12="",P12=0,P12=""),"",($D12/$N12)),""), 'Painel Geral'!$B$5="Média",IFERROR(IF(OR(D12="",P12=0,P12=""),"",($D12/$O12)),""),'Painel Geral'!$B$5="3º Quartil",IFERROR(IF(OR(D12="",P12=0,P12=""),"",($D12/$Q12)),""),'Painel Geral'!$B$5="Maior Salário",IFERROR(IF(OR(D12="",P12=0,P12=""),"",($D12/$R12)),"")) | T12: =IFS(OR(M12="",M12=0,D12="", D12=0),"",S12<=80%,"Muito Defasado",S12<=90%,"Defasado",S12<=100%,"Na Média",S12<=110%,"Competitivo",S12<=120%,"Muito Competitivo",S12>120%,"Agressivo") | U12: =IFERROR(VLOOKUP($K12,'C-02'!$D:$L,4,0),"") | V12: =IFERROR(VLOOKUP($K12,'C-02'!$D:$L,5,0),"") | W12: =IFERROR(VLOOKUP($K12,'C-02'!$D:$L,6,0),"") | X12: =IFERROR(VLOOKUP($K12,'C-02'!$D:$L,7,0),"") | Y12: =IFERROR(VLOOKUP($K12,'C-02'!$D:$L,8,0),"") | Z12: =IFERROR(VLOOKUP($K12,'C-02'!$D:$L,9,0),"") | AA12: =IFS('Painel Geral'!$B$5="Mediana",IFERROR(IF(OR(D12="",X12=0,X12=""),"",($D12/$X12)),""),'Painel Geral'!$B$5="Menor Salário",IFERROR(IF(OR(D12="",X12=0,X12=""),"",($D12/$U12)),""),'Painel Geral'!$B$5="1º Quartil",IFERROR(IF(OR(D12="",X12=0,X12=""),"",($D12/$V12)),""),'Painel Geral'!$B$5="Média",IFERROR(IF(OR(D12="",X12=0,X12=""),"",($D12/$W12)),""),'Painel Geral'!$B$5="3º Quartil",IFERROR(IF(OR(D12="",X12=0,X12=""),"",($D12/$Y12)),""), 'Painel Geral'!$B$5="Maior Salário",IFERROR(IF(OR(D12="",X12=0,X12=""),"",($D12/$Z12)),"")) | AB12: =IFS(OR(U12="",U12=0,D12="", D12=0),"",AA12<=80%,"Muito Defasado",AA12<=90%,"Defasado",AA12<=100%,"Na Média",AA12<=110%,"Competitivo",AA12<=120%,"Muito Competitivo",AA12>120%,"Agressivo")
C13: Analista Infraestrutura Pl | F13: DEV | H13: 15 | I13: Analista de Infraestrutura de TI | J13: Pleno | K13: =H13&J13 -> 15Pleno | M13: =IFERROR(VLOOKUP(K13,'C-01'!$D:$L,4,0),"") -> 3247.23 | N13: =IFERROR(VLOOKUP(K13,'C-01'!$D:$L,5,0),"") -> 3753.88 | O13: =IFERROR(VLOOKUP(K13,'C-01'!$D:$L,6,0),"") -> 4254.3 | P13: =IFERROR(VLOOKUP(K13,'C-01'!$D:$L,7,0),"") -> 4178.94 | Q13: =IFERROR(VLOOKUP(K13,'C-01'!$D:$L,8,0),"") -> 4856.44 | R13: =IFERROR(VLOOKUP(K13,'C-01'!$D:$L,9,0),"") -> 5596.75 | S13: =IFS('Painel Geral'!$B$5="Mediana",IFERROR(IF(OR(D13="",P13=0,P13=""),"",($D13/$P13)),""),'Painel Geral'!$B$5="Menor Salário",IFERROR(IF(OR(D13="",P13=0,P13=""),"",($D13/$M13)),""),'Painel Geral'!$B$5="1º Quartil",IFERROR(IF(OR(D13="",P13=0,P13=""),"",($D13/$N13)),""), 'Painel Geral'!$B$5="Média",IFERROR(IF(OR(D13="",P13=0,P13=""),"",($D13/$O13)),""),'Painel Geral'!$B$5="3º Quartil",IFERROR(IF(OR(D13="",P13=0,P13=""),"",($D13/$Q13)),""),'Painel Geral'!$B$5="Maior Salário",IFERROR(IF(OR(D13="",P13=0,P13=""),"",($D13/$R13)),"")) | T13: =IFS(OR(M13="",M13=0,D13="", D13=0),"",S13<=80%,"Muito Defasado",S13<=90%,"Defasado",S13<=100%,"Na Média",S13<=110%,"Competitivo",S13<=120%,"Muito Competitivo",S13>120%,"Agressivo") | U13: =IFERROR(VLOOKUP($K13,'C-02'!$D:$L,4,0),"") | V13: =IFERROR(VLOOKUP($K13,'C-02'!$D:$L,5,0),"") | W13: =IFERROR(VLOOKUP($K13,'C-02'!$D:$L,6,0),"") | X13: =IFERROR(VLOOKUP($K13,'C-02'!$D:$L,7,0),"") | Y13: =IFERROR(VLOOKUP($K13,'C-02'!$D:$L,8,0),"") | Z13: =IFERROR(VLOOKUP($K13,'C-02'!$D:$L,9,0),"") | AA13: =IFS('Painel Geral'!$B$5="Mediana",IFERROR(IF(OR(D13="",X13=0,X13=""),"",($D13/$X13)),""),'Painel Geral'!$B$5="Menor Salário",IFERROR(IF(OR(D13="",X13=0,X13=""),"",($D13/$U13)),""),'Painel Geral'!$B$5="1º Quartil",IFERROR(IF(OR(D13="",X13=0,X13=""),"",($D13/$V13)),""),'Painel Geral'!$B$5="Média",IFERROR(IF(OR(D13="",X13=0,X13=""),"",($D13/$W13)),""),'Painel Geral'!$B$5="3º Quartil",IFERROR(IF(OR(D13="",X13=0,X13=""),"",($D13/$Y13)),""), 'Painel Geral'!$B$5="Maior Salário",IFERROR(IF(OR(D13="",X13=0,X13=""),"",($D13/$Z13)),"")) | AB13: =IFS(OR(U13="",U13=0,D13="", D13=0),"",AA13<=80%,"Muito Defasado",AA13<=90%,"Defasado",AA13<=100%,"Na Média",AA13<=110%,"Competitivo",AA13<=120%,"Muito Competitivo",AA13>120%,"Agressivo")
C14: Analista Infraestrutura Sr | F14: DEV | H14: 15 | I14: Analista de Infraestrutura de TI | J14: Sênior | K14: =H14&J14 -> 15Sênior | M14: =IFERROR(VLOOKUP(K14,'C-01'!$D:$L,4,0),"") -> 4663.49 | N14: =IFERROR(VLOOKUP(K14,'C-01'!$D:$L,5,0),"") -> 5285.89 | O14: =IFERROR(VLOOKUP(K14,'C-01'!$D:$L,6,0),"") -> 5775.86 | P14: =IFERROR(VLOOKUP(K14,'C-01'!$D:$L,7,0),"") -> 5574.65 | Q14: =IFERROR(VLOOKUP(K14,'C-01'!$D:$L,8,0),"") -> 6292.99 | R14: =IFERROR(VLOOKUP(K14,'C-01'!$D:$L,9,0),"") -> 7288.6 | S14: =IFS('Painel Geral'!$B$5="Mediana",IFERROR(IF(OR(D14="",P14=0,P14=""),"",($D14/$P14)),""),'Painel Geral'!$B$5="Menor Salário",IFERROR(IF(OR(D14="",P14=0,P14=""),"",($D14/$M14)),""),'Painel Geral'!$B$5="1º Quartil",IFERROR(IF(OR(D14="",P14=0,P14=""),"",($D14/$N14)),""), 'Painel Geral'!$B$5="Média",IFERROR(IF(OR(D14="",P14=0,P14=""),"",($D14/$O14)),""),'Painel Geral'!$B$5="3º Quartil",IFERROR(IF(OR(D14="",P14=0,P14=""),"",($D14/$Q14)),""),'Painel Geral'!$B$5="Maior Salário",IFERROR(IF(OR(D14="",P14=0,P14=""),"",($D14/$R14)),"")) | T14: =IFS(OR(M14="",M14=0,D14="", D14=0),"",S14<=80%,"Muito Defasado",S14<=90%,"Defasado",S14<=100%,"Na Média",S14<=110%,"Competitivo",S14<=120%,"Muito Competitivo",S14>120%,"Agressivo") | U14: =IFERROR(VLOOKUP($K14,'C-02'!$D:$L,4,0),"") | V14: =IFERROR(VLOOKUP($K14,'C-02'!$D:$L,5,0),"") | W14: =IFERROR(VLOOKUP($K14,'C-02'!$D:$L,6,0),"") | X14: =IFERROR(VLOOKUP($K14,'C-02'!$D:$L,7,0),"") | Y14: =IFERROR(VLOOKUP($K14,'C-02'!$D:$L,8,0),"") | Z14: =IFERROR(VLOOKUP($K14,'C-02'!$D:$L,9,0),"") | AA14: =IFS('Painel Geral'!$B$5="Mediana",IFERROR(IF(OR(D14="",X14=0,X14=""),"",($D14/$X14)),""),'Painel Geral'!$B$5="Menor Salário",IFERROR(IF(OR(D14="",X14=0,X14=""),"",($D14/$U14)),""),'Painel Geral'!$B$5="1º Quartil",IFERROR(IF(OR(D14="",X14=0,X14=""),"",($D14/$V14)),""),'Painel Geral'!$B$5="Média",IFERROR(IF(OR(D14="",X14=0,X14=""),"",($D14/$W14)),""),'Painel Geral'!$B$5="3º Quartil",IFERROR(IF(OR(D14="",X14=0,X14=""),"",($D14/$Y14)),""), 'Painel Geral'!$B$5="Maior Salário",IFERROR(IF(OR(D14="",X14=0,X14=""),"",($D14/$Z14)),"")) | AB14: =IFS(OR(U14="",U14=0,D14="", D14=0),"",AA14<=80%,"Muito Defasado",AA14<=90%,"Defasado",AA14<=100%,"Na Média",AA14<=110%,"Competitivo",AA14<=120%,"Muito Competitivo",AA14>120%,"Agressivo")

Sheet Tabela
H1: DADOS PARA COMPARAÇÃO | M1: ='Informações Relevantes Cenários'!A1 -> Cenário 01: Pesquisa TI - Nacional | Q1: Cenário 01: Pesquisa TI - Nacional | AR1: ="% Distância da "&'Painel Geral'!B5 -> % Distância da Mediana | AS1: Posicionamento | AT1: ='Informações Relevantes Cenários'!C1 -> Cenário 02: Pesquisa TI - Corte por Santa Catarina | AZ1: ="% Distância da "&'Painel Geral'!B5 -> % Distância da Mediana | BA1: Posicionamento
A3: Cod. | B3: Cargos Empresa | C3: Cargos Padronizados | D3: Média Empresa | E3: Cod. Área | F3: Área | G3: Nível Organizacional | H3: Cod. Pesquisa | I3: Cargos Pesquisa | J3: Senioridade | K3: Código+Senioridade | L3: Qtd de Colab | M3: Menor Salário | N3: 1º Quartil | O3: Média | P3: Grade | Q3: Mediana | AP3: 3º Quartil | AQ3: Maior Salário | AR3: C-01 | AS3: C-01 (Posicionamento) | AT3: Menor Salário | AU3: 1º Quartil | AV3: Média | AW3: Mediana | AX3: 3º Quartil | AY3: Maior Salário | AZ3: C-02 | BA3: C-02 (Posicionamento)
A4: 1 | B4: =VLOOKUP(A4,Jobmatch!A:F,2,0) -> Engenheiro de Software Full Stack Jr | C4: Técnico Infraestrutura | F4: DEV | H4: 69 | I4: Assistente de Infraestrutura de TI | J4: Indiferente | K4: =H4&J4 -> 69Indiferente | M4: =IFERROR(VLOOKUP(K4,'C-01'!$D:$L,4,0),"") -> 1782.06 | N4: =IFERROR(VLOOKUP(K4,'C-01'!$D:$L,5,0),"") -> 2143.44 | O4: =IFERROR(VLOOKUP(K4,'C-01'!$D:$L,6,0),"") -> 2238.54 | P4: 10 | Q4: 2220.51 | R4: =Q4*1.2 -> 2664.612 | AP4: =IFERROR(VLOOKUP(K4,'C-01'!$D:$L,8,0),"") -> 2220.51 | AQ4: =IFERROR(VLOOKUP(K4,'C-01'!$D:$L,9,0),"") -> 2726.11 | AR4: =IFS('Painel Geral'!$B$5="Mediana",IFERROR(IF(OR(D4="",Q4=0,Q4=""),"",($D4/$Q4)),""),'Painel Geral'!$B$5="Menor Salário",IFERROR(IF(OR(D4="",Q4=0,Q4=""),"",($D4/$M4)),""),'Painel Geral'!$B$5="1º Quartil",IFERROR(IF(OR(D4="",Q4=0,Q4=""),"",($D4/$N4)),""), 'Painel Geral'!$B$5="Média",IFERROR(IF(OR(D4="",Q4=0,Q4=""),"",($D4/$O4)),""),'Painel Geral'!$B$5="3º Quartil",IFERROR(IF(OR(D4="",Q4=0,Q4=""),"",($D4/$AP4)),""),'Painel Geral'!$B$5="Maior Salário",IFERROR(IF(OR(D4="",Q4=0,Q4=""),"",($D4/$AQ4)),"")) | AS4: =IFS(OR(M4="",M4=0,D4="", D4=0),"",AR4<=80%,"Muito Defasado",AR4<=90%,"Defasado",AR4<=100%,"Na Média",AR4<=110%,"Competitivo",AR4<=120%,"Muito Competitivo",AR4>120%,"Agressivo") | AT4: =IFERROR(VLOOKUP($K4,'C-02'!$D:$L,4,0),"") | AU4: =IFERROR(VLOOKUP($K4,'C-02'!$D:$L,5,0),"") | AV4: =IFERROR(VLOOKUP($K4,'C-02'!$D:$L,6,0),"") | AW4: =IFERROR(VLOOKUP($K4,'C-02'!$D:$L,7,0),"") | AX4: =IFERROR(VLOOKUP($K4,'C-02'!$D:$L,8,0),"") | AY4: =IFERROR(VLOOKUP($K4,'C-02'!$D:$L,9,0),"") | AZ4: =IFS('Painel Geral'!$B$5="Mediana",IFERROR(IF(OR(D4="",AW4=0,AW4=""),"",($D4/$AW4)),""),'Painel Geral'!$B$5="Menor Salário",IFERROR(IF(OR(D4="",AW4=0,AW4=""),"",($D4/$AT4)),""),'Painel Geral'!$B$5="1º Quartil",IFERROR(IF(OR(D4="",AW4=0,AW4=""),"",($D4/$AU4)),""),'Painel Geral'!$B$5="Média",IFERROR(IF(OR(D4="",AW4=0,AW4=""),"",($D4/$AV4)),""),'Painel Geral'!$B$5="3º Quartil",IFERROR(IF(OR(D4="",AW4=0,AW4=""),"",($D4/$AX4)),""), 'Painel Geral'!$B$5="Maior Salário",IFERROR(IF(OR(D4="",AW4=0,AW4=""),"",($D4/$AY4)),"")) | BA4: =IFS(OR(AT4="",AT4=0,D4="", D4=0),"",AZ4<=80%,"Muito Defasado",AZ4<=90%,"Defasado",AZ4<=100%,"Na Média",AZ4<=110%,"Competitivo",AZ4<=120%,"Muito Competitivo",AZ4>120%,"Agressivo")
A5: 2 | B5: =VLOOKUP(A5,Jobmatch!A:F,2,0) -> Engenheiro de Software Full Stack Pl | C5: Analista Infraestrutura Jr | F5: DEV | H5: 15 | I5: Analista de Infraestrutura de TI | J5: Júnior | K5: =H5&J5 -> 15Júnior | M5: =IFERROR(VLOOKUP(K5,'C-01'!$D:$L,4,0),"") -> 2093.28 | N5: =IFERROR(VLOOKUP(K5,'C-01'!$D:$L,5,0),"") -> 2289.58 | O5: =IFERROR(VLOOKUP(K5,'C-01'!$D:$L,6,0),"") -> 2653.62 | P5: 11 | Q5: 2644.46 | R5: =Q5*1.2 -> 3173.352 | AP5: =IFERROR(VLOOKUP(K5,'C-01'!$D:$L,8,0),"") -> 2908.53 | AQ5: =IFERROR(VLOOKUP(K5,'C-01'!$D:$L,9,0),"") -> 3400.19 | AR5: =IFS('Painel Geral'!$B$5="Mediana",IFERROR(IF(OR(D5="",Q5=0,Q5=""),"",($D5/$Q5)),""),'Painel Geral'!$B$5="Menor Salário",IFERROR(IF(OR(D5="",Q5=0,Q5=""),"",($D5/$M5)),""),'Painel Geral'!$B$5="1º Quartil",IFERROR(IF(OR(D5="",Q5=0,Q5=""),"",($D5/$N5)),""), 'Painel Geral'!$B$5="Média",IFERROR(IF(OR(D5="",Q5=0,Q5=""),"",($D5/$O5)),""),'Painel Geral'!$B$5="3º Quartil",IFERROR(IF(OR(D5="",Q5=0,Q5=""),"",($D5/$AP5)),""),'Painel Geral'!$B$5="Maior Salário",IFERROR(IF(OR(D5="",Q5=0,Q5=""),"",($D5/$AQ5)),"")) | AS5: =IFS(OR(M5="",M5=0,D5="", D5=0),"",AR5<=80%,"Muito Defasado",AR5<=90%,"Defasado",AR5<=100%,"Na Média",AR5<=110%,"Competitivo",AR5<=120%,"Muito Competitivo",AR5>120%,"Agressivo") | AT5: =IFERROR(VLOOKUP($K5,'C-02'!$D:$L,4,0),"") | AU5: =IFERROR(VLOOKUP($K5,'C-02'!$D:$L,5,0),"") | AV5: =IFERROR(VLOOKUP($K5,'C-02'!$D:$L,6,0),"") | AW5: =IFERROR(VLOOKUP($K5,'C-02'!$D:$L,7,0),"") | AX5: =IFERROR(VLOOKUP($K5,'C-02'!$D:$L,8,0),"") | AY5: =IFERROR(VLOOKUP($K5,'C-02'!$D:$L,9,0),"") | AZ5: =IFS('Painel Geral'!$B$5="Mediana",IFERROR(IF(OR(D5="",AW5=0,AW5=""),"",($D5/$AW5)),""),'Painel Geral'!$B$5="Menor Salário",IFERROR(IF(OR(D5="",AW5=0,AW5=""),"",($D5/$AT5)),""),'Painel Geral'!$B$5="1º Quartil",IFERROR(IF(OR(D5="",AW5=0,AW5=""),"",($D5/$AU5)),""),'Painel Geral'!$B$5="Média",IFERROR(IF(OR(D5="",AW5=0,AW5=""),"",($D5/$AV5)),""),'Painel Geral'!$B$5="3º Quartil",IFERROR(IF(OR(D5="",AW5=0,AW5=""),"",($D5/$AX5)),""), 'Painel Geral'!$B$5="Maior Salário",IFERROR(IF(OR(D5="",AW5=0,AW5=""),"",($D5/$AY5)),"")) | BA5: =IFS(OR(AT5="",AT5=0,D5="", D5=0),"",AZ5<=80%,"Muito Defasado",AZ5<=90%,"Defasado",AZ5<=100%,"Na Média",AZ5<=110%,"Competitivo",AZ5<=120%,"Muito Competitivo",AZ5>120%,"Agressivo")
A6: 3 | B6: =VLOOKUP(A6,Jobmatch!A:F,2,0) -> Engenheiro de Software Full Stack Sr | C6: Desenvolvedor Jr | D6: =IFERROR(AVERAGEIF('Folha de Pagamento'!A:A,A6,'Folha de Pagamento'!I:I),"") -> 6458.4 | E6: 1 | F6: =VLOOKUP(A6,Jobmatch!A:G,3,0) -> DEV | G6: =VLOOKUP(A6,Jobmatch!A:H,4,0) -> Tático | H6: =VLOOKUP(A6,Jobmatch!A:H,5,0) -> 1 | I6: =VLOOKUP(A6,Jobmatch!A:H,6,0) -> Desenvolvedor | J6: =VLOOKUP(A6,Jobmatch!A:H,7,0) -> Sênior | K6: =H6&J6 -> 1Sênior | L6: =COUNTIF('Folha de Pagamento'!A:A,A6) -> 2 | M6: =IFERROR(VLOOKUP(K6,'C-01'!$D:$L,4,0),"") -> 5873.21 | N6: =IFERROR(VLOOKUP(K6,'C-01'!$D:$L,5,0),"") -> 7005.56 | O6: =IFERROR(VLOOKUP(K6,'C-01'!$D:$L,6,0),"") -> 8047.78 | P6: 12 | Q6: 3379.04 | R6: =Q6*1.2 -> 4054.848 | AP6: =IFERROR(VLOOKUP(K6,'C-01'!$D:$L,8,0),"") -> 9271.4 | AQ6: =IFERROR(VLOOKUP(K6,'C-01'!$D:$L,9,0),"") -> 10095.14 | AR6: =IFS('Painel Geral'!$B$5="Mediana",IFERROR(IF(OR(D6="",Q6=0,Q6=""),"",($D6/$Q6)),""),'Painel Geral'!$B$5="Menor Salário",IFERROR(IF(OR(D6="",Q6=0,Q6=""),"",($D6/$M6)),""),'Painel Geral'!$B$5="1º Quartil",IFERROR(IF(OR(D6="",Q6=0,Q6=""),"",($D6/$N6)),""), 'Painel Geral'!$B$5="Média",IFERROR(IF(OR(D6="",Q6=0,Q6=""),"",($D6/$O6)),""),'Painel Geral'!$B$5="3º Quartil",IFERROR(IF(OR(D6="",Q6=0,Q6=""),"",($D6/$AP6)),""),'Painel Geral'!$B$5="Maior Salário",IFERROR(IF(OR(D6="",Q6=0,Q6=""),"",($D6/$AQ6)),"")) -> 1.9113121 | AS6: =IFS(OR(M6="",M6=0,D6="", D6=0),"",AR6<=80%,"Muito Defasado",AR6<=90%,"Defasado",AR6<=100%,"Na Média",AR6<=110%,"Competitivo",AR6<=120%,"Muito Competitivo",AR6>120%,"Agressivo") -> Agressivo | AT6: =IFERROR(VLOOKUP($K6,'C-02'!$D:$L,4,0),"") -> 5928.64 | AU6: =IFERROR(VLOOKUP($K6,'C-02'!$D:$L,5,0),"") -> 6791.87 | AV6: =IFERROR(VLOOKUP($K6,'C-02'!$D:$L,6,0),"") -> 7984.54 | AW6: =IFERROR(VLOOKUP($K6,'C-02'!$D:$L,7,0),"") -> 7851.14 | AX6: =IFERROR(VLOOKUP($K6,'C-02'!$D:$L,8,0),"") -> 9534.06 | AY6: =IFERROR(VLOOKUP($K6,'C-02'!$D:$L,9,0),"") -> 9921.51 | AZ6: =IFS('Painel Geral'!$B$5="Mediana",IFERROR(IF(OR(D6="",AW6=0,AW6=""),"",($D6/$AW6)),""),'Painel Geral'!$B$5="Menor Salário",IFERROR(IF(OR(D6="",AW6=0,AW6=""),"",($D6/$AT6)),""),'Painel Geral'!$B$5="1º Quartil",IFERROR(IF(OR(D6="",AW6=0,AW6=""),"",($D6/$AU6)),""),'Painel Geral'!$B$5="Média",IFERROR(IF(OR(D6="",AW6=0,AW6=""),"",($D6/$AV6)),""),'Painel Geral'!$B$5="3º Quartil",IFERROR(IF(OR(D6="",AW6=0,AW6=""),"",($D6/$AX6)),""), 'Painel Geral'!$B$5="Maior Salário",IFERROR(IF(OR(D6="",AW6=0,AW6=""),"",($D6/$AY6)),"")) -> 0.82260665 | BA6: =IFS(OR(AT6="",AT6=0,D6="", D6=0),"",AZ6<=80%,"Muito Defasado",AZ6<=90%,"Defasado",AZ6<=100%,"Na Média",AZ6<=110%,"Competitivo",AZ6<=120%,"Muito Competitivo",AZ6>120%,"Agressivo") -> Defasado
A7: 4 | B7: =VLOOKUP(A7,Jobmatch!A:F,2,0) -> Analista de Requisitos | C7: Analista Requisitos Jr | D7: =IFERROR(AVERAGEIF('Folha de Pagamento'!A:A,A7,'Folha de Pagamento'!I:I),"") -> 2859.19 | E7: 1 | F7: =VLOOKUP(A7,Jobmatch!A:G,3,0) -> DEV | G7: =VLOOKUP(A7,Jobmatch!A:H,4,0) -> Operacional | H7: =VLOOKUP(A7,Jobmatch!A:H,5,0) -> 796 | I7: =VLOOKUP(A7,Jobmatch!A:H,6,0) -> Analista de Requisitos | J7: =VLOOKUP(A7,Jobmatch!A:H,7,0) -> Júnior | K7: =H7&J7 -> 796Júnior | L7: =COUNTIF('Folha de Pagamento'!A:A,A7) -> 2 | M7: =IFERROR(VLOOKUP(K7,'C-01'!$D:$L,4,0),"") -> 2626.68 | N7: =IFERROR(VLOOKUP(K7,'C-01'!$D:$L,5,0),"") -> 3508.61 | O7: =IFERROR(VLOOKUP(K7,'C-01'!$D:$L,6,0),"") -> 4174.12 | P7: 13 | Q7: 3618.72 | R7: =Q7*1.2 -> 4342.464 | AC7: Pisos | AD7: Base: 1º de Julho de 2024 | AF7: Com INPC | AP7: =IFERROR(VLOOKUP(K7,'C-01'!$D:$L,8,0),"") -> 5081.15 | AQ7: =IFERROR(VLOOKUP(K7,'C-01'!$D:$L,9,0),"") -> 5977.75 | AR7: =IFS('Painel Geral'!$B$5="Mediana",IFERROR(IF(OR(D7="",Q7=0,Q7=""),"",($D7/$Q7)),""),'Painel Geral'!$B$5="Menor Salário",IFERROR(IF(OR(D7="",Q7=0,Q7=""),"",($D7/$M7)),""),'Painel Geral'!$B$5="1º Quartil",IFERROR(IF(OR(D7="",Q7=0,Q7=""),"",($D7/$N7)),""), 'Painel Geral'!$B$5="Média",IFERROR(IF(OR(D7="",Q7=0,Q7=""),"",($D7/$O7)),""),'Painel Geral'!$B$5="3º Quartil",IFERROR(IF(OR(D7="",Q7=0,Q7=""),"",($D7/$AP7)),""),'Painel Geral'!$B$5="Maior Salário",IFERROR(IF(OR(D7="",Q7=0,Q7=""),"",($D7/$AQ7)),"")) -> 0.79011087 | AS7: =IFS(OR(M7="",M7=0,D7="", D7=0),"",AR7<=80%,"Muito Defasado",AR7<=90%,"Defasado",AR7<=100%,"Na Média",AR7<=110%,"Competitivo",AR7<=120%,"Muito Competitivo",AR7>120%,"Agressivo") -> Muito Defasado | AT7: =IFERROR(VLOOKUP($K7,'C-02'!$D:$L,4,0),"") -> 0 | AU7: =IFERROR(VLOOKUP($K7,'C-02'!$D:$L,5,0),"") -> 0 | AV7: =IFERROR(VLOOKUP($K7,'C-02'!$D:$L,6,0),"") -> 0 | AW7: =IFERROR(VLOOKUP($K7,'C-02'!$D:$L,7,0),"") -> 0 | AX7: =IFERROR(VLOOKUP($K7,'C-02'!$D:$L,8,0),"") -> 0 | AY7: =IFERROR(VLOOKUP($K7,'C-02'!$D:$L,9,0),"") -> 0 | AZ7: =IFS('Painel Geral'!$B$5="Mediana",IFERROR(IF(OR(D7="",AW7=0,AW7=""),"",($D7/$AW7)),""),'Painel Geral'!$B$5="Menor Salário",IFERROR(IF(OR(D7="",AW7=0,AW7=""),"",($D7/$AT7)),""),'Painel Geral'!$B$5="1º Quartil",IFERROR(IF(OR(D7="",AW7=0,AW7=""),"",($D7/$AU7)),""),'Painel Geral'!$B$5="Média",IFERROR(IF(OR(D7="",AW7=0,AW7=""),"",($D7/$AV7)),""),'Painel Geral'!$B$5="3º Quartil",IFERROR(IF(OR(D7="",AW7=0,AW7=""),"",($D7/$AX7)),""), 'Painel Geral'!$B$5="Maior Salário",IFERROR(IF(OR(D7="",AW7=0,AW7=""),"",($D7/$AY7)),"")) | BA7: =IFS(OR(AT7="",AT7=0,D7="", D7=0),"",AZ7<=80%,"Muito Defasado",AZ7<=90%,"Defasado",AZ7<=100%,"Na Média",AZ7<=110%,"Competitivo",AZ7<=120%,"Muito Competitivo",AZ7>120%,"Agressivo")
C8: Analista Infraestrutura Pl | F8: DEV | H8: 15 | I8: Analista de Infraestrutura de TI | J8: Pleno | K8: =H8&J8 -> 15Pleno | M8: =IFERROR(VLOOKUP(K8,'C-01'!$D:$L,4,0),"") -> 3247.23 | N8: =IFERROR(VLOOKUP(K8,'C-01'!$D:$L,5,0),"") -> 3753.88 | O8: =IFERROR(VLOOKUP(K8,'C-01'!$D:$L,6,0),"") -> 4254.3 | P8: 13 | Q8: 4178.94 | R8: =Q8*1.2 -> 5014.728 | AA8: (menor com + amplitude) | AC8: Atividade Meio | AD8: 1599.66 | AF8: =AD8*1.0518 -> 1682.5224 | AP8: =IFERROR(VLOOKUP(K8,'C-01'!$D:$L,8,0),"") -> 4856.44 | AQ8: =IFERROR(VLOOKUP(K8,'C-01'!$D:$L,9,0),"") -> 5596.75 | AR8: =IFS('Painel Geral'!$B$5="Mediana",IFERROR(IF(OR(D8="",Q8=0,Q8=""),"",($D8/$Q8)),""),'Painel Geral'!$B$5="Menor Salário",IFERROR(IF(OR(D8="",Q8=0,Q8=""),"",($D8/$M8)),""),'Painel Geral'!$B$5="1º Quartil",IFERROR(IF(OR(D8="",Q8=0,Q8=""),"",($D8/$N8)),""), 'Painel Geral'!$B$5="Média",IFERROR(IF(OR(D8="",Q8=0,Q8=""),"",($D8/$O8)),""),'Painel Geral'!$B$5="3º Quartil",IFERROR(IF(OR(D8="",Q8=0,Q8=""),"",($D8/$AP8)),""),'Painel Geral'!$B$5="Maior Salário",IFERROR(IF(OR(D8="",Q8=0,Q8=""),"",($D8/$AQ8)),"")) | AS8: =IFS(OR(M8="",M8=0,D8="", D8=0),"",AR8<=80%,"Muito Defasado",AR8<=90%,"Defasado",AR8<=100%,"Na Média",AR8<=110%,"Competitivo",AR8<=120%,"Muito Competitivo",AR8>120%,"Agressivo") | AT8: =IFERROR(VLOOKUP($K8,'C-02'!$D:$L,4,0),"") | AU8: =IFERROR(VLOOKUP($K8,'C-02'!$D:$L,5,0),"") | AV8: =IFERROR(VLOOKUP($K8,'C-02'!$D:$L,6,0),"") | AW8: =IFERROR(VLOOKUP($K8,'C-02'!$D:$L,7,0),"") | AX8: =IFERROR(VLOOKUP($K8,'C-02'!$D:$L,8,0),"") | AY8: =IFERROR(VLOOKUP($K8,'C-02'!$D:$L,9,0),"") | AZ8: =IFS('Painel Geral'!$B$5="Mediana",IFERROR(IF(OR(D8="",AW8=0,AW8=""),"",($D8/$AW8)),""),'Painel Geral'!$B$5="Menor Salário",IFERROR(IF(OR(D8="",AW8=0,AW8=""),"",($D8/$AT8)),""),'Painel Geral'!$B$5="1º Quartil",IFERROR(IF(OR(D8="",AW8=0,AW8=""),"",($D8/$AU8)),""),'Painel Geral'!$B$5="Média",IFERROR(IF(OR(D8="",AW8=0,AW8=""),"",($D8/$AV8)),""),'Painel Geral'!$B$5="3º Quartil",IFERROR(IF(OR(D8="",AW8=0,AW8=""),"",($D8/$AX8)),""), 'Painel Geral'!$B$5="Maior Salário",IFERROR(IF(OR(D8="",AW8=0,AW8=""),"",($D8/$AY8)),"")) | BA8: =IFS(OR(AT8="",AT8=0,D8="", D8=0),"",AZ8<=80%,"Muito Defasado",AZ8<=90%,"Defasado",AZ8<=100%,"Na Média",AZ8<=110%,"Competitivo",AZ8<=120%,"Muito Competitivo",AZ8>120%,"Agressivo")
C9: Analista Requisitos Pl | F9: DEV | H9: 796 | I9: Analista de Requisitos | J9: Pleno | K9: =H9&J9 -> 796Pleno | M9: =IFERROR(VLOOKUP(K9,'C-01'!$D:$L,4,0),"") -> 3810.77 | N9: =IFERROR(VLOOKUP(K9,'C-01'!$D:$L,5,0),"") -> 4192.12 | O9: =IFERROR(VLOOKUP(K9,'C-01'!$D:$L,6,0),"") -> 4717.97 | P9: 14 | Q9: 4465.27 | R9: =Q9*1.2 -> 5358.324 | AA9: (menor) | AC9: Digitadores e Auxiliares de Processamento de Dados | AD9: 1563.26 | AF9: =AD9*1.0518 -> 1644.2369 | AP9: =IFERROR(VLOOKUP(K9,'C-01'!$D:$L,8,0),"") -> 5273.23 | AQ9: =IFERROR(VLOOKUP(K9,'C-01'!$D:$L,9,0),"") -> 6105.55 | AR9: =IFS('Painel Geral'!$B$5="Mediana",IFERROR(IF(OR(D9="",Q9=0,Q9=""),"",($D9/$Q9)),""),'Painel Geral'!$B$5="Menor Salário",IFERROR(IF(OR(D9="",Q9=0,Q9=""),"",($D9/$M9)),""),'Painel Geral'!$B$5="1º Quartil",IFERROR(IF(OR(D9="",Q9=0,Q9=""),"",($D9/$N9)),""), 'Painel Geral'!$B$5="Média",IFERROR(IF(OR(D9="",Q9=0,Q9=""),"",($D9/$O9)),""),'Painel Geral'!$B$5="3º Quartil",IFERROR(IF(OR(D9="",Q9=0,Q9=""),"",($D9/$AP9)),""),'Painel Geral'!$B$5="Maior Salário",IFERROR(IF(OR(D9="",Q9=0,Q9=""),"",($D9/$AQ9)),"")) | AS9: =IFS(OR(M9="",M9=0,D9="", D9=0),"",AR9<=80%,"Muito Defasado",AR9<=90%,"Defasado",AR9<=100%,"Na Média",AR9<=110%,"Competitivo",AR9<=120%,"Muito Competitivo",AR9>120%,"Agressivo") | AT9: =IFERROR(VLOOKUP($K9,'C-02'!$D:$L,4,0),"") -> 0 | AU9: =IFERROR(VLOOKUP($K9,'C-02'!$D:$L,5,0),"") -> 0 | AV9: =IFERROR(VLOOKUP($K9,'C-02'!$D:$L,6,0),"") -> 0 | AW9: =IFERROR(VLOOKUP($K9,'C-02'!$D:$L,7,0),"") -> 0 | AX9: =IFERROR(VLOOKUP($K9,'C-02'!$D:$L,8,0),"") -> 0 | AY9: =IFERROR(VLOOKUP($K9,'C-02'!$D:$L,9,0),"") -> 0 | AZ9: =IFS('Painel Geral'!$B$5="Mediana",IFERROR(IF(OR(D9="",AW9=0,AW9=""),"",($D9/$AW9)),""),'Painel Geral'!$B$5="Menor Salário",IFERROR(IF(OR(D9="",AW9=0,AW9=""),"",($D9/$AT9)),""),'Painel Geral'!$B$5="1º Quartil",IFERROR(IF(OR(D9="",AW9=0,AW9=""),"",($D9/$AU9)),""),'Painel Geral'!$B$5="Média",IFERROR(IF(OR(D9="",AW9=0,AW9=""),"",($D9/$AV9)),""),'Painel Geral'!$B$5="3º Quartil",IFERROR(IF(OR(D9="",AW9=0,AW9=""),"",($D9/$AX9)),""), 'Painel Geral'!$B$5="Maior Salário",IFERROR(IF(OR(D9="",AW9=0,AW9=""),"",($D9/$AY9)),"")) | BA9: =IFS(OR(AT9="",AT9=0,D9="", D9=0),"",AZ9<=80%,"Muito Defasado",AZ9<=90%,"Defasado",AZ9<=100%,"Na Média",AZ9<=110%,"Competitivo",AZ9<=120%,"Muito Competitivo",AZ9>120%,"Agressivo")
A10: 5 | B10: =VLOOKUP(A10,Jobmatch!A:F,2,0) -> Lider | C10: Desenvolvedor Pl | D10: =IFERROR(AVERAGEIF('Folha de Pagamento'!A:A,A10,'Folha de Pagamento'!I:I),"") -> 8611.2 | E10: 1 | F10: =VLOOKUP(A10,Jobmatch!A:G,3,0) -> DEV | G10: =VLOOKUP(A10,Jobmatch!A:H,4,0) -> Estratégico | H10: =VLOOKUP(A10,Jobmatch!A:H,5,0) -> 1016 | I10: =VLOOKUP(A10,Jobmatch!A:H,6,0) -> Líder Técnico | J10: =VLOOKUP(A10,Jobmatch!A:H,7,0) -> Indiferente | K10: =H10&J10 -> 1016Indiferente | L10: =COUNTIF('Folha de Pagamento'!A:A,A10) -> 1 | M10: =IFERROR(VLOOKUP(K10,'C-01'!$D:$L,4,0),"") -> 5639.53 | N10: =IFERROR(VLOOKUP(K10,'C-01'!$D:$L,5,0),"") -> 7452.03 | O10: =IFERROR(VLOOKUP(K10,'C-01'!$D:$L,6,0),"") -> 8919.44 | P10: 14 | Q10: 5342.35 | R10: =Q10*1.2 -> 6410.82 | AC10: Técnico Profissional de Informática | AD10: 1741.84 | AF10: =AD10*1.0518 -> 1832.0673 | AP10: =IFERROR(VLOOKUP(K10,'C-01'!$D:$L,8,0),"") -> 10057.47 | AQ10: =IFERROR(VLOOKUP(K10,'C-01'!$D:$L,9,0),"") -> 12817.68 | AR10: =IFS('Painel Geral'!$B$5="Mediana",IFERROR(IF(OR(D10="",Q10=0,Q10=""),"",($D10/$Q10)),""),'Painel Geral'!$B$5="Menor Salário",IFERROR(IF(OR(D10="",Q10=0,Q10=""),"",($D10/$M10)),""),'Painel Geral'!$B$5="1º Quartil",IFERROR(IF(OR(D10="",Q10=0,Q10=""),"",($D10/$N10)),""), 'Painel Geral'!$B$5="Média",IFERROR(IF(OR(D10="",Q10=0,Q10=""),"",($D10/$O10)),""),'Painel Geral'!$B$5="3º Quartil",IFERROR(IF(OR(D10="",Q10=0,Q10=""),"",($D10/$AP10)),""),'Painel Geral'!$B$5="Maior Salário",IFERROR(IF(OR(D10="",Q10=0,Q10=""),"",($D10/$AQ10)),"")) -> 1.6118749 | AS10: =IFS(OR(M10="",M10=0,D10="", D10=0),"",AR10<=80%,"Muito Defasado",AR10<=90%,"Defasado",AR10<=100%,"Na Média",AR10<=110%,"Competitivo",AR10<=120%,"Muito Competitivo",AR10>120%,"Agressivo") -> Agressivo | AT10: =IFERROR(VLOOKUP($K10,'C-02'!$D:$L,4,0),"") -> 5288.93 | AU10: =IFERROR(VLOOKUP($K10,'C-02'!$D:$L,5,0),"") -> 7107.92 | AV10: =IFERROR(VLOOKUP($K10,'C-02'!$D:$L,6,0),"") -> 8904.46 | AW10: =IFERROR(VLOOKUP($K10,'C-02'!$D:$L,7,0),"") -> 9047.66 | AX10: =IFERROR(VLOOKUP($K10,'C-02'!$D:$L,8,0),"") -> 10074.15 | AY10: =IFERROR(VLOOKUP($K10,'C-02'!$D:$L,9,0),"") -> 12817.68 | AZ10: =IFS('Painel Geral'!$B$5="Mediana",IFERROR(IF(OR(D10="",AW10=0,AW10=""),"",($D10/$AW10)),""),'Painel Geral'!$B$5="Menor Salário",IFERROR(IF(OR(D10="",AW10=0,AW10=""),"",($D10/$AT10)),""),'Painel Geral'!$B$5="1º Quartil",IFERROR(IF(OR(D10="",AW10=0,AW10=""),"",($D10/$AU10)),""),'Painel Geral'!$B$5="Média",IFERROR(IF(OR(D10="",AW10=0,AW10=""),"",($D10/$AV10)),""),'Painel Geral'!$B$5="3º Quartil",IFERROR(IF(OR(D10="",AW10=0,AW10=""),"",($D10/$AX10)),""), 'Painel Geral'!$B$5="Maior Salário",IFERROR(IF(OR(D10="",AW10=0,AW10=""),"",($D10/$AY10)),"")) -> 0.9517599 | BA10: =IFS(OR(AT10="",AT10=0,D10="", D10=0),"",AZ10<=80%,"Muito Defasado",AZ10<=90%,"Defasado",AZ10<=100%,"Na Média",AZ10<=110%,"Competitivo",AZ10<=120%,"Muito Competitivo",AZ10>120%,"Agressivo") -> Na Média
C11: Analista Infraestrutura Sr | F11: DEV | H11: 15 | I11: Analista de Infraestrutura de TI | J11: Sênior | K11: =H11&J11 -> 15Sênior | M11: =IFERROR(VLOOKUP(K11,'C-01'!$D:$L,4,0),"") -> 4663.49 | N11: =IFERROR(VLOOKUP(K11,'C-01'!$D:$L,5,0),"") -> 5285.89 | O11: =IFERROR(VLOOKUP(K11,'C-01'!$D:$L,6,0),"") -> 5775.86 | P11: 15 | Q11: 5574.65 | R11: =Q11*1.2 -> 6689.58 | AC11: Conferentes | AD11: 1919.58 | AF11: =AD11*1.0518 -> 2019.0142 | AP11: =IFERROR(VLOOKUP(K11,'C-01'!$D:$L,8,0),"") -> 6292.99 | AQ11: =IFERROR(VLOOKUP(K11,'C-01'!$D:$L,9,0),"") -> 7288.6 | AR11: =IFS('Painel Geral'!$B$5="Mediana",IFERROR(IF(OR(D11="",Q11=0,Q11=""),"",($D11/$Q11)),""),'Painel Geral'!$B$5="Menor Salário",IFERROR(IF(OR(D11="",Q11=0,Q11=""),"",($D11/$M11)),""),'Painel Geral'!$B$5="1º Quartil",IFERROR(IF(OR(D11="",Q11=0,Q11=""),"",($D11/$N11)),""), 'Painel Geral'!$B$5="Média",IFERROR(IF(OR(D11="",Q11=0,Q11=""),"",($D11/$O11)),""),'Painel Geral'!$B$5="3º Quartil",IFERROR(IF(OR(D11="",Q11=0,Q11=""),"",($D11/$AP11)),""),'Painel Geral'!$B$5="Maior Salário",IFERROR(IF(OR(D11="",Q11=0,Q11=""),"",($D11/$AQ11)),"")) | AS11: =IFS(OR(M11="",M11=0,D11="", D11=0),"",AR11<=80%,"Muito Defasado",AR11<=90%,"Defasado",AR11<=100%,"Na Média",AR11<=110%,"Competitivo",AR11<=120%,"Muito Competitivo",AR11>120%,"Agressivo") | AT11: =IFERROR(VLOOKUP($K11,'C-02'!$D:$L,4,0),"") | AU11: =IFERROR(VLOOKUP($K11,'C-02'!$D:$L,5,0),"") | AV11: =IFERROR(VLOOKUP($K11,'C-02'!$D:$L,6,0),"") | AW11: =IFERROR(VLOOKUP($K11,'C-02'!$D:$L,7,0),"") | AX11: =IFERROR(VLOOKUP($K11,'C-02'!$D:$L,8,0),"") | AY11: =IFERROR(VLOOKUP($K11,'C-02'!$D:$L,9,0),"") | AZ11: =IFS('Painel Geral'!$B$5="Mediana",IFERROR(IF(OR(D11="",AW11=0,AW11=""),"",($D11/$AW11)),""),'Painel Geral'!$B$5="Menor Salário",IFERROR(IF(OR(D11="",AW11=0,AW11=""),"",($D11/$AT11)),""),'Painel Geral'!$B$5="1º Quartil",IFERROR(IF(OR(D11="",AW11=0,AW11=""),"",($D11/$AU11)),""),'Painel Geral'!$B$5="Média",IFERROR(IF(OR(D11="",AW11=0,AW11=""),"",($D11/$AV11)),""),'Painel Geral'!$B$5="3º Quartil",IFERROR(IF(OR(D11="",AW11=0,AW11=""),"",($D11/$AX11)),""), 'Painel Geral'!$B$5="Maior Salário",IFERROR(IF(OR(D11="",AW11=0,AW11=""),"",($D11/$AY11)),"")) | BA11: =IFS(OR(AT11="",AT11=0,D11="", D11=0),"",AZ11<=80%,"Muito Defasado",AZ11<=90%,"Defasado",AZ11<=100%,"Na Média",AZ11<=110%,"Competitivo",AZ11<=120%,"Muito Competitivo",AZ11>120%,"Agressivo")
C12: Analista Requisitos Sr | F12: DEV | H12: 796 | I12: Analista de Requisitos | J12: Sênior | K12: =H12&J12 -> 796Sênior | M12: =IFERROR(VLOOKUP(K12,'C-01'!$D:$L,4,0),"") -> 6472.04 | N12: =IFERROR(VLOOKUP(K12,'C-01'!$D:$L,5,0),"") -> 7185.89 | O12: =IFERROR(VLOOKUP(K12,'C-01'!$D:$L,6,0),"") -> 7572.48 | P12: 16 | Q12: 7264.21 | R12: =Q12*1.2 -> 8717.052 | AC12: Programadores | AD12: 2132.87 | AF12: =AD12*1.0518 -> 2243.3527 | AP12: =IFERROR(VLOOKUP(K12,'C-01'!$D:$L,8,0),"") -> 8100.12 | AQ12: =IFERROR(VLOOKUP(K12,'C-01'!$D:$L,9,0),"") -> 8614.28 | AR12: =IFS('Painel Geral'!$B$5="Mediana",IFERROR(IF(OR(D12="",Q12=0,Q12=""),"",($D12/$Q12)),""),'Painel Geral'!$B$5="Menor Salário",IFERROR(IF(OR(D12="",Q12=0,Q12=""),"",($D12/$M12)),""),'Painel Geral'!$B$5="1º Quartil",IFERROR(IF(OR(D12="",Q12=0,Q12=""),"",($D12/$N12)),""), 'Painel Geral'!$B$5="Média",IFERROR(IF(OR(D12="",Q12=0,Q12=""),"",($D12/$O12)),""),'Painel Geral'!$B$5="3º Quartil",IFERROR(IF(OR(D12="",Q12=0,Q12=""),"",($D12/$AP12)),""),'Painel Geral'!$B$5="Maior Salário",IFERROR(IF(OR(D12="",Q12=0,Q12=""),"",($D12/$AQ12)),"")) | AS12: =IFS(OR(M12="",M12=0,D12="", D12=0),"",AR12<=80%,"Muito Defasado",AR12<=90%,"Defasado",AR12<=100%,"Na Média",AR12<=110%,"Competitivo",AR12<=120%,"Muito Competitivo",AR12>120%,"Agressivo") | AT12: =IFERROR(VLOOKUP($K12,'C-02'!$D:$L,4,0),"") -> 0 | AU12: =IFERROR(VLOOKUP($K12,'C-02'!$D:$L,5,0),"") -> 0 | AV12: =IFERROR(VLOOKUP($K12,'C-02'!$D:$L,6,0),"") -> 0 | AW12: =IFERROR(VLOOKUP($K12,'C-02'!$D:$L,7,0),"") -> 0 | AX12: =IFERROR(VLOOKUP($K12,'C-02'!$D:$L,8,0),"") -> 0 | AY12: =IFERROR(VLOOKUP($K12,'C-02'!$D:$L,9,0),"") -> 0 | AZ12: =IFS('Painel Geral'!$B$5="Mediana",IFERROR(IF(OR(D12="",AW12=0,AW12=""),"",($D12/$AW12)),""),'Painel Geral'!$B$5="Menor Salário",IFERROR(IF(OR(D12="",AW12=0,AW12=""),"",($D12/$AT12)),""),'Painel Geral'!$B$5="1º Quartil",IFERROR(IF(OR(D12="",AW12=0,AW12=""),"",($D12/$AU12)),""),'Painel Geral'!$B$5="Média",IFERROR(IF(OR(D12="",AW12=0,AW12=""),"",($D12/$AV12)),""),'Painel Geral'!$B$5="3º Quartil",IFERROR(IF(OR(D12="",AW12=0,AW12=""),"",($D12/$AX12)),""), 'Painel Geral'!$B$5="Maior Salário",IFERROR(IF(OR(D12="",AW12=0,AW12=""),"",($D12/$AY12)),"")) | BA12: =IFS(OR(AT12="",AT12=0,D12="", D12=0),"",AZ12<=80%,"Muito Defasado",AZ12<=90%,"Defasado",AZ12<=100%,"Na Média",AZ12<=110%,"Competitivo",AZ12<=120%,"Muito Competitivo",AZ12>120%,"Agressivo")
