Workbook

Sheet Folha de Pagamento
B1: Folha de Pagamento | G1: CNPJ da empresa: Referência da Folha de Pagamento: Quantidade de horas mensais usada: Data de Construção:
A3: Cod. | B3: Cod. contrato funcionário | C3: Cargo atual | D3: Novo Cargo | E3: Senioridade | F3: Nível Organizacional | G3: Área | H3: Departamento | I3: Carga Horária | J3: Salários | K3: Tipo de Contratação | L3: CBO | M3: Gênero | N3: Data de Admissão | O3: Unidade | P3: Observações
A4: 1 | B4: 1362 | C4: ALMOXARIFE | E4: Não trabalhamos senioridade | F4: Operacional | G4: Edificação | I4: 220 | J4: 3683 | K4: CLT | L4: 818631 | M4: Masculino | N4: 45871
A5: 1 | B5: 1957 | C5: ALMOXARIFE | E5: Não trabalhamos senioridade | F5: Operacional | G5: Edificação | I5: 220 | J5: 3683 | K5: CLT | L5: 818631 | M5: Feminino | N5: 45870
A6: 2 | B6: 1964 | C6: ANALISTA DE COMPRAS | E6: Não trabalhamos senioridade | F6: Operacional | G6: Suprimentos | I6: 220 | J6: 3780 | K6: CLT | L6: 599850 | M6: Masculino | N6: 45872
A7: 3 | B7: 1910 | C7: ANALISTA DE CRIAÇAO | E7: Não trabalhamos senioridade | F7: Operacional | G7: Marketing | I7: 220 | J7: 5429 | K7: CLT | L7: 1423-35 | M7: Masculino | N7: 45873
A8: 4 | B8: PJ1 | C8: ANALISTA DE INOVAÇÃO | E8: Não trabalhamos senioridade | F8: Tático | G8: Inovação | I8: 220 | J8: =10000/1.37 -> 7299.2701 | K8: PJ | M8: Masculino | N8: 45874
A9: 5 | B9: 1373 | C9: ANALISTA DE MANUTENÇÃO II | E9: Pleno | F9: Operacional | G9: Edificação | I9: 220 | J9: 4550 | K9: CLT | L9: 5143-25 | M9: Masculino | N9: 45875
A10: 6 | B10: 139 | C10: ANALISTA DE MARKETING l | E10: Não trabalhamos senioridade | F10: Operacional | G10: Marketing | I10: 220 | J10: 4025.88 | K10: CLT | L10: 1423-35 | M10: Feminino | N10: 45876
A11: 7 | B11: 1962 | C11: ANALISTA DE PÓS VENDAS II | E11: Pleno | F11: Operacional | G11: Pós Vendas | I11: 220 | J11: 4550 | K11: CLT | L11: 226938 | M11: Masculino | N11: 45877
A12: 8 | B12: 187 | C12: ANALISTA DE URBANISMO | E12: Não trabalhamos senioridade | F12: Operacional | G12: Urbanismo | I12: 220 | J12: 5830 | K12: CLT | L12: 446083 | M12: Feminino | N12: 45878
A13: 9 | B13: 1868 | C13: ANALISTA FINANCEIRO COMERCIAL III | E13: Sênior | F13: Operacional | G13: Financeiro | I13: 220 | J13: 5213 | K13: CLT | L13: 226938 | M13: Feminino | N13: 45879
A14: 10 | B14: 176 | C14: ANALISTA FINANCEIRO DE CAPTAÇÃO DE RECURSOS III | E14: Sênior | F14: Operacional | G14: Financeiro | I14: 220 | J14: 5213 | K14: CLT | L14: 2525-45 | M14: Feminino | N14: 45880
A15: 11 | B15: 1927 | C15: ANALISTA FINANCEIRO I | E15: Júnior | F15: Operacional | G15: Financeiro | I15: 220 | J15: 3993 | K15: CLT | L15: 226938 | M15: Feminino | N15: 45881
A16: 12 | B16: 164 | C16: ASSISTENTE ADM DE LEGALIZAÇÃO III | E16: Sênior | F16: Operacional | G16: Legalização | I16: 220 | J16: 3652 | K16: CLT | L16: 807461 | M16: Feminino | N16: 45882
A17: 13 | B17: 1892 | C17: ASSISTENTE ADMINISTRATIVO lll | E17: Sênior | F17: Operacional | G17: Administrativo | I17: 220 | J17: 3439.7 | K17: CLT | L17: 807461 | M17: Feminino | N17: 45883
A18: 14 | B18: 1940 | C18: ASSISTENTE DE CONTROLADORIA III | E18: Sênior | F18: Operacional | G18: Controladoria | I18: 220 | J18: 3652 | K18: CLT | L18: 807461 | M18: Feminino | N18: 45884
A19: 15 | B19: 1963 | C19: ASSISTENTE DE ENGENHARIA lll | E19: Sênior | F19: Operacional | G19: Edificação | I19: 220 | J19: 3652 | K19: CLT | L19: 446083 | M19: Feminino | N19: 45885
A20: 16 | B20: 190 | C20: ASSISTENTE DE MARKETING | E20: Não trabalhamos senioridade | F20: Operacional | G20: Marketing | I20: 220 | J20: 2919 | K20: CLT | L20: 807461 | M20: Feminino | N20: 45886
A21: 17 | B21: 189 | C21: ASSISTENTE DE RECURSOS HUMANOS | E21: Não trabalhamos senioridade | F21: Operacional | G21: DHO | I21: 220 | J21: 2919 | K21: CLT | L21: 807461 | M21: Feminino | N21: 45887
A22: 18 | B22: 1656 | C22: ASSISTENTE DE TI | E22: Não trabalhamos senioridade | F22: Operacional | G22: Tecnologia da Informação | I22: 220 | J22: 2919 | K22: CLT | L22: 464864 | M22: Masculino | N22: 45888
A23: 19 | B23: 192 | C23: ASSISTENTE FINANCEIRO CONTAS A PAGAR | E23: Não trabalhamos senioridade | F23: Operacional | G23: Financeiro | I23: 220 | J23: 2919 | K23: CLT | L23: 815131 | M23: Masculino | N23: 45889
A24: 19 | B24: 193 | C24: ASSISTENTE FINANCEIRO CONTAS A PAGAR | E24: Não trabalhamos senioridade | F24: Operacional | G24: Financeiro | I24: 220 | J24: 2919 | K24: CLT | L24: 815131 | M24: Masculino | N24: 45890
A25: 19 | B25: 1941 | C25: ASSISTENTE FINANCEIRO CONTAS A PAGAR III | E25: Não trabalhamos senioridade | F25: Operacional | G25: Financeiro | I25: 220 | J25: 3652 | K25: CLT | L25: 815131 | M25: Masculino | N25: 45891
A26: 20 | B26: 1961 | C26: AUXILIAR ADMINISTRATIVO | E26: Não trabalhamos senioridade | F26: Operacional | G26: Administrativo | I26: 220 | J26: 2254 | K26: CLT | L26: 807308 | M26: Feminino | N26: 45892
... A29: 23 | B29: 191 | C29: AUXILIAR DE ENGENHARIA | E29: Não trabalhamos senioridade | F29: Operacional | G29: Urbanismo | I29: 220 | J29: 2560 | K29: CLT | L29: 446083 | M29: Masculino | N29: 45895
A30: 24 | B30: PJ2 | C30: CONTROLER JURÍDICO | E30: Não trabalhamos senioridade | F30: Tático | G30: Administrativo | I30: 220 | J30: =11339/1.37 -> 8276.6423 | K30: PJ | M30: Feminino | N30: 45896
A31: 25 | B31: PJ3 | C31: CONTROLLER GERAL | E31: Não trabalhamos senioridade | F31: Tático | G31: Controladoria | I31: 220 | J31: =16000/1.37 -> 11678.832 | K31: PJ | M31: Feminino | N31: 45897
A32: 26 | B32: PJ4 | C32: CONTROLLER TÉCNICO | E32: Não trabalhamos senioridade | F32: Tático | G32: Controladoria | I32: 220 | J32: =12663.6/1.37 -> 9243.5037 | K32: PJ | M32: Masculino | N32: 45898
A33: 27 | B33: 1959 | C33: COORDENADOR DE DHO | E33: Não trabalhamos senioridade | F33: Tático | G33: DHO | I33: 220 | J33: 7420 | K33: CLT | L33: 1422-05 | M33: Feminino | N33: 45899
A34: 28 | B34: 151 | C34: COORDENADOR DE LEGAIZAÇÃO ll | E34: Pleno | F34: Tático | G34: Legalização | I34: 220 | J34: 8647 | K34: CLT | L34: 840698 | M34: Masculino | N34: 45900
A35: 29 | B35: 1911 | C35: COORDENADOR DE MARKETING II | E35: Pleno | F35: Tático | G35: Marketing | I35: 220 | J35: 8647 | K35: CLT | L35: 1423-15 | M35: Feminino | N35: 45870
A36: 30 | B36: 1452 | C36: COORDENADOR DE OBRAS | E36: Não trabalhamos senioridade | F36: Operacional | G36: Edificação | I36: 220 | J36: 8714 | K36: CLT | L36: 1413-05 | M36: Masculino | N36: 45871
A37: 31 | B37: PJ5 | C37: COORDENADOR DE SUPRIMENTOS | E37: Não trabalhamos senioridade | F37: Tático | G37: Suprimentos | I37: 220 | J37: =16000/1.51 -> 10596.026 | K37: PJ | M37: Feminino | N37: 45872
A38: 32 | B38: PJ6 | C38: COORDENADOR FINANCEIRO | E38: Não trabalhamos senioridade | F38: Tático | G38: Financeiro | I38: 220 | J38: =12000/1.51 -> 7947.0199 | K38: PJ | M38: Masculino | N38: 45873
A39: 33 | B39: PJ7 | C39: DIRETOR | E39: Não trabalhamos senioridade | F39: Estratégico | G39: Comercial | I39: 220 | J39: =58000/1.04 -> 55769.231 | K39: PJ | M39: Masculino | N39: 45874
A40: 34 | B40: 132 | C40: ENCARREGADO DE OBRAS | E40: Não trabalhamos senioridade | F40: Operacional | G40: Urbanismo | I40: 220 | J40: 8461 | K40: CLT | L40: 1900113 | M40: Masculino | N40: 45875
A41: 34 | B41: 182 | C41: ENCARREGADO DE OBRAS | E41: Não trabalhamos senioridade | F41: Operacional | G41: Urbanismo | I41: 220 | J41: 11540 | K41: CLT | L41: 1900113 | M41: Masculino | N41: 45876
A42: 35 | B42: 1351 | C42: ENCARREGADO OBRAS/MANUTENCAO | E42: Não trabalhamos senioridade | F42: Operacional | G42: Edificação | I42: 220 | J42: 8714 | K42: CLT | L42: 5143-25 | M42: Masculino
A43: 36 | B43: PJ8 | C43: ENGENHEIRO JUNIOR DE URBANISMO | E43: Júnior | F43: Operacional | G43: Urbanismo | I43: 220 | J43: =8390/1.49 -> 5630.8725 | K43: PJ | M43: Masculino
...

Sheet Jobmatch
A1: Jobmatch
A3: Cod. | B3: Cargos Empresa | C3: Área | D3: Departamento | E3: Nível Organizacional | F3: Cod. Pesquisa | G3: Cargos Pesquisa | H3: Senioridade | I3: Observações | J3: Tipo de Contrato | K3: Pesquisa | L3: Pesquisas
A4: 1 | B4: =VLOOKUP(A4,'Folha de Pagamento'!A:C,3,0) -> ALMOXARIFE | C4: =VLOOKUP(A4,'Folha de Pagamento'!A:G,7,0) -> Edificação | D4: 8 - ADM PROJETOS | E4: =VLOOKUP(A4,'Folha de Pagamento'!A:F,6,0) -> Operacional | F4: 203 | G4: Almoxarife | H4: Indiferente | L4: Construção | M4: TI | O4: Geral
A5: 2 | B5: =VLOOKUP(A5,'Folha de Pagamento'!A:C,3,0) -> ANALISTA DE COMPRAS | C5: =VLOOKUP(A5,'Folha de Pagamento'!A:G,7,0) -> Suprimentos | D5: 9 - ADM PROJETOS | E5: =VLOOKUP(A5,'Folha de Pagamento'!A:F,6,0) -> Operacional | F5: 136 | G5: Analista de Compras | H5: Pleno | L5: Construção | M5: TI | N5: Industria | O5: Geral
A6: 3 | B6: =VLOOKUP(A6,'Folha de Pagamento'!A:C,3,0) -> ANALISTA DE CRIAÇAO | C6: =VLOOKUP(A6,'Folha de Pagamento'!A:G,7,0) -> Marketing | D6: 10 - ADM PROJETOS | E6: =VLOOKUP(A6,'Folha de Pagamento'!A:F,6,0) -> Operacional | F6: 45 | G6: Analista de Criação | H6: Indiferente | L6: Construção | O6: Geral
A7: 4 | B7: =VLOOKUP(A7,'Folha de Pagamento'!A:C,3,0) -> ANALISTA DE INOVAÇÃO | C7: =VLOOKUP(A7,'Folha de Pagamento'!A:G,7,0) -> Inovação | D7: 11 - ADM PROJETOS | E7: =VLOOKUP(A7,'Folha de Pagamento'!A:F,6,0) -> Tático | F7: 437 | G7: Analista de Inovação | H7: Indiferente
A8: 5 | B8: =VLOOKUP(A8,'Folha de Pagamento'!A:C,3,0) -> ANALISTA DE MANUTENÇÃO II | C8: =VLOOKUP(A8,'Folha de Pagamento'!A:G,7,0) -> Edificação | D8: 12 - ADM PROJETOS | E8: =VLOOKUP(A8,'Folha de Pagamento'!A:F,6,0) -> Operacional | F8: 820 | G8: Encarregado de Manutenção | H8: Indiferente | L8: Construção | M8: TI | O8: Geral
A9: 6 | B9: =VLOOKUP(A9,'Folha de Pagamento'!A:C,3,0) -> ANALISTA DE MARKETING l | C9: =VLOOKUP(A9,'Folha de Pagamento'!A:G,7,0) -> Marketing | D9: 13 - ADM PROJETOS | E9: =VLOOKUP(A9,'Folha de Pagamento'!A:F,6,0) -> Operacional | F9: 42 | G9: Analista de Marketing | H9: Júnior | O9: Geral
A10: 7 | B10: =VLOOKUP(A10,'Folha de Pagamento'!A:C,3,0) -> ANALISTA DE PÓS VENDAS II | C10: =VLOOKUP(A10,'Folha de Pagamento'!A:G,7,0) -> Pós Vendas | D10: 14 - ADM PROJETOS | E10: =VLOOKUP(A10,'Folha de Pagamento'!A:F,6,0) -> Operacional | F10: 19 | G10: Analista Comercial | H10: Pleno | O10: Geral
A11: 8 | B11: =VLOOKUP(A11,'Folha de Pagamento'!A:C,3,0) -> ANALISTA DE URBANISMO | C11: =VLOOKUP(A11,'Folha de Pagamento'!A:G,7,0) -> Urbanismo | D11: 15 - ADM PROJETOS | E11: =VLOOKUP(A11,'Folha de Pagamento'!A:F,6,0) -> Operacional | F11: 1199 | G11: Analista de Urbanismo | H11: Indiferente | L11: Construção | M11: TI | N11: Industria | O11: Geral
A12: 9 | B12: =VLOOKUP(A12,'Folha de Pagamento'!A:C,3,0) -> ANALISTA FINANCEIRO COMERCIAL III | C12: =VLOOKUP(A12,'Folha de Pagamento'!A:G,7,0) -> Financeiro | D12: 16 - ADM PROJETOS | E12: =VLOOKUP(A12,'Folha de Pagamento'!A:F,6,0) -> Operacional | F12: 16 | G12: Analista Financeiro | H12: Sênior | L12: Construção | M12: TI | O12: Geral
A13: 10 | B13: =VLOOKUP(A13,'Folha de Pagamento'!A:C,3,0) -> ANALISTA FINANCEIRO DE CAPTAÇÃO DE RECURSOS III | C13: =VLOOKUP(A13,'Folha de Pagamento'!A:G,7,0) -> Financeiro | D13: 17 - ADM PROJETOS | E13: =VLOOKUP(A13,'Folha de Pagamento'!A:F,6,0) -> Operacional | F13: 16 | G13: Analista Financeiro | H13: Sênior | L13: Construção | M13: TI | N13: Industria | O13: Geral
A14: 11 | B14: =VLOOKUP(A14,'Folha de Pagamento'!A:C,3,0) -> ANALISTA FINANCEIRO I | C14: =VLOOKUP(A14,'Folha de Pagamento'!A:G,7,0) -> Financeiro | D14: 18 - ADM PROJETOS | E14: =VLOOKUP(A14,'Folha de Pagamento'!A:F,6,0) -> Operacional | F14: 16 | G14: Analista Financeiro | H14: Júnior | L14: Construção | M14: TI | N14: Industria | O14: Geral
A15: 12 | B15: =VLOOKUP(A15,'Folha de Pagamento'!A:C,3,0) -> ASSISTENTE ADM DE LEGALIZAÇÃO III | C15: =VLOOKUP(A15,'Folha de Pagamento'!A:G,7,0) -> Legalização | D15: 19 - ADM PROJETOS | E15: =VLOOKUP(A15,'Folha de Pagamento'!A:F,6,0) -> Operacional | F15: 1201 | G15: Assistente de Legalização | H15: Indiferente
A16: 13 | B16: =VLOOKUP(A16,'Folha de Pagamento'!A:C,3,0) -> ASSISTENTE ADMINISTRATIVO lll | C16: =VLOOKUP(A16,'Folha de Pagamento'!A:G,7,0) -> Administrativo | D16: 20 - ADM PROJETOS | E16: =VLOOKUP(A16,'Folha de Pagamento'!A:F,6,0) -> Operacional | F16: 59 | G16: Assistente Administrativo | H16: Indiferente | O16: Geral
A17: 14 | B17: =VLOOKUP(A17,'Folha de Pagamento'!A:C,3,0) -> ASSISTENTE DE CONTROLADORIA III | C17: =VLOOKUP(A17,'Folha de Pagamento'!A:G,7,0) -> Controladoria | D17: 21 - ADM PROJETOS | E17: =VLOOKUP(A17,'Folha de Pagamento'!A:F,6,0) -> Operacional | F17: 150 | G17: Assistente de Controladoria | H17: Indiferente
A18: 15 | B18: =VLOOKUP(A18,'Folha de Pagamento'!A:C,3,0) -> ASSISTENTE DE ENGENHARIA lll | C18: =VLOOKUP(A18,'Folha de Pagamento'!A:G,7,0) -> Edificação | D18: 22 - ADM PROJETOS | E18: =VLOOKUP(A18,'Folha de Pagamento'!A:F,6,0) -> Operacional | F18: 531 | G18: Assistente de Engenharia | H18: Indiferente | O18: Geral
A19: 16 | B19: =VLOOKUP(A19,'Folha de Pagamento'!A:C,3,0) -> ASSISTENTE DE MARKETING | C19: =VLOOKUP(A19,'Folha de Pagamento'!A:G,7,0) -> Marketing | D19: 23 - ADM PROJETOS | E19: =VLOOKUP(A19,'Folha de Pagamento'!A:F,6,0) -> Operacional | F19: 71 | G19: Assistente de Marketing | H19: Indiferente | L19: Construção | M19: TI | O19: Geral
A20: 17 | B20: =VLOOKUP(A20,'Folha de Pagamento'!A:C,3,0) -> ASSISTENTE DE RECURSOS HUMANOS | C20: =VLOOKUP(A20,'Folha de Pagamento'!A:G,7,0) -> DHO | D20: 24 - ADM PROJETOS | E20: =VLOOKUP(A20,'Folha de Pagamento'!A:F,6,0) -> Operacional | F20: 77 | G20: Assistente de Recursos Humanos | H20: Indiferente | L20: Construção | M20: TI | N20: Industria | O20: Geral
A21: 18 | B21: =VLOOKUP(A21,'Folha de Pagamento'!A:C,3,0) -> ASSISTENTE DE TI | C21: =VLOOKUP(A21,'Folha de Pagamento'!A:G,7,0) -> Tecnologia da Informação | D21: 25 - ADM PROJETOS | E21: =VLOOKUP(A21,'Folha de Pagamento'!A:F,6,0) -> Operacional | F21: 31 | G21: Assistente de Tecnologia da Informação | H21: Indiferente | L21: Construção | O21: Geral
A22: 19 | B22: =VLOOKUP(A22,'Folha de Pagamento'!A:C,3,0) -> ASSISTENTE FINANCEIRO CONTAS A PAGAR | C22: =VLOOKUP(A22,'Folha de Pagamento'!A:G,7,0) -> Financeiro | D22: 26 - ADM PROJETOS | E22: =VLOOKUP(A22,'Folha de Pagamento'!A:F,6,0) -> Operacional | F22: 79 | G22: Assistente Financeiro | H22: Indiferente | L22: Construção | M22: TI | O22: Geral
A23: 20 | B23: =VLOOKUP(A23,'Folha de Pagamento'!A:C,3,0) -> AUXILIAR ADMINISTRATIVO | C23: =VLOOKUP(A23,'Folha de Pagamento'!A:G,7,0) -> Administrativo | D23: 27 - ADM PROJETOS | E23: =VLOOKUP(A23,'Folha de Pagamento'!A:F,6,0) -> Operacional | F23: 83 | G23: Auxiliar Administrativo | H23: Indiferente | L23: Construção | O23: Geral
A24: 21 | B24: =VLOOKUP(A24,'Folha de Pagamento'!A:C,3,0) -> AUXILIAR ADMINISTRATIVO III | C24: =VLOOKUP(A24,'Folha de Pagamento'!A:G,7,0) -> Administrativo | D24: 28 - ADM PROJETOS | E24: =VLOOKUP(A24,'Folha de Pagamento'!A:F,6,0) -> Operacional | F24: 83 | G24: Auxiliar Administrativo | H24: Indiferente | M24: TI | O24: Geral
A25: 22 | B25: =VLOOKUP(A25,'Folha de Pagamento'!A:C,3,0) -> AUXILIAR DE ATENDIMENTO II | C25: =VLOOKUP(A25,'Folha de Pagamento'!A:G,7,0) -> Recepção | D25: 29 - ADM PROJETOS | E25: =VLOOKUP(A25,'Folha de Pagamento'!A:F,6,0) -> Operacional | F25: 318 | G25: Auxiliar de Atendimento | H25: Indiferente | L25: Construção | M25: TI | O25: Geral
A26: 23 | B26: =VLOOKUP(A26,'Folha de Pagamento'!A:C,3,0) -> AUXILIAR DE ENGENHARIA | C26: =VLOOKUP(A26,'Folha de Pagamento'!A:G,7,0) -> Urbanismo | D26: 30 - ADM PROJETOS | E26: =VLOOKUP(A26,'Folha de Pagamento'!A:F,6,0) -> Operacional | F26: 207 | G26: Auxiliar de Engenharia | H26: Indiferente | M26: TI | O26: Geral
A27: 24 | B27: =VLOOKUP(A27,'Folha de Pagamento'!A:C,3,0) -> CONTROLER JURÍDICO | C27: =VLOOKUP(A27,'Folha de Pagamento'!A:G,7,0) -> Administrativo | D27: 31 - ADM PROJETOS | E27: =VLOOKUP(A27,'Folha de Pagamento'!A:F,6,0) -> Tático | F27: 9 | G27: Advogado | H27: Sênior | M27: TI | O27: Geral
A28: 25 | B28: =VLOOKUP(A28,'Folha de Pagamento'!A:C,3,0) -> CONTROLLER GERAL | C28: =VLOOKUP(A28,'Folha de Pagamento'!A:G,7,0) -> Controladoria | D28: 32 - ADM PROJETOS | E28: =VLOOKUP(A28,'Folha de Pagamento'!A:F,6,0) -> Tático | F28: 95 | G28: Controller | H28: Indiferente | M28: TI | N28: Industria | O28: Geral
A29: 26 | B29: =VLOOKUP(A29,'Folha de Pagamento'!A:C,3,0) -> CONTROLLER TÉCNICO | C29: =VLOOKUP(A29,'Folha de Pagamento'!A:G,7,0) -> Controladoria | D29: 33 - ADM PROJETOS | E29: =VLOOKUP(A29,'Folha de Pagamento'!A:F,6,0) -> Tático | F29: 26 | G29: Analista de Controladoria | H29: Especialista | M29: TI | O29: Geral
A30: 27 | B30: =VLOOKUP(A30,'Folha de Pagamento'!A:C,3,0) -> COORDENADOR DE DHO | C30: =VLOOKUP(A30,'Folha de Pagamento'!A:G,7,0) -> DHO | D30: 34 - ADM PROJETOS | E30: =VLOOKUP(A30,'Folha de Pagamento'!A:F,6,0) -> Tático | F30: 121 | G30: Coordenador de Recursos Humanos | H30: Indiferente | L30: Construção | M30: TI | N30: Industria | O30: Geral
A31: 28 | B31: =VLOOKUP(A31,'Folha de Pagamento'!A:C,3,0) -> COORDENADOR DE LEGAIZAÇÃO ll | C31: =VLOOKUP(A31,'Folha de Pagamento'!A:G,7,0) -> Legalização | D31: 35 - ADM PROJETOS | E31: =VLOOKUP(A31,'Folha de Pagamento'!A:F,6,0) -> Tático | F31: 1203 | G31: Coordenador de Legalização | H31: Indiferente | L31: Construção | M31: TI | N31: Industria | O31: Geral
A32: 29 | B32: =VLOOKUP(A32,'Folha de Pagamento'!A:C,3,0) -> COORDENADOR DE MARKETING II | C32: =VLOOKUP(A32,'Folha de Pagamento'!A:G,7,0) -> Marketing | D32: 36 - ADM PROJETOS | E32: =VLOOKUP(A32,'Folha de Pagamento'!A:F,6,0) -> Tático | F32: 56 | G32: Coordenador de Marketing | H32: Indiferente | L32: Construção | M32: TI | N32: Industria | O32: Geral
A33: 30 | B33: =VLOOKUP(A33,'Folha de Pagamento'!A:C,3,0) -> COORDENADOR DE OBRAS | C33: =VLOOKUP(A33,'Folha de Pagamento'!A:G,7,0) -> Edificação | D33: 37 - ADM PROJETOS | E33: Tático | F33: 209 | G33: Coordenador de Obras | H33: Indiferente | L33: Construção | M33: TI | N33: Industria | O33: Geral
A34: 31 | B34: =VLOOKUP(A34,'Folha de Pagamento'!A:C,3,0) -> COORDENADOR DE SUPRIMENTOS | C34: =VLOOKUP(A34,'Folha de Pagamento'!A:G,7,0) -> Suprimentos | D34: 38 - ADM PROJETOS | E34: =VLOOKUP(A34,'Folha de Pagamento'!A:F,6,0) -> Tático | F34: 137 | G34: Coordenador de Compras | H34: Indiferente | L34: Construção | M34: TI | O34: Geral
A35: 32 | B35: =VLOOKUP(A35,'Folha de Pagamento'!A:C,3,0) -> COORDENADOR FINANCEIRO | C35: =VLOOKUP(A35,'Folha de Pagamento'!A:G,7,0) -> Financeiro | D35: 39 - ADM PROJETOS | E35: =VLOOKUP(A35,'Folha de Pagamento'!A:F,6,0) -> Tático | F35: 122 | G35: Coordenador Financeiro | H35: Indiferente | L35: Construção | M35: TI | O35: Geral
A36: 33 | B36: =VLOOKUP(A36,'Folha de Pagamento'!A:C,3,0) -> DIRETOR | C36: =VLOOKUP(A36,'Folha de Pagamento'!A:G,7,0) -> Comercial | D36: 40 - ADM PROJETOS | E36: =VLOOKUP(A36,'Folha de Pagamento'!A:F,6,0) -> Estratégico | F36: 456 | G36: CEO | H36: Indiferente | L36: Construção | M36: TI | N36: Industria | O36: Geral
A37: 34 | B37: =VLOOKUP(A37,'Folha de Pagamento'!A:C,3,0) -> ENCARREGADO DE OBRAS | C37: =VLOOKUP(A37,'Folha de Pagamento'!A:G,7,0) -> Urbanismo | D37: 41 - ADM PROJETOS | E37: =VLOOKUP(A37,'Folha de Pagamento'!A:F,6,0) -> Operacional | F37: 470 | G37: Mestre de Obras | H37: Indiferente | L37: Construção | M37: TI | O37: Geral
A38: 35 | B38: =VLOOKUP(A38,'Folha de Pagamento'!A:C,3,0) -> ENCARREGADO OBRAS/MANUTENCAO | C38: =VLOOKUP(A38,'Folha de Pagamento'!A:G,7,0) -> Edificação | D38: 42 - ADM PROJETOS | E38: =VLOOKUP(A38,'Folha de Pagamento'!A:F,6,0) -> Operacional | F38: 470 | G38: Mestre de Obras | H38: Indiferente
A39: 36 | B39: =VLOOKUP(A39,'Folha de Pagamento'!A:C,3,0) -> ENGENHEIRO JUNIOR DE URBANISMO | C39: =VLOOKUP(A39,'Folha de Pagamento'!A:G,7,0) -> Urbanismo | D39: 43 - ADM PROJETOS | E39: =VLOOKUP(A39,'Folha de Pagamento'!A:F,6,0) -> Operacional | F39: 212 | G39: Engenheiro de Urbanismo | H39: Indiferente | L39: Construção | M39: TI | O39: Geral
A40: 37 | B40: =VLOOKUP(A40,'Folha de Pagamento'!A:C,3,0) -> ENGENHEIRO SÊNIOR | C40: =VLOOKUP(A40,'Folha de Pagamento'!A:G,7,0) -> Edificação | D40: 44 - ADM PROJETOS | E40: =VLOOKUP(A40,'Folha de Pagamento'!A:F,6,0) -> Tático | F40: 212 | G40: Engenheiro de Urbanismo | H40: Indiferente | L40: Construção | O40: Geral
A41: 38 | B41: =VLOOKUP(A41,'Folha de Pagamento'!A:C,3,0) -> ESTAGIARIO (A) | C41: =VLOOKUP(A41,'Folha de Pagamento'!A:G,7,0) -> Novos Negócios | D41: 45 - ADM PROJETOS | E41: =VLOOKUP(A41,'Folha de Pagamento'!A:F,6,0) -> Operacional | F41: 338 | G41: Estagiário Administrativo | H41: Indiferente | L41: Construção | M41: TI | N41: Industria | O41: Geral
...

Sheet Cálculos Comparativos
J1: DADOS PARA COMPARAÇÃO | O1: ='Informações Relevantes Cenário'!A1 -> Cenário 01: Pesquisas Consolidadas - Nacional | U1: ="% Distância da "&'Painel Geral'!B5 -> % Distância da Mediana | V1: Posicionamento
A3: Cod. | B3: Cargos Empresa | C3: Média Empresa | D3: Cod. Área | E3: Diretoria | F3: Novo Cargo | H3: Centro de Custo | I3: Nível Organizacional | J3: Cod. Pesquisa | K3: Cargos Pesquisa | L3: Senioridade | M3: Código+Senioridade | N3: Número de Colaboradores | O3: Menor Salário | P3: 1º Quartil | Q3: Média | R3: Mediana | S3: 3º Quartil | T3: Maior Salário | U3: C-01 | V3: C-01 (Posicionamento)
A4: 13 | B4: =VLOOKUP(A4,Jobmatch!A:G,2,0) -> ASSISTENTE ADMINISTRATIVO lll | C4: =IFERROR(AVERAGEIF('Folha de Pagamento'!A:A,A4,'Folha de Pagamento'!J:J),"") -> 3439.7 | D4: 1 | E4: =VLOOKUP(A4,Jobmatch!A:H,3,0) -> Administrativo | F4: Assistente Administrativo | G4: =VLOOKUP(F4,'Página24'!A:A,1,0) -> Assistente Administrativo | H4: =VLOOKUP(A4,Jobmatch!A:I,4,0) -> 20 - ADM PROJETOS | I4: =VLOOKUP(A4,Jobmatch!A:I,5,0) -> Operacional | J4: =VLOOKUP(A4,Jobmatch!A:I,6,0) -> 59 | K4: =VLOOKUP(A4,Jobmatch!A:I,7,0) -> Assistente Administrativo | L4: =VLOOKUP(A4,Jobmatch!A:I,8,0) -> Indiferente | M4: =J4&L4 -> 59Indiferente | N4: =COUNTIF('Folha de Pagamento'!A:A,A4) -> 1 | O4: =IFERROR(VLOOKUP(M4,'C-01'!$D:$L,4,0),"") -> 2076.09 | P4: =IFERROR(VLOOKUP(M4,'C-01'!$D:$L,5,0),"") -> 2329.53 | Q4: =IFERROR(VLOOKUP(M4,'C-01'!$D:$L,6,0),"") -> 2673.92 | R4: =IFERROR(VLOOKUP(M4,'C-01'!$D:$L,7,0),"") -> 2630.61 | S4: =IFERROR(VLOOKUP(M4,'C-01'!$D:$L,8,0),"") -> 2914.75 | T4: =IFERROR(VLOOKUP(M4,'C-01'!$D:$L,9,0),"") -> 3662.52 | U4: =IFS('Painel Geral'!$B$5="Mediana",IFERROR(IF(OR(C4="",R4=0,R4=""),"",($C4/$R4)),""),'Painel Geral'!$B$5="Menor Salário",IFERROR(IF(OR(C4="",R4=0,R4=""),"",($C4/$O4)),""),'Painel Geral'!$B$5="1º Quartil",IFERROR(IF(OR(C4="",R4=0,R4=""),"",($C4/$P4)),""), 'Painel Geral'!$B$5="Média",IFERROR(IF(OR(C4="",R4=0,R4=""),"",($C4/$Q4)),""),'Painel Geral'!$B$5="3º Quartil",IFERROR(IF(OR(C4="",R4=0,R4=""),"",($C4/$S4)),""),'Painel Geral'!$B$5="Maior Salário",IFERROR(IF(OR(C4="",R4=0,R4=""),"",($C4/$T4)),"")) -> 1.3075674 | V4: =IFS(OR(O4="",O4=0,C4="", C4=0),"",U4<=80%,"Muito Defasado",U4<=90%,"Defasado",U4<=100%,"Na Média",U4<=110%,"Competitivo",U4<=120%,"Muito Competitivo",U4>120%,"Agressivo") -> Agressivo
A5: 20 | B5: =VLOOKUP(A5,Jobmatch!A:G,2,0) -> AUXILIAR ADMINISTRATIVO | C5: =IFERROR(AVERAGEIF('Folha de Pagamento'!A:A,A5,'Folha de Pagamento'!J:J),"") -> 2254 | D5: 1 | E5: =VLOOKUP(A5,Jobmatch!A:H,3,0) -> Administrativo | F5: Auxiliar Administrativo | G5: =VLOOKUP(F5,'Página24'!A:A,1,0) -> Auxiliar Administrativo | H5: =VLOOKUP(A5,Jobmatch!A:I,4,0) -> 27 - ADM PROJETOS | I5: =VLOOKUP(A5,Jobmatch!A:I,5,0) -> Operacional | J5: =VLOOKUP(A5,Jobmatch!A:I,6,0) -> 83 | K5: =VLOOKUP(A5,Jobmatch!A:I,7,0) -> Auxiliar Administrativo | L5: =VLOOKUP(A5,Jobmatch!A:I,8,0) -> Indiferente | M5: =J5&L5 -> 83Indiferente | N5: =COUNTIF('Folha de Pagamento'!A:A,A5) -> 1 | O5: =IFERROR(VLOOKUP(M5,'C-01'!$D:$L,4,0),"") -> 1771.74 | P5: =IFERROR(VLOOKUP(M5,'C-01'!$D:$L,5,0),"") -> 2128.74 | Q5: =IFERROR(VLOOKUP(M5,'C-01'!$D:$L,6,0),"") -> 2292.87 | R5: =IFERROR(VLOOKUP(M5,'C-01'!$D:$L,7,0),"") -> 2309.71 | S5: =IFERROR(VLOOKUP(M5,'C-01'!$D:$L,8,0),"") -> 2375.14 | T5: =IFERROR(VLOOKUP(M5,'C-01'!$D:$L,9,0),"") -> 3073.32 | U5: =IFS('Painel Geral'!$B$5="Mediana",IFERROR(IF(OR(C5="",R5=0,R5=""),"",($C5/$R5)),""),'Painel Geral'!$B$5="Menor Salário",IFERROR(IF(OR(C5="",R5=0,R5=""),"",($C5/$O5)),""),'Painel Geral'!$B$5="1º Quartil",IFERROR(IF(OR(C5="",R5=0,R5=""),"",($C5/$P5)),""), 'Painel Geral'!$B$5="Média",IFERROR(IF(OR(C5="",R5=0,R5=""),"",($C5/$Q5)),""),'Painel Geral'!$B$5="3º Quartil",IFERROR(IF(OR(C5="",R5=0,R5=""),"",($C5/$S5)),""),'Painel Geral'!$B$5="Maior Salário",IFERROR(IF(OR(C5="",R5=0,R5=""),"",($C5/$T5)),"")) -> 0.97588009 | V5: =IFS(OR(O5="",O5=0,C5="", C5=0),"",U5<=80%,"Muito Defasado",U5<=90%,"Defasado",U5<=100%,"Na Média",U5<=110%,"Competitivo",U5<=120%,"Muito Competitivo",U5>120%,"Agressivo") -> Na Média
A6: 21 | B6: =VLOOKUP(A6,Jobmatch!A:G,2,0) -> AUXILIAR ADMINISTRATIVO III | C6: =IFERROR(AVERAGEIF('Folha de Pagamento'!A:A,A6,'Folha de Pagamento'!J:J),"") -> 2739.04 | D6: 1 | E6: =VLOOKUP(A6,Jobmatch!A:H,3,0) -> Administrativo | F6: Auxiliar Administrativo | G6: =VLOOKUP(F6,'Página24'!A:A,1,0) -> Auxiliar Administrativo | H6: =VLOOKUP(A6,Jobmatch!A:I,4,0) -> 28 - ADM PROJETOS | I6: =VLOOKUP(A6,Jobmatch!A:I,5,0) -> Operacional | J6: =VLOOKUP(A6,Jobmatch!A:I,6,0) -> 83 | K6: =VLOOKUP(A6,Jobmatch!A:I,7,0) -> Auxiliar Administrativo | L6: =VLOOKUP(A6,Jobmatch!A:I,8,0) -> Indiferente | M6: =J6&L6 -> 83Indiferente | N6: =COUNTIF('Folha de Pagamento'!A:A,A6) -> 1 | O6: =IFERROR(VLOOKUP(M6,'C-01'!$D:$L,4,0),"") -> 1771.74 | P6: =IFERROR(VLOOKUP(M6,'C-01'!$D:$L,5,0),"") -> 2128.74 | Q6: =IFERROR(VLOOKUP(M6,'C-01'!$D:$L,6,0),"") -> 2292.87 | R6: =IFERROR(VLOOKUP(M6,'C-01'!$D:$L,7,0),"") -> 2309.71 | S6: =IFERROR(VLOOKUP(M6,'C-01'!$D:$L,8,0),"") -> 2375.14 | T6: =IFERROR(VLOOKUP(M6,'C-01'!$D:$L,9,0),"") -> 3073.32 | U6: =IFS('Painel Geral'!$B$5="Mediana",IFERROR(IF(OR(C6="",R6=0,R6=""),"",($C6/$R6)),""),'Painel Geral'!$B$5="Menor Salário",IFERROR(IF(OR(C6="",R6=0,R6=""),"",($C6/$O6)),""),'Painel Geral'!$B$5="1º Quartil",IFERROR(IF(OR(C6="",R6=0,R6=""),"",($C6/$P6)),""), 'Painel Geral'!$B$5="Média",IFERROR(IF(OR(C6="",R6=0,R6=""),"",($C6/$Q6)),""),'Painel Geral'!$B$5="3º Quartil",IFERROR(IF(OR(C6="",R6=0,R6=""),"",($C6/$S6)),""),'Painel Geral'!$B$5="Maior Salário",IFERROR(IF(OR(C6="",R6=0,R6=""),"",($C6/$T6)),"")) -> 1.1858805 | V6: =IFS(OR(O6="",O6=0,C6="", C6=0),"",U6<=80%,"Muito Defasado",U6<=90%,"Defasado",U6<=100%,"Na Média",U6<=110%,"Competitivo",U6<=120%,"Muito Competitivo",U6>120%,"Agressivo") -> Muito Competitivo
A7: 24 | B7: =VLOOKUP(A7,Jobmatch!A:G,2,0) -> CONTROLER JURÍDICO | C7: =IFERROR(AVERAGEIF('Folha de Pagamento'!A:A,A7,'Folha de Pagamento'!J:J),"") -> 8276.6423 | D7: 1 | E7: =VLOOKUP(A7,Jobmatch!A:H,3,0) -> Administrativo | F7: Controller Jurídico | G7: =VLOOKUP(F7,'Página24'!A:A,1,0) -> #N/A | H7: =VLOOKUP(A7,Jobmatch!A:I,4,0) -> 31 - ADM PROJETOS | I7: =VLOOKUP(A7,Jobmatch!A:I,5,0) -> Tático | J7: =VLOOKUP(A7,Jobmatch!A:I,6,0) -> 9 | K7: =VLOOKUP(A7,Jobmatch!A:I,7,0) -> Advogado | L7: =VLOOKUP(A7,Jobmatch!A:I,8,0) -> Sênior | M7: =J7&L7 -> 9Sênior | N7: =COUNTIF('Folha de Pagamento'!A:A,A7) -> 1 | O7: =IFERROR(VLOOKUP(M7,'C-01'!$D:$L,4,0),"") -> 0 | P7: =IFERROR(VLOOKUP(M7,'C-01'!$D:$L,5,0),"") -> 0 | Q7: =IFERROR(VLOOKUP(M7,'C-01'!$D:$L,6,0),"") -> 0 | R7: =IFERROR(VLOOKUP(M7,'C-01'!$D:$L,7,0),"") -> 0 | S7: =IFERROR(VLOOKUP(M7,'C-01'!$D:$L,8,0),"") -> 0 | T7: =IFERROR(VLOOKUP(M7,'C-01'!$D:$L,9,0),"") -> 0 | U7: =IFS('Painel Geral'!$B$5="Mediana",IFERROR(IF(OR(C7="",R7=0,R7=""),"",($C7/$R7)),""),'Painel Geral'!$B$5="Menor Salário",IFERROR(IF(OR(C7="",R7=0,R7=""),"",($C7/$O7)),""),'Painel Geral'!$B$5="1º Quartil",IFERROR(IF(OR(C7="",R7=0,R7=""),"",($C7/$P7)),""), 'Painel Geral'!$B$5="Média",IFERROR(IF(OR(C7="",R7=0,R7=""),"",($C7/$Q7)),""),'Painel Geral'!$B$5="3º Quartil",IFERROR(IF(OR(C7="",R7=0,R7=""),"",($C7/$S7)),""),'Painel Geral'!$B$5="Maior Salário",IFERROR(IF(OR(C7="",R7=0,R7=""),"",($C7/$T7)),"")) | V7: =IFS(OR(O7="",O7=0,C7="", C7=0),"",U7<=80%,"Muito Defasado",U7<=90%,"Defasado",U7<=100%,"Na Média",U7<=110%,"Competitivo",U7<=120%,"Muito Competitivo",U7>120%,"Agressivo")
A8: 39 | B8: =VLOOKUP(A8,Jobmatch!A:G,2,0) -> ESTAGIÁRIO(A) ADM | C8: =IFERROR(AVERAGEIF('Folha de Pagamento'!A:A,A8,'Folha de Pagamento'!J:J),"") -> 1521 | D8: 1 | E8: =VLOOKUP(A8,Jobmatch!A:H,3,0) -> Administrativo | F8: Estagiário Administrativo | G8: =VLOOKUP(F8,'Página24'!A:A,1,0) -> #N/A | H8: =VLOOKUP(A8,Jobmatch!A:I,4,0) -> 46 - ADM PROJETOS | I8: =VLOOKUP(A8,Jobmatch!A:I,5,0) -> Operacional | J8: =VLOOKUP(A8,Jobmatch!A:I,6,0) -> 338 | K8: =VLOOKUP(A8,Jobmatch!A:I,7,0) -> Estagiário Administrativo | L8: =VLOOKUP(A8,Jobmatch!A:I,8,0) -> Indiferente | M8: =J8&L8 -> 338Indiferente | N8: =COUNTIF('Folha de Pagamento'!A:A,A8) -> 1 | O8: =IFERROR(VLOOKUP(M8,'C-01'!$D:$L,4,0),"") -> 1558.5273 | P8: =IFERROR(VLOOKUP(M8,'C-01'!$D:$L,5,0),"") -> 1615.0841 | Q8: =IFERROR(VLOOKUP(M8,'C-01'!$D:$L,6,0),"") -> 1753.3432 | R8: =IFERROR(VLOOKUP(M8,'C-01'!$D:$L,7,0),"") -> 1721.9182 | S8: =IFERROR(VLOOKUP(M8,'C-01'!$D:$L,8,0),"") -> 1860.1773 | T8: =IFERROR(VLOOKUP(M8,'C-01'!$D:$L,9,0),"") -> 2011.0023 | U8: =IFS('Painel Geral'!$B$5="Mediana",IFERROR(IF(OR(C8="",R8=0,R8=""),"",($C8/$R8)),""),'Painel Geral'!$B$5="Menor Salário",IFERROR(IF(OR(C8="",R8=0,R8=""),"",($C8/$O8)),""),'Painel Geral'!$B$5="1º Quartil",IFERROR(IF(OR(C8="",R8=0,R8=""),"",($C8/$P8)),""), 'Painel Geral'!$B$5="Média",IFERROR(IF(OR(C8="",R8=0,R8=""),"",($C8/$Q8)),""),'Painel Geral'!$B$5="3º Quartil",IFERROR(IF(OR(C8="",R8=0,R8=""),"",($C8/$S8)),""),'Painel Geral'!$B$5="Maior Salário",IFERROR(IF(OR(C8="",R8=0,R8=""),"",($C8/$T8)),"")) -> 0.88331723 | V8: =IFS(OR(O8="",O8=0,C8="", C8=0),"",U8<=80%,"Muito Defasado",U8<=90%,"Defasado",U8<=100%,"Na Média",U8<=110%,"Competitivo",U8<=120%,"Muito Competitivo",U8>120%,"Agressivo") -> Defasado
A9: 42 | B9: =VLOOKUP(A9,Jobmatch!A:G,2,0) -> GERENTE ADMINISTRATIVA | C9: =IFERROR(AVERAGEIF('Folha de Pagamento'!A:A,A9,'Folha de Pagamento'!J:J),"") -> 12242.424 | D9: 1 | E9: =VLOOKUP(A9,Jobmatch!A:H,3,0) -> Administrativo | F9: Gerente Administrativa | G9: =VLOOKUP(F9,'Página24'!A:A,1,0) -> Gerente Administrativa | H9: =VLOOKUP(A9,Jobmatch!A:I,4,0) -> 49 - ADM PROJETOS | I9: =VLOOKUP(A9,Jobmatch!A:I,5,0) -> Tático | J9: =VLOOKUP(A9,Jobmatch!A:I,6,0) -> 106 | K9: =VLOOKUP(A9,Jobmatch!A:I,7,0) -> Gerente Administrativo | L9: =VLOOKUP(A9,Jobmatch!A:I,8,0) -> Indiferente | M9: =J9&L9 -> 106Indiferente | N9: =COUNTIF('Folha de Pagamento'!A:A,A9) -> 2 | O9: =IFERROR(VLOOKUP(M9,'C-01'!$D:$L,4,0),"") -> 5281.61 | P9: =IFERROR(VLOOKUP(M9,'C-01'!$D:$L,5,0),"") -> 6616.13 | Q9: =IFERROR(VLOOKUP(M9,'C-01'!$D:$L,6,0),"") -> 9881.52 | R9: =IFERROR(VLOOKUP(M9,'C-01'!$D:$L,7,0),"") -> 10052.23 | S9: =IFERROR(VLOOKUP(M9,'C-01'!$D:$L,8,0),"") -> 12479.94 | T9: =IFERROR(VLOOKUP(M9,'C-01'!$D:$L,9,0),"") -> 15257.82 | U9: =IFS('Painel Geral'!$B$5="Mediana",IFERROR(IF(OR(C9="",R9=0,R9=""),"",($C9/$R9)),""),'Painel Geral'!$B$5="Menor Salário",IFERROR(IF(OR(C9="",R9=0,R9=""),"",($C9/$O9)),""),'Painel Geral'!$B$5="1º Quartil",IFERROR(IF(OR(C9="",R9=0,R9=""),"",($C9/$P9)),""), 'Painel Geral'!$B$5="Média",IFERROR(IF(OR(C9="",R9=0,R9=""),"",($C9/$Q9)),""),'Painel Geral'!$B$5="3º Quartil",IFERROR(IF(OR(C9="",R9=0,R9=""),"",($C9/$S9)),""),'Painel Geral'!$B$5="Maior Salário",IFERROR(IF(OR(C9="",R9=0,R9=""),"",($C9/$T9)),"")) -> 1.2178814 | V9: =IFS(OR(O9="",O9=0,C9="", C9=0),"",U9<=80%,"Muito Defasado",U9<=90%,"Defasado",U9<=100%,"Na Média",U9<=110%,"Competitivo",U9<=120%,"Muito Competitivo",U9>120%,"Agressivo") -> Agressivo
A10: 33 | B10: =VLOOKUP(A10,Jobmatch!A:G,2,0) -> DIRETOR | C10: =IFERROR(AVERAGEIF('Folha de Pagamento'!A:A,A10,'Folha de Pagamento'!J:J),"") -> 55769.231 | D10: 2 | E10: =VLOOKUP(A10,Jobmatch!A:H,3,0) -> Comercial | F10: Diretor | G10: =VLOOKUP(F10,'Página24'!A:A,1,0) -> Diretor | H10: =VLOOKUP(A10,Jobmatch!A:I,4,0) -> 40 - ADM PROJETOS | I10: =VLOOKUP(A10,Jobmatch!A:I,5,0) -> Estratégico | J10: =VLOOKUP(A10,Jobmatch!A:I,6,0) -> 456 | K10: =VLOOKUP(A10,Jobmatch!A:I,7,0) -> CEO | L10: =VLOOKUP(A10,Jobmatch!A:I,8,0) -> Indiferente | M10: =J10&L10 -> 456Indiferente | N10: =COUNTIF('Folha de Pagamento'!A:A,A10) -> 1 | O10: =IFERROR(VLOOKUP(M10,'C-01'!$D:$L,4,0),"") -> 18287.31 | P10: =IFERROR(VLOOKUP(M10,'C-01'!$D:$L,5,0),"") -> 24816.78 | Q10: =IFERROR(VLOOKUP(M10,'C-01'!$D:$L,6,0),"") -> 32648.36 | R10: =IFERROR(VLOOKUP(M10,'C-01'!$D:$L,7,0),"") -> 29147.75 | S10: =IFERROR(VLOOKUP(M10,'C-01'!$D:$L,8,0),"") -> 37122.89 | T10: =IFERROR(VLOOKUP(M10,'C-01'!$D:$L,9,0),"") -> 55429.54 | U10: =IFS('Painel Geral'!$B$5="Mediana",IFERROR(IF(OR(C10="",R10=0,R10=""),"",($C10/$R10)),""),'Painel Geral'!$B$5="Menor Salário",IFERROR(IF(OR(C10="",R10=0,R10=""),"",($C10/$O10)),""),'Painel Geral'!$B$5="1º Quartil",IFERROR(IF(OR(C10="",R10=0,R10=""),"",($C10/$P10)),""), 'Painel Geral'!$B$5="Média",IFERROR(IF(OR(C10="",R10=0,R10=""),"",($C10/$Q10)),""),'Painel Geral'!$B$5="3º Quartil",IFERROR(IF(OR(C10="",R10=0,R10=""),"",($C10/$S10)),""),'Painel Geral'!$B$5="Maior Salário",IFERROR(IF(OR(C10="",R10=0,R10=""),"",($C10/$T10)),"")) -> 1.9133288 | V10: =IFS(OR(O10="",O10=0,C10="", C10=0),"",U10<=80%,"Muito Defasado",U10<=90%,"Defasado",U10<=100%,"Na Média",U10<=110%,"Competitivo",U10<=120%,"Muito Competitivo",U10>120%,"Agressivo") -> Agressivo
A11: 43 | B11: =VLOOKUP(A11,Jobmatch!A:G,2,0) -> GERENTE COMERCIAL | C11: =IFERROR(AVERAGEIF('Folha de Pagamento'!A:A,A11,'Folha de Pagamento'!J:J),"") -> 12090.909 | D11: 2 | E11: =VLOOKUP(A11,Jobmatch!A:H,3,0) -> Comercial | F11: Gerente Comercial | G11: =VLOOKUP(F11,'Página24'!A:A,1,0) -> Gerente Comercial | H11: =VLOOKUP(A11,Jobmatch!A:I,4,0) -> 50 - ADM PROJETOS | I11: =VLOOKUP(A11,Jobmatch!A:I,5,0) -> Tático | J11: =VLOOKUP(A11,Jobmatch!A:I,6,0) -> 107 | K11: =VLOOKUP(A11,Jobmatch!A:I,7,0) -> Gerente Comercial | L11: =VLOOKUP(A11,Jobmatch!A:I,8,0) -> Indiferente | M11: =J11&L11 -> 107Indiferente | N11: =COUNTIF('Folha de Pagamento'!A:A,A11) -> 4 | O11: =IFERROR(VLOOKUP(M11,'C-01'!$D:$L,4,0),"") -> 5570.67 | P11: =IFERROR(VLOOKUP(M11,'C-01'!$D:$L,5,0),"") -> 9778.91 | Q11: =IFERROR(VLOOKUP(M11,'C-01'!$D:$L,6,0),"") -> 12281.04 | R11: =IFERROR(VLOOKUP(M11,'C-01'!$D:$L,7,0),"") -> 12107.57 | S11: =IFERROR(VLOOKUP(M11,'C-01'!$D:$L,8,0),"") -> 15321.87 | T11: =IFERROR(VLOOKUP(M11,'C-01'!$D:$L,9,0),"") -> 19289.48 | U11: =IFS('Painel Geral'!$B$5="Mediana",IFERROR(IF(OR(C11="",R11=0,R11=""),"",($C11/$R11)),""),'Painel Geral'!$B$5="Menor Salário",IFERROR(IF(OR(C11="",R11=0,R11=""),"",($C11/$O11)),""),'Painel Geral'!$B$5="1º Quartil",IFERROR(IF(OR(C11="",R11=0,R11=""),"",($C11/$P11)),""), 'Painel Geral'!$B$5="Média",IFERROR(IF(OR(C11="",R11=0,R11=""),"",($C11/$Q11)),""),'Painel Geral'!$B$5="3º Quartil",IFERROR(IF(OR(C11="",R11=0,R11=""),"",($C11/$S11)),""),'Painel Geral'!$B$5="Maior Salário",IFERROR(IF(OR(C11="",R11=0,R11=""),"",($C11/$T11)),"")) -> 0.99862393 | V11: =IFS(OR(O11="",O11=0,C11="", C11=0),"",U11<=80%,"Muito Defasado",U11<=90%,"Defasado",U11<=100%,"Na Média",U11<=110%,"Competitivo",U11<=120%,"Muito Competitivo",U11>120%,"Agressivo") -> Na Média
A12: 45 | B12: =VLOOKUP(A12,Jobmatch!A:G,2,0) -> GERENTE DE HOUSE | C12: =IFERROR(AVERAGEIF('Folha de Pagamento'!A:A,A12,'Folha de Pagamento'!J:J),"") -> 5125 | D12: 2 | E12: =VLOOKUP(A12,Jobmatch!A:H,3,0) -> Comercial | F12: Gerente House | G12: =VLOOKUP(F12,'Página24'!A:A,1,0) -> Gerente House | H12: =VLOOKUP(A12,Jobmatch!A:I,4,0) -> 52 - ADM PROJETOS | I12: =VLOOKUP(A12,Jobmatch!A:I,5,0) -> Tático | J12: =VLOOKUP(A12,Jobmatch!A:I,6,0) -> 107 | K12: =VLOOKUP(A12,Jobmatch!A:I,7,0) -> Gerente Comercial | L12: =VLOOKUP(A12,Jobmatch!A:I,8,0) -> Indiferente | M12: =J12&L12 -> 107Indiferente | N12: =COUNTIF('Folha de Pagamento'!A:A,A12) -> 1 | O12: =IFERROR(VLOOKUP(M12,'C-01'!$D:$L,4,0),"") -> 5570.67 | P12: =IFERROR(VLOOKUP(M12,'C-01'!$D:$L,5,0),"") -> 9778.91 | Q12: =IFERROR(VLOOKUP(M12,'C-01'!$D:$L,6,0),"") -> 12281.04 | R12: =IFERROR(VLOOKUP(M12,'C-01'!$D:$L,7,0),"") -> 12107.57 | S12: =IFERROR(VLOOKUP(M12,'C-01'!$D:$L,8,0),"") -> 15321.87 | T12: =IFERROR(VLOOKUP(M12,'C-01'!$D:$L,9,0),"") -> 19289.48 | U12: =IFS('Painel Geral'!$B$5="Mediana",IFERROR(IF(OR(C12="",R12=0,R12=""),"",($C12/$R12)),""),'Painel Geral'!$B$5="Menor Salário",IFERROR(IF(OR(C12="",R12=0,R12=""),"",($C12/$O12)),""),'Painel Geral'!$B$5="1º Quartil",IFERROR(IF(OR(C12="",R12=0,R12=""),"",($C12/$P12)),""), 'Painel Geral'!$B$5="Média",IFERROR(IF(OR(C12="",R12=0,R12=""),"",($C12/$Q12)),""),'Painel Geral'!$B$5="3º Quartil",IFERROR(IF(OR(C12="",R12=0,R12=""),"",($C12/$S12)),""),'Painel Geral'!$B$5="Maior Salário",IFERROR(IF(OR(C12="",R12=0,R12=""),"",($C12/$T12)),"")) -> 0.4232889 | V12: =IFS(OR(O12="",O12=0,C12="", C12=0),"",U12<=80%,"Muito Defasado",U12<=90%,"Defasado",U12<=100%,"Na Média",U12<=110%,"Competitivo",U12<=120%,"Muito Competitivo",U12>120%,"Agressivo") -> Muito Defasado
A13: 46 | B13: =VLOOKUP(A13,Jobmatch!A:G,2,0) -> GERENTE DE IMOBILIÁRIAS EXTERNAS | C13: =IFERROR(AVERAGEIF('Folha de Pagamento'!A:A,A13,'Folha de Pagamento'!J:J),"") -> 5530.5 | D13: 2 | E13: =VLOOKUP(A13,Jobmatch!A:H,3,0) -> Comercial | F13: Gerente Imobiliárias Externas | G13: =VLOOKUP(F13,'Página24'!A:A,1,0) -> #N/A | H13: =VLOOKUP(A13,Jobmatch!A:I,4,0) -> 53 - ADM PROJETOS | I13: =VLOOKUP(A13,Jobmatch!A:I,5,0) -> Tático | J13: =VLOOKUP(A13,Jobmatch!A:I,6,0) -> 1205 | K13: =VLOOKUP(A13,Jobmatch!A:I,7,0) -> Gerente de Imobiliárias | L13: =VLOOKUP(A13,Jobmatch!A:I,8,0) -> Indiferente | M13: =J13&L13 -> 1205Indiferente | N13: =COUNTIF('Folha de Pagamento'!A:A,A13) -> 2 | O13: =IFERROR(VLOOKUP(M13,'C-01'!$D:$L,4,0),"") -> 0 | P13: =IFERROR(VLOOKUP(M13,'C-01'!$D:$L,5,0),"") -> 0 | Q13: =IFERROR(VLOOKUP(M13,'C-01'!$D:$L,6,0),"") -> 0 | R13: =IFERROR(VLOOKUP(M13,'C-01'!$D:$L,7,0),"") -> 0 | S13: =IFERROR(VLOOKUP(M13,'C-01'!$D:$L,8,0),"") -> 0 | T13: =IFERROR(VLOOKUP(M13,'C-01'!$D:$L,9,0),"") -> 0 | U13: =IFS('Painel Geral'!$B$5="Mediana",IFERROR(IF(OR(C13="",R13=0,R13=""),"",($C13/$R13)),""),'Painel Geral'!$B$5="Menor Salário",IFERROR(IF(OR(C13="",R13=0,R13=""),"",($C13/$O13)),""),'Painel Geral'!$B$5="1º Quartil",IFERROR(IF(OR(C13="",R13=0,R13=""),"",($C13/$P13)),""), 'Painel Geral'!$B$5="Média",IFERROR(IF(OR(C13="",R13=0,R13=""),"",($C13/$Q13)),""),'Painel Geral'!$B$5="3º Quartil",IFERROR(IF(OR(C13="",R13=0,R13=""),"",($C13/$S13)),""),'Painel Geral'!$B$5="Maior Salário",IFERROR(IF(OR(C13="",R13=0,R13=""),"",($C13/$T13)),"")) | V13: =IFS(OR(O13="",O13=0,C13="", C13=0),"",U13<=80%,"Muito Defasado",U13<=90%,"Defasado",U13<=100%,"Na Média",U13<=110%,"Competitivo",U13<=120%,"Muito Competitivo",U13>120%,"Agressivo")
A14: 48 | B14: =VLOOKUP(A14,Jobmatch!A:G,2,0) -> GERENTE DE PARCERIAS | C14: =IFERROR(AVERAGEIF('Folha de Pagamento'!A:A,A14,'Folha de Pagamento'!J:J),"") -> 5345 | D14: 2 | E14: =VLOOKUP(A14,Jobmatch!A:H,3,0) -> Comercial | F14: Gerente Parcerias | G14: =VLOOKUP(F14,'Página24'!A:A,1,0) -> Gerente Parcerias | H14: =VLOOKUP(A14,Jobmatch!A:I,4,0) -> 55 - ADM PROJETOS | I14: =VLOOKUP(A14,Jobmatch!A:I,5,0) -> Tático | J14: =VLOOKUP(A14,Jobmatch!A:I,6,0) -> 408 | K14: =VLOOKUP(A14,Jobmatch!A:I,7,0) -> Gerente de Relacionamento | L14: =VLOOKUP(A14,Jobmatch!A:I,8,0) -> Indiferente | M14: =J14&L14 -> 408Indiferente | N14: =COUNTIF('Folha de Pagamento'!A:A,A14) -> 2 | O14: =IFERROR(VLOOKUP(M14,'C-01'!$D:$L,4,0),"") -> 5772.56 | P14: =IFERROR(VLOOKUP(M14,'C-01'!$D:$L,5,0),"") -> 7608.96 | Q14: =IFERROR(VLOOKUP(M14,'C-01'!$D:$L,6,0),"") -> 10973.95 | R14: =IFERROR(VLOOKUP(M14,'C-01'!$D:$L,7,0),"") -> 10996.97 | S14: =IFERROR(VLOOKUP(M14,'C-01'!$D:$L,8,0),"") -> 14004.27 | T14: =IFERROR(VLOOKUP(M14,'C-01'!$D:$L,9,0),"") -> 16628.86 | U14: =IFS('Painel Geral'!$B$5="Mediana",IFERROR(IF(OR(C14="",R14=0,R14=""),"",($C14/$R14)),""),'Painel Geral'!$B$5="Menor Salário",IFERROR(IF(OR(C14="",R14=0,R14=""),"",($C14/$O14)),""),'Painel Geral'!$B$5="1º Quartil",IFERROR(IF(OR(C14="",R14=0,R14=""),"",($C14/$P14)),""), 'Painel Geral'!$B$5="Média",IFERROR(IF(OR(C14="",R14=0,R14=""),"",($C14/$Q14)),""),'Painel Geral'!$B$5="3º Quartil",IFERROR(IF(OR(C14="",R14=0,R14=""),"",($C14/$S14)),""),'Painel Geral'!$B$5="Maior Salário",IFERROR(IF(OR(C14="",R14=0,R14=""),"",($C14/$T14)),"")) -> 0.48604297 | V14: =IFS(OR(O14="",O14=0,C14="", C14=0),"",U14<=80%,"Muito Defasado",U14<=90%,"Defasado",U14<=100%,"Na Média",U14<=110%,"Competitivo",U14<=120%,"Muito Competitivo",U14>120%,"Agressivo") -> Muito Defasado
A15: 49 | B15: =VLOOKUP(A15,Jobmatch!A:G,2,0) -> GERENTE DE PARCERIAS EXTERNAS | C15: =IFERROR(AVERAGEIF('Folha de Pagamento'!A:A,A15,'Folha de Pagamento'!J:J),"") -> 5000 | D15: 2 | E15: =VLOOKUP(A15,Jobmatch!A:H,3,0) -> Comercial | F15: Gerente Parcerias Externas | G15: =VLOOKUP(F15,'Página24'!A:A,1,0) -> Gerente Parcerias Externas | H15: =VLOOKUP(A15,Jobmatch!A:I,4,0) -> 56 - ADM PROJETOS | I15: =VLOOKUP(A15,Jobmatch!A:I,5,0) -> Tático | J15: =VLOOKUP(A15,Jobmatch!A:I,6,0) -> 408 | K15: =VLOOKUP(A15,Jobmatch!A:I,7,0) -> Gerente de Relacionamento | L15: =VLOOKUP(A15,Jobmatch!A:I,8,0) -> Indiferente | M15: =J15&L15 -> 408Indiferente | N15: =COUNTIF('Folha de Pagamento'!A:A,A15) -> 2 | O15: =IFERROR(VLOOKUP(M15,'C-01'!$D:$L,4,0),"") -> 5772.56 | P15: =IFERROR(VLOOKUP(M15,'C-01'!$D:$L,5,0),"") -> 7608.96 | Q15: =IFERROR(VLOOKUP(M15,'C-01'!$D:$L,6,0),"") -> 10973.95 | R15: =IFERROR(VLOOKUP(M15,'C-01'!$D:$L,7,0),"") -> 10996.97 | S15: =IFERROR(VLOOKUP(M15,'C-01'!$D:$L,8,0),"") -> 14004.27 | T15: =IFERROR(VLOOKUP(M15,'C-01'!$D:$L,9,0),"") -> 16628.86 | U15: =IFS('Painel Geral'!$B$5="Mediana",IFERROR(IF(OR(C15="",R15=0,R15=""),"",($C15/$R15)),""),'Painel Geral'!$B$5="Menor Salário",IFERROR(IF(OR(C15="",R15=0,R15=""),"",($C15/$O15)),""),'Painel Geral'!$B$5="1º Quartil",IFERROR(IF(OR(C15="",R15=0,R15=""),"",($C15/$P15)),""), 'Painel Geral'!$B$5="Média",IFERROR(IF(OR(C15="",R15=0,R15=""),"",($C15/$Q15)),""),'Painel Geral'!$B$5="3º Quartil",IFERROR(IF(OR(C15="",R15=0,R15=""),"",($C15/$S15)),""),'Painel Geral'!$B$5="Maior Salário",IFERROR(IF(OR(C15="",R15=0,R15=""),"",($C15/$T15)),"")) -> 0.4546707 | V15: =IFS(OR(O15="",O15=0,C15="", C15=0),"",U15<=80%,"Muito Defasado",U15<=90%,"Defasado",U15<=100%,"Na Média",U15<=110%,"Competitivo",U15<=120%,"Muito Competitivo",U15>120%,"Agressivo") -> Muito Defasado
... A57: 50 | B57: =VLOOKUP(A57,Jobmatch!A:G,2,0) -> GERENTE DE URBANISMO | C57: =IFERROR(AVERAGEIF('Folha de Pagamento'!A:A,A57,'Folha de Pagamento'!J:J),"") -> 28030.303 | D57: 10 | E57: =VLOOKUP(A57,Jobmatch!A:H,3,0) -> Urbanismo | F57: Gerente Urbanismo | G57: =VLOOKUP(F57,'Página24'!A:A,1,0) -> Gerente Urbanismo | H57: =VLOOKUP(A57,Jobmatch!A:I,4,0) -> 57 - ADM PROJETOS | I57: =VLOOKUP(A57,Jobmatch!A:I,5,0) -> Tático | J57: =VLOOKUP(A57,Jobmatch!A:I,6,0) -> 311 | K57: =VLOOKUP(A57,Jobmatch!A:I,7,0) -> Gerente de Operações | L57: =VLOOKUP(A57,Jobmatch!A:I,8,0) -> Indiferente | M57: =J57&L57 -> 311Indiferente | N57: =COUNTIF('Folha de Pagamento'!A:A,A57) -> 2 | O57: =IFERROR(VLOOKUP(M57,'C-01'!$D:$L,4,0),"") -> 7331.45 | P57: =IFERROR(VLOOKUP(M57,'C-01'!$D:$L,5,0),"") -> 10114.75 | Q57: =IFERROR(VLOOKUP(M57,'C-01'!$D:$L,6,0),"") -> 12711.42 | R57: =IFERROR(VLOOKUP(M57,'C-01'!$D:$L,7,0),"") -> 12517.82 | S57: =IFERROR(VLOOKUP(M57,'C-01'!$D:$L,8,0),"") -> 14749 | T57: =IFERROR(VLOOKUP(M57,'C-01'!$D:$L,9,0),"") -> 19098.65 | U57: =IFS('Painel Geral'!$B$5="Mediana",IFERROR(IF(OR(C57="",R57=0,R57=""),"",($C57/$R57)),""),'Painel Geral'!$B$5="Menor Salário",IFERROR(IF(OR(C57="",R57=0,R57=""),"",($C57/$O57)),""),'Painel Geral'!$B$5="1º Quartil",IFERROR(IF(OR(C57="",R57=0,R57=""),"",($C57/$P57)),""), 'Painel Geral'!$B$5="Média",IFERROR(IF(OR(C57="",R57=0,R57=""),"",($C57/$Q57)),""),'Painel Geral'!$B$5="3º Quartil",IFERROR(IF(OR(C57="",R57=0,R57=""),"",($C57/$S57)),""),'Painel Geral'!$B$5="Maior Salário",IFERROR(IF(OR(C57="",R57=0,R57=""),"",($C57/$T57)),"")) -> 2.239232 | V57: =IFS(OR(O57="",O57=0,C57="", C57=0),"",U57<=80%,"Muito Defasado",U57<=90%,"Defasado",U57<=100%,"Na Média",U57<=110%,"Competitivo",U57<=120%,"Muito Competitivo",U57>120%,"Agressivo") -> Agressivo

Sheet Página24
A1: Auxiliar Administrativo
A2: Auxiliar Administrativo
A3: Assistente Administrativo
A4: Gerente Administrativa
A5: Assistente Controladoria
A6: Controller Técnico
A7: Controller Geral
A8: Gerente Parcerias
A9: Gerente Parcerias Externas
A10: Gerente Comercial
A11: Gerente House
A12: Diretor
... A44: Gerente Urbanismo

Sheet Tabela 7
I1: DADOS PARA COMPARAÇÃO | O1: ='Informações Relevantes Cenário'!A1 -> Cenário 01: Pesquisas Consolidadas - Nacional | T1: ="% Distância da "&'Painel Geral'!B5 -> % Distância da Mediana | U1: Posicionamento
A3: Cod. | B3: Cargos Empresa | C3: Média Empresa | D3: Cod. Área | E3: Diretoria | F3: Novo Cargo | G3: Centro de Custo | H3: Nível Organizacional | I3: Cod. Pesquisa | J3: Cargos Pesquisa | K3: Senioridade | L3: Código+Senioridade | M3: Número de Colaboradores | O3: 1º Quartil | P3: Média | Q3: Mediana | R3: 3º Quartil | S3: Maior Salário | T3: C-01 | U3: C-01 (Posicionamento)
A4: 22 | B4: =VLOOKUP(A4,Jobmatch!A:G,2,0) -> AUXILIAR DE ATENDIMENTO II | C4: =IFERROR(AVERAGEIF('Folha de Pagamento'!A:A,A4,'Folha de Pagamento'!J:J),"") -> 2560 | D4: 1 | E4: =VLOOKUP(A4,Jobmatch!A:H,3,0) -> Recepção | F4: Auxiliar Atendimento | G4: =VLOOKUP(A4,Jobmatch!A:I,4,0) -> 29 - ADM PROJETOS | H4: =VLOOKUP(A4,Jobmatch!A:I,5,0) -> Operacional | I4: =VLOOKUP(A4,Jobmatch!A:I,6,0) -> 318 | J4: =VLOOKUP(A4,Jobmatch!A:I,7,0) -> Auxiliar de Atendimento | K4: =VLOOKUP(A4,Jobmatch!A:I,8,0) -> Indiferente | L4: =I4&K4 -> 318Indiferente | M4: =COUNTIF('Folha de Pagamento'!A:A,A4) -> 1 | N4: 10 | O4: =IFERROR(VLOOKUP(L4,'C-01'!$D:$L,5,0),"") -> 1778.55 | P4: =IFERROR(VLOOKUP(L4,'C-01'!$D:$L,6,0),"") -> 2041.06 | Q4: =IFERROR(VLOOKUP(L4,'C-01'!$D:$L,7,0),"") -> 2052.94 | R4: =IFERROR(VLOOKUP(L4,'C-01'!$D:$L,8,0),"") -> 2169.15 | S4: =IFERROR(VLOOKUP(L4,'C-01'!$D:$L,9,0),"") -> 2574.08 | T4: =IFS('Painel Geral'!$B$5="Mediana",IFERROR(IF(OR(C4="",Q4=0,Q4=""),"",($C4/$Q4)),""),'Painel Geral'!$B$5="Menor Salário",IFERROR(IF(OR(C4="",Q4=0,Q4=""),"",($C4/$N4)),""),'Painel Geral'!$B$5="1º Quartil",IFERROR(IF(OR(C4="",Q4=0,Q4=""),"",($C4/$O4)),""), 'Painel Geral'!$B$5="Média",IFERROR(IF(OR(C4="",Q4=0,Q4=""),"",($C4/$P4)),""),'Painel Geral'!$B$5="3º Quartil",IFERROR(IF(OR(C4="",Q4=0,Q4=""),"",($C4/$R4)),""),'Painel Geral'!$B$5="Maior Salário",IFERROR(IF(OR(C4="",Q4=0,Q4=""),"",($C4/$S4)),"")) -> 1.2469921 | U4: =IFS(OR(N4="",N4=0,C4="", C4=0),"",T4<=80%,"Muito Defasado",T4<=90%,"Defasado",T4<=100%,"Na Média",T4<=110%,"Competitivo",T4<=120%,"Muito Competitivo",T4>120%,"Agressivo") -> Agressivo | V4: =Z29*1.2 -> 2176.3124 | W4: =V4*1.2 -> 2611.5749 | X4: =W4*1.2 -> 3133.8899 | Y4: =X4*1.2 -> 3760.6679 | Z4: =Y4*1.2 -> 4512.8014 | AA4: =Z4*1.2 -> 5415.3617 | AB4: =AA4*1.2 -> 6498.4341 | AC4: =AB4*1.2 -> 7798.1209 | AD4: =AC4*1.2 -> 9357.7451 | ... AJ4: =AI4*1.2 -> 27942.077
A5: 20 | B5: =VLOOKUP(A5,Jobmatch!A:G,2,0) -> AUXILIAR ADMINISTRATIVO | C5: =IFERROR(AVERAGEIF('Folha de Pagamento'!A:A,A5,'Folha de Pagamento'!J:J),"") -> 2254 | D5: 1 | E5: =VLOOKUP(A5,Jobmatch!A:H,3,0) -> Administrativo | F5: Auxiliar Administrativo | G5: =VLOOKUP(A5,Jobmatch!A:I,4,0) -> 27 - ADM PROJETOS | H5: =VLOOKUP(A5,Jobmatch!A:I,5,0) -> Operacional | I5: =VLOOKUP(A5,Jobmatch!A:I,6,0) -> 83 | J5: =VLOOKUP(A5,Jobmatch!A:I,7,0) -> Auxiliar Administrativo | K5: =VLOOKUP(A5,Jobmatch!A:I,8,0) -> Indiferente | L5: =I5&K5 -> 83Indiferente | M5: =COUNTIF('Folha de Pagamento'!A:A,A5) -> 1 | N5: 10 | O5: =IFERROR(VLOOKUP(L5,'C-01'!$D:$L,5,0),"") -> 2128.74 | P5: =IFERROR(VLOOKUP(L5,'C-01'!$D:$L,6,0),"") -> 2292.87 | Q5: =IFERROR(VLOOKUP(L5,'C-01'!$D:$L,7,0),"") -> 2309.71 | R5: =IFERROR(VLOOKUP(L5,'C-01'!$D:$L,8,0),"") -> 2375.14 | S5: =IFERROR(VLOOKUP(L5,'C-01'!$D:$L,9,0),"") -> 3073.32 | T5: =IFS('Painel Geral'!$B$5="Mediana",IFERROR(IF(OR(C5="",Q5=0,Q5=""),"",($C5/$Q5)),""),'Painel Geral'!$B$5="Menor Salário",IFERROR(IF(OR(C5="",Q5=0,Q5=""),"",($C5/$N5)),""),'Painel Geral'!$B$5="1º Quartil",IFERROR(IF(OR(C5="",Q5=0,Q5=""),"",($C5/$O5)),""), 'Painel Geral'!$B$5="Média",IFERROR(IF(OR(C5="",Q5=0,Q5=""),"",($C5/$P5)),""),'Painel Geral'!$B$5="3º Quartil",IFERROR(IF(OR(C5="",Q5=0,Q5=""),"",($C5/$R5)),""),'Painel Geral'!$B$5="Maior Salário",IFERROR(IF(OR(C5="",Q5=0,Q5=""),"",($C5/$S5)),"")) -> 0.97588009 | U5: =IFS(OR(N5="",N5=0,C5="", C5=0),"",T5<=80%,"Muito Defasado",T5<=90%,"Defasado",T5<=100%,"Na Média",T5<=110%,"Competitivo",T5<=120%,"Muito Competitivo",T5>120%,"Agressivo") -> Na Média | V5: 10 | W5: 11 | X5: 12 | Y5: 13 | Z5: 14 | AA5: 15 | AB5: 16 | AC5: 17 | AD5: 18 | AE5: 19 | AF5: 20 | AG5: 21 | AH5: 22 | AI5: 23 | AJ5: 24
A6: 21 | B6: =VLOOKUP(A6,Jobmatch!A:G,2,0) -> AUXILIAR ADMINISTRATIVO III | C6: =IFERROR(AVERAGEIF('Folha de Pagamento'!A:A,A6,'Folha de Pagamento'!J:J),"") -> 2739.04 | D6: 1 | E6: =VLOOKUP(A6,Jobmatch!A:H,3,0) -> Administrativo | F6: Auxiliar Administrativo | G6: =VLOOKUP(A6,Jobmatch!A:I,4,0) -> 28 - ADM PROJETOS | H6: =VLOOKUP(A6,Jobmatch!A:I,5,0) -> Operacional | I6: =VLOOKUP(A6,Jobmatch!A:I,6,0) -> 83 | J6: =VLOOKUP(A6,Jobmatch!A:I,7,0) -> Auxiliar Administrativo | K6: =VLOOKUP(A6,Jobmatch!A:I,8,0) -> Indiferente | L6: =I6&K6 -> 83Indiferente | M6: =COUNTIF('Folha de Pagamento'!A:A,A6) -> 1 | N6: 10 | O6: =IFERROR(VLOOKUP(L6,'C-01'!$D:$L,5,0),"") -> 2128.74 | P6: =IFERROR(VLOOKUP(L6,'C-01'!$D:$L,6,0),"") -> 2292.87 | Q6: =IFERROR(VLOOKUP(L6,'C-01'!$D:$L,7,0),"") -> 2309.71 | R6: =IFERROR(VLOOKUP(L6,'C-01'!$D:$L,8,0),"") -> 2375.14 | S6: =IFERROR(VLOOKUP(L6,'C-01'!$D:$L,9,0),"") -> 3073.32 | T6: =IFS('Painel Geral'!$B$5="Mediana",IFERROR(IF(OR(C6="",Q6=0,Q6=""),"",($C6/$Q6)),""),'Painel Geral'!$B$5="Menor Salário",IFERROR(IF(OR(C6="",Q6=0,Q6=""),"",($C6/$N6)),""),'Painel Geral'!$B$5="1º Quartil",IFERROR(IF(OR(C6="",Q6=0,Q6=""),"",($C6/$O6)),""), 'Painel Geral'!$B$5="Média",IFERROR(IF(OR(C6="",Q6=0,Q6=""),"",($C6/$P6)),""),'Painel Geral'!$B$5="3º Quartil",IFERROR(IF(OR(C6="",Q6=0,Q6=""),"",($C6/$R6)),""),'Painel Geral'!$B$5="Maior Salário",IFERROR(IF(OR(C6="",Q6=0,Q6=""),"",($C6/$S6)),"")) -> 1.1858805 | U6: =IFS(OR(N6="",N6=0,C6="", C6=0),"",T6<=80%,"Muito Defasado",T6<=90%,"Defasado",T6<=100%,"Na Média",T6<=110%,"Competitivo",T6<=120%,"Muito Competitivo",T6>120%,"Agressivo") -> Muito Competitivo
A7: 18 | B7: =VLOOKUP(A7,Jobmatch!A:G,2,0) -> ASSISTENTE DE TI | C7: =IFERROR(AVERAGEIF('Folha de Pagamento'!A:A,A7,'Folha de Pagamento'!J:J),"") -> 2919 | D7: 1 | E7: =VLOOKUP(A7,Jobmatch!A:H,3,0) -> Tecnologia da Informação | F7: Assistente TI | G7: =VLOOKUP(A7,Jobmatch!A:I,4,0) -> 25 - ADM PROJETOS | H7: =VLOOKUP(A7,Jobmatch!A:I,5,0) -> Operacional | I7: =VLOOKUP(A7,Jobmatch!A:I,6,0) -> 31 | J7: =VLOOKUP(A7,Jobmatch!A:I,7,0) -> Assistente de Tecnologia da Informação | K7: =VLOOKUP(A7,Jobmatch!A:I,8,0) -> Indiferente | L7: =I7&K7 -> 31Indiferente | M7: =COUNTIF('Folha de Pagamento'!A:A,A7) -> 2 | N7: 10 | O7: =IFERROR(VLOOKUP(L7,'C-01'!$D:$L,5,0),"") -> 2066.4 | P7: =IFERROR(VLOOKUP(L7,'C-01'!$D:$L,6,0),"") -> 2589.89 | Q7: =IFERROR(VLOOKUP(L7,'C-01'!$D:$L,7,0),"") -> 2413.7 | R7: =IFERROR(VLOOKUP(L7,'C-01'!$D:$L,8,0),"") -> 3121.21 | S7: =IFERROR(VLOOKUP(L7,'C-01'!$D:$L,9,0),"") -> 3521.6 | T7: =IFS('Painel Geral'!$B$5="Mediana",IFERROR(IF(OR(C7="",Q7=0,Q7=""),"",($C7/$Q7)),""),'Painel Geral'!$B$5="Menor Salário",IFERROR(IF(OR(C7="",Q7=0,Q7=""),"",($C7/$N7)),""),'Painel Geral'!$B$5="1º Quartil",IFERROR(IF(OR(C7="",Q7=0,Q7=""),"",($C7/$O7)),""), 'Painel Geral'!$B$5="Média",IFERROR(IF(OR(C7="",Q7=0,Q7=""),"",($C7/$P7)),""),'Painel Geral'!$B$5="3º Quartil",IFERROR(IF(OR(C7="",Q7=0,Q7=""),"",($C7/$R7)),""),'Painel Geral'!$B$5="Maior Salário",IFERROR(IF(OR(C7="",Q7=0,Q7=""),"",($C7/$S7)),"")) -> 1.2093466 | U7: =IFS(OR(N7="",N7=0,C7="", C7=0),"",T7<=80%,"Muito Defasado",T7<=90%,"Defasado",T7<=100%,"Na Média",T7<=110%,"Competitivo",T7<=120%,"Muito Competitivo",T7>120%,"Agressivo") -> Agressivo
A8: 13 | B8: =VLOOKUP(A8,Jobmatch!A:G,2,0) -> ASSISTENTE ADMINISTRATIVO lll | C8: =IFERROR(AVERAGEIF('Folha de Pagamento'!A:A,A8,'Folha de Pagamento'!J:J),"") -> 3439.7 | D8: 1 | E8: =VLOOKUP(A8,Jobmatch!A:H,3,0) -> Administrativo | F8: Assistente Administrativo | G8: =VLOOKUP(A8,Jobmatch!A:I,4,0) -> 20 - ADM PROJETOS | H8: =VLOOKUP(A8,Jobmatch!A:I,5,0) -> Operacional | I8: =VLOOKUP(A8,Jobmatch!A:I,6,0) -> 59 | J8: =VLOOKUP(A8,Jobmatch!A:I,7,0) -> Assistente Administrativo | K8: =VLOOKUP(A8,Jobmatch!A:I,8,0) -> Indiferente | L8: =I8&K8 -> 59Indiferente | M8: =COUNTIF('Folha de Pagamento'!A:A,A8) -> 1 | N8: 10 | O8: =IFERROR(VLOOKUP(L8,'C-01'!$D:$L,5,0),"") -> 2329.53 | P8: =IFERROR(VLOOKUP(L8,'C-01'!$D:$L,6,0),"") -> 2673.92 | Q8: =IFERROR(VLOOKUP(L8,'C-01'!$D:$L,7,0),"") -> 2630.61 | R8: =IFERROR(VLOOKUP(L8,'C-01'!$D:$L,8,0),"") -> 2914.75 | S8: =IFERROR(VLOOKUP(L8,'C-01'!$D:$L,9,0),"") -> 3662.52 | T8: =IFS('Painel Geral'!$B$5="Mediana",IFERROR(IF(OR(C8="",Q8=0,Q8=""),"",($C8/$Q8)),""),'Painel Geral'!$B$5="Menor Salário",IFERROR(IF(OR(C8="",Q8=0,Q8=""),"",($C8/$N8)),""),'Painel Geral'!$B$5="1º Quartil",IFERROR(IF(OR(C8="",Q8=0,Q8=""),"",($C8/$O8)),""), 'Painel Geral'!$B$5="Média",IFERROR(IF(OR(C8="",Q8=0,Q8=""),"",($C8/$P8)),""),'Painel Geral'!$B$5="3º Quartil",IFERROR(IF(OR(C8="",Q8=0,Q8=""),"",($C8/$R8)),""),'Painel Geral'!$B$5="Maior Salário",IFERROR(IF(OR(C8="",Q8=0,Q8=""),"",($C8/$S8)),"")) -> 1.3075674 | U8: =IFS(OR(N8="",N8=0,C8="", C8=0),"",T8<=80%,"Muito Defasado",T8<=90%,"Defasado",T8<=100%,"Na Média",T8<=110%,"Competitivo",T8<=120%,"Muito Competitivo",T8>120%,"Agressivo") -> Agressivo
A9: 19 | B9: =VLOOKUP(A9,Jobmatch!A:G,2,0) -> ASSISTENTE FINANCEIRO CONTAS A PAGAR | C9: =IFERROR(AVERAGEIF('Folha de Pagamento'!A:A,A9,'Folha de Pagamento'!J:J),"") -> 3163.3333 | D9: 6 | E9: =VLOOKUP(A9,Jobmatch!A:H,3,0) -> Financeiro | F9: Assistente Financeiro Contas a Pagar | G9: =VLOOKUP(A9,Jobmatch!A:I,4,0) -> 26 - ADM PROJETOS | H9: =VLOOKUP(A9,Jobmatch!A:I,5,0) -> Operacional | I9: =VLOOKUP(A9,Jobmatch!A:I,6,0) -> 79 | J9: =VLOOKUP(A9,Jobmatch!A:I,7,0) -> Assistente Financeiro | K9: =VLOOKUP(A9,Jobmatch!A:I,8,0) -> Indiferente | L9: =I9&K9 -> 79Indiferente | M9: =COUNTIF('Folha de Pagamento'!A:A,A9) -> 3 | N9: 10 | O9: =IFERROR(VLOOKUP(L9,'C-01'!$D:$L,5,0),"") -> 2560.05 | P9: =IFERROR(VLOOKUP(L9,'C-01'!$D:$L,6,0),"") -> 2799.02 | Q9: =IFERROR(VLOOKUP(L9,'C-01'!$D:$L,7,0),"") -> 2658.89 | R9: =IFERROR(VLOOKUP(L9,'C-01'!$D:$L,8,0),"") -> 2935.06 | S9: =IFERROR(VLOOKUP(L9,'C-01'!$D:$L,9,0),"") -> 3630.87 | T9: =IFS('Painel Geral'!$B$5="Mediana",IFERROR(IF(OR(C9="",Q9=0,Q9=""),"",($C9/$Q9)),""),'Painel Geral'!$B$5="Menor Salário",IFERROR(IF(OR(C9="",Q9=0,Q9=""),"",($C9/$N9)),""),'Painel Geral'!$B$5="1º Quartil",IFERROR(IF(OR(C9="",Q9=0,Q9=""),"",($C9/$O9)),""), 'Painel Geral'!$B$5="Média",IFERROR(IF(OR(C9="",Q9=0,Q9=""),"",($C9/$P9)),""),'Painel Geral'!$B$5="3º Quartil",IFERROR(IF(OR(C9="",Q9=0,Q9=""),"",($C9/$R9)),""),'Painel Geral'!$B$5="Maior Salário",IFERROR(IF(OR(C9="",Q9=0,Q9=""),"",($C9/$S9)),"")) -> 1.1897195 | U9: =IFS(OR(N9="",N9=0,C9="", C9=0),"",T9<=80%,"Muito Defasado",T9<=90%,"Defasado",T9<=100%,"Na Média",T9<=110%,"Competitivo",T9<=120%,"Muito Competitivo",T9>120%,"Agressivo") -> Muito Competitivo
A10: 23 | B10: =VLOOKUP(A10,Jobmatch!A:G,2,0) -> AUXILIAR DE ENGENHARIA | C10: =IFERROR(AVERAGEIF('Folha de Pagamento'!A:A,A10,'Folha de Pagamento'!J:J),"") -> 2560 | D10: 10 | E10: =VLOOKUP(A10,Jobmatch!A:H,3,0) -> Urbanismo | F10: Auxiliar Engenharia | G10: =VLOOKUP(A10,Jobmatch!A:I,4,0) -> 30 - ADM PROJETOS | H10: =VLOOKUP(A10,Jobmatch!A:I,5,0) -> Operacional | I10: =VLOOKUP(A10,Jobmatch!A:I,6,0) -> 207 | J10: =VLOOKUP(A10,Jobmatch!A:I,7,0) -> Auxiliar de Engenharia | K10: =VLOOKUP(A10,Jobmatch!A:I,8,0) -> Indiferente | L10: =I10&K10 -> 207Indiferente | M10: =COUNTIF('Folha de Pagamento'!A:A,A10) -> 1 | N10: 11 | O10: =IFERROR(VLOOKUP(L10,'C-01'!$D:$L,5,0),"") -> 2644.47 | P10: =IFERROR(VLOOKUP(L10,'C-01'!$D:$L,6,0),"") -> 2819.08 | Q10: =IFERROR(VLOOKUP(L10,'C-01'!$D:$L,7,0),"") -> 2714.85 | R10: =IFERROR(VLOOKUP(L10,'C-01'!$D:$L,8,0),"") -> 2941.58 | S10: =IFERROR(VLOOKUP(L10,'C-01'!$D:$L,9,0),"") -> 3168.31 | T10: =IFS('Painel Geral'!$B$5="Mediana",IFERROR(IF(OR(C10="",Q10=0,Q10=""),"",($C10/$Q10)),""),'Painel Geral'!$B$5="Menor Salário",IFERROR(IF(OR(C10="",Q10=0,Q10=""),"",($C10/$N10)),""),'Painel Geral'!$B$5="1º Quartil",IFERROR(IF(OR(C10="",Q10=0,Q10=""),"",($C10/$O10)),""), 'Painel Geral'!$B$5="Média",IFERROR(IF(OR(C10="",Q10=0,Q10=""),"",($C10/$P10)),""),'Painel Geral'!$B$5="3º Quartil",IFERROR(IF(OR(C10="",Q10=0,Q10=""),"",($C10/$R10)),""),'Painel Geral'!$B$5="Maior Salário",IFERROR(IF(OR(C10="",Q10=0,Q10=""),"",($C10/$S10)),"")) -> 0.94296186 | U10: =IFS(OR(N10="",N10=0,C10="", C10=0),"",T10<=80%,"Muito Defasado",T10<=90%,"Defasado",T10<=100%,"Na Média",T10<=110%,"Competitivo",T10<=120%,"Muito Competitivo",T10>120%,"Agressivo") -> Na Média
A11: 14 | B11: =VLOOKUP(A11,Jobmatch!A:G,2,0) -> ASSISTENTE DE CONTROLADORIA III | C11: =IFERROR(AVERAGEIF('Folha de Pagamento'!A:A,A11,'Folha de Pagamento'!J:J),"") -> 3652 | D11: 3 | E11: =VLOOKUP(A11,Jobmatch!A:H,3,0) -> Controladoria | F11: Assistente Controladoria | G11: =VLOOKUP(A11,Jobmatch!A:I,4,0) -> 21 - ADM PROJETOS | H11: =VLOOKUP(A11,Jobmatch!A:I,5,0) -> Operacional | I11: =VLOOKUP(A11,Jobmatch!A:I,6,0) -> 150 | J11: =VLOOKUP(A11,Jobmatch!A:I,7,0) -> Assistente de Controladoria | K11: =VLOOKUP(A11,Jobmatch!A:I,8,0) -> Indiferente | L11: =I11&K11 -> 150Indiferente | M11: =COUNTIF('Folha de Pagamento'!A:A,A11) -> 1 | N11: 11 | O11: =IFERROR(VLOOKUP(L11,'C-01'!$D:$L,5,0),"") -> 2640.81 | P11: =IFERROR(VLOOKUP(L11,'C-01'!$D:$L,6,0),"") -> 2821.08 | Q11: =IFERROR(VLOOKUP(L11,'C-01'!$D:$L,7,0),"") -> 2766.4 | R11: =IFERROR(VLOOKUP(L11,'C-01'!$D:$L,8,0),"") -> 3222.24 | S11: =IFERROR(VLOOKUP(L11,'C-01'!$D:$L,9,0),"") -> 3327.42 | T11: =IFS('Painel Geral'!$B$5="Mediana",IFERROR(IF(OR(C11="",Q11=0,Q11=""),"",($C11/$Q11)),""),'Painel Geral'!$B$5="Menor Salário",IFERROR(IF(OR(C11="",Q11=0,Q11=""),"",($C11/$N11)),""),'Painel Geral'!$B$5="1º Quartil",IFERROR(IF(OR(C11="",Q11=0,Q11=""),"",($C11/$O11)),""), 'Painel Geral'!$B$5="Média",IFERROR(IF(OR(C11="",Q11=0,Q11=""),"",($C11/$P11)),""),'Painel Geral'!$B$5="3º Quartil",IFERROR(IF(OR(C11="",Q11=0,Q11=""),"",($C11/$R11)),""),'Painel Geral'!$B$5="Maior Salário",IFERROR(IF(OR(C11="",Q11=0,Q11=""),"",($C11/$S11)),"")) -> 1.3201272 | U11: =IFS(OR(N11="",N11=0,C11="", C11=0),"",T11<=80%,"Muito Defasado",T11<=90%,"Defasado",T11<=100%,"Na Média",T11<=110%,"Competitivo",T11<=120%,"Muito Competitivo",T11>120%,"Agressivo") -> Agressivo
