Workbook

Sheet Folha de Pagamento
C1: Folha de Pagamento | G1: CNPJ da empresa: Referência da Folha de Pagamento: Quantidade de horas mensais usada: Data de Construção:
A3: Cod. | B3: Cod. contrato funcionário | C3: Cargo atual | D3: Novo Cargo | E3: Senioridade | F3: Nível Organizacional | G3: Área | H3: Departamento | I3: Carga Horária | J3: Salários | K3: Salários Convertidos CLT | L3: Tipo de Contratação | M3: CBO | N3: Gênero | O3: Data de Admissão | P3: Unidade | Q3: Observações
A4: 1 | B4: 1362 | C4: ALMOXARIFE | E4: Não trabalhamos senioridade | F4: Operacional | G4: Edificação | I4: 220 | J4: 3683 | K4: 3683 | L4: CLT | M4: 818631 | N4: Masculino | O4: 45871
A5: 1 | B5: 1957 | C5: ALMOXARIFE | E5: Não trabalhamos senioridade | F5: Operacional | G5: Edificação | I5: 220 | J5: 3683 | K5: 3683 | L5: CLT | M5: 818631 | N5: Feminino | O5: 45870
A6: 2 | B6: 1964 | C6: ANALISTA DE COMPRAS | E6: Não trabalhamos senioridade | F6: Operacional | G6: Suprimentos | I6: 220 | J6: 3780 | K6: 3780 | L6: CLT | M6: 599850 | N6: Masculino | O6: 45872
A7: 3 | B7: 1910 | C7: ANALISTA DE CRIAÇAO | E7: Não trabalhamos senioridade | F7: Operacional | G7: Marketing | I7: 220 | J7: 5429 | K7: 5429 | L7: CLT | M7: 1423-35 | N7: Masculino | O7: 45873
A8: 4 | B8: PJ1 | C8: ANALISTA DE INOVAÇÃO | E8: Não trabalhamos senioridade | F8: Tático | G8: Inovação | I8: 220 | J8: 10000 | K8: =10000/1.37 -> 7299.2701 | L8: PJ | N8: Masculino | O8: 45874
A9: 5 | B9: 1373 | C9: ANALISTA DE MANUTENÇÃO II | E9: Pleno | F9: Operacional | G9: Edificação | I9: 220 | J9: 4550 | K9: 4550 | L9: CLT | M9: 5143-25 | N9: Masculino | O9: 45875
A10: 6 | B10: 139 | C10: ANALISTA DE MARKETING l | E10: Não trabalhamos senioridade | F10: Operacional | G10: Marketing | I10: 220 | J10: 4025.88 | K10: 4025.88 | L10: CLT | M10: 1423-35 | N10: Feminino | O10: 45876
A11: 7 | B11: 1962 | C11: ANALISTA DE PÓS VENDAS II | E11: Pleno | F11: Operacional | G11: Pós Vendas | I11: 220 | J11: 4550 | K11: 4550 | L11: CLT | M11: 226938 | N11: Masculino | O11: 45877
A12: 8 | B12: 187 | C12: ANALISTA DE URBANISMO | E12: Não trabalhamos senioridade | F12: Operacional | G12: Urbanismo | I12: 220 | J12: 5830 | K12: 5830 | L12: CLT | M12: 446083 | N12: Feminino | O12: 45878
A13: 9 | B13: 1868 | C13: ANALISTA FINANCEIRO COMERCIAL III | E13: Sênior | F13: Operacional | G13: Financeiro | I13: 220 | J13: 5213 | K13: 5213 | L13: CLT | M13: 226938 | N13: Feminino | O13: 45879
A14: 10 | B14: 176 | C14: ANALISTA FINANCEIRO DE CAPTAÇÃO DE RECURSOS III | E14: Sênior | F14: Operacional | G14: Financeiro | I14: 220 | J14: 5213 | K14: 5213 | L14: CLT | M14: 2525-45 | N14: Feminino | O14: 45880
A15: 11 | B15: 1927 | C15: ANALISTA FINANCEIRO I | E15: Júnior | F15: Operacional | G15: Financeiro | I15: 220 | J15: 3993 | K15: 3993 | L15: CLT | M15: 226938 | N15: Feminino | O15: 45881
A16: 12 | B16: 164 | C16: ASSISTENTE ADM DE LEGALIZAÇÃO III | E16: Sênior | F16: Operacional | G16: Legalização | I16: 220 | J16: 3652 | K16: 3652 | L16: CLT | M16: 807461 | N16: Feminino | O16: 45882
A17: 13 | B17: 1892 | C17: ASSISTENTE ADMINISTRATIVO lll | E17: Sênior | F17: Operacional | G17: Administrativo | I17: 220 | J17: 3439.7 | K17: 3439.7 | L17: CLT | M17: 807461 | N17: Feminino | O17: 45883
A18: 14 | B18: 1940 | C18: ASSISTENTE DE CONTROLADORIA III | E18: Sênior | F18: Operacional | G18: Controladoria | I18: 220 | J18: 3652 | K18: 3652 | L18: CLT | M18: 807461 | N18: Feminino | O18: 45884
A19: 15 | B19: 1963 | C19: ASSISTENTE DE ENGENHARIA lll | E19: Sênior | F19: Operacional | G19: Edificação | I19: 220 | J19: 3652 | K19: 3652 | L19: CLT | M19: 446083 | N19: Feminino | O19: 45885
A20: 16 | B20: 190 | C20: ASSISTENTE DE MARKETING | E20: Não trabalhamos senioridade | F20: Operacional | G20: Marketing | I20: 220 | J20: 2919 | K20: 2919 | L20: CLT | M20: 807461 | N20: Feminino | O20: 45886
A21: 17 | B21: 189 | C21: ASSISTENTE DE RECURSOS HUMANOS | E21: Não trabalhamos senioridade | F21: Operacional | G21: DHO | I21: 220 | J21: 2919 | K21: 2919 | L21: CLT | M21: 807461 | N21: Feminino | O21: 45887
A22: 18 | B22: 1656 | C22: ASSISTENTE DE TI | E22: Não trabalhamos senioridade | F22: Operacional | G22: Tecnologia da Informação | I22: 220 | J22: 2919 | K22: 2919 | L22: CLT | M22: 464864 | N22: Masculino | O22: 45888
A23: 19 | B23: 192 | C23: ASSISTENTE FINANCEIRO CONTAS A PAGAR | E23: Não trabalhamos senioridade | F23: Operacional | G23: Financeiro | I23: 220 | J23: 2919 | K23: 2919 | L23: CLT | M23: 815131 | N23: Masculino | O23: 45889
A24: 19 | B24: 193 | C24: ASSISTENTE FINANCEIRO CONTAS A PAGAR | E24: Não trabalhamos senioridade | F24: Operacional | G24: Financeiro | I24: 220 | J24: 2919 | K24: 2919 | L24: CLT | M24: 815131 | N24: Masculino | O24: 45890
A25: 19 | B25: 1941 | C25: ASSISTENTE FINANCEIRO CONTAS A PAGAR III | E25: Não trabalhamos senioridade | F25: Operacional | G25: Financeiro | I25: 220 | J25: 3652 | K25: 3652 | L25: CLT | M25: 815131 | N25: Masculino | O25: 45891
A26: 20 | B26: 1961 | C26: AUXILIAR ADMINISTRATIVO | E26: Não trabalhamos senioridade | F26: Operacional | G26: Administrativo | I26: 220 | J26: 2254 | K26: 2254 | L26: CLT | M26: 807308 | N26: Feminino | O26: 45892
A27: 20 | B27: 184 | C27: AUXILIAR ADMINISTRATIVO III | D27: AUXILIAR ADMINISTRATIVO | E27: Sênior | F27: Operacional | G27: Administrativo | I27: 220 | J27: 2739.04 | K27: 2739.04 | L27: CLT | M27: 807308 | N27: Feminino | O27: 45893
A28: 22 | B28: 1951 | C28: AUXILIAR DE ATENDIMENTO II | E28: Pleno | F28: Operacional | G28: Recepção | I28: 220 | J28: 2560 | K28: 2560 | L28: CLT | M28: 807308 | N28: Feminino | O28: 45894
A29: 23 | B29: 191 | C29: AUXILIAR DE ENGENHARIA | E29: Não trabalhamos senioridade | F29: Operacional | G29: Urbanismo | I29: 220 | J29: 2560 | K29: 2560 | L29: CLT | M29: 446083 | N29: Masculino | O29: 45895
A30: 24 | B30: PJ2 | C30: CONTROLER JURÍDICO | E30: Não trabalhamos senioridade | F30: Tático | G30: Administrativo | I30: 220 | J30: 11339 | K30: =11339/1.37 -> 8276.6423 | L30: PJ | N30: Feminino | O30: 45896
A31: 25 | B31: PJ3 | C31: CONTROLLER GERAL | E31: Não trabalhamos senioridade | F31: Tático | G31: Controladoria | I31: 220 | J31: 16000 | K31: =16000/1.37 -> 11678.832 | L31: PJ | N31: Feminino | O31: 45897
A32: 26 | B32: PJ4 | C32: CONTROLLER TÉCNICO | E32: Não trabalhamos senioridade | F32: Tático | G32: Controladoria | I32: 220 | J32: 12663.6 | K32: =12663.6/1.37 -> 9243.5037 | L32: PJ | N32: Masculino | O32: 45898
A33: 27 | B33: 1959 | C33: COORDENADOR DE DHO | E33: Não trabalhamos senioridade | F33: Tático | G33: DHO | I33: 220 | J33: 7420 | K33: 7420 | L33: CLT | M33: 1422-05 | N33: Feminino | O33: 45899
A34: 28 | B34: 151 | C34: COORDENADOR DE LEGAIZAÇÃO ll | E34: Pleno | F34: Tático | G34: Legalização | I34: 220 | J34: 8647 | K34: 8647 | L34: CLT | M34: 840698 | N34: Masculino | O34: 45900
A35: 29 | B35: 1911 | C35: COORDENADOR DE MARKETING II | E35: Pleno | F35: Tático | G35: Marketing | I35: 220 | J35: 8647 | K35: 8647 | L35: CLT | M35: 1423-15 | N35: Feminino | O35: 45870
A36: 30 | B36: 1452 | C36: COORDENADOR DE OBRAS | E36: Não trabalhamos senioridade | F36: Operacional | G36: Edificação | I36: 220 | J36: 8714 | K36: 8714 | L36: CLT | M36: 1413-05 | N36: Masculino | O36: 45871
A37: 31 | B37: PJ5 | C37: COORDENADOR DE SUPRIMENTOS | E37: Não trabalhamos senioridade | F37: Tático | G37: Suprimentos | I37: 220 | J37: 16000 | K37: =16000/1.51 -> 10596.026 | L37: PJ | N37: Feminino | O37: 45872
A38: 32 | B38: PJ6 | C38: COORDENADOR FINANCEIRO | E38: Não trabalhamos senioridade | F38: Tático | G38: Financeiro | I38: 220 | J38: 12000 | K38: =12000/1.51 -> 7947.0199 | L38: PJ | N38: Masculino | O38: 45873
A39: 33 | B39: PJ7 | C39: DIRETOR | E39: Não trabalhamos senioridade | F39: Estratégico | G39: Comercial | I39: 220 | J39: 58000 | K39: =58000/1.04 -> 55769.231 | L39: PJ | N39: Masculino | O39: 45874
A40: 34 | B40: 132 | C40: ENCARREGADO DE OBRAS | E40: Não trabalhamos senioridade | F40: Operacional | G40: Urbanismo | I40: 220 | J40: 8461 | K40: 8461 | L40: CLT | M40: 1900113 | N40: Masculino | O40: 45875
A41: 34 | B41: 182 | C41: ENCARREGADO DE OBRAS | E41: Não trabalhamos senioridade | F41: Operacional | G41: Urbanismo | I41: 220 | J41: 11540 | K41: 11540 | L41: CLT | M41: 1900113 | N41: Masculino | O41: 45876
...

Sheet Jobmatch
A1: Jobmatch
A3: Cod. | B3: Cargos Empresa | C3: Área | D3: Departamento | E3: Nível Organizacional | F3: Cod. Pesquisa | G3: Cargos Pesquisa | H3: Senioridade | I3: Observações | J3: Tipo de Contrato | K3: Pesquisa | L3: Pesquisas
A4: 13 | B4: =VLOOKUP(A4,'Folha de Pagamento'!A:C,3,0) -> ASSISTENTE ADMINISTRATIVO lll | C4: =VLOOKUP(A4,'Folha de Pagamento'!A:G,7,0) -> Administrativo | D4: 20 - ADM PROJETOS | E4: =VLOOKUP(A4,'Folha de Pagamento'!A:F,6,0) -> Operacional | F4: 59 | G4: Assistente Administrativo | H4: Indiferente | O4: Geral
A5: 20 | B5: =VLOOKUP(A5,'Folha de Pagamento'!A:C,3,0) -> AUXILIAR ADMINISTRATIVO | C5: =VLOOKUP(A5,'Folha de Pagamento'!A:G,7,0) -> Administrativo | D5: 27 - ADM PROJETOS | E5: =VLOOKUP(A5,'Folha de Pagamento'!A:F,6,0) -> Operacional | F5: 83 | G5: Auxiliar Administrativo | H5: Indiferente | L5: Construção | O5: Geral
A6: 24 | B6: =VLOOKUP(A6,'Folha de Pagamento'!A:C,3,0) -> CONTROLER JURÍDICO | C6: =VLOOKUP(A6,'Folha de Pagamento'!A:G,7,0) -> Administrativo | D6: 31 - ADM PROJETOS | E6: =VLOOKUP(A6,'Folha de Pagamento'!A:F,6,0) -> Tático | F6: 9 | G6: Advogado | H6: Sênior | M6: TI | O6: Geral
A7: 39 | B7: =VLOOKUP(A7,'Folha de Pagamento'!A:C,3,0) -> ESTAGIÁRIO(A) ADM | C7: =VLOOKUP(A7,'Folha de Pagamento'!A:G,7,0) -> Administrativo | D7: 46 - ADM PROJETOS | E7: =VLOOKUP(A7,'Folha de Pagamento'!A:F,6,0) -> Operacional | F7: 338 | G7: Estagiário Administrativo | H7: Indiferente | L7: Construção | M7: TI | N7: Industria | O7: Geral
A8: 42 | B8: =VLOOKUP(A8,'Folha de Pagamento'!A:C,3,0) -> GERENTE ADMINISTRATIVA | C8: =VLOOKUP(A8,'Folha de Pagamento'!A:G,7,0) -> Administrativo | D8: 49 - ADM PROJETOS | E8: =VLOOKUP(A8,'Folha de Pagamento'!A:F,6,0) -> Tático | F8: 106 | G8: Gerente Administrativo | H8: Indiferente
A9: 33 | B9: =VLOOKUP(A9,'Folha de Pagamento'!A:C,3,0) -> DIRETOR | C9: =VLOOKUP(A9,'Folha de Pagamento'!A:G,7,0) -> Comercial | D9: 40 - ADM PROJETOS | E9: =VLOOKUP(A9,'Folha de Pagamento'!A:F,6,0) -> Estratégico | F9: 456 | G9: CEO | H9: Indiferente | L9: Construção | M9: TI | N9: Industria | O9: Geral
A10: 43 | B10: =VLOOKUP(A10,'Folha de Pagamento'!A:C,3,0) -> GERENTE COMERCIAL | C10: =VLOOKUP(A10,'Folha de Pagamento'!A:G,7,0) -> Comercial | D10: 50 - ADM PROJETOS | E10: =VLOOKUP(A10,'Folha de Pagamento'!A:F,6,0) -> Tático | F10: 107 | G10: Gerente Comercial | H10: Indiferente | L10: Construção | M10: TI | O10: Geral
A11: 45 | B11: =VLOOKUP(A11,'Folha de Pagamento'!A:C,3,0) -> GERENTE DE HOUSE | C11: =VLOOKUP(A11,'Folha de Pagamento'!A:G,7,0) -> Comercial | D11: 52 - ADM PROJETOS | E11: =VLOOKUP(A11,'Folha de Pagamento'!A:F,6,0) -> Tático | F11: 107 | G11: Gerente Comercial | H11: Indiferente
A12: 46 | B12: =VLOOKUP(A12,'Folha de Pagamento'!A:C,3,0) -> GERENTE DE IMOBILIÁRIAS EXTERNAS | C12: =VLOOKUP(A12,'Folha de Pagamento'!A:G,7,0) -> Comercial | D12: 53 - ADM PROJETOS | E12: =VLOOKUP(A12,'Folha de Pagamento'!A:F,6,0) -> Tático | F12: 1205 | G12: Gerente de Imobiliárias | H12: Indiferente | L12: Construção | O12: Geral
A13: 48 | B13: =VLOOKUP(A13,'Folha de Pagamento'!A:C,3,0) -> GERENTE DE PARCERIAS | C13: =VLOOKUP(A13,'Folha de Pagamento'!A:G,7,0) -> Comercial | D13: 55 - ADM PROJETOS | E13: =VLOOKUP(A13,'Folha de Pagamento'!A:F,6,0) -> Tático | F13: 408 | G13: Gerente de Relacionamento | H13: Indiferente
A14: 49 | B14: =VLOOKUP(A14,'Folha de Pagamento'!A:C,3,0) -> GERENTE DE PARCERIAS EXTERNAS | C14: =VLOOKUP(A14,'Folha de Pagamento'!A:G,7,0) -> Comercial | D14: 56 - ADM PROJETOS | E14: =VLOOKUP(A14,'Folha de Pagamento'!A:F,6,0) -> Tático | F14: 408 | G14: Gerente de Relacionamento | H14: Indiferente | L14: Construção | M14: TI | N14: Industria | O14: Geral
A15: 14 | B15: =VLOOKUP(A15,'Folha de Pagamento'!A:C,3,0) -> ASSISTENTE DE CONTROLADORIA III | C15: =VLOOKUP(A15,'Folha de Pagamento'!A:G,7,0) -> Controladoria | D15: 21 - ADM PROJETOS | E15: =VLOOKUP(A15,'Folha de Pagamento'!A:F,6,0) -> Operacional | F15: 150 | G15: Assistente de Controladoria | H15: Indiferente
A16: 25 | B16: =VLOOKUP(A16,'Folha de Pagamento'!A:C,3,0) -> CONTROLLER GERAL | C16: =VLOOKUP(A16,'Folha de Pagamento'!A:G,7,0) -> Controladoria | D16: 32 - ADM PROJETOS | E16: =VLOOKUP(A16,'Folha de Pagamento'!A:F,6,0) -> Tático | F16: 95 | G16: Controller | H16: Indiferente | M16: TI | N16: Industria | O16: Geral
A17: 26 | B17: =VLOOKUP(A17,'Folha de Pagamento'!A:C,3,0) -> CONTROLLER TÉCNICO | C17: =VLOOKUP(A17,'Folha de Pagamento'!A:G,7,0) -> Controladoria | D17: 33 - ADM PROJETOS | E17: =VLOOKUP(A17,'Folha de Pagamento'!A:F,6,0) -> Tático | F17: 26 | G17: Analista de Controladoria | H17: Especialista | M17: TI | O17: Geral
A18: 17 | B18: =VLOOKUP(A18,'Folha de Pagamento'!A:C,3,0) -> ASSISTENTE DE RECURSOS HUMANOS | C18: =VLOOKUP(A18,'Folha de Pagamento'!A:G,7,0) -> DHO | D18: 24 - ADM PROJETOS | E18: =VLOOKUP(A18,'Folha de Pagamento'!A:F,6,0) -> Operacional | F18: 77 | G18: Assistente de Recursos Humanos | H18: Indiferente | L18: Construção | M18: TI | N18: Industria | O18: Geral
A19: 27 | B19: =VLOOKUP(A19,'Folha de Pagamento'!A:C,3,0) -> COORDENADOR DE DHO | C19: =VLOOKUP(A19,'Folha de Pagamento'!A:G,7,0) -> DHO | D19: 34 - ADM PROJETOS | E19: =VLOOKUP(A19,'Folha de Pagamento'!A:F,6,0) -> Tático | F19: 121 | G19: Coordenador de Recursos Humanos | H19: Indiferente | L19: Construção | M19: TI | N19: Industria | O19: Geral
A20: 41 | B20: =VLOOKUP(A20,'Folha de Pagamento'!A:C,3,0) -> ESTAGIÁRIO(A) RH/DP | C20: =VLOOKUP(A20,'Folha de Pagamento'!A:G,7,0) -> DHO | D20: 48 - ADM PROJETOS | E20: =VLOOKUP(A20,'Folha de Pagamento'!A:F,6,0) -> Operacional | F20: 338 | G20: Estagiário Administrativo | H20: Indiferente | L20: Construção | M20: TI | O20: Geral
A21: 1 | B21: =VLOOKUP(A21,'Folha de Pagamento'!A:C,3,0) -> ALMOXARIFE | C21: =VLOOKUP(A21,'Folha de Pagamento'!A:G,7,0) -> Edificação | D21: 8 - ADM PROJETOS | E21: =VLOOKUP(A21,'Folha de Pagamento'!A:F,6,0) -> Operacional | F21: 203 | G21: Almoxarife | H21: Indiferente | L21: Construção | M21: TI | O21: Geral
A22: 5 | B22: =VLOOKUP(A22,'Folha de Pagamento'!A:C,3,0) -> ANALISTA DE MANUTENÇÃO II | C22: =VLOOKUP(A22,'Folha de Pagamento'!A:G,7,0) -> Edificação | D22: 12 - ADM PROJETOS | E22: =VLOOKUP(A22,'Folha de Pagamento'!A:F,6,0) -> Operacional | F22: 820 | G22: Encarregado de Manutenção | H22: Indiferente | L22: Construção | M22: TI | O22: Geral
A23: 15 | B23: =VLOOKUP(A23,'Folha de Pagamento'!A:C,3,0) -> ASSISTENTE DE ENGENHARIA lll | C23: =VLOOKUP(A23,'Folha de Pagamento'!A:G,7,0) -> Edificação | D23: 22 - ADM PROJETOS | E23: =VLOOKUP(A23,'Folha de Pagamento'!A:F,6,0) -> Operacional | F23: 531 | G23: Assistente de Engenharia | H23: Indiferente | O23: Geral
A24: 30 | B24: =VLOOKUP(A24,'Folha de Pagamento'!A:C,3,0) -> COORDENADOR DE OBRAS | C24: =VLOOKUP(A24,'Folha de Pagamento'!A:G,7,0) -> Edificação | D24: 37 - ADM PROJETOS | E24: Tático | F24: 209 | G24: Coordenador de Obras | H24: Indiferente | L24: Construção | M24: TI | N24: Industria | O24: Geral
A25: 35 | B25: =VLOOKUP(A25,'Folha de Pagamento'!A:C,3,0) -> ENCARREGADO OBRAS/MANUTENCAO | C25: =VLOOKUP(A25,'Folha de Pagamento'!A:G,7,0) -> Edificação | D25: 42 - ADM PROJETOS | E25: =VLOOKUP(A25,'Folha de Pagamento'!A:F,6,0) -> Operacional | F25: 470 | G25: Mestre de Obras | H25: Indiferente
A26: 37 | B26: =VLOOKUP(A26,'Folha de Pagamento'!A:C,3,0) -> ENGENHEIRO SÊNIOR | C26: =VLOOKUP(A26,'Folha de Pagamento'!A:G,7,0) -> Edificação | D26: 44 - ADM PROJETOS | E26: =VLOOKUP(A26,'Folha de Pagamento'!A:F,6,0) -> Tático | F26: 212 | G26: Engenheiro de Urbanismo | H26: Indiferente | L26: Construção | O26: Geral
A27: 44 | B27: =VLOOKUP(A27,'Folha de Pagamento'!A:C,3,0) -> GERENTE DE EDIFICAÇÕES | C27: =VLOOKUP(A27,'Folha de Pagamento'!A:G,7,0) -> Edificação | D27: 51 - ADM PROJETOS | E27: =VLOOKUP(A27,'Folha de Pagamento'!A:F,6,0) -> Tático | F27: 213 | G27: Gerente de Engenharia | H27: Indiferente | N27: Industria | O27: Geral
A28: 53 | B28: =VLOOKUP(A28,'Folha de Pagamento'!A:C,3,0) -> TECNICO ANALISTA DE CUSTOS | C28: =VLOOKUP(A28,'Folha de Pagamento'!A:G,7,0) -> Edificação | D28: 60 - ADM PROJETOS | E28: =VLOOKUP(A28,'Folha de Pagamento'!A:F,6,0) -> Operacional | F28: 876 | G28: Analista de Custos | H28: Indiferente | O28: Geral
A29: 54 | B29: =VLOOKUP(A29,'Folha de Pagamento'!A:C,3,0) -> TECNOLOGO EM CONSTRUÇÃO DE EDIFICIOS | C29: =VLOOKUP(A29,'Folha de Pagamento'!A:G,7,0) -> Edificação | D29: 61 - ADM PROJETOS | E29: =VLOOKUP(A29,'Folha de Pagamento'!A:F,6,0) -> Operacional | F29: 269 | G29: Técnico em Edificações | H29: Indiferente | L29: Construção | M29: TI | N29: Industria | O29: Geral
A30: 9 | B30: =VLOOKUP(A30,'Folha de Pagamento'!A:C,3,0) -> ANALISTA FINANCEIRO COMERCIAL III | C30: =VLOOKUP(A30,'Folha de Pagamento'!A:G,7,0) -> Financeiro | D30: 16 - ADM PROJETOS | E30: =VLOOKUP(A30,'Folha de Pagamento'!A:F,6,0) -> Operacional | F30: 16 | G30: Analista Financeiro | H30: Sênior | L30: Construção | M30: TI | O30: Geral
A31: 10 | B31: =VLOOKUP(A31,'Folha de Pagamento'!A:C,3,0) -> ANALISTA FINANCEIRO DE CAPTAÇÃO DE RECURSOS III | C31: =VLOOKUP(A31,'Folha de Pagamento'!A:G,7,0) -> Financeiro | D31: 17 - ADM PROJETOS | E31: =VLOOKUP(A31,'Folha de Pagamento'!A:F,6,0) -> Operacional | F31: 16 | G31: Analista Financeiro | H31: Sênior | L31: Construção | M31: TI | N31: Industria | O31: Geral
A32: 11 | B32: =VLOOKUP(A32,'Folha de Pagamento'!A:C,3,0) -> ANALISTA FINANCEIRO I | C32: =VLOOKUP(A32,'Folha de Pagamento'!A:G,7,0) -> Financeiro | D32: 18 - ADM PROJETOS | E32: =VLOOKUP(A32,'Folha de Pagamento'!A:F,6,0) -> Operacional | F32: 16 | G32: Analista Financeiro | H32: Júnior | L32: Construção | M32: TI | N32: Industria | O32: Geral
A33: 19 | B33: =VLOOKUP(A33,'Folha de Pagamento'!A:C,3,0) -> ASSISTENTE FINANCEIRO CONTAS A PAGAR | C33: =VLOOKUP(A33,'Folha de Pagamento'!A:G,7,0) -> Financeiro | D33: 26 - ADM PROJETOS | E33: =VLOOKUP(A33,'Folha de Pagamento'!A:F,6,0) -> Operacional | F33: 79 | G33: Assistente Financeiro | H33: Indiferente | L33: Construção | M33: TI | O33: Geral
A34: 32 | B34: =VLOOKUP(A34,'Folha de Pagamento'!A:C,3,0) -> COORDENADOR FINANCEIRO | C34: =VLOOKUP(A34,'Folha de Pagamento'!A:G,7,0) -> Financeiro | D34: 39 - ADM PROJETOS | E34: =VLOOKUP(A34,'Folha de Pagamento'!A:F,6,0) -> Tático | F34: 122 | G34: Coordenador Financeiro | H34: Indiferente | L34: Construção | M34: TI | O34: Geral
A35: 52 | B35: =VLOOKUP(A35,'Folha de Pagamento'!A:C,3,0) -> SUPERVISOR(A) FINANCEIRO I | C35: =VLOOKUP(A35,'Folha de Pagamento'!A:G,7,0) -> Financeiro | D35: 59 - ADM PROJETOS | E35: =VLOOKUP(A35,'Folha de Pagamento'!A:F,6,0) -> Operacional | F35: 469 | G35: Supervisor Financeiro | H35: Indiferente | L35: Construção | O35: Geral
A36: 47 | B36: =VLOOKUP(A36,'Folha de Pagamento'!A:C,3,0) -> GERENTE DE INCORPORAÇÃO | C36: =VLOOKUP(A36,'Folha de Pagamento'!A:G,7,0) -> Incorporação | D36: 54 - ADM PROJETOS | E36: =VLOOKUP(A36,'Folha de Pagamento'!A:F,6,0) -> Tático | F36: 548 | G36: Gerente de Incorporação | H36: Indiferente | L36: Construção | M36: TI | N36: Industria | O36: Geral
A37: 4 | B37: =VLOOKUP(A37,'Folha de Pagamento'!A:C,3,0) -> ANALISTA DE INOVAÇÃO | C37: =VLOOKUP(A37,'Folha de Pagamento'!A:G,7,0) -> Inovação | D37: 11 - ADM PROJETOS | E37: =VLOOKUP(A37,'Folha de Pagamento'!A:F,6,0) -> Tático | F37: 437 | G37: Analista de Inovação | H37: Indiferente
A38: 12 | B38: =VLOOKUP(A38,'Folha de Pagamento'!A:C,3,0) -> ASSISTENTE ADM DE LEGALIZAÇÃO III | C38: =VLOOKUP(A38,'Folha de Pagamento'!A:G,7,0) -> Legalização | D38: 19 - ADM PROJETOS | E38: =VLOOKUP(A38,'Folha de Pagamento'!A:F,6,0) -> Operacional | F38: 1201 | G38: Assistente de Legalização | H38: Indiferente
A39: 28 | B39: =VLOOKUP(A39,'Folha de Pagamento'!A:C,3,0) -> COORDENADOR DE LEGAIZAÇÃO ll | C39: =VLOOKUP(A39,'Folha de Pagamento'!A:G,7,0) -> Legalização | D39: 35 - ADM PROJETOS | E39: =VLOOKUP(A39,'Folha de Pagamento'!A:F,6,0) -> Tático | F39: 1203 | G39: Coordenador de Legalização | H39: Indiferente | L39: Construção | M39: TI | N39: Industria | O39: Geral
A40: 3 | B40: =VLOOKUP(A40,'Folha de Pagamento'!A:C,3,0) -> ANALISTA DE CRIAÇAO | C40: =VLOOKUP(A40,'Folha de Pagamento'!A:G,7,0) -> Marketing | D40: 10 - ADM PROJETOS | E40: =VLOOKUP(A40,'Folha de Pagamento'!A:F,6,0) -> Operacional | F40: 45 | G40: Analista de Criação | H40: Indiferente | L40: Construção | O40: Geral
A41: 6 | B41: =VLOOKUP(A41,'Folha de Pagamento'!A:C,3,0) -> ANALISTA DE MARKETING l | C41: =VLOOKUP(A41,'Folha de Pagamento'!A:G,7,0) -> Marketing | D41: 13 - ADM PROJETOS | E41: =VLOOKUP(A41,'Folha de Pagamento'!A:F,6,0) -> Operacional | F41: 42 | G41: Analista de Marketing | H41: Júnior | O41: Geral
...

Sheet Cálculos Comparativos
H1: DADOS PARA COMPARAÇÃO | M1: ='Informações Relevantes Pesquisa'!A1 -> Pesquisa Contrução Civil e Consolidadas | S1: ="% Distância da "&'Painel Geral'!B5 -> % Distância da Mediana | T1: Posicionamento
A3: Cod. | B3: Cargos Empresa | C3: Média Empresa CLT | D3: Cod. Área | E3: Diretoria | F3: Centro de Custo | G3: Nível Organizacional | H3: Cod. Pesquisa | I3: Cargos Pesquisa | J3: Senioridade | K3: Código+Senioridade | L3: Número de Colaboradores | M3: Menor Salário | N3: 1º Quartil | O3: Média | P3: Mediana | Q3: 3º Quartil | R3: Maior Salário | S3: C-01 | T3: C-01 (Posicionamento)
A4: 1 | B4: =VLOOKUP(A4,Jobmatch!A:G,2,0) -> ALMOXARIFE | C4: =IFERROR(AVERAGEIF('Folha de Pagamento'!A:A,A4,'Folha de Pagamento'!K:K),"") -> 3683 | D4: 5 | E4: =VLOOKUP(A4,Jobmatch!A:H,3,0) -> Edificação | F4: =VLOOKUP(A4,Jobmatch!A:I,4,0) -> 8 - ADM PROJETOS | G4: =VLOOKUP(A4,Jobmatch!A:I,5,0) -> Operacional | H4: =VLOOKUP(A4,Jobmatch!A:I,6,0) -> 203 | I4: =VLOOKUP(A4,Jobmatch!A:I,7,0) -> Almoxarife | J4: =VLOOKUP(A4,Jobmatch!A:I,8,0) -> Indiferente | K4: =H4&J4 -> 203Indiferente | L4: =COUNTIF('Folha de Pagamento'!A:A,A4) -> 2 | M4: =IFERROR(VLOOKUP(K4,Pesquisa!$D:$L,4,0),"") -> 2973.35 | N4: =IFERROR(VLOOKUP(K4,Pesquisa!$D:$L,5,0),"") -> 3096.32 | O4: =IFERROR(VLOOKUP(K4,Pesquisa!$D:$L,6,0),"") -> 3405.54 | P4: =IFERROR(VLOOKUP(K4,Pesquisa!$D:$L,7,0),"") -> 3096.32 | Q4: =IFERROR(VLOOKUP(K4,Pesquisa!$D:$L,8,0),"") -> 3712.15 | R4: =IFERROR(VLOOKUP(K4,Pesquisa!$D:$L,9,0),"") -> 4435.84 | S4: =IFS('Painel Geral'!$B$5="Mediana",IFERROR(IF(OR(C4="",P4=0,P4=""),"",($C4/$P4)),""),'Painel Geral'!$B$5="Menor Salário",IFERROR(IF(OR(C4="",P4=0,P4=""),"",($C4/$M4)),""),'Painel Geral'!$B$5="1º Quartil",IFERROR(IF(OR(C4="",P4=0,P4=""),"",($C4/$N4)),""), 'Painel Geral'!$B$5="Média",IFERROR(IF(OR(C4="",P4=0,P4=""),"",($C4/$O4)),""),'Painel Geral'!$B$5="3º Quartil",IFERROR(IF(OR(C4="",P4=0,P4=""),"",($C4/$Q4)),""),'Painel Geral'!$B$5="Maior Salário",IFERROR(IF(OR(C4="",P4=0,P4=""),"",($C4/$R4)),"")) -> 1.1894765 | T4: =IFS(OR(M4="",M4=0,C4="", C4=0),"",S4<=80%,"Muito Defasado",S4<=90%,"Defasado",S4<=100%,"Na Média",S4<=110%,"Na Média",S4<=120%,"Muito Competitivo",S4>120%,"Agressivo") -> Muito Competitivo
A5: 2 | B5: =VLOOKUP(A5,Jobmatch!A:G,2,0) -> ANALISTA DE COMPRAS | C5: =IFERROR(AVERAGEIF('Folha de Pagamento'!A:A,A5,'Folha de Pagamento'!K:K),"") -> 3780 | D5: 1 | E5: =VLOOKUP(A5,Jobmatch!A:H,3,0) -> Suprimentos | F5: =VLOOKUP(A5,Jobmatch!A:I,4,0) -> 9 - ADM PROJETOS | G5: =VLOOKUP(A5,Jobmatch!A:I,5,0) -> Operacional | H5: =VLOOKUP(A5,Jobmatch!A:I,6,0) -> 136 | I5: =VLOOKUP(A5,Jobmatch!A:I,7,0) -> Analista de Compras | J5: =VLOOKUP(A5,Jobmatch!A:I,8,0) -> Pleno | K5: =H5&J5 -> 136Pleno | L5: =COUNTIF('Folha de Pagamento'!A:A,A5) -> 1 | M5: =IFERROR(VLOOKUP(K5,Pesquisa!$D:$L,4,0),"") -> 4535.62 | N5: =IFERROR(VLOOKUP(K5,Pesquisa!$D:$L,5,0),"") -> 4535.62 | O5: =IFERROR(VLOOKUP(K5,Pesquisa!$D:$L,6,0),"") -> 6016.64 | P5: =IFERROR(VLOOKUP(K5,Pesquisa!$D:$L,7,0),"") -> 5288.53 | Q5: =IFERROR(VLOOKUP(K5,Pesquisa!$D:$L,8,0),"") -> 7861.72 | R5: =IFERROR(VLOOKUP(K5,Pesquisa!$D:$L,9,0),"") -> 7861.72 | S5: =IFS('Painel Geral'!$B$5="Mediana",IFERROR(IF(OR(C5="",P5=0,P5=""),"",($C5/$P5)),""),'Painel Geral'!$B$5="Menor Salário",IFERROR(IF(OR(C5="",P5=0,P5=""),"",($C5/$M5)),""),'Painel Geral'!$B$5="1º Quartil",IFERROR(IF(OR(C5="",P5=0,P5=""),"",($C5/$N5)),""), 'Painel Geral'!$B$5="Média",IFERROR(IF(OR(C5="",P5=0,P5=""),"",($C5/$O5)),""),'Painel Geral'!$B$5="3º Quartil",IFERROR(IF(OR(C5="",P5=0,P5=""),"",($C5/$Q5)),""),'Painel Geral'!$B$5="Maior Salário",IFERROR(IF(OR(C5="",P5=0,P5=""),"",($C5/$R5)),"")) -> 0.71475438 | T5: =IFS(OR(M5="",M5=0,C5="", C5=0),"",S5<=80%,"Muito Defasado",S5<=90%,"Defasado",S5<=100%,"Na Média",S5<=110%,"Na Média",S5<=120%,"Muito Competitivo",S5>120%,"Agressivo") -> Muito Defasado
A6: 3 | B6: =VLOOKUP(A6,Jobmatch!A:G,2,0) -> ANALISTA DE CRIAÇAO | C6: =IFERROR(AVERAGEIF('Folha de Pagamento'!A:A,A6,'Folha de Pagamento'!K:K),"") -> 5429 | D6: 8 | E6: =VLOOKUP(A6,Jobmatch!A:H,3,0) -> Marketing | F6: =VLOOKUP(A6,Jobmatch!A:I,4,0) -> 10 - ADM PROJETOS | G6: =VLOOKUP(A6,Jobmatch!A:I,5,0) -> Operacional | H6: =VLOOKUP(A6,Jobmatch!A:I,6,0) -> 45 | I6: =VLOOKUP(A6,Jobmatch!A:I,7,0) -> Analista de Criação | J6: =VLOOKUP(A6,Jobmatch!A:I,8,0) -> Indiferente | K6: =H6&J6 -> 45Indiferente | L6: =COUNTIF('Folha de Pagamento'!A:A,A6) -> 1 | M6: =IFERROR(VLOOKUP(K6,Pesquisa!$D:$L,4,0),"") -> 2771.48 | N6: =IFERROR(VLOOKUP(K6,Pesquisa!$D:$L,5,0),"") -> 3527.33 | O6: =IFERROR(VLOOKUP(K6,Pesquisa!$D:$L,6,0),"") -> 4325.16 | P6: =IFERROR(VLOOKUP(K6,Pesquisa!$D:$L,7,0),"") -> 4325.72 | Q6: =IFERROR(VLOOKUP(K6,Pesquisa!$D:$L,8,0),"") -> 4988.66 | R6: =IFERROR(VLOOKUP(K6,Pesquisa!$D:$L,9,0),"") -> 6418.74 | S6: =IFS('Painel Geral'!$B$5="Mediana",IFERROR(IF(OR(C6="",P6=0,P6=""),"",($C6/$P6)),""),'Painel Geral'!$B$5="Menor Salário",IFERROR(IF(OR(C6="",P6=0,P6=""),"",($C6/$M6)),""),'Painel Geral'!$B$5="1º Quartil",IFERROR(IF(OR(C6="",P6=0,P6=""),"",($C6/$N6)),""), 'Painel Geral'!$B$5="Média",IFERROR(IF(OR(C6="",P6=0,P6=""),"",($C6/$O6)),""),'Painel Geral'!$B$5="3º Quartil",IFERROR(IF(OR(C6="",P6=0,P6=""),"",($C6/$Q6)),""),'Painel Geral'!$B$5="Maior Salário",IFERROR(IF(OR(C6="",P6=0,P6=""),"",($C6/$R6)),"")) -> 1.2550512 | T6: =IFS(OR(M6="",M6=0,C6="", C6=0),"",S6<=80%,"Muito Defasado",S6<=90%,"Defasado",S6<=100%,"Na Média",S6<=110%,"Na Média",S6<=120%,"Muito Competitivo",S6>120%,"Agressivo") -> Agressivo
A7: 4 | B7: =VLOOKUP(A7,Jobmatch!A:G,2,0) -> ANALISTA DE INOVAÇÃO | C7: =IFERROR(AVERAGEIF('Folha de Pagamento'!A:A,A7,'Folha de Pagamento'!K:K),"") -> 7299.2701 | D7: 7 | E7: =VLOOKUP(A7,Jobmatch!A:H,3,0) -> Inovação | F7: =VLOOKUP(A7,Jobmatch!A:I,4,0) -> 11 - ADM PROJETOS | G7: =VLOOKUP(A7,Jobmatch!A:I,5,0) -> Tático | H7: =VLOOKUP(A7,Jobmatch!A:I,6,0) -> 437 | I7: =VLOOKUP(A7,Jobmatch!A:I,7,0) -> Analista de Inovação | J7: =VLOOKUP(A7,Jobmatch!A:I,8,0) -> Indiferente | K7: =H7&J7 -> 437Indiferente | L7: =COUNTIF('Folha de Pagamento'!A:A,A7) -> 1 | M7: =IFERROR(VLOOKUP(K7,Pesquisa!$D:$L,4,0),"") -> 5039.5 | N7: =IFERROR(VLOOKUP(K7,Pesquisa!$D:$L,5,0),"") -> 5955.7727 | O7: =IFERROR(VLOOKUP(K7,Pesquisa!$D:$L,6,0),"") -> 6515.7172 | P7: =IFERROR(VLOOKUP(K7,Pesquisa!$D:$L,7,0),"") -> 6872.0455 | Q7: =IFERROR(VLOOKUP(K7,Pesquisa!$D:$L,8,0),"") -> 7253.8258 | R7: =IFERROR(VLOOKUP(K7,Pesquisa!$D:$L,9,0),"") -> 7635.6061 | S7: =IFS('Painel Geral'!$B$5="Mediana",IFERROR(IF(OR(C7="",P7=0,P7=""),"",($C7/$P7)),""),'Painel Geral'!$B$5="Menor Salário",IFERROR(IF(OR(C7="",P7=0,P7=""),"",($C7/$M7)),""),'Painel Geral'!$B$5="1º Quartil",IFERROR(IF(OR(C7="",P7=0,P7=""),"",($C7/$N7)),""), 'Painel Geral'!$B$5="Média",IFERROR(IF(OR(C7="",P7=0,P7=""),"",($C7/$O7)),""),'Painel Geral'!$B$5="3º Quartil",IFERROR(IF(OR(C7="",P7=0,P7=""),"",($C7/$Q7)),""),'Painel Geral'!$B$5="Maior Salário",IFERROR(IF(OR(C7="",P7=0,P7=""),"",($C7/$R7)),"")) -> 1.0621685 | T7: =IFS(OR(M7="",M7=0,C7="", C7=0),"",S7<=80%,"Muito Defasado",S7<=90%,"Defasado",S7<=100%,"Na Média",S7<=110%,"Na Média",S7<=120%,"Muito Competitivo",S7>120%,"Agressivo") -> Na Média
A8: 5 | B8: =VLOOKUP(A8,Jobmatch!A:G,2,0) -> ANALISTA DE MANUTENÇÃO II | C8: =IFERROR(AVERAGEIF('Folha de Pagamento'!A:A,A8,'Folha de Pagamento'!K:K),"") -> 4550 | D8: 5 | E8: =VLOOKUP(A8,Jobmatch!A:H,3,0) -> Edificação | F8: =VLOOKUP(A8,Jobmatch!A:I,4,0) -> 12 - ADM PROJETOS | G8: =VLOOKUP(A8,Jobmatch!A:I,5,0) -> Operacional | H8: =VLOOKUP(A8,Jobmatch!A:I,6,0) -> 820 | I8: =VLOOKUP(A8,Jobmatch!A:I,7,0) -> Encarregado de Manutenção | J8: =VLOOKUP(A8,Jobmatch!A:I,8,0) -> Indiferente | K8: =H8&J8 -> 820Indiferente | L8: =COUNTIF('Folha de Pagamento'!A:A,A8) -> 1 | M8: =IFERROR(VLOOKUP(K8,Pesquisa!$D:$L,4,0),"") -> 4348.38 | N8: =IFERROR(VLOOKUP(K8,Pesquisa!$D:$L,5,0),"") -> 5743.67 | O8: =IFERROR(VLOOKUP(K8,Pesquisa!$D:$L,6,0),"") -> 6811.3 | P8: =IFERROR(VLOOKUP(K8,Pesquisa!$D:$L,7,0),"") -> 6232.3 | Q8: =IFERROR(VLOOKUP(K8,Pesquisa!$D:$L,8,0),"") -> 8417.62 | R8: =IFERROR(VLOOKUP(K8,Pesquisa!$D:$L,9,0),"") -> 9486.51 | S8: =IFS('Painel Geral'!$B$5="Mediana",IFERROR(IF(OR(C8="",P8=0,P8=""),"",($C8/$P8)),""),'Painel Geral'!$B$5="Menor Salário",IFERROR(IF(OR(C8="",P8=0,P8=""),"",($C8/$M8)),""),'Painel Geral'!$B$5="1º Quartil",IFERROR(IF(OR(C8="",P8=0,P8=""),"",($C8/$N8)),""), 'Painel Geral'!$B$5="Média",IFERROR(IF(OR(C8="",P8=0,P8=""),"",($C8/$O8)),""),'Painel Geral'!$B$5="3º Quartil",IFERROR(IF(OR(C8="",P8=0,P8=""),"",($C8/$Q8)),""),'Painel Geral'!$B$5="Maior Salário",IFERROR(IF(OR(C8="",P8=0,P8=""),"",($C8/$R8)),"")) -> 0.73006755 | T8: =IFS(OR(M8="",M8=0,C8="", C8=0),"",S8<=80%,"Muito Defasado",S8<=90%,"Defasado",S8<=100%,"Na Média",S8<=110%,"Na Média",S8<=120%,"Muito Competitivo",S8>120%,"Agressivo") -> Muito Defasado
A9: 6 | B9: =VLOOKUP(A9,Jobmatch!A:G,2,0) -> ANALISTA DE MARKETING l | C9: =IFERROR(AVERAGEIF('Folha de Pagamento'!A:A,A9,'Folha de Pagamento'!K:K),"") -> 4025.88 | D9: 8 | E9: =VLOOKUP(A9,Jobmatch!A:H,3,0) -> Marketing | F9: =VLOOKUP(A9,Jobmatch!A:I,4,0) -> 13 - ADM PROJETOS | G9: =VLOOKUP(A9,Jobmatch!A:I,5,0) -> Operacional | H9: =VLOOKUP(A9,Jobmatch!A:I,6,0) -> 42 | I9: =VLOOKUP(A9,Jobmatch!A:I,7,0) -> Analista de Marketing | J9: =VLOOKUP(A9,Jobmatch!A:I,8,0) -> Júnior | K9: =H9&J9 -> 42Júnior | L9: =COUNTIF('Folha de Pagamento'!A:A,A9) -> 1 | M9: =IFERROR(VLOOKUP(K9,Pesquisa!$D:$L,4,0),"") -> 3225.33 | N9: =IFERROR(VLOOKUP(K9,Pesquisa!$D:$L,5,0),"") -> 3261.57 | O9: =IFERROR(VLOOKUP(K9,Pesquisa!$D:$L,6,0),"") -> 4114.38 | P9: =IFERROR(VLOOKUP(K9,Pesquisa!$D:$L,7,0),"") -> 3297.81 | Q9: =IFERROR(VLOOKUP(K9,Pesquisa!$D:$L,8,0),"") -> 4558.91 | R9: =IFERROR(VLOOKUP(K9,Pesquisa!$D:$L,9,0),"") -> 5820.01 | S9: =IFS('Painel Geral'!$B$5="Mediana",IFERROR(IF(OR(C9="",P9=0,P9=""),"",($C9/$P9)),""),'Painel Geral'!$B$5="Menor Salário",IFERROR(IF(OR(C9="",P9=0,P9=""),"",($C9/$M9)),""),'Painel Geral'!$B$5="1º Quartil",IFERROR(IF(OR(C9="",P9=0,P9=""),"",($C9/$N9)),""), 'Painel Geral'!$B$5="Média",IFERROR(IF(OR(C9="",P9=0,P9=""),"",($C9/$O9)),""),'Painel Geral'!$B$5="3º Quartil",IFERROR(IF(OR(C9="",P9=0,P9=""),"",($C9/$Q9)),""),'Painel Geral'!$B$5="Maior Salário",IFERROR(IF(OR(C9="",P9=0,P9=""),"",($C9/$R9)),"")) -> 1.2207738 | T9: =IFS(OR(M9="",M9=0,C9="", C9=0),"",S9<=80%,"Muito Defasado",S9<=90%,"Defasado",S9<=100%,"Na Média",S9<=110%,"Na Média",S9<=120%,"Muito Competitivo",S9>120%,"Agressivo") -> Agressivo
A10: 7 | B10: =VLOOKUP(A10,Jobmatch!A:G,2,0) -> ANALISTA DE PÓS VENDAS II | C10: =IFERROR(AVERAGEIF('Folha de Pagamento'!A:A,A10,'Folha de Pagamento'!K:K),"") -> 4550 | D10: 9 | E10: =VLOOKUP(A10,Jobmatch!A:H,3,0) -> Pós Vendas | F10: =VLOOKUP(A10,Jobmatch!A:I,4,0) -> 14 - ADM PROJETOS | G10: =VLOOKUP(A10,Jobmatch!A:I,5,0) -> Operacional | H10: =VLOOKUP(A10,Jobmatch!A:I,6,0) -> 376 | I10: =VLOOKUP(A10,Jobmatch!A:I,7,0) -> Analista de Relacionamento | J10: =VLOOKUP(A10,Jobmatch!A:I,8,0) -> Indiferente | K10: =H10&J10 -> 376Indiferente | L10: =COUNTIF('Folha de Pagamento'!A:A,A10) -> 1 | M10: =IFERROR(VLOOKUP(K10,Pesquisa!$D:$L,4,0),"") -> 2872.56 | N10: =IFERROR(VLOOKUP(K10,Pesquisa!$D:$L,5,0),"") -> 3241.46 | O10: =IFERROR(VLOOKUP(K10,Pesquisa!$D:$L,6,0),"") -> 3918.59 | P10: =IFERROR(VLOOKUP(K10,Pesquisa!$D:$L,7,0),"") -> 3830.08 | Q10: =IFERROR(VLOOKUP(K10,Pesquisa!$D:$L,8,0),"") -> 4233.24 | R10: =IFERROR(VLOOKUP(K10,Pesquisa!$D:$L,9,0),"") -> 5820.01 | S10: =IFS('Painel Geral'!$B$5="Mediana",IFERROR(IF(OR(C10="",P10=0,P10=""),"",($C10/$P10)),""),'Painel Geral'!$B$5="Menor Salário",IFERROR(IF(OR(C10="",P10=0,P10=""),"",($C10/$M10)),""),'Painel Geral'!$B$5="1º Quartil",IFERROR(IF(OR(C10="",P10=0,P10=""),"",($C10/$N10)),""), 'Painel Geral'!$B$5="Média",IFERROR(IF(OR(C10="",P10=0,P10=""),"",($C10/$O10)),""),'Painel Geral'!$B$5="3º Quartil",IFERROR(IF(OR(C10="",P10=0,P10=""),"",($C10/$Q10)),""),'Painel Geral'!$B$5="Maior Salário",IFERROR(IF(OR(C10="",P10=0,P10=""),"",($C10/$R10)),"")) -> 1.1879647 | T10: =IFS(OR(M10="",M10=0,C10="", C10=0),"",S10<=80%,"Muito Defasado",S10<=90%,"Defasado",S10<=100%,"Na Média",S10<=110%,"Na Média",S10<=120%,"Muito Competitivo",S10>120%,"Agressivo") -> Muito Competitivo
A11: 8 | B11: =VLOOKUP(A11,Jobmatch!A:G,2,0) -> ANALISTA DE URBANISMO | C11: =IFERROR(AVERAGEIF('Folha de Pagamento'!A:A,A11,'Folha de Pagamento'!K:K),"") -> 5830 | D11: 10 | E11: =VLOOKUP(A11,Jobmatch!A:H,3,0) -> Urbanismo | F11: =VLOOKUP(A11,Jobmatch!A:I,4,0) -> 15 - ADM PROJETOS | G11: =VLOOKUP(A11,Jobmatch!A:I,5,0) -> Operacional | H11: =VLOOKUP(A11,Jobmatch!A:I,6,0) -> 1199 | I11: =VLOOKUP(A11,Jobmatch!A:I,7,0) -> Analista de Urbanismo | J11: =VLOOKUP(A11,Jobmatch!A:I,8,0) -> Indiferente | K11: =H11&J11 -> 1199Indiferente | L11: =COUNTIF('Folha de Pagamento'!A:A,A11) -> 1 | M11: =IFERROR(VLOOKUP(K11,Pesquisa!$D:$L,4,0),"") -> 5876.15 | N11: =IFERROR(VLOOKUP(K11,Pesquisa!$D:$L,5,0),"") -> 6106.16 | O11: =IFERROR(VLOOKUP(K11,Pesquisa!$D:$L,6,0),"") -> 7655.79 | P11: =IFERROR(VLOOKUP(K11,Pesquisa!$D:$L,7,0),"") -> 7867.3 | Q11: =IFERROR(VLOOKUP(K11,Pesquisa!$D:$L,8,0),"") -> 9183.14 | R11: =IFERROR(VLOOKUP(K11,Pesquisa!$D:$L,9,0),"") -> 9183.14 | S11: =IFS('Painel Geral'!$B$5="Mediana",IFERROR(IF(OR(C11="",P11=0,P11=""),"",($C11/$P11)),""),'Painel Geral'!$B$5="Menor Salário",IFERROR(IF(OR(C11="",P11=0,P11=""),"",($C11/$M11)),""),'Painel Geral'!$B$5="1º Quartil",IFERROR(IF(OR(C11="",P11=0,P11=""),"",($C11/$N11)),""), 'Painel Geral'!$B$5="Média",IFERROR(IF(OR(C11="",P11=0,P11=""),"",($C11/$O11)),""),'Painel Geral'!$B$5="3º Quartil",IFERROR(IF(OR(C11="",P11=0,P11=""),"",($C11/$Q11)),""),'Painel Geral'!$B$5="Maior Salário",IFERROR(IF(OR(C11="",P11=0,P11=""),"",($C11/$R11)),"")) -> 0.74104203 | T11: =IFS(OR(M11="",M11=0,C11="", C11=0),"",S11<=80%,"Muito Defasado",S11<=90%,"Defasado",S11<=100%,"Na Média",S11<=110%,"Na Média",S11<=120%,"Muito Competitivo",S11>120%,"Agressivo") -> Muito Defasado
A12: 9 | B12: =VLOOKUP(A12,Jobmatch!A:G,2,0) -> ANALISTA FINANCEIRO COMERCIAL III | C12: =IFERROR(AVERAGEIF('Folha de Pagamento'!A:A,A12,'Folha de Pagamento'!K:K),"") -> 5213 | D12: 6 | E12: =VLOOKUP(A12,Jobmatch!A:H,3,0) -> Financeiro | F12: =VLOOKUP(A12,Jobmatch!A:I,4,0) -> 16 - ADM PROJETOS | G12: =VLOOKUP(A12,Jobmatch!A:I,5,0) -> Operacional | H12: =VLOOKUP(A12,Jobmatch!A:I,6,0) -> 16 | I12: =VLOOKUP(A12,Jobmatch!A:I,7,0) -> Analista Financeiro | J12: =VLOOKUP(A12,Jobmatch!A:I,8,0) -> Sênior | K12: =H12&J12 -> 16Sênior | L12: =COUNTIF('Folha de Pagamento'!A:A,A12) -> 1 | M12: =IFERROR(VLOOKUP(K12,Pesquisa!$D:$L,4,0),"") -> 4882.37 | N12: =IFERROR(VLOOKUP(K12,Pesquisa!$D:$L,5,0),"") -> 5489.27 | O12: =IFERROR(VLOOKUP(K12,Pesquisa!$D:$L,6,0),"") -> 6172.24 | P12: =IFERROR(VLOOKUP(K12,Pesquisa!$D:$L,7,0),"") -> 5910.71 | Q12: =IFERROR(VLOOKUP(K12,Pesquisa!$D:$L,8,0),"") -> 6737.39 | R12: =IFERROR(VLOOKUP(K12,Pesquisa!$D:$L,9,0),"") -> 8185.08 | S12: =IFS('Painel Geral'!$B$5="Mediana",IFERROR(IF(OR(C12="",P12=0,P12=""),"",($C12/$P12)),""),'Painel Geral'!$B$5="Menor Salário",IFERROR(IF(OR(C12="",P12=0,P12=""),"",($C12/$M12)),""),'Painel Geral'!$B$5="1º Quartil",IFERROR(IF(OR(C12="",P12=0,P12=""),"",($C12/$N12)),""), 'Painel Geral'!$B$5="Média",IFERROR(IF(OR(C12="",P12=0,P12=""),"",($C12/$O12)),""),'Painel Geral'!$B$5="3º Quartil",IFERROR(IF(OR(C12="",P12=0,P12=""),"",($C12/$Q12)),""),'Painel Geral'!$B$5="Maior Salário",IFERROR(IF(OR(C12="",P12=0,P12=""),"",($C12/$R12)),"")) -> 0.88195834 | T12: =IFS(OR(M12="",M12=0,C12="", C12=0),"",S12<=80%,"Muito Defasado",S12<=90%,"Defasado",S12<=100%,"Na Média",S12<=110%,"Na Média",S12<=120%,"Muito Competitivo",S12>120%,"Agressivo") -> Defasado
A13: 10 | B13: =VLOOKUP(A13,Jobmatch!A:G,2,0) -> ANALISTA FINANCEIRO DE CAPTAÇÃO DE RECURSOS III | C13: =IFERROR(AVERAGEIF('Folha de Pagamento'!A:A,A13,'Folha de Pagamento'!K:K),"") -> 5213 | D13: 6 | E13: =VLOOKUP(A13,Jobmatch!A:H,3,0) -> Financeiro | F13: =VLOOKUP(A13,Jobmatch!A:I,4,0) -> 17 - ADM PROJETOS | G13: =VLOOKUP(A13,Jobmatch!A:I,5,0) -> Operacional | H13: =VLOOKUP(A13,Jobmatch!A:I,6,0) -> 16 | I13: =VLOOKUP(A13,Jobmatch!A:I,7,0) -> Analista Financeiro | J13: =VLOOKUP(A13,Jobmatch!A:I,8,0) -> Sênior | K13: =H13&J13 -> 16Sênior | L13: =COUNTIF('Folha de Pagamento'!A:A,A13) -> 1 | M13: =IFERROR(VLOOKUP(K13,Pesquisa!$D:$L,4,0),"") -> 4882.37 | N13: =IFERROR(VLOOKUP(K13,Pesquisa!$D:$L,5,0),"") -> 5489.27 | O13: =IFERROR(VLOOKUP(K13,Pesquisa!$D:$L,6,0),"") -> 6172.24 | P13: =IFERROR(VLOOKUP(K13,Pesquisa!$D:$L,7,0),"") -> 5910.71 | Q13: =IFERROR(VLOOKUP(K13,Pesquisa!$D:$L,8,0),"") -> 6737.39 | R13: =IFERROR(VLOOKUP(K13,Pesquisa!$D:$L,9,0),"") -> 8185.08 | S13: =IFS('Painel Geral'!$B$5="Mediana",IFERROR(IF(OR(C13="",P13=0,P13=""),"",($C13/$P13)),""),'Painel Geral'!$B$5="Menor Salário",IFERROR(IF(OR(C13="",P13=0,P13=""),"",($C13/$M13)),""),'Painel Geral'!$B$5="1º Quartil",IFERROR(IF(OR(C13="",P13=0,P13=""),"",($C13/$N13)),""), 'Painel Geral'!$B$5="Média",IFERROR(IF(OR(C13="",P13=0,P13=""),"",($C13/$O13)),""),'Painel Geral'!$B$5="3º Quartil",IFERROR(IF(OR(C13="",P13=0,P13=""),"",($C13/$Q13)),""),'Painel Geral'!$B$5="Maior Salário",IFERROR(IF(OR(C13="",P13=0,P13=""),"",($C13/$R13)),"")) -> 0.88195834 | T13: =IFS(OR(M13="",M13=0,C13="", C13=0),"",S13<=80%,"Muito Defasado",S13<=90%,"Defasado",S13<=100%,"Na Média",S13<=110%,"Na Média",S13<=120%,"Muito Competitivo",S13>120%,"Agressivo") -> Defasado
A14: 11 | B14: =VLOOKUP(A14,Jobmatch!A:G,2,0) -> ANALISTA FINANCEIRO I | C14: =IFERROR(AVERAGEIF('Folha de Pagamento'!A:A,A14,'Folha de Pagamento'!K:K),"") -> 3993 | D14: 6 | E14: =VLOOKUP(A14,Jobmatch!A:H,3,0) -> Financeiro | F14: =VLOOKUP(A14,Jobmatch!A:I,4,0) -> 18 - ADM PROJETOS | G14: =VLOOKUP(A14,Jobmatch!A:I,5,0) -> Operacional | H14: =VLOOKUP(A14,Jobmatch!A:I,6,0) -> 16 | I14: =VLOOKUP(A14,Jobmatch!A:I,7,0) -> Analista Financeiro | J14: =VLOOKUP(A14,Jobmatch!A:I,8,0) -> Júnior | K14: =H14&J14 -> 16Júnior | L14: =COUNTIF('Folha de Pagamento'!A:A,A14) -> 1 | M14: =IFERROR(VLOOKUP(K14,Pesquisa!$D:$L,4,0),"") -> 2937.55 | N14: =IFERROR(VLOOKUP(K14,Pesquisa!$D:$L,5,0),"") -> 3176.35 | O14: =IFERROR(VLOOKUP(K14,Pesquisa!$D:$L,6,0),"") -> 3539.11 | P14: =IFERROR(VLOOKUP(K14,Pesquisa!$D:$L,7,0),"") -> 3493.97 | Q14: =IFERROR(VLOOKUP(K14,Pesquisa!$D:$L,8,0),"") -> 3798.49 | R14: =IFERROR(VLOOKUP(K14,Pesquisa!$D:$L,9,0),"") -> 4392.23 | S14: =IFS('Painel Geral'!$B$5="Mediana",IFERROR(IF(OR(C14="",P14=0,P14=""),"",($C14/$P14)),""),'Painel Geral'!$B$5="Menor Salário",IFERROR(IF(OR(C14="",P14=0,P14=""),"",($C14/$M14)),""),'Painel Geral'!$B$5="1º Quartil",IFERROR(IF(OR(C14="",P14=0,P14=""),"",($C14/$N14)),""), 'Painel Geral'!$B$5="Média",IFERROR(IF(OR(C14="",P14=0,P14=""),"",($C14/$O14)),""),'Painel Geral'!$B$5="3º Quartil",IFERROR(IF(OR(C14="",P14=0,P14=""),"",($C14/$Q14)),""),'Painel Geral'!$B$5="Maior Salário",IFERROR(IF(OR(C14="",P14=0,P14=""),"",($C14/$R14)),"")) -> 1.1428261 | T14: =IFS(OR(M14="",M14=0,C14="", C14=0),"",S14<=80%,"Muito Defasado",S14<=90%,"Defasado",S14<=100%,"Na Média",S14<=110%,"Na Média",S14<=120%,"Muito Competitivo",S14>120%,"Agressivo") -> Muito Competitivo
A15: 12 | B15: =VLOOKUP(A15,Jobmatch!A:G,2,0) -> ASSISTENTE ADM DE LEGALIZAÇÃO III | C15: =IFERROR(AVERAGEIF('Folha de Pagamento'!A:A,A15,'Folha de Pagamento'!K:K),"") -> 3652 | D15: 7 | E15: =VLOOKUP(A15,Jobmatch!A:H,3,0) -> Legalização | F15: =VLOOKUP(A15,Jobmatch!A:I,4,0) -> 19 - ADM PROJETOS | G15: =VLOOKUP(A15,Jobmatch!A:I,5,0) -> Operacional | H15: =VLOOKUP(A15,Jobmatch!A:I,6,0) -> 1201 | I15: =VLOOKUP(A15,Jobmatch!A:I,7,0) -> Assistente de Legalização | J15: =VLOOKUP(A15,Jobmatch!A:I,8,0) -> Indiferente | K15: =H15&J15 -> 1201Indiferente | L15: =COUNTIF('Folha de Pagamento'!A:A,A15) -> 1 | M15: =IFERROR(VLOOKUP(K15,Pesquisa!$D:$L,4,0),"") -> 2513.75 | N15: =IFERROR(VLOOKUP(K15,Pesquisa!$D:$L,5,0),"") -> 2803.34 | O15: =IFERROR(VLOOKUP(K15,Pesquisa!$D:$L,6,0),"") -> 3092.92 | P15: =IFERROR(VLOOKUP(K15,Pesquisa!$D:$L,7,0),"") -> 3092.92 | Q15: =IFERROR(VLOOKUP(K15,Pesquisa!$D:$L,8,0),"") -> 3382.51 | R15: =IFERROR(VLOOKUP(K15,Pesquisa!$D:$L,9,0),"") -> 3672.09 | S15: =IFS('Painel Geral'!$B$5="Mediana",IFERROR(IF(OR(C15="",P15=0,P15=""),"",($C15/$P15)),""),'Painel Geral'!$B$5="Menor Salário",IFERROR(IF(OR(C15="",P15=0,P15=""),"",($C15/$M15)),""),'Painel Geral'!$B$5="1º Quartil",IFERROR(IF(OR(C15="",P15=0,P15=""),"",($C15/$N15)),""), 'Painel Geral'!$B$5="Média",IFERROR(IF(OR(C15="",P15=0,P15=""),"",($C15/$O15)),""),'Painel Geral'!$B$5="3º Quartil",IFERROR(IF(OR(C15="",P15=0,P15=""),"",($C15/$Q15)),""),'Painel Geral'!$B$5="Maior Salário",IFERROR(IF(OR(C15="",P15=0,P15=""),"",($C15/$R15)),"")) -> 1.1807612 | T15: =IFS(OR(M15="",M15=0,C15="", C15=0),"",S15<=80%,"Muito Defasado",S15<=90%,"Defasado",S15<=100%,"Na Média",S15<=110%,"Na Média",S15<=120%,"Muito Competitivo",S15>120%,"Agressivo") -> Muito Competitivo
... A56: 54 | B56: =VLOOKUP(A56,Jobmatch!A:G,2,0) -> TECNOLOGO EM CONSTRUÇÃO DE EDIFICIOS | C56: =IFERROR(AVERAGEIF('Folha de Pagamento'!A:A,A56,'Folha de Pagamento'!K:K),"") -> 8585 | D56: 5 | E56: =VLOOKUP(A56,Jobmatch!A:H,3,0) -> Edificação | F56: =VLOOKUP(A56,Jobmatch!A:I,4,0) -> 61 - ADM PROJETOS | G56: =VLOOKUP(A56,Jobmatch!A:I,5,0) -> Operacional | H56: =VLOOKUP(A56,Jobmatch!A:I,6,0) -> 269 | I56: =VLOOKUP(A56,Jobmatch!A:I,7,0) -> Técnico em Edificações | J56: =VLOOKUP(A56,Jobmatch!A:I,8,0) -> Indiferente | K56: =H56&J56 -> 269Indiferente | L56: =COUNTIF('Folha de Pagamento'!A:A,A56) -> 1 | M56: =IFERROR(VLOOKUP(K56,Pesquisa!$D:$L,4,0),"") -> 3023.75 | N56: =IFERROR(VLOOKUP(K56,Pesquisa!$D:$L,5,0),"") -> 3741.13 | O56: =IFERROR(VLOOKUP(K56,Pesquisa!$D:$L,6,0),"") -> 4594.42 | P56: =IFERROR(VLOOKUP(K56,Pesquisa!$D:$L,7,0),"") -> 4031.66 | Q56: =IFERROR(VLOOKUP(K56,Pesquisa!$D:$L,8,0),"") -> 4427.77 | R56: =IFERROR(VLOOKUP(K56,Pesquisa!$D:$L,9,0),"") -> 9097.17 | S56: =IFS('Painel Geral'!$B$5="Mediana",IFERROR(IF(OR(C56="",P56=0,P56=""),"",($C56/$P56)),""),'Painel Geral'!$B$5="Menor Salário",IFERROR(IF(OR(C56="",P56=0,P56=""),"",($C56/$M56)),""),'Painel Geral'!$B$5="1º Quartil",IFERROR(IF(OR(C56="",P56=0,P56=""),"",($C56/$N56)),""), 'Painel Geral'!$B$5="Média",IFERROR(IF(OR(C56="",P56=0,P56=""),"",($C56/$O56)),""),'Painel Geral'!$B$5="3º Quartil",IFERROR(IF(OR(C56="",P56=0,P56=""),"",($C56/$Q56)),""),'Painel Geral'!$B$5="Maior Salário",IFERROR(IF(OR(C56="",P56=0,P56=""),"",($C56/$R56)),"")) -> 2.1293958 | T56: =IFS(OR(M56="",M56=0,C56="", C56=0),"",S56<=80%,"Muito Defasado",S56<=90%,"Defasado",S56<=100%,"Na Média",S56<=110%,"Na Média",S56<=120%,"Muito Competitivo",S56>120%,"Agressivo") -> Agressivo

Sheet Painel Geral
B3: Posicionamento e Gráficos em Relação à: | F3: ="Legenda (em relação à "&B5&"):" -> Legenda (em relação à Mediana):
F4: ▇ | G4: <=80% | H4: Muito Defasado
B5: Mediana | F5: ▇ | G5: 80% - 90% | H5: Defasado
F6: ▇ | G6: 90% - 100% | H6: Na Média
F7: ▇ | G7: 100% - 110% | H7: Na Média
F8: ▇ | G8: 110% - 120% | H8: Muito Competitivo
F9: ▇ | G9: >120% | H9: Agressivo
B12: Pesquisa
D15: =D41 -> 51
D17: cargos com amostra
D24: =IF(SUM(C36:C37)>SUM(C39:C40),SUM(C36:C37),SUM(C39:C40)) -> 0.37254902
D26: =IF(SUM(C36:C37)>SUM(C39:C40),"dos cargos abaixo "&IF(B5="Mediana","da ",IF(B5="Média","da ","do "))&B5,"dos cargos acima "&IF(B5="Mediana","da ",IF(B5="Média","da ","do "))&B5) -> dos cargos abaixo da Mediana
B35: Posição | C35: Percentual | D35: Qtde de Cargos
B36: Muito Defasado | C36: =IFERROR(D36/$D$41,0) -> 0.23529412 | D36: =COUNTIF('Cálculos Comparativos'!T:T,$B36) -> 12
B37: Defasado | C37: =IFERROR(D37/$D$41,0) -> 0.1372549 | D37: =COUNTIF('Cálculos Comparativos'!T:T,$B37) -> 7
B38: Na Média | C38: =IFERROR(D38/$D$41,0) -> 0.29411765 | D38: =COUNTIF('Cálculos Comparativos'!T:T,$B38) -> 15
B39: Muito Competitivo | C39: =IFERROR(D39/$D$41,0) -> 0.11764706 | D39: =COUNTIF('Cálculos Comparativos'!T:T,$B39) -> 6
B40: Agressivo | C40: =IFERROR(D40/$D$41,0) -> 0.21568627 | D40: =COUNTIF('Cálculos Comparativos'!T:T,$B40) -> 11
B41: Total Geral | C41: =SUM(C36:C40) -> 1 | D41: =SUM(D36:D40) -> 51
B44: ANÁLISE DE SALÁRIOS
B45: NÍVEIS ORGANIZACIONAIS
B48: Operacional
B51: Posição | C51: Pesquisa
B52: Muito Defasado | C52: =IFERROR(COUNTIFS('Cálculos Comparativos'!G:G,$B$48,'Cálculos Comparativos'!T:T,$B52)/C$57, 0) -> 0.12903226
B53: Defasado | C53: =IFERROR(COUNTIFS('Cálculos Comparativos'!G:G,$B$48,'Cálculos Comparativos'!T:T,$B53)/C$57, 0) -> 0.16129032
B54: Na Média | C54: =IFERROR(COUNTIFS('Cálculos Comparativos'!G:G,$B$48,'Cálculos Comparativos'!T:T,$B54)/C$57, 0) -> 0.25806452
B55: Muito Competitivo | C55: =IFERROR(COUNTIFS('Cálculos Comparativos'!G:G,$B$48,'Cálculos Comparativos'!T:T,$B55)/C$57, 0) -> 0.19354839
B56: Agressivo | C56: =IFERROR(COUNTIFS('Cálculos Comparativos'!G:G,$B$48,'Cálculos Comparativos'!T:T,$B56)/C$57, 0) -> 0.25806452
B57: Nº de Cargos Total | C57: =COUNTIFS('Cálculos Comparativos'!G:G,B48,'Cálculos Comparativos'!T:T,"?*") -> 31
G65: =IF(SUM(C52:C53)>SUM(C55:C56),SUM(C52:C53),SUM(C55:C56)) -> 0.4516129 | H65: =IF(SUM(C52:C53)>SUM(C55:C56),"dos cargos abaixo "&IF(B5="Mediana","da ",IF(B5="Média","da ","do "))&B5,"dos cargos acima "&IF(B5="Mediana","da ",IF(B5="Média","da ","do "))&B5) -> dos cargos acima da Mediana
B70: ="5 Maiores Salários acima "&IF(B5="Mediana","da ",IF(B5="Média","da ","do "))&B5 -> 5 Maiores Salários acima da Mediana
B72: Classificado pelo C-01 | E72: Pesquisa
B73: Cargos Empresa | C73: Cargos Pesquisa | D73: Média empresa | E73: =$B$5 -> Mediana | F73: Posição
A74: {=INDEX('Cálculos Comparativos'!A:A, MATCH(LARGE('Cálculos Comparativos'!S:S, ROW(A1)), 'Cálculos Comparativos'!S:S, 0))} -> 54 | B74: =iferror(VLOOKUP($A74,'Cálculos Comparativos'!$A:$T,2,0),"") -> TECNOLOGO EM CONSTRUÇÃO DE EDIFICIOS | C74: =iferror(VLOOKUP($A74,'Cálculos Comparativos'!$A:$T,9,0)&" "&if(VLOOKUP($A74,'Cálculos Comparativos'!$A:$T,10,0)="Indiferente","",VLOOKUP($A74,'Cálculos Comparativos'!$A:$T,10,0)),"") -> Técnico em Edificações | D74: =VLOOKUP(A74,'Cálculos Comparativos'!$A:$T,3,0) -> 8585 | E74: =IFS($B$5="Mediana",VLOOKUP(A74,'Cálculos Comparativos'!A:T,16,0),$B$5="Menor Salário",VLOOKUP(A74,'Cálculos Comparativos'!A:T,13,0),$B$5="1º Quartil",VLOOKUP(A74,'Cálculos Comparativos'!A:T,13,0),$B$5="Média",VLOOKUP(A74,'Cálculos Comparativos'!A:T,15,0),$B$5="3º Quartil",VLOOKUP(A74,'Cálculos Comparativos'!A:T,17,0),$B$5="Maior Salário",VLOOKUP(A74,'Cálculos Comparativos'!A:T,18,0)) -> 4031.66 | F74: =VLOOKUP(A74,'Cálculos Comparativos'!$A:$T,19,0) -> 2.1293958
A75: {=INDEX('Cálculos Comparativos'!A:A, MATCH(LARGE('Cálculos Comparativos'!S:S, ROW(A2)), 'Cálculos Comparativos'!S:S, 0))} -> 33 | B75: =iferror(VLOOKUP($A75,'Cálculos Comparativos'!$A:$T,2,0),"") -> DIRETOR | C75: =iferror(VLOOKUP($A75,'Cálculos Comparativos'!$A:$T,9,0)&" "&if(VLOOKUP($A75,'Cálculos Comparativos'!$A:$T,10,0)="Indiferente","",VLOOKUP($A75,'Cálculos Comparativos'!$A:$T,10,0)),"") -> CEO | D75: =VLOOKUP(A75,'Cálculos Comparativos'!$A:$T,3,0) -> 55769.231 | E75: =IFS($B$5="Mediana",VLOOKUP(A75,'Cálculos Comparativos'!A:T,16,0),$B$5="Menor Salário",VLOOKUP(A75,'Cálculos Comparativos'!A:T,13,0),$B$5="1º Quartil",VLOOKUP(A75,'Cálculos Comparativos'!A:T,13,0),$B$5="Média",VLOOKUP(A75,'Cálculos Comparativos'!A:T,15,0),$B$5="3º Quartil",VLOOKUP(A75,'Cálculos Comparativos'!A:T,17,0),$B$5="Maior Salário",VLOOKUP(A75,'Cálculos Comparativos'!A:T,18,0)) -> 29147.75 | F75: =VLOOKUP(A75,'Cálculos Comparativos'!$A:$T,19,0) -> 1.9133288
A76: {=INDEX('Cálculos Comparativos'!A:A, MATCH(LARGE('Cálculos Comparativos'!S:S, ROW(A3)), 'Cálculos Comparativos'!S:S, 0))} -> 44 | B76: =iferror(VLOOKUP($A76,'Cálculos Comparativos'!$A:$T,2,0),"") -> GERENTE DE EDIFICAÇÕES | C76: =iferror(VLOOKUP($A76,'Cálculos Comparativos'!$A:$T,9,0)&" "&if(VLOOKUP($A76,'Cálculos Comparativos'!$A:$T,10,0)="Indiferente","",VLOOKUP($A76,'Cálculos Comparativos'!$A:$T,10,0)),"") -> Gerente de Engenharia | D76: =VLOOKUP(A76,'Cálculos Comparativos'!$A:$T,3,0) -> 30106.061 | E76: =IFS($B$5="Mediana",VLOOKUP(A76,'Cálculos Comparativos'!A:T,16,0),$B$5="Menor Salário",VLOOKUP(A76,'Cálculos Comparativos'!A:T,13,0),$B$5="1º Quartil",VLOOKUP(A76,'Cálculos Comparativos'!A:T,13,0),$B$5="Média",VLOOKUP(A76,'Cálculos Comparativos'!A:T,15,0),$B$5="3º Quartil",VLOOKUP(A76,'Cálculos Comparativos'!A:T,17,0),$B$5="Maior Salário",VLOOKUP(A76,'Cálculos Comparativos'!A:T,18,0)) -> 19054.35 | F76: =VLOOKUP(A76,'Cálculos Comparativos'!$A:$T,19,0) -> 1.5800098
A77: {=INDEX('Cálculos Comparativos'!A:A, MATCH(LARGE('Cálculos Comparativos'!S:S, ROW(A4)), 'Cálculos Comparativos'!S:S, 0))} -> 50 | B77: =iferror(VLOOKUP($A77,'Cálculos Comparativos'!$A:$T,2,0),"") -> GERENTE DE URBANISMO | C77: =iferror(VLOOKUP($A77,'Cálculos Comparativos'!$A:$T,9,0)&" "&if(VLOOKUP($A77,'Cálculos Comparativos'!$A:$T,10,0)="Indiferente","",VLOOKUP($A77,'Cálculos Comparativos'!$A:$T,10,0)),"") -> Gerente de Urbanismo | D77: =VLOOKUP(A77,'Cálculos Comparativos'!$A:$T,3,0) -> 28030.303 | E77: =IFS($B$5="Mediana",VLOOKUP(A77,'Cálculos Comparativos'!A:T,16,0),$B$5="Menor Salário",VLOOKUP(A77,'Cálculos Comparativos'!A:T,13,0),$B$5="1º Quartil",VLOOKUP(A77,'Cálculos Comparativos'!A:T,13,0),$B$5="Média",VLOOKUP(A77,'Cálculos Comparativos'!A:T,15,0),$B$5="3º Quartil",VLOOKUP(A77,'Cálculos Comparativos'!A:T,17,0),$B$5="Maior Salário",VLOOKUP(A77,'Cálculos Comparativos'!A:T,18,0)) -> 20040.08 | F77: =VLOOKUP(A77,'Cálculos Comparativos'!$A:$T,19,0) -> 1.3987121
A78: {=INDEX('Cálculos Comparativos'!A:A, MATCH(LARGE('Cálculos Comparativos'!S:S, ROW(A5)), 'Cálculos Comparativos'!S:S, 0))} -> 34 | B78: =iferror(VLOOKUP($A78,'Cálculos Comparativos'!$A:$T,2,0),"") -> ENCARREGADO DE OBRAS | C78: =iferror(VLOOKUP($A78,'Cálculos Comparativos'!$A:$T,9,0)&" "&if(VLOOKUP($A78,'Cálculos Comparativos'!$A:$T,10,0)="Indiferente","",VLOOKUP($A78,'Cálculos Comparativos'!$A:$T,10,0)),"") -> Mestre de Obras | D78: =VLOOKUP(A78,'Cálculos Comparativos'!$A:$T,3,0) -> 10000.5 | E78: =IFS($B$5="Mediana",VLOOKUP(A78,'Cálculos Comparativos'!A:T,16,0),$B$5="Menor Salário",VLOOKUP(A78,'Cálculos Comparativos'!A:T,13,0),$B$5="1º Quartil",VLOOKUP(A78,'Cálculos Comparativos'!A:T,13,0),$B$5="Média",VLOOKUP(A78,'Cálculos Comparativos'!A:T,15,0),$B$5="3º Quartil",VLOOKUP(A78,'Cálculos Comparativos'!A:T,17,0),$B$5="Maior Salário",VLOOKUP(A78,'Cálculos Comparativos'!A:T,18,0)) -> 7478.73 | F78: =VLOOKUP(A78,'Cálculos Comparativos'!$A:$T,19,0) -> 1.3371923
B82: ="5 Menores Salários abaixo "&IF(B5="Mediana","da ",IF(B5="Média","da ","do "))&B5 -> 5 Menores Salários abaixo da Mediana
B84: Classificado pelo C-01 | E84: Pesquisa
...

Sheet Painel Áreas
E1: Pesquisa | P1: Administrativo, Recepção, Suprimentos, Tecnologia da Informação | Q1: 1
P2: Comercial | Q2: 2
B3: Posicionamento e Gráficos em Relação à: | P3: Controladoria | Q3: 3
E4: =$D$27 -> 4 | P4: DHO | Q4: 4
B5: ='Painel Geral'!$B$5 -> Mediana | P5: Edificação | Q5: 5
E6: cargos com amostra | P6: Financeiro | Q6: 6
B7: (Para alterar o dado de comparação use a aba Painel Geral) | P7: Incorporação, Inovação, Legalização | Q7: 7
P8: Marketing | Q8: 8
B9: ANÁLISE DE | P9: Novos Negócios, Pós Vendas | Q9: 9
B10: COMPARATIVOS SALARIAIS | P10: Urbanismo | Q10: 10
B11: POR ÁREAS | E11: =IF(SUM(C22:C24)>SUM(C25:C26),SUM(C22:C24),SUM(C25:C26)) -> 0.75
B13: Incorporação, Inovação, Legalização | E13: =IF(SUM(C22:C24)>SUM(C25:C26),"dos cargos abaixo "&IF(B5="Mediana","da ",IF(B5="Média","da ","do "))&B5,"dos cargos acima "&IF(B5="Mediana","da ",IF(B5="Média","da ","do "))&B5) -> dos cargos abaixo da Mediana
B15: =VLOOKUP(B13,P:Q,2,0) -> 7
A20: 2 | C20: Pesquisa | H20: Posição | I20: Percentual
B21: Posição | C21: Percentual | D21: Qtd Cargos | H21: Muito Defasado | I21: =C22 -> 0.25
B22: Muito Defasado | C22: =iferror(D22/D$27,0) -> 0.25 | D22: =COUNTIFS('Cálculos Comparativos'!T:T,$B22,'Cálculos Comparativos'!D:D,$B$15) -> 1 | H22: Defasado | I22: =C23 -> 0
B23: Defasado | C23: =iferror(D23/D$27,0) -> 0 | D23: =COUNTIFS('Cálculos Comparativos'!T:T,$B23,'Cálculos Comparativos'!D:D,$B$15) -> 0 | H23: Na Média | I23: =C24 -> 0.5
B24: Na Média | C24: =iferror(D24/D$27,0) -> 0.5 | D24: =COUNTIFS('Cálculos Comparativos'!T:T,$B24,'Cálculos Comparativos'!D:D,$B$15) -> 2 | H24: Muito Competitivo | I24: =C25 -> 0.25
B25: Muito Competitivo | C25: =iferror(D25/D$27,0) -> 0.25 | D25: =COUNTIFS('Cálculos Comparativos'!T:T,$B25,'Cálculos Comparativos'!D:D,$B$15) -> 1 | H25: Agressivo | I25: =C26 -> 0
A26: 2 | B26: Agressivo | C26: =iferror(D26/D$27,0) -> 0 | D26: =COUNTIFS('Cálculos Comparativos'!T:T,$B26,'Cálculos Comparativos'!D:D,$B$15) -> 0 | H26: Total Geral | I26: =SUM(I21:I25) -> 1
B27: Total Geral | C27: =SUM(C22:C26) -> 1 | D27: =SUM(D22:D26) -> 4
E29: Pesquisa
B30: Cargos Empresa | C30: Cargos Pesquisa | D30: Média Empresa | E30: =B5 -> Mediana | F30: Posição
A31: =IFERROR(__xludf.DUMMYFUNCTION("FILTER('Cálculos Comparativos'!A:A,'Cálculos Comparativos'!D:D=$B$15,'Cálculos Comparativos'!T:T<>"""")"),"4") -> 4 | B31: =IFERROR(VLOOKUP($A31,'Cálculos Comparativos'!$A:$T,2,0),"") -> ANALISTA DE INOVAÇÃO | C31: =IFERROR(VLOOKUP($A31,'Cálculos Comparativos'!$A:$T,9,0)&" "&if(VLOOKUP($A31,'Cálculos Comparativos'!$A:$T,10,0)="Indiferente","",VLOOKUP($A31,'Cálculos Comparativos'!$A:$T,10,0)),"") -> Analista de Inovação | D31: =IFERROR(VLOOKUP(A31,'Cálculos Comparativos'!A:L,3,0),"") -> 7299.2701 | E31: =IFERROR(IFS($B$5="Mediana",VLOOKUP(A31,'Cálculos Comparativos'!A:T,16,0),$B$5="Menor Salário",VLOOKUP(A31,'Cálculos Comparativos'!A:T,13,0),$B$5="1º Quartil",VLOOKUP(A31,'Cálculos Comparativos'!A:T,14,0),$B$5="Média",VLOOKUP(A31,'Cálculos Comparativos'!A:T,15,0),$B$5="3º Quartil",VLOOKUP(A31,'Cálculos Comparativos'!A:T,17,0),$B$5="Maior Salário",VLOOKUP(A31,'Cálculos Comparativos'!A:T,18,0)),"") -> 6872.0455 | F31: =IFERROR(VLOOKUP($A31,'Cálculos Comparativos'!$A:$T,19,0),"") -> 1.0621685 | G31: =IFERROR(VLOOKUP($A31,'Cálculos Comparativos'!$A:$T,20,0),"") -> Na Média
A32: =IFERROR(__xludf.DUMMYFUNCTION("""COMPUTED_VALUE"""),"12") -> 12 | B32: =IFERROR(VLOOKUP($A32,'Cálculos Comparativos'!$A:$T,2,0),"") -> ASSISTENTE ADM DE LEGALIZAÇÃO III | C32: =IFERROR(VLOOKUP($A32,'Cálculos Comparativos'!$A:$T,9,0)&" "&if(VLOOKUP($A32,'Cálculos Comparativos'!$A:$T,10,0)="Indiferente","",VLOOKUP($A32,'Cálculos Comparativos'!$A:$T,10,0)),"") -> Assistente de Legalização | D32: =IFERROR(VLOOKUP(A32,'Cálculos Comparativos'!A:L,3,0),"") -> 3652 | E32: =IFERROR(IFS($B$5="Mediana",VLOOKUP(A32,'Cálculos Comparativos'!A:T,16,0),$B$5="Menor Salário",VLOOKUP(A32,'Cálculos Comparativos'!A:T,13,0),$B$5="1º Quartil",VLOOKUP(A32,'Cálculos Comparativos'!A:T,14,0),$B$5="Média",VLOOKUP(A32,'Cálculos Comparativos'!A:T,15,0),$B$5="3º Quartil",VLOOKUP(A32,'Cálculos Comparativos'!A:T,17,0),$B$5="Maior Salário",VLOOKUP(A32,'Cálculos Comparativos'!A:T,18,0)),"") -> 3092.92 | F32: =IFERROR(VLOOKUP($A32,'Cálculos Comparativos'!$A:$T,19,0),"") -> 1.1807612 | G32: =IFERROR(VLOOKUP($A32,'Cálculos Comparativos'!$A:$T,20,0),"") -> Muito Competitivo
A33: =IFERROR(__xludf.DUMMYFUNCTION("""COMPUTED_VALUE"""),"28") -> 28 | B33: =IFERROR(VLOOKUP($A33,'Cálculos Comparativos'!$A:$T,2,0),"") -> COORDENADOR DE LEGAIZAÇÃO ll | C33: =IFERROR(VLOOKUP($A33,'Cálculos Comparativos'!$A:$T,9,0)&" "&if(VLOOKUP($A33,'Cálculos Comparativos'!$A:$T,10,0)="Indiferente","",VLOOKUP($A33,'Cálculos Comparativos'!$A:$T,10,0)),"") -> Coordenador de Legalização | D33: =IFERROR(VLOOKUP(A33,'Cálculos Comparativos'!A:L,3,0),"") -> 8647 | E33: =IFERROR(IFS($B$5="Mediana",VLOOKUP(A33,'Cálculos Comparativos'!A:T,16,0),$B$5="Menor Salário",VLOOKUP(A33,'Cálculos Comparativos'!A:T,13,0),$B$5="1º Quartil",VLOOKUP(A33,'Cálculos Comparativos'!A:T,14,0),$B$5="Média",VLOOKUP(A33,'Cálculos Comparativos'!A:T,15,0),$B$5="3º Quartil",VLOOKUP(A33,'Cálculos Comparativos'!A:T,17,0),$B$5="Maior Salário",VLOOKUP(A33,'Cálculos Comparativos'!A:T,18,0)),"") -> 8872.04 | F33: =IFERROR(VLOOKUP($A33,'Cálculos Comparativos'!$A:$T,19,0),"") -> 0.97463492 | G33: =IFERROR(VLOOKUP($A33,'Cálculos Comparativos'!$A:$T,20,0),"") -> Na Média
A34: =IFERROR(__xludf.DUMMYFUNCTION("""COMPUTED_VALUE"""),"47") -> 47 | B34: =IFERROR(VLOOKUP($A34,'Cálculos Comparativos'!$A:$T,2,0),"") -> GERENTE DE INCORPORAÇÃO | C34: =IFERROR(VLOOKUP($A34,'Cálculos Comparativos'!$A:$T,9,0)&" "&if(VLOOKUP($A34,'Cálculos Comparativos'!$A:$T,10,0)="Indiferente","",VLOOKUP($A34,'Cálculos Comparativos'!$A:$T,10,0)),"") -> Gerente de Incorporação | D34: =IFERROR(VLOOKUP(A34,'Cálculos Comparativos'!A:L,3,0),"") -> 14045.455 | E34: =IFERROR(IFS($B$5="Mediana",VLOOKUP(A34,'Cálculos Comparativos'!A:T,16,0),$B$5="Menor Salário",VLOOKUP(A34,'Cálculos Comparativos'!A:T,13,0),$B$5="1º Quartil",VLOOKUP(A34,'Cálculos Comparativos'!A:T,14,0),$B$5="Média",VLOOKUP(A34,'Cálculos Comparativos'!A:T,15,0),$B$5="3º Quartil",VLOOKUP(A34,'Cálculos Comparativos'!A:T,17,0),$B$5="Maior Salário",VLOOKUP(A34,'Cálculos Comparativos'!A:T,18,0)),"") -> 18908.464 | F34: =IFERROR(VLOOKUP($A34,'Cálculos Comparativos'!$A:$T,19,0),"") -> 0.7428131 | G34: =IFERROR(VLOOKUP($A34,'Cálculos Comparativos'!$A:$T,20,0),"") -> Muito Defasado
B35: =IFERROR(VLOOKUP($A35,'Cálculos Comparativos'!$A:$T,2,0),"") | C35: =IFERROR(VLOOKUP($A35,'Cálculos Comparativos'!$A:$T,9,0)&" "&if(VLOOKUP($A35,'Cálculos Comparativos'!$A:$T,10,0)="Indiferente","",VLOOKUP($A35,'Cálculos Comparativos'!$A:$T,10,0)),"") | D35: =IFERROR(VLOOKUP(A35,'Cálculos Comparativos'!A:L,3,0),"") | E35: =IFERROR(IFS($B$5="Mediana",VLOOKUP(A35,'Cálculos Comparativos'!A:T,16,0),$B$5="Menor Salário",VLOOKUP(A35,'Cálculos Comparativos'!A:T,13,0),$B$5="1º Quartil",VLOOKUP(A35,'Cálculos Comparativos'!A:T,14,0),$B$5="Média",VLOOKUP(A35,'Cálculos Comparativos'!A:T,15,0),$B$5="3º Quartil",VLOOKUP(A35,'Cálculos Comparativos'!A:T,17,0),$B$5="Maior Salário",VLOOKUP(A35,'Cálculos Comparativos'!A:T,18,0)),"") | F35: =IFERROR(VLOOKUP($A35,'Cálculos Comparativos'!$A:$T,19,0),"") | G35: =IFERROR(VLOOKUP($A35,'Cálculos Comparativos'!$A:$T,20,0),"")
B36: =IFERROR(VLOOKUP($A36,'Cálculos Comparativos'!$A:$T,2,0),"") | C36: =IFERROR(VLOOKUP($A36,'Cálculos Comparativos'!$A:$T,9,0)&" "&if(VLOOKUP($A36,'Cálculos Comparativos'!$A:$T,10,0)="Indiferente","",VLOOKUP($A36,'Cálculos Comparativos'!$A:$T,10,0)),"") | D36: =IFERROR(VLOOKUP(A36,'Cálculos Comparativos'!A:L,3,0),"") | E36: =IFERROR(IFS($B$5="Mediana",VLOOKUP(A36,'Cálculos Comparativos'!A:T,16,0),$B$5="Menor Salário",VLOOKUP(A36,'Cálculos Comparativos'!A:T,13,0),$B$5="1º Quartil",VLOOKUP(A36,'Cálculos Comparativos'!A:T,14,0),$B$5="Média",VLOOKUP(A36,'Cálculos Comparativos'!A:T,15,0),$B$5="3º Quartil",VLOOKUP(A36,'Cálculos Comparativos'!A:T,17,0),$B$5="Maior Salário",VLOOKUP(A36,'Cálculos Comparativos'!A:T,18,0)),"") | F36: =IFERROR(VLOOKUP($A36,'Cálculos Comparativos'!$A:$T,19,0),"") | G36: =IFERROR(VLOOKUP($A36,'Cálculos Comparativos'!$A:$T,20,0),"")
