Workbook

Sheet Estrutura Salarial
C2: Estrutura Salarial Lumis
G5: Desempenho Inicial | K5: Ideal | L5: Alto Desempenho
B6: Cargo | C6: Área | D6: Média Lumis CLT | E6: Referência Pesquisa CLT | F6: Grade | G6: 0.8 | H6: 0.85 | I6: 0.9 | J6: 0.95 | K6: 1 | L6: 1.05 | M6: 1.1 | N6: 1.15 | O6: 1.2
B7: Auxiliar Administrativo | C7: Administrativo | D7: 2254 | E7: 2309.71 | F7: 10 | G7: =IFERROR((K7*$G$6)," ") -> 1867.2 | H7: =IFERROR((K7*$H$6)," ") -> 1983.9 | I7: =IFERROR((K7*$I$6)," ") -> 2100.6 | J7: =IFERROR((K7*$J$6)," ") -> 2217.3 | K7: =VLOOKUP(F7,'Tabela Salarial_CLT'!$B:$G,6,0) -> 2334 | L7: =IFERROR((K7*$L$6)," ") -> 2450.7 | M7: =IFERROR((K7*$M$6)," ") -> 2567.4 | N7: =IFERROR((K7*$N$6)," ") -> 2684.1 | O7: =IFERROR((K7*$O$6)," ") -> 2800.8
B8: Auxiliar Atendimento | C8: Recepção | D8: 2560 | E8: 2052.94 | F8: 10 | G8: =IFERROR((K8*$G$6)," ") -> 1867.2 | H8: =IFERROR((K8*$H$6)," ") -> 1983.9 | I8: =IFERROR((K8*$I$6)," ") -> 2100.6 | J8: =IFERROR((K8*$J$6)," ") -> 2217.3 | K8: =VLOOKUP(F8,'Tabela Salarial_CLT'!$B:$G,6,0) -> 2334 | L8: =IFERROR((K8*$L$6)," ") -> 2450.7 | M8: =IFERROR((K8*$M$6)," ") -> 2567.4 | N8: =IFERROR((K8*$N$6)," ") -> 2684.1 | O8: =IFERROR((K8*$O$6)," ") -> 2800.8
B9: Assistente Administrativo | C9: Administrativo | D9: 3439.7 | E9: 2640.74 | F9: 11 | G9: =IFERROR((K9*$G$6)," ") -> 2191.112 | H9: =IFERROR((K9*$H$6)," ") -> 2328.0565 | I9: =IFERROR((K9*$I$6)," ") -> 2465.001 | J9: =IFERROR((K9*$J$6)," ") -> 2601.9455 | K9: =VLOOKUP(F9,'Tabela Salarial_CLT'!$B:$G,6,0) -> 2738.89 | L9: =IFERROR((K9*$L$6)," ") -> 2875.8345 | M9: =IFERROR((K9*$M$6)," ") -> 3012.779 | N9: =IFERROR((K9*$N$6)," ") -> 3149.7235 | O9: =IFERROR((K9*$O$6)," ") -> 3286.668
B10: Assistente Atendimento | C10: Recepção | E10: R$ 2.517,88 | F10: 11 | G10: =IFERROR((K10*$G$6)," ") -> 2191.112 | H10: =IFERROR((K10*$H$6)," ") -> 2328.0565 | I10: =IFERROR((K10*$I$6)," ") -> 2465.001 | J10: =IFERROR((K10*$J$6)," ") -> 2601.9455 | K10: =VLOOKUP(F10,'Tabela Salarial_CLT'!$B:$G,6,0) -> 2738.89 | L10: =IFERROR((K10*$L$6)," ") -> 2875.8345 | M10: =IFERROR((K10*$M$6)," ") -> 3012.779 | N10: =IFERROR((K10*$N$6)," ") -> 3149.7235 | O10: =IFERROR((K10*$O$6)," ") -> 3286.668
B11: Assistente Compras | C11: Suprimentos | E11: R$ 2.667,83 | F11: 11 | G11: =IFERROR((K11*$G$6)," ") -> 2191.112 | H11: =IFERROR((K11*$H$6)," ") -> 2328.0565 | I11: =IFERROR((K11*$I$6)," ") -> 2465.001 | J11: =IFERROR((K11*$J$6)," ") -> 2601.9455 | K11: =VLOOKUP(F11,'Tabela Salarial_CLT'!$B:$G,6,0) -> 2738.89 | L11: =IFERROR((K11*$L$6)," ") -> 2875.8345 | M11: =IFERROR((K11*$M$6)," ") -> 3012.779 | N11: =IFERROR((K11*$N$6)," ") -> 3149.7235 | O11: =IFERROR((K11*$O$6)," ") -> 3286.668
B12: Assistente Financeiro | C12: Financeiro | E12: R$ 2.665,28 | F12: 11 | G12: =IFERROR((K12*$G$6)," ") -> 2191.112 | H12: =IFERROR((K12*$H$6)," ") -> 2328.0565 | I12: =IFERROR((K12*$I$6)," ") -> 2465.001 | J12: =IFERROR((K12*$J$6)," ") -> 2601.9455 | K12: =VLOOKUP(F12,'Tabela Salarial_CLT'!$B:$G,6,0) -> 2738.89 | L12: =IFERROR((K12*$L$6)," ") -> 2875.8345 | M12: =IFERROR((K12*$M$6)," ") -> 3012.779 | N12: =IFERROR((K12*$N$6)," ") -> 3149.7235 | O12: =IFERROR((K12*$O$6)," ") -> 3286.668
B13: Assistente Financeiro Contas a Pagar | C13: Financeiro | D13: 3163.3333 | E13: 2665.28 | F13: 11 | G13: =IFERROR((K13*$G$6)," ") -> 2191.112 | H13: =IFERROR((K13*$H$6)," ") -> 2328.0565 | I13: =IFERROR((K13*$I$6)," ") -> 2465.001 | J13: =IFERROR((K13*$J$6)," ") -> 2601.9455 | K13: =VLOOKUP(F13,'Tabela Salarial_CLT'!$B:$G,6,0) -> 2738.89 | L13: =IFERROR((K13*$L$6)," ") -> 2875.8345 | M13: =IFERROR((K13*$M$6)," ") -> 3012.779 | N13: =IFERROR((K13*$N$6)," ") -> 3149.7235 | O13: =IFERROR((K13*$O$6)," ") -> 3286.668
B14: Assistente Marketing | C14: Marketing | D14: 2919 | E14: 2889.19 | F14: 11 | G14: =IFERROR((K14*$G$6)," ") -> 2191.112 | H14: =IFERROR((K14*$H$6)," ") -> 2328.0565 | I14: =IFERROR((K14*$I$6)," ") -> 2465.001 | J14: =IFERROR((K14*$J$6)," ") -> 2601.9455 | K14: =VLOOKUP(F14,'Tabela Salarial_CLT'!$B:$G,6,0) -> 2738.89 | L14: =IFERROR((K14*$L$6)," ") -> 2875.8345 | M14: =IFERROR((K14*$M$6)," ") -> 3012.779 | N14: =IFERROR((K14*$N$6)," ") -> 3149.7235 | O14: =IFERROR((K14*$O$6)," ") -> 3286.668
B15: Assistente TI | C15: Tecnologia da Informação | D15: 2919 | E15: 2413.7 | F15: 11 | G15: =IFERROR((K15*$G$6)," ") -> 2191.112 | H15: =IFERROR((K15*$H$6)," ") -> 2328.0565 | I15: =IFERROR((K15*$I$6)," ") -> 2465.001 | J15: =IFERROR((K15*$J$6)," ") -> 2601.9455 | K15: =VLOOKUP(F15,'Tabela Salarial_CLT'!$B:$G,6,0) -> 2738.89 | L15: =IFERROR((K15*$L$6)," ") -> 2875.8345 | M15: =IFERROR((K15*$M$6)," ") -> 3012.779 | N15: =IFERROR((K15*$N$6)," ") -> 3149.7235 | O15: =IFERROR((K15*$O$6)," ") -> 3286.668
B16: Auxiliar Engenharia | C16: Urbanismo | D16: 2560 | E16: 2721.37 | F16: 11 | G16: =IFERROR((K16*$G$6)," ") -> 2191.112 | H16: =IFERROR((K16*$H$6)," ") -> 2328.0565 | I16: =IFERROR((K16*$I$6)," ") -> 2465.001 | J16: =IFERROR((K16*$J$6)," ") -> 2601.9455 | K16: =VLOOKUP(F16,'Tabela Salarial_CLT'!$B:$G,6,0) -> 2738.89 | L16: =IFERROR((K16*$L$6)," ") -> 2875.8345 | M16: =IFERROR((K16*$M$6)," ") -> 3012.779 | N16: =IFERROR((K16*$N$6)," ") -> 3149.7235 | O16: =IFERROR((K16*$O$6)," ") -> 3286.668
B17: Almoxarife | C17: Edificação | D17: 3683 | E17: 3096.32 | F17: 12 | G17: =IFERROR((K17*$G$6)," ") -> 2593.856 | H17: =IFERROR((K17*$H$6)," ") -> 2755.972 | I17: =IFERROR((K17*$I$6)," ") -> 2918.088 | J17: =IFERROR((K17*$J$6)," ") -> 3080.204 | K17: =VLOOKUP(F17,'Tabela Salarial_CLT'!$B:$G,6,0) -> 3242.32 | L17: =IFERROR((K17*$L$6)," ") -> 3404.436 | M17: =IFERROR((K17*$M$6)," ") -> 3566.552 | N17: =IFERROR((K17*$N$6)," ") -> 3728.668 | O17: =IFERROR((K17*$O$6)," ") -> 3890.784
B18: Assistente Adm Legalização | C18: Legalização | D18: 3652 | E18: 3092.92 | F18: 12 | G18: =IFERROR((K18*$G$6)," ") -> 2593.856 | H18: =IFERROR((K18*$H$6)," ") -> 2755.972 | I18: =IFERROR((K18*$I$6)," ") -> 2918.088 | J18: =IFERROR((K18*$J$6)," ") -> 3080.204 | K18: =VLOOKUP(F18,'Tabela Salarial_CLT'!$B:$G,6,0) -> 3242.32 | L18: =IFERROR((K18*$L$6)," ") -> 3404.436 | M18: =IFERROR((K18*$M$6)," ") -> 3566.552 | N18: =IFERROR((K18*$N$6)," ") -> 3728.668 | O18: =IFERROR((K18*$O$6)," ") -> 3890.784
B19: Assistente Controladoria | C19: Controladoria | D19: 3652 | E19: 2766.4 | F19: 12 | G19: =IFERROR((K19*$G$6)," ") -> 2593.856 | H19: =IFERROR((K19*$H$6)," ") -> 2755.972 | I19: =IFERROR((K19*$I$6)," ") -> 2918.088 | J19: =IFERROR((K19*$J$6)," ") -> 3080.204 | K19: =VLOOKUP(F19,'Tabela Salarial_CLT'!$B:$G,6,0) -> 3242.32 | L19: =IFERROR((K19*$L$6)," ") -> 3404.436 | M19: =IFERROR((K19*$M$6)," ") -> 3566.552 | N19: =IFERROR((K19*$N$6)," ") -> 3728.668 | O19: =IFERROR((K19*$O$6)," ") -> 3890.784
B20: Assistente Recursos Humanos | C20: DHO | D20: 2919 | E20: 3087.62 | F20: 12 | G20: =IFERROR((K20*$G$6)," ") -> 2593.856 | H20: =IFERROR((K20*$H$6)," ") -> 2755.972 | I20: =IFERROR((K20*$I$6)," ") -> 2918.088 | J20: =IFERROR((K20*$J$6)," ") -> 3080.204 | K20: =VLOOKUP(F20,'Tabela Salarial_CLT'!$B:$G,6,0) -> 3242.32 | L20: =IFERROR((K20*$L$6)," ") -> 3404.436 | M20: =IFERROR((K20*$M$6)," ") -> 3566.552 | N20: =IFERROR((K20*$N$6)," ") -> 3728.668 | O20: =IFERROR((K20*$O$6)," ") -> 3890.784
B21: Analista Financeiro Captação Recursos Jr | C21: Financeiro | E21: 3493.97 | F21: 13 | G21: =IFERROR((K21*$G$6)," ") -> 3105.144 | H21: =IFERROR((K21*$H$6)," ") -> 3299.2155 | I21: =IFERROR((K21*$I$6)," ") -> 3493.287 | J21: =IFERROR((K21*$J$6)," ") -> 3687.3585 | K21: =VLOOKUP(F21,'Tabela Salarial_CLT'!$B:$G,6,0) -> 3881.43 | L21: =IFERROR((K21*$L$6)," ") -> 4075.5015 | M21: =IFERROR((K21*$M$6)," ") -> 4269.573 | N21: =IFERROR((K21*$N$6)," ") -> 4463.6445 | O21: =IFERROR((K21*$O$6)," ") -> 4657.716
B22: Analista Financeiro Comercial Jr | C22: Financeiro | E22: 3493.97 | F22: 13 | G22: =IFERROR((K22*$G$6)," ") -> 3105.144 | H22: =IFERROR((K22*$H$6)," ") -> 3299.2155 | I22: =IFERROR((K22*$I$6)," ") -> 3493.287 | J22: =IFERROR((K22*$J$6)," ") -> 3687.3585 | K22: =VLOOKUP(F22,'Tabela Salarial_CLT'!$B:$G,6,0) -> 3881.43 | L22: =IFERROR((K22*$L$6)," ") -> 4075.5015 | M22: =IFERROR((K22*$M$6)," ") -> 4269.573 | N22: =IFERROR((K22*$N$6)," ") -> 4463.6445 | O22: =IFERROR((K22*$O$6)," ") -> 4657.716
B23: Analista Financeiro Jr | C23: Financeiro | D23: 3993 | E23: 3493.97 | F23: 13 | G23: =IFERROR((K23*$G$6)," ") -> 3105.144 | H23: =IFERROR((K23*$H$6)," ") -> 3299.2155 | I23: =IFERROR((K23*$I$6)," ") -> 3493.287 | J23: =IFERROR((K23*$J$6)," ") -> 3687.3585 | K23: =VLOOKUP(F23,'Tabela Salarial_CLT'!$B:$G,6,0) -> 3881.43 | L23: =IFERROR((K23*$L$6)," ") -> 4075.5015 | M23: =IFERROR((K23*$M$6)," ") -> 4269.573 | N23: =IFERROR((K23*$N$6)," ") -> 4463.6445 | O23: =IFERROR((K23*$O$6)," ") -> 4657.716
B24: Analista Manutenção Jr | C24: Edificação | F24: 13 | G24: =IFERROR((K24*$G$6)," ") -> 3105.144 | H24: =IFERROR((K24*$H$6)," ") -> 3299.2155 | I24: =IFERROR((K24*$I$6)," ") -> 3493.287 | J24: =IFERROR((K24*$J$6)," ") -> 3687.3585 | K24: =VLOOKUP(F24,'Tabela Salarial_CLT'!$B:$G,6,0) -> 3881.43 | L24: =IFERROR((K24*$L$6)," ") -> 4075.5015 | M24: =IFERROR((K24*$M$6)," ") -> 4269.573 | N24: =IFERROR((K24*$N$6)," ") -> 4463.6445 | O24: =IFERROR((K24*$O$6)," ") -> 4657.716
B25: Analista Marketing Jr | C25: Marketing | D25: 4025.88 | E25: 3297.81 | F25: 13 | G25: =IFERROR((K25*$G$6)," ") -> 3105.144 | H25: =IFERROR((K25*$H$6)," ") -> 3299.2155 | I25: =IFERROR((K25*$I$6)," ") -> 3493.287 | J25: =IFERROR((K25*$J$6)," ") -> 3687.3585 | K25: =VLOOKUP(F25,'Tabela Salarial_CLT'!$B:$G,6,0) -> 3881.43 | L25: =IFERROR((K25*$L$6)," ") -> 4075.5015 | M25: =IFERROR((K25*$M$6)," ") -> 4269.573 | N25: =IFERROR((K25*$N$6)," ") -> 4463.6445 | O25: =IFERROR((K25*$O$6)," ") -> 4657.716
B26: Analista Pós-Vendas Jr | C26: Pós Vendas | F26: 13 | G26: =IFERROR((K26*$G$6)," ") -> 3105.144 | H26: =IFERROR((K26*$H$6)," ") -> 3299.2155 | I26: =IFERROR((K26*$I$6)," ") -> 3493.287 | J26: =IFERROR((K26*$J$6)," ") -> 3687.3585 | K26: =VLOOKUP(F26,'Tabela Salarial_CLT'!$B:$G,6,0) -> 3881.43 | L26: =IFERROR((K26*$L$6)," ") -> 4075.5015 | M26: =IFERROR((K26*$M$6)," ") -> 4269.573 | N26: =IFERROR((K26*$N$6)," ") -> 4463.6445 | O26: =IFERROR((K26*$O$6)," ") -> 4657.716
B27: Assistente Engenharia | C27: Edificação | D27: 3652 | E27: 3954.91 | F27: 13 | G27: =IFERROR((K27*$G$6)," ") -> 3105.144 | H27: =IFERROR((K27*$H$6)," ") -> 3299.2155 | I27: =IFERROR((K27*$I$6)," ") -> 3493.287 | J27: =IFERROR((K27*$J$6)," ") -> 3687.3585 | K27: =VLOOKUP(F27,'Tabela Salarial_CLT'!$B:$G,6,0) -> 3881.43 | L27: =IFERROR((K27*$L$6)," ") -> 4075.5015 | M27: =IFERROR((K27*$M$6)," ") -> 4269.573 | N27: =IFERROR((K27*$N$6)," ") -> 4463.6445 | O27: =IFERROR((K27*$O$6)," ") -> 4657.716
B28: Analista Compras Jr | C28: Suprimentos | E28: 3492.43 | F28: 14 | G28: =IFERROR((K28*$G$6)," ") -> 3754.688 | H28: =IFERROR((K28*$H$6)," ") -> 3989.356 | I28: =IFERROR((K28*$I$6)," ") -> 4224.024 | J28: =IFERROR((K28*$J$6)," ") -> 4458.692 | K28: =VLOOKUP(F28,'Tabela Salarial_CLT'!$B:$G,6,0) -> 4693.36 | L28: =IFERROR((K28*$L$6)," ") -> 4928.028 | M28: =IFERROR((K28*$M$6)," ") -> 5162.696 | N28: =IFERROR((K28*$N$6)," ") -> 5397.364 | O28: =IFERROR((K28*$O$6)," ") -> 5632.032
B29: Analista Criação | C29: Marketing | D29: 5429 | E29: 4325.72 | F29: 14 | G29: =IFERROR((K29*$G$6)," ") -> 3754.688 | H29: =IFERROR((K29*$H$6)," ") -> 3989.356 | I29: =IFERROR((K29*$I$6)," ") -> 4224.024 | J29: =IFERROR((K29*$J$6)," ") -> 4458.692 | K29: =VLOOKUP(F29,'Tabela Salarial_CLT'!$B:$G,6,0) -> 4693.36 | L29: =IFERROR((K29*$L$6)," ") -> 4928.028 | M29: =IFERROR((K29*$M$6)," ") -> 5162.696 | N29: =IFERROR((K29*$N$6)," ") -> 5397.364 | O29: =IFERROR((K29*$O$6)," ") -> 5632.032
B30: Analista Financeiro Captação Recursos Pl | C30: Financeiro | E30: 4714.28 | F30: 14 | G30: =IFERROR((K30*$G$6)," ") -> 3754.688 | H30: =IFERROR((K30*$H$6)," ") -> 3989.356 | I30: =IFERROR((K30*$I$6)," ") -> 4224.024 | J30: =IFERROR((K30*$J$6)," ") -> 4458.692 | K30: =VLOOKUP(F30,'Tabela Salarial_CLT'!$B:$G,6,0) -> 4693.36 | L30: =IFERROR((K30*$L$6)," ") -> 4928.028 | M30: =IFERROR((K30*$M$6)," ") -> 5162.696 | N30: =IFERROR((K30*$N$6)," ") -> 5397.364 | O30: =IFERROR((K30*$O$6)," ") -> 5632.032
B31: Analista Financeiro Comercial Pl | C31: Financeiro | E31: 4714.28 | F31: 14 | G31: =IFERROR((K31*$G$6)," ") -> 3754.688 | H31: =IFERROR((K31*$H$6)," ") -> 3989.356 | I31: =IFERROR((K31*$I$6)," ") -> 4224.024 | J31: =IFERROR((K31*$J$6)," ") -> 4458.692 | K31: =VLOOKUP(F31,'Tabela Salarial_CLT'!$B:$G,6,0) -> 4693.36 | L31: =IFERROR((K31*$L$6)," ") -> 4928.028 | M31: =IFERROR((K31*$M$6)," ") -> 5162.696 | N31: =IFERROR((K31*$N$6)," ") -> 5397.364 | O31: =IFERROR((K31*$O$6)," ") -> 5632.032
B32: Analista Financeiro Pl | C32: Financeiro | E32: 4714.28 | F32: 14 | G32: =IFERROR((K32*$G$6)," ") -> 3754.688 | H32: =IFERROR((K32*$H$6)," ") -> 3989.356 | I32: =IFERROR((K32*$I$6)," ") -> 4224.024 | J32: =IFERROR((K32*$J$6)," ") -> 4458.692 | K32: =VLOOKUP(F32,'Tabela Salarial_CLT'!$B:$G,6,0) -> 4693.36 | L32: =IFERROR((K32*$L$6)," ") -> 4928.028 | M32: =IFERROR((K32*$M$6)," ") -> 5162.696 | N32: =IFERROR((K32*$N$6)," ") -> 5397.364 | O32: =IFERROR((K32*$O$6)," ") -> 5632.032
B33: Analista Manutenção Pl | C33: Edificação | D33: 4550 | E33: 6232.3 | F33: 14 | G33: =IFERROR((K33*$G$6)," ") -> 3754.688 | H33: =IFERROR((K33*$H$6)," ") -> 3989.356 | I33: =IFERROR((K33*$I$6)," ") -> 4224.024 | J33: =IFERROR((K33*$J$6)," ") -> 4458.692 | K33: =VLOOKUP(F33,'Tabela Salarial_CLT'!$B:$G,6,0) -> 4693.36 | L33: =IFERROR((K33*$L$6)," ") -> 4928.028 | M33: =IFERROR((K33*$M$6)," ") -> 5162.696 | N33: =IFERROR((K33*$N$6)," ") -> 5397.364 | O33: =IFERROR((K33*$O$6)," ") -> 5632.032
B34: Analista Marketing Pl | C34: Marketing | E34: 4910.03 | F34: 14 | G34: =IFERROR((K34*$G$6)," ") -> 3754.688 | H34: =IFERROR((K34*$H$6)," ") -> 3989.356 | I34: =IFERROR((K34*$I$6)," ") -> 4224.024 | J34: =IFERROR((K34*$J$6)," ") -> 4458.692 | K34: =VLOOKUP(F34,'Tabela Salarial_CLT'!$B:$G,6,0) -> 4693.36 | L34: =IFERROR((K34*$L$6)," ") -> 4928.028 | M34: =IFERROR((K34*$M$6)," ") -> 5162.696 | N34: =IFERROR((K34*$N$6)," ") -> 5397.364 | O34: =IFERROR((K34*$O$6)," ") -> 5632.032
B35: Analista Pós-Vendas Pl | C35: Pós Vendas | D35: 4550 | E35: 3830.08 | F35: 14 | G35: =IFERROR((K35*$G$6)," ") -> 3754.688 | H35: =IFERROR((K35*$H$6)," ") -> 3989.356 | I35: =IFERROR((K35*$I$6)," ") -> 4224.024 | J35: =IFERROR((K35*$J$6)," ") -> 4458.692 | K35: =VLOOKUP(F35,'Tabela Salarial_CLT'!$B:$G,6,0) -> 4693.36 | L35: =IFERROR((K35*$L$6)," ") -> 4928.028 | M35: =IFERROR((K35*$M$6)," ") -> 5162.696 | N35: =IFERROR((K35*$N$6)," ") -> 5397.364 | O35: =IFERROR((K35*$O$6)," ") -> 5632.032
B36: Analista Compras Pl | C36: Suprimentos | D36: 3780 | E36: 5288.53 | F36: 15 | G36: =IFERROR((K36*$G$6)," ") -> 4572.2 | H36: =IFERROR((K36*$H$6)," ") -> 4857.9625 | I36: =IFERROR((K36*$I$6)," ") -> 5143.725 | J36: =IFERROR((K36*$J$6)," ") -> 5429.4875 | K36: =VLOOKUP(F36,'Tabela Salarial_CLT'!$B:$G,6,0) -> 5715.25 | L36: =IFERROR((K36*$L$6)," ") -> 6001.0125 | M36: =IFERROR((K36*$M$6)," ") -> 6286.775 | N36: =IFERROR((K36*$N$6)," ") -> 6572.5375 | O36: =IFERROR((K36*$O$6)," ") -> 6858.3
B37: Analista Engenharia | C37: Edificação | E37: R$ 5.281,61 | F37: 15 | G37: =IFERROR((K37*$G$6)," ") -> 4572.2 | H37: =IFERROR((K37*$H$6)," ") -> 4857.9625 | I37: =IFERROR((K37*$I$6)," ") -> 5143.725 | J37: =IFERROR((K37*$J$6)," ") -> 5429.4875 | K37: =VLOOKUP(F37,'Tabela Salarial_CLT'!$B:$G,6,0) -> 5715.25 | L37: =IFERROR((K37*$L$6)," ") -> 6001.0125 | M37: =IFERROR((K37*$M$6)," ") -> 6286.775 | N37: =IFERROR((K37*$N$6)," ") -> 6572.5375 | O37: =IFERROR((K37*$O$6)," ") -> 6858.3
B38: Analista Financeiro Captação Recursos Sr | C38: Financeiro | D38: 5213 | E38: 5910.71 | F38: 15 | G38: =IFERROR((K38*$G$6)," ") -> 4572.2 | H38: =IFERROR((K38*$H$6)," ") -> 4857.9625 | I38: =IFERROR((K38*$I$6)," ") -> 5143.725 | J38: =IFERROR((K38*$J$6)," ") -> 5429.4875 | K38: =VLOOKUP(F38,'Tabela Salarial_CLT'!$B:$G,6,0) -> 5715.25 | L38: =IFERROR((K38*$L$6)," ") -> 6001.0125 | M38: =IFERROR((K38*$M$6)," ") -> 6286.775 | N38: =IFERROR((K38*$N$6)," ") -> 6572.5375 | O38: =IFERROR((K38*$O$6)," ") -> 6858.3
B39: Analista Financeiro Comercial Sr | C39: Financeiro | D39: 5213 | E39: 5910.71 | F39: 15 | G39: =IFERROR((K39*$G$6)," ") -> 4572.2 | H39: =IFERROR((K39*$H$6)," ") -> 4857.9625 | I39: =IFERROR((K39*$I$6)," ") -> 5143.725 | J39: =IFERROR((K39*$J$6)," ") -> 5429.4875 | K39: =VLOOKUP(F39,'Tabela Salarial_CLT'!$B:$G,6,0) -> 5715.25 | L39: =IFERROR((K39*$L$6)," ") -> 6001.0125 | M39: =IFERROR((K39*$M$6)," ") -> 6286.775 | N39: =IFERROR((K39*$N$6)," ") -> 6572.5375 | O39: =IFERROR((K39*$O$6)," ") -> 6858.3
B40: Analista Financeiro Sr | C40: Financeiro | E40: 5910.71 | F40: 15 | G40: =IFERROR((K40*$G$6)," ") -> 4572.2 | H40: =IFERROR((K40*$H$6)," ") -> 4857.9625 | I40: =IFERROR((K40*$I$6)," ") -> 5143.725 | J40: =IFERROR((K40*$J$6)," ") -> 5429.4875 | K40: =VLOOKUP(F40,'Tabela Salarial_CLT'!$B:$G,6,0) -> 5715.25 | L40: =IFERROR((K40*$L$6)," ") -> 6001.0125 | M40: =IFERROR((K40*$M$6)," ") -> 6286.775 | N40: =IFERROR((K40*$N$6)," ") -> 6572.5375 | O40: =IFERROR((K40*$O$6)," ") -> 6858.3
B41: Analista Inovação | C41: Inovação | D41: 7299.2701 | E41: 6872.05 | F41: 15 | G41: =IFERROR((K41*$G$6)," ") -> 4572.2 | H41: =IFERROR((K41*$H$6)," ") -> 4857.9625 | I41: =IFERROR((K41*$I$6)," ") -> 5143.725 | J41: =IFERROR((K41*$J$6)," ") -> 5429.4875 | K41: =VLOOKUP(F41,'Tabela Salarial_CLT'!$B:$G,6,0) -> 5715.25 | L41: =IFERROR((K41*$L$6)," ") -> 6001.0125 | M41: =IFERROR((K41*$M$6)," ") -> 6286.775 | N41: =IFERROR((K41*$N$6)," ") -> 6572.5375 | O41: =IFERROR((K41*$O$6)," ") -> 6858.3
B42: Analista Manutenção Sr | C42: Edificação | F42: 15 | G42: =IFERROR((K42*$G$6)," ") -> 4572.2 | H42: =IFERROR((K42*$H$6)," ") -> 4857.9625 | I42: =IFERROR((K42*$I$6)," ") -> 5143.725 | J42: =IFERROR((K42*$J$6)," ") -> 5429.4875 | K42: =VLOOKUP(F42,'Tabela Salarial_CLT'!$B:$G,6,0) -> 5715.25 | L42: =IFERROR((K42*$L$6)," ") -> 6001.0125 | M42: =IFERROR((K42*$M$6)," ") -> 6286.775 | N42: =IFERROR((K42*$N$6)," ") -> 6572.5375 | O42: =IFERROR((K42*$O$6)," ") -> 6858.3
B43: Analista Marketing Sr | C43: Marketing | F43: 15 | G43: =IFERROR((K43*$G$6)," ") -> 4572.2 | H43: =IFERROR((K43*$H$6)," ") -> 4857.9625 | I43: =IFERROR((K43*$I$6)," ") -> 5143.725 | J43: =IFERROR((K43*$J$6)," ") -> 5429.4875 | K43: =VLOOKUP(F43,'Tabela Salarial_CLT'!$B:$G,6,0) -> 5715.25 | L43: =IFERROR((K43*$L$6)," ") -> 6001.0125 | M43: =IFERROR((K43*$M$6)," ") -> 6286.775 | N43: =IFERROR((K43*$N$6)," ") -> 6572.5375 | O43: =IFERROR((K43*$O$6)," ") -> 6858.3
...

Sheet Tabela Salarial_CLT
B2: Tabela Salarial - CLT Amplitude Horizontal (no mesmo Nível): 50%
B4: Grades
C5: 0.8 | D5: 0.85 | E5: 0.9 | F5: 0.95 | G5: 1 | H5: 1.05 | I5: 1.1 | J5: 1.15 | K5: 1.2
B6: 10 | C6: =ROUND(G6*$C$5,2) -> 1867.2 | D6: =G6*$D$5 -> 1983.9 | E6: =G6*$E$5 -> 2100.6 | F6: =G6*$F$5 -> 2217.3 | G6: 2334 | H6: =G6*$H$5 -> 2450.7 | I6: =G6*$I$5 -> 2567.4 | J6: =G6*$J$5 -> 2684.1 | K6: =G6*$K$5 -> 2800.8
B7: 11 | C7: =ROUND(G7*$C$5,2) -> 2191.11 | D7: =G7*$D$5 -> 2328.0565 | E7: =G7*$E$5 -> 2465.001 | F7: =G7*$F$5 -> 2601.9455 | G7: 2738.89 | H7: =G7*$H$5 -> 2875.8345 | I7: =G7*$I$5 -> 3012.779 | J7: =G7*$J$5 -> 3149.7235 | K7: =G7*$K$5 -> 3286.668
B8: 12 | C8: =ROUND(G8*$C$5,2) -> 2593.86 | D8: =G8*$D$5 -> 2755.972 | E8: =G8*$E$5 -> 2918.088 | F8: =G8*$F$5 -> 3080.204 | G8: 3242.32 | H8: =G8*$H$5 -> 3404.436 | I8: =G8*$I$5 -> 3566.552 | J8: =G8*$J$5 -> 3728.668 | K8: =G8*$K$5 -> 3890.784
B9: 13 | C9: =ROUND(G9*$C$5,2) -> 3105.14 | D9: =G9*$D$5 -> 3299.2155 | E9: =G9*$E$5 -> 3493.287 | F9: =G9*$F$5 -> 3687.3585 | G9: 3881.43 | H9: =G9*$H$5 -> 4075.5015 | I9: =G9*$I$5 -> 4269.573 | J9: =G9*$J$5 -> 4463.6445 | K9: =G9*$K$5 -> 4657.716
B10: 14 | C10: =ROUND(G10*$C$5,2) -> 3754.69 | D10: =G10*$D$5 -> 3989.356 | E10: =G10*$E$5 -> 4224.024 | F10: =G10*$F$5 -> 4458.692 | G10: 4693.36 | H10: =G10*$H$5 -> 4928.028 | I10: =G10*$I$5 -> 5162.696 | J10: =G10*$J$5 -> 5397.364 | K10: =G10*$K$5 -> 5632.032
B11: 15 | C11: =ROUND(G11*$C$5,2) -> 4572.2 | D11: =G11*$D$5 -> 4857.9625 | E11: =G11*$E$5 -> 5143.725 | F11: =G11*$F$5 -> 5429.4875 | G11: 5715.25 | H11: =G11*$H$5 -> 6001.0125 | I11: =G11*$I$5 -> 6286.775 | J11: =G11*$J$5 -> 6572.5375 | K11: =G11*$K$5 -> 6858.3
B12: 16 | C12: =ROUND(G12*$C$5,2) -> 5587.39 | D12: =G12*$D$5 -> 5936.604 | E12: =G12*$E$5 -> 6285.816 | F12: =G12*$F$5 -> 6635.028 | G12: 6984.24 | H12: =G12*$H$5 -> 7333.452 | I12: =G12*$I$5 -> 7682.664 | J12: =G12*$J$5 -> 8031.876 | K12: =G12*$K$5 -> 8381.088
B13: 17 | C13: =ROUND(G13*$C$5,2) -> 6829.98 | D13: =G13*$D$5 -> 7256.8495 | E13: =G13*$E$5 -> 7683.723 | F13: =G13*$F$5 -> 8110.5965 | G13: 8537.47 | H13: =G13*$H$5 -> 8964.3435 | I13: =G13*$I$5 -> 9391.217 | J13: =G13*$J$5 -> 9818.0905 | K13: =G13*$K$5 -> 10244.964 | N13: S
B14: 18 | C14: =ROUND(G14*$C$5,2) -> 8329.66 | D14: =G14*$D$5 -> 8850.268 | E14: =G14*$E$5 -> 9370.872 | F14: =G14*$F$5 -> 9891.476 | G14: 10412.08 | H14: =G14*$H$5 -> 10932.684 | I14: =G14*$I$5 -> 11453.288 | J14: =G14*$J$5 -> 11973.892 | K14: =G14*$K$5 -> 12494.496
B15: 19 | C15: =ROUND(G15*$C$5,2) -> 10116.17 | D15: =G15*$D$5 -> 10748.428 | E15: =G15*$E$5 -> 11380.689 | F15: =G15*$F$5 -> 12012.95 | G15: 12645.21 | H15: =G15*$H$5 -> 13277.47 | I15: =G15*$I$5 -> 13909.731 | J15: =G15*$J$5 -> 14541.992 | K15: =G15*$K$5 -> 15174.252
B16: 20 | C16: =ROUND(G16*$C$5,2) -> 12219.2 | D16: =G16*$D$5 -> 12982.9 | E16: =G16*$E$5 -> 13746.6 | F16: =G16*$F$5 -> 14510.3 | G16: 15274 | H16: =G16*$H$5 -> 16037.7 | I16: =G16*$I$5 -> 16801.4 | J16: =G16*$J$5 -> 17565.1 | K16: =G16*$K$5 -> 18328.8
B17: 21 | C17: =ROUND(G17*$C$5,2) -> 14668.47 | D17: =G17*$D$5 -> 15585.252 | E17: =G17*$E$5 -> 16502.031 | F17: =G17*$F$5 -> 17418.81 | G17: 18335.59 | H17: =G17*$H$5 -> 19252.37 | I17: =G17*$I$5 -> 20169.149 | J17: =G17*$J$5 -> 21085.929 | K17: =G17*$K$5 -> 22002.708
B18: 22 | C18: =ROUND(G18*$C$5,2) -> 17493.7 | D18: =G18*$D$5 -> 18587.052 | E18: =G18*$E$5 -> 19680.408 | F18: =G18*$F$5 -> 20773.764 | G18: 21867.12 | H18: =G18*$H$5 -> 22960.476 | I18: =G18*$I$5 -> 24053.832 | J18: =G18*$J$5 -> 25147.188 | K18: =G18*$K$5 -> 26240.544
B19: 23 | C19: =ROUND(G19*$C$5,2) -> 20724.58 | D19: =G19*$D$5 -> 22019.871 | E19: =G19*$E$5 -> 23315.157 | F19: =G19*$F$5 -> 24610.444 | G19: 25905.73 | H19: =G19*$H$5 -> 27201.017 | I19: =G19*$I$5 -> 28496.303 | J19: =G19*$J$5 -> 29791.589 | K19: =G19*$K$5 -> 31086.876
B20: 24 | C20: =ROUND(G20*$C$5,2) -> 24390.85 | D20: =G20*$D$5 -> 25915.276 | E20: =G20*$E$5 -> 27439.704 | F20: =G20*$F$5 -> 28964.132 | G20: 30488.56 | H20: =G20*$H$5 -> 32012.988 | I20: =G20*$I$5 -> 33537.416 | J20: =G20*$J$5 -> 35061.844 | K20: =G20*$K$5 -> 36586.272
B21: 25 | C21: =ROUND(G21*$C$5,2) -> 28522.2 | D21: =G21*$D$5 -> 30304.838 | E21: =G21*$E$5 -> 32087.475 | F21: =G21*$F$5 -> 33870.113 | G21: 35652.75 | H21: =G21*$H$5 -> 37435.387 | I21: =G21*$I$5 -> 39218.025 | J21: =G21*$J$5 -> 41000.662 | K21: =G21*$K$5 -> 42783.3
B22: 26 | C22: =ROUND(G22*$C$5,2) -> 33148.35 | D22: =G22*$D$5 -> 35220.124 | E22: =G22*$E$5 -> 37291.896 | F22: =G22*$F$5 -> 39363.668 | G22: 41435.44 | H22: =G22*$H$5 -> 43507.212 | I22: =G22*$I$5 -> 45578.984 | J22: =G22*$J$5 -> 47650.756 | K22: =G22*$K$5 -> 49722.528
B23: 27 | C23: =ROUND(G23*$C$5,2) -> 38299.02 | D23: =G23*$D$5 -> 40692.704 | E23: =G23*$E$5 -> 43086.393 | F23: =G23*$F$5 -> 45480.082 | G23: 47873.77 | H23: =G23*$H$5 -> 50267.459 | I23: =G23*$I$5 -> 52661.147 | J23: =G23*$J$5 -> 55054.836 | K23: =G23*$K$5 -> 57448.524
B24: 28 | C24: =ROUND(G24*$C$5,2) -> 44003.9 | D24: =G24*$D$5 -> 46754.148 | E24: =G24*$E$5 -> 49504.392 | F24: =G24*$F$5 -> 52254.636 | G24: 55004.88 | H24: =G24*$H$5 -> 57755.124 | I24: =G24*$I$5 -> 60505.368 | J24: =G24*$J$5 -> 63255.612 | K24: =G24*$K$5 -> 66005.856

Sheet Tabela Salarial_PJ
B2: Tabela Salarial PJ Amplitude Horizontal (no mesmo Nível): 50%
B4: Grades | M4: Nível Operacional / Nível de Liderança | N4: Mult | O4: Grades
C5: 0.8 | D5: 0.85 | E5: 0.9 | F5: 0.95 | G5: 1 | H5: 1.05 | I5: 1.1 | J5: 1.15 | K5: 1.2
B6: 10 | C6: =ROUND(G6*$C$5,2) -> 2782.13 | D6: =G6*$D$5 -> 2956.011 | E6: =G6*$E$5 -> 3129.894 | F6: =G6*$F$5 -> 3303.777 | G6: ='Tabela Salarial_CLT'!G6*N6 -> 3477.66 | H6: =G6*$H$5 -> 3651.543 | I6: =G6*$I$5 -> 3825.426 | J6: =G6*$J$5 -> 3999.309 | K6: =G6*$K$5 -> 4173.192 | M6: Operacional | N6: 1.49 | O6: 10 | P6: =N6 -> 1.49
B7: 11 | C7: =ROUND(G7*$C$5,2) -> 3264.76 | D7: =G7*$D$5 -> 3468.8042 | E7: =G7*$E$5 -> 3672.8515 | F7: =G7*$F$5 -> 3876.8988 | G7: ='Tabela Salarial_CLT'!G7*N7 -> 4080.9461 | H7: =G7*$H$5 -> 4284.9934 | I7: =G7*$I$5 -> 4489.0407 | J7: =G7*$J$5 -> 4693.088 | K7: =G7*$K$5 -> 4897.1353 | M7: Operacional | N7: 1.49 | O7: 11 | P7: =N7 -> 1.49
B8: 12 | C8: =ROUND(G8*$C$5,2) -> 3864.85 | D8: =G8*$D$5 -> 4106.3983 | E8: =G8*$E$5 -> 4347.9511 | F8: =G8*$F$5 -> 4589.504 | G8: ='Tabela Salarial_CLT'!G8*N8 -> 4831.0568 | H8: =G8*$H$5 -> 5072.6096 | I8: =G8*$I$5 -> 5314.1625 | J8: =G8*$J$5 -> 5555.7153 | K8: =G8*$K$5 -> 5797.2682 | M8: Operacional | N8: 1.49 | O8: 12 | P8: =N8 -> 1.49
B9: 13 | C9: =ROUND(G9*$C$5,2) -> 4626.66 | D9: =G9*$D$5 -> 4915.8311 | E9: =G9*$E$5 -> 5204.9976 | F9: =G9*$F$5 -> 5494.1642 | G9: ='Tabela Salarial_CLT'!G9*N9 -> 5783.3307 | H9: =G9*$H$5 -> 6072.4972 | I9: =G9*$I$5 -> 6361.6638 | J9: =G9*$J$5 -> 6650.8303 | K9: =G9*$K$5 -> 6939.9968 | M9: Operacional | N9: 1.49 | O9: 13 | P9: =N9 -> 1.49
B10: 14 | C10: =ROUND(G10*$C$5,2) -> 5594.49 | D10: =G10*$D$5 -> 5944.1404 | E10: =G10*$E$5 -> 6293.7958 | F10: =G10*$F$5 -> 6643.4511 | G10: ='Tabela Salarial_CLT'!G10*N10 -> 6993.1064 | H10: =G10*$H$5 -> 7342.7617 | I10: =G10*$I$5 -> 7692.417 | J10: =G10*$J$5 -> 8042.0724 | K10: =G10*$K$5 -> 8391.7277 | M10: Operacional | N10: 1.49 | O10: 14 | P10: =N10 -> 1.49
B11: 15 | C11: =ROUND(G11*$C$5,2) -> 6812.58 | D11: =G11*$D$5 -> 7238.3641 | E11: =G11*$E$5 -> 7664.1502 | F11: =G11*$F$5 -> 8089.9364 | G11: ='Tabela Salarial_CLT'!G11*N11 -> 8515.7225 | H11: =G11*$H$5 -> 8941.5086 | I11: =G11*$I$5 -> 9367.2947 | J11: =G11*$J$5 -> 9793.0809 | K11: =G11*$K$5 -> 10218.867 | M11: Operacional | N11: 1.49 | O11: 15 | P11: =N11 -> 1.49
B12: 16 | C12: =ROUND(G12*$C$5,2) -> 8325.21 | D12: =G12*$D$5 -> 8845.54 | E12: =G12*$E$5 -> 9365.8658 | F12: =G12*$F$5 -> 9886.1917 | G12: ='Tabela Salarial_CLT'!G12*N12 -> 10406.518 | H12: =G12*$H$5 -> 10926.843 | I12: =G12*$I$5 -> 11447.169 | J12: =G12*$J$5 -> 11967.495 | K12: =G12*$K$5 -> 12487.821 | M12: Operacional | N12: 1.49 | O12: 16 | P12: =N12 -> 1.49
B13: 17 | C13: =ROUND(G13*$C$5,2) -> 10244.96 | D13: =G13*$D$5 -> 10885.274 | E13: =G13*$E$5 -> 11525.585 | F13: =G13*$F$5 -> 12165.895 | G13: ='Tabela Salarial_CLT'!G13*N13 -> 12806.205 | H13: =G13*$H$5 -> 13446.515 | I13: =G13*$I$5 -> 14086.826 | J13: =G13*$J$5 -> 14727.136 | K13: =G13*$K$5 -> 15367.446 | M13: Operacional/Coordenador | N13: 1.5 | O13: 17 | P13: =N13 -> 1.5
B14: 18 | C14: =ROUND(G14*$C$5,2) -> 12105.78 | D14: =G14*$D$5 -> 12862.389 | E14: =G14*$E$5 -> 13619.001 | F14: =G14*$F$5 -> 14375.612 | G14: ='Tabela Salarial_CLT'!G14*N14 -> 15132.223 | H14: =G14*$H$5 -> 15888.834 | I14: =G14*$I$5 -> 16645.445 | J14: =G14*$J$5 -> 17402.056 | K14: =G14*$K$5 -> 18158.668 | M14: Operacional/Gerente/Coordenador | N14: 1.4533333 | O14: 18 | P14: =N14 -> 1.4533333
B15: 19 | C15: =ROUND(G15*$C$5,2) -> 14314.38 | D15: =G15*$D$5 -> 15209.026 | E15: =G15*$E$5 -> 16103.675 | F15: =G15*$F$5 -> 16998.324 | G15: ='Tabela Salarial_CLT'!G15*N15 -> 17892.972 | H15: =G15*$H$5 -> 18787.621 | I15: =G15*$I$5 -> 19682.269 | J15: =G15*$J$5 -> 20576.918 | K15: =G15*$K$5 -> 21471.567 | M15: Coordenador/Gerente | N15: 1.415 | O15: 19 | P15: =N15 -> 1.415
B16: 20 | C16: =ROUND(G16*$C$5,2) -> 17290.17 | D16: =G16*$D$5 -> 18370.804 | E16: =G16*$E$5 -> 19451.439 | F16: =G16*$F$5 -> 20532.074 | G16: ='Tabela Salarial_CLT'!G16*N16 -> 21612.71 | H16: =G16*$H$5 -> 22693.345 | I16: =G16*$I$5 -> 23773.981 | J16: =G16*$J$5 -> 24854.617 | K16: =G16*$K$5 -> 25935.252 | M16: Coordenador/Gerente | N16: 1.415 | O16: 20 | P16: =N16 -> 1.415
B17: 21 | C17: =ROUND(G17*$C$5,2) -> 20755.89 | D17: =G17*$D$5 -> 22053.131 | E17: =G17*$E$5 -> 23350.374 | F17: =G17*$F$5 -> 24647.617 | G17: ='Tabela Salarial_CLT'!G17*N17 -> 25944.86 | H17: =G17*$H$5 -> 27242.103 | I17: =G17*$I$5 -> 28539.346 | J17: =G17*$J$5 -> 29836.589 | K17: =G17*$K$5 -> 31133.832 | M17: Coordenador/Gerente | N17: 1.415 | O17: 21 | P17: =N17 -> 1.415
... B24: 28 | C24: =ROUND(G24*$C$5,2) -> 45764.06 | D24: =G24*$D$5 -> 48624.314 | E24: =G24*$E$5 -> 51484.568 | F24: =G24*$F$5 -> 54344.821 | G24: ='Tabela Salarial_CLT'!G24*N24 -> 57205.075 | H24: =G24*$H$5 -> 60065.329 | I24: =G24*$I$5 -> 62925.583 | J24: =G24*$J$5 -> 65785.836 | K24: =G24*$K$5 -> 68646.09 | M24: Diretor | N24: 1.04 | O24: 28 | P24: =N24 -> 1.04

Sheet Previsão Custo Enquadramento
A1: Cod do funcionário | B1: Cargo Atual | C1: Cargo Estrutura Salarial | D1: Área | E1: Nível Organizacional | F1: Tipo de Contratação | G1: Carga Horária | H1: Salário | I1: Grade Tabela | J1: Tabela - Inicial Faixa | K1: Dif Tabela | L1: Dif Enquadramento Tabela | M1: Posicionamento na Tabela | N1: Tabela - 100% | O1: Dif 100% | P1: Todos 100% | Q1: Atual - Máximo
A2: 1362 | B2: ALMOXARIFE | C2: Almoxarife | D2: Edificação | E2: Operacional | F2: CLT | G2: 220 | H2: 3683 | I2: =VLOOKUP(C2,'Estrutura Salarial'!B:F,5,0) -> 12 | J2: =IF(F2="CLT",IFERROR(VLOOKUP(I2,'Tabela Salarial_CLT'!B:C,2,0),""),IFERROR(VLOOKUP(I2,'Tabela Salarial_PJ'!B:C,2,0),"")) -> 2593.86 | K2: =J2-H2 -> -1089.14 | L2: =IF(K2<0,0,IF(K2>0,K2,IF(K2=0,0,""))) -> 0 | M2: =IF(F2="CLT",H2/(VLOOKUP(I2,'Tabela Salarial_CLT'!B:G,6,0)),H2/(VLOOKUP(I2,'Tabela Salarial_PJ'!B:G,6,0))) -> 1.135915 | N2: =IF(F2="CLT",IFERROR(VLOOKUP(I2,'Tabela Salarial_CLT'!B:G,6,0),""),IFERROR(VLOOKUP(I2,'Tabela Salarial_PJ'!B:G,6,0),"")) -> 3242.32 | O2: =IF(F2="CLT",N2-H2,-(H2)+N2) -> -440.68 | P2: =IF(O2<0,0,if(O2>0,O2,if(O2=0,0,""))) -> 0 | Q2: =IF(F2="CLT",(VLOOKUP(I2,'Tabela Salarial_CLT'!B:K,10,0))-H2,(VLOOKUP(I2,'Tabela Salarial_PJ'!B:K,10,0))-H2) -> 207.784
A3: 1957 | B3: ALMOXARIFE | C3: Almoxarife | D3: Edificação | E3: Operacional | F3: CLT | G3: 220 | H3: 3683 | I3: =VLOOKUP(C3,'Estrutura Salarial'!B:F,5,0) -> 12 | J3: =IF(F3="CLT",IFERROR(VLOOKUP(I3,'Tabela Salarial_CLT'!B:C,2,0),""),IFERROR(VLOOKUP(I3,'Tabela Salarial_PJ'!B:C,2,0),"")) -> 2593.86 | K3: =J3-H3 -> -1089.14 | L3: =IF(K3<0,0,IF(K3>0,K3,IF(K3=0,0,""))) -> 0 | M3: =IF(F3="CLT",H3/(VLOOKUP(I3,'Tabela Salarial_CLT'!B:G,6,0)),H3/(VLOOKUP(I3,'Tabela Salarial_PJ'!B:G,6,0))) -> 1.135915 | N3: =IF(F3="CLT",IFERROR(VLOOKUP(I3,'Tabela Salarial_CLT'!B:G,6,0),""),IFERROR(VLOOKUP(I3,'Tabela Salarial_PJ'!B:G,6,0),"")) -> 3242.32 | O3: =IF(F3="CLT",N3-H3,-(H3)+N3) -> -440.68 | P3: =IF(O3<0,0,if(O3>0,O3,if(O3=0,0,""))) -> 0 | Q3: =IF(F3="CLT",(VLOOKUP(I3,'Tabela Salarial_CLT'!B:K,10,0))-H3,(VLOOKUP(I3,'Tabela Salarial_PJ'!B:K,10,0))-H3) -> 207.784
A4: 1964 | B4: ANALISTA DE COMPRAS | C4: Analista Compras Jr | D4: Suprimentos | E4: Operacional | F4: CLT | G4: 220 | H4: 3780 | I4: =VLOOKUP(C4,'Estrutura Salarial'!B:F,5,0) -> 14 | J4: =IF(F4="CLT",IFERROR(VLOOKUP(I4,'Tabela Salarial_CLT'!B:C,2,0),""),IFERROR(VLOOKUP(I4,'Tabela Salarial_PJ'!B:C,2,0),"")) -> 3754.69 | K4: =J4-H4 -> -25.31 | L4: =IF(K4<0,0,IF(K4>0,K4,IF(K4=0,0,""))) -> 0 | M4: =IF(F4="CLT",H4/(VLOOKUP(I4,'Tabela Salarial_CLT'!B:G,6,0)),H4/(VLOOKUP(I4,'Tabela Salarial_PJ'!B:G,6,0))) -> 0.80539315 | N4: =IF(F4="CLT",IFERROR(VLOOKUP(I4,'Tabela Salarial_CLT'!B:G,6,0),""),IFERROR(VLOOKUP(I4,'Tabela Salarial_PJ'!B:G,6,0),"")) -> 4693.36 | O4: =IF(F4="CLT",N4-H4,-(H4)+N4) -> 913.36 | P4: =IF(O4<0,0,if(O4>0,O4,if(O4=0,0,""))) -> 913.36 | Q4: =IF(F4="CLT",(VLOOKUP(I4,'Tabela Salarial_CLT'!B:K,10,0))-H4,(VLOOKUP(I4,'Tabela Salarial_PJ'!B:K,10,0))-H4) -> 1852.032
A5: 1910 | B5: ANALISTA DE CRIAÇAO | C5: Analista Criação | D5: Marketing | E5: Operacional | F5: CLT | G5: 220 | H5: 5429 | I5: =VLOOKUP(C5,'Estrutura Salarial'!B:F,5,0) -> 14 | J5: =IF(F5="CLT",IFERROR(VLOOKUP(I5,'Tabela Salarial_CLT'!B:C,2,0),""),IFERROR(VLOOKUP(I5,'Tabela Salarial_PJ'!B:C,2,0),"")) -> 3754.69 | K5: =J5-H5 -> -1674.31 | L5: =IF(K5<0,0,IF(K5>0,K5,IF(K5=0,0,""))) -> 0 | M5: =IF(F5="CLT",H5/(VLOOKUP(I5,'Tabela Salarial_CLT'!B:G,6,0)),H5/(VLOOKUP(I5,'Tabela Salarial_PJ'!B:G,6,0))) -> 1.1567406 | N5: =IF(F5="CLT",IFERROR(VLOOKUP(I5,'Tabela Salarial_CLT'!B:G,6,0),""),IFERROR(VLOOKUP(I5,'Tabela Salarial_PJ'!B:G,6,0),"")) -> 4693.36 | O5: =IF(F5="CLT",N5-H5,-(H5)+N5) -> -735.64 | P5: =IF(O5<0,0,if(O5>0,O5,if(O5=0,0,""))) -> 0 | Q5: =IF(F5="CLT",(VLOOKUP(I5,'Tabela Salarial_CLT'!B:K,10,0))-H5,(VLOOKUP(I5,'Tabela Salarial_PJ'!B:K,10,0))-H5) -> 203.032
A6: PJ1 | B6: ANALISTA DE INOVAÇÃO | C6: Analista Inovação | D6: Inovação | E6: Tático | F6: PJ | G6: 220 | H6: 10000 | I6: =VLOOKUP(C6,'Estrutura Salarial'!B:F,5,0) -> 15 | J6: =IF(F6="CLT",IFERROR(VLOOKUP(I6,'Tabela Salarial_CLT'!B:C,2,0),""),IFERROR(VLOOKUP(I6,'Tabela Salarial_PJ'!B:C,2,0),"")) -> 6812.58 | K6: =J6-H6 -> -3187.42 | L6: =IF(K6<0,0,IF(K6>0,K6,IF(K6=0,0,""))) -> 0 | M6: =IF(F6="CLT",H6/(VLOOKUP(I6,'Tabela Salarial_CLT'!B:G,6,0)),H6/(VLOOKUP(I6,'Tabela Salarial_PJ'!B:G,6,0))) -> 1.1742985 | N6: =IF(F6="CLT",IFERROR(VLOOKUP(I6,'Tabela Salarial_CLT'!B:G,6,0),""),IFERROR(VLOOKUP(I6,'Tabela Salarial_PJ'!B:G,6,0),"")) -> 8515.7225 | O6: =IF(F6="CLT",N6-H6,-(H6)+N6) -> -1484.2775 | P6: =IF(O6<0,0,if(O6>0,O6,if(O6=0,0,""))) -> 0 | Q6: =IF(F6="CLT",(VLOOKUP(I6,'Tabela Salarial_CLT'!B:K,10,0))-H6,(VLOOKUP(I6,'Tabela Salarial_PJ'!B:K,10,0))-H6) -> 218.867
A7: 1373 | B7: ANALISTA DE MANUTENÇÃO II | C7: Analista Manutenção Pl | D7: Edificação | E7: Operacional | F7: CLT | G7: 220 | H7: 4550 | I7: =VLOOKUP(C7,'Estrutura Salarial'!B:F,5,0) -> 14 | J7: =IF(F7="CLT",IFERROR(VLOOKUP(I7,'Tabela Salarial_CLT'!B:C,2,0),""),IFERROR(VLOOKUP(I7,'Tabela Salarial_PJ'!B:C,2,0),"")) -> 3754.69 | K7: =J7-H7 -> -795.31 | L7: =IF(K7<0,0,IF(K7>0,K7,IF(K7=0,0,""))) -> 0 | M7: =IF(F7="CLT",H7/(VLOOKUP(I7,'Tabela Salarial_CLT'!B:G,6,0)),H7/(VLOOKUP(I7,'Tabela Salarial_PJ'!B:G,6,0))) -> 0.96945472 | N7: =IF(F7="CLT",IFERROR(VLOOKUP(I7,'Tabela Salarial_CLT'!B:G,6,0),""),IFERROR(VLOOKUP(I7,'Tabela Salarial_PJ'!B:G,6,0),"")) -> 4693.36 | O7: =IF(F7="CLT",N7-H7,-(H7)+N7) -> 143.36 | P7: =IF(O7<0,0,if(O7>0,O7,if(O7=0,0,""))) -> 143.36 | Q7: =IF(F7="CLT",(VLOOKUP(I7,'Tabela Salarial_CLT'!B:K,10,0))-H7,(VLOOKUP(I7,'Tabela Salarial_PJ'!B:K,10,0))-H7) -> 1082.032
A8: 139 | B8: ANALISTA DE MARKETING l | C8: Analista Marketing Jr | D8: Marketing | E8: Operacional | F8: CLT | G8: 220 | H8: 4025.88 | I8: =VLOOKUP(C8,'Estrutura Salarial'!B:F,5,0) -> 13 | J8: =IF(F8="CLT",IFERROR(VLOOKUP(I8,'Tabela Salarial_CLT'!B:C,2,0),""),IFERROR(VLOOKUP(I8,'Tabela Salarial_PJ'!B:C,2,0),"")) -> 3105.14 | K8: =J8-H8 -> -920.74 | L8: =IF(K8<0,0,IF(K8>0,K8,IF(K8=0,0,""))) -> 0 | M8: =IF(F8="CLT",H8/(VLOOKUP(I8,'Tabela Salarial_CLT'!B:G,6,0)),H8/(VLOOKUP(I8,'Tabela Salarial_PJ'!B:G,6,0))) -> 1.0372157 | N8: =IF(F8="CLT",IFERROR(VLOOKUP(I8,'Tabela Salarial_CLT'!B:G,6,0),""),IFERROR(VLOOKUP(I8,'Tabela Salarial_PJ'!B:G,6,0),"")) -> 3881.43 | O8: =IF(F8="CLT",N8-H8,-(H8)+N8) -> -144.45 | P8: =IF(O8<0,0,if(O8>0,O8,if(O8=0,0,""))) -> 0 | Q8: =IF(F8="CLT",(VLOOKUP(I8,'Tabela Salarial_CLT'!B:K,10,0))-H8,(VLOOKUP(I8,'Tabela Salarial_PJ'!B:K,10,0))-H8) -> 631.836
A9: 1962 | B9: ANALISTA DE PÓS VENDAS II | C9: Analista Pós-Vendas Pl | D9: Pós Vendas | E9: Operacional | F9: CLT | G9: 220 | H9: 4550 | I9: =VLOOKUP(C9,'Estrutura Salarial'!B:F,5,0) -> 14 | J9: =IF(F9="CLT",IFERROR(VLOOKUP(I9,'Tabela Salarial_CLT'!B:C,2,0),""),IFERROR(VLOOKUP(I9,'Tabela Salarial_PJ'!B:C,2,0),"")) -> 3754.69 | K9: =J9-H9 -> -795.31 | L9: =IF(K9<0,0,IF(K9>0,K9,IF(K9=0,0,""))) -> 0 | M9: =IF(F9="CLT",H9/(VLOOKUP(I9,'Tabela Salarial_CLT'!B:G,6,0)),H9/(VLOOKUP(I9,'Tabela Salarial_PJ'!B:G,6,0))) -> 0.96945472 | N9: =IF(F9="CLT",IFERROR(VLOOKUP(I9,'Tabela Salarial_CLT'!B:G,6,0),""),IFERROR(VLOOKUP(I9,'Tabela Salarial_PJ'!B:G,6,0),"")) -> 4693.36 | O9: =IF(F9="CLT",N9-H9,-(H9)+N9) -> 143.36 | P9: =IF(O9<0,0,if(O9>0,O9,if(O9=0,0,""))) -> 143.36 | Q9: =IF(F9="CLT",(VLOOKUP(I9,'Tabela Salarial_CLT'!B:K,10,0))-H9,(VLOOKUP(I9,'Tabela Salarial_PJ'!B:K,10,0))-H9) -> 1082.032
A10: 187 | B10: ANALISTA DE URBANISMO | C10: Analista Urbanismo Pl | D10: Urbanismo | E10: Operacional | F10: CLT | G10: 220 | H10: 5830 | I10: =VLOOKUP(C10,'Estrutura Salarial'!B:F,5,0) -> 16 | J10: =IF(F10="CLT",IFERROR(VLOOKUP(I10,'Tabela Salarial_CLT'!B:C,2,0),""),IFERROR(VLOOKUP(I10,'Tabela Salarial_PJ'!B:C,2,0),"")) -> 5587.39 | K10: =J10-H10 -> -242.61 | L10: =IF(K10<0,0,IF(K10>0,K10,IF(K10=0,0,""))) -> 0 | M10: =IF(F10="CLT",H10/(VLOOKUP(I10,'Tabela Salarial_CLT'!B:G,6,0)),H10/(VLOOKUP(I10,'Tabela Salarial_PJ'!B:G,6,0))) -> 0.83473649 | N10: =IF(F10="CLT",IFERROR(VLOOKUP(I10,'Tabela Salarial_CLT'!B:G,6,0),""),IFERROR(VLOOKUP(I10,'Tabela Salarial_PJ'!B:G,6,0),"")) -> 6984.24 | O10: =IF(F10="CLT",N10-H10,-(H10)+N10) -> 1154.24 | P10: =IF(O10<0,0,if(O10>0,O10,if(O10=0,0,""))) -> 1154.24 | Q10: =IF(F10="CLT",(VLOOKUP(I10,'Tabela Salarial_CLT'!B:K,10,0))-H10,(VLOOKUP(I10,'Tabela Salarial_PJ'!B:K,10,0))-H10) -> 2551.088
A11: 1868 | B11: ANALISTA FINANCEIRO COMERCIAL III | C11: Analista Financeiro Comercial Sr | D11: Financeiro | E11: Operacional | F11: CLT | G11: 220 | H11: 5213 | I11: =VLOOKUP(C11,'Estrutura Salarial'!B:F,5,0) -> 15 | J11: =IF(F11="CLT",IFERROR(VLOOKUP(I11,'Tabela Salarial_CLT'!B:C,2,0),""),IFERROR(VLOOKUP(I11,'Tabela Salarial_PJ'!B:C,2,0),"")) -> 4572.2 | K11: =J11-H11 -> -640.8 | L11: =IF(K11<0,0,IF(K11>0,K11,IF(K11=0,0,""))) -> 0 | M11: =IF(F11="CLT",H11/(VLOOKUP(I11,'Tabela Salarial_CLT'!B:G,6,0)),H11/(VLOOKUP(I11,'Tabela Salarial_PJ'!B:G,6,0))) -> 0.91212108 | N11: =IF(F11="CLT",IFERROR(VLOOKUP(I11,'Tabela Salarial_CLT'!B:G,6,0),""),IFERROR(VLOOKUP(I11,'Tabela Salarial_PJ'!B:G,6,0),"")) -> 5715.25 | O11: =IF(F11="CLT",N11-H11,-(H11)+N11) -> 502.25 | P11: =IF(O11<0,0,if(O11>0,O11,if(O11=0,0,""))) -> 502.25 | Q11: =IF(F11="CLT",(VLOOKUP(I11,'Tabela Salarial_CLT'!B:K,10,0))-H11,(VLOOKUP(I11,'Tabela Salarial_PJ'!B:K,10,0))-H11) -> 1645.3
A12: 176 | B12: ANALISTA FINANCEIRO DE CAPTAÇÃO DE RECURSOS III | C12: Analista Financeiro Captação Recursos Sr | D12: Financeiro | E12: Operacional | F12: CLT | G12: 220 | H12: 5213 | I12: =VLOOKUP(C12,'Estrutura Salarial'!B:F,5,0) -> 15 | J12: =IF(F12="CLT",IFERROR(VLOOKUP(I12,'Tabela Salarial_CLT'!B:C,2,0),""),IFERROR(VLOOKUP(I12,'Tabela Salarial_PJ'!B:C,2,0),"")) -> 4572.2 | K12: =J12-H12 -> -640.8 | L12: =IF(K12<0,0,IF(K12>0,K12,IF(K12=0,0,""))) -> 0 | M12: =IF(F12="CLT",H12/(VLOOKUP(I12,'Tabela Salarial_CLT'!B:G,6,0)),H12/(VLOOKUP(I12,'Tabela Salarial_PJ'!B:G,6,0))) -> 0.91212108 | N12: =IF(F12="CLT",IFERROR(VLOOKUP(I12,'Tabela Salarial_CLT'!B:G,6,0),""),IFERROR(VLOOKUP(I12,'Tabela Salarial_PJ'!B:G,6,0),"")) -> 5715.25 | O12: =IF(F12="CLT",N12-H12,-(H12)+N12) -> 502.25 | P12: =IF(O12<0,0,if(O12>0,O12,if(O12=0,0,""))) -> 502.25 | Q12: =IF(F12="CLT",(VLOOKUP(I12,'Tabela Salarial_CLT'!B:K,10,0))-H12,(VLOOKUP(I12,'Tabela Salarial_PJ'!B:K,10,0))-H12) -> 1645.3
A13: 1927 | B13: ANALISTA FINANCEIRO I | C13: Analista Financeiro Jr | D13: Financeiro | E13: Operacional | F13: CLT | G13: 220 | H13: 3993 | I13: =VLOOKUP(C13,'Estrutura Salarial'!B:F,5,0) -> 13 | J13: =IF(F13="CLT",IFERROR(VLOOKUP(I13,'Tabela Salarial_CLT'!B:C,2,0),""),IFERROR(VLOOKUP(I13,'Tabela Salarial_PJ'!B:C,2,0),"")) -> 3105.14 | K13: =J13-H13 -> -887.86 | L13: =IF(K13<0,0,IF(K13>0,K13,IF(K13=0,0,""))) -> 0 | M13: =IF(F13="CLT",H13/(VLOOKUP(I13,'Tabela Salarial_CLT'!B:G,6,0)),H13/(VLOOKUP(I13,'Tabela Salarial_PJ'!B:G,6,0))) -> 1.0287446 | N13: =IF(F13="CLT",IFERROR(VLOOKUP(I13,'Tabela Salarial_CLT'!B:G,6,0),""),IFERROR(VLOOKUP(I13,'Tabela Salarial_PJ'!B:G,6,0),"")) -> 3881.43 | O13: =IF(F13="CLT",N13-H13,-(H13)+N13) -> -111.57 | P13: =IF(O13<0,0,if(O13>0,O13,if(O13=0,0,""))) -> 0 | Q13: =IF(F13="CLT",(VLOOKUP(I13,'Tabela Salarial_CLT'!B:K,10,0))-H13,(VLOOKUP(I13,'Tabela Salarial_PJ'!B:K,10,0))-H13) -> 664.716
A14: 164 | B14: ASSISTENTE ADM DE LEGALIZAÇÃO III | C14: Assistente Adm Legalização | D14: Legalização | E14: Operacional | F14: CLT | G14: 220 | H14: 3652 | I14: =VLOOKUP(C14,'Estrutura Salarial'!B:F,5,0) -> 12 | J14: =IF(F14="CLT",IFERROR(VLOOKUP(I14,'Tabela Salarial_CLT'!B:C,2,0),""),IFERROR(VLOOKUP(I14,'Tabela Salarial_PJ'!B:C,2,0),"")) -> 2593.86 | K14: =J14-H14 -> -1058.14 | L14: =IF(K14<0,0,IF(K14>0,K14,IF(K14=0,0,""))) -> 0 | M14: =IF(F14="CLT",H14/(VLOOKUP(I14,'Tabela Salarial_CLT'!B:G,6,0)),H14/(VLOOKUP(I14,'Tabela Salarial_PJ'!B:G,6,0))) -> 1.126354 | N14: =IF(F14="CLT",IFERROR(VLOOKUP(I14,'Tabela Salarial_CLT'!B:G,6,0),""),IFERROR(VLOOKUP(I14,'Tabela Salarial_PJ'!B:G,6,0),"")) -> 3242.32 | O14: =IF(F14="CLT",N14-H14,-(H14)+N14) -> -409.68 | P14: =IF(O14<0,0,if(O14>0,O14,if(O14=0,0,""))) -> 0 | Q14: =IF(F14="CLT",(VLOOKUP(I14,'Tabela Salarial_CLT'!B:K,10,0))-H14,(VLOOKUP(I14,'Tabela Salarial_PJ'!B:K,10,0))-H14) -> 238.784
A15: 1892 | B15: ASSISTENTE ADMINISTRATIVO lll | C15: Assistente Administrativo | D15: Administrativo | E15: Operacional | F15: CLT | G15: 220 | H15: 3439.7 | I15: =VLOOKUP(C15,'Estrutura Salarial'!B:F,5,0) -> 11 | J15: =IF(F15="CLT",IFERROR(VLOOKUP(I15,'Tabela Salarial_CLT'!B:C,2,0),""),IFERROR(VLOOKUP(I15,'Tabela Salarial_PJ'!B:C,2,0),"")) -> 2191.11 | K15: =J15-H15 -> -1248.59 | L15: =IF(K15<0,0,IF(K15>0,K15,IF(K15=0,0,""))) -> 0 | M15: =IF(F15="CLT",H15/(VLOOKUP(I15,'Tabela Salarial_CLT'!B:G,6,0)),H15/(VLOOKUP(I15,'Tabela Salarial_PJ'!B:G,6,0))) -> 1.2558737 | N15: =IF(F15="CLT",IFERROR(VLOOKUP(I15,'Tabela Salarial_CLT'!B:G,6,0),""),IFERROR(VLOOKUP(I15,'Tabela Salarial_PJ'!B:G,6,0),"")) -> 2738.89 | O15: =IF(F15="CLT",N15-H15,-(H15)+N15) -> -700.81 | P15: =IF(O15<0,0,if(O15>0,O15,if(O15=0,0,""))) -> 0 | Q15: =IF(F15="CLT",(VLOOKUP(I15,'Tabela Salarial_CLT'!B:K,10,0))-H15,(VLOOKUP(I15,'Tabela Salarial_PJ'!B:K,10,0))-H15) -> -153.032
A16: 1940 | B16: ASSISTENTE DE CONTROLADORIA III | C16: Assistente Controladoria | D16: Controladoria | E16: Operacional | F16: CLT | G16: 220 | H16: 3652 | I16: =VLOOKUP(C16,'Estrutura Salarial'!B:F,5,0) -> 12 | J16: =IF(F16="CLT",IFERROR(VLOOKUP(I16,'Tabela Salarial_CLT'!B:C,2,0),""),IFERROR(VLOOKUP(I16,'Tabela Salarial_PJ'!B:C,2,0),"")) -> 2593.86 | K16: =J16-H16 -> -1058.14 | L16: =IF(K16<0,0,IF(K16>0,K16,IF(K16=0,0,""))) -> 0 | M16: =IF(F16="CLT",H16/(VLOOKUP(I16,'Tabela Salarial_CLT'!B:G,6,0)),H16/(VLOOKUP(I16,'Tabela Salarial_PJ'!B:G,6,0))) -> 1.126354 | N16: =IF(F16="CLT",IFERROR(VLOOKUP(I16,'Tabela Salarial_CLT'!B:G,6,0),""),IFERROR(VLOOKUP(I16,'Tabela Salarial_PJ'!B:G,6,0),"")) -> 3242.32 | O16: =IF(F16="CLT",N16-H16,-(H16)+N16) -> -409.68 | P16: =IF(O16<0,0,if(O16>0,O16,if(O16=0,0,""))) -> 0 | Q16: =IF(F16="CLT",(VLOOKUP(I16,'Tabela Salarial_CLT'!B:K,10,0))-H16,(VLOOKUP(I16,'Tabela Salarial_PJ'!B:K,10,0))-H16) -> 238.784
A17: 1963 | B17: ASSISTENTE DE ENGENHARIA lll | C17: Assistente Engenharia | D17: Edificação | E17: Operacional | F17: CLT | G17: 220 | H17: 3652 | I17: =VLOOKUP(C17,'Estrutura Salarial'!B:F,5,0) -> 13 | J17: =IF(F17="CLT",IFERROR(VLOOKUP(I17,'Tabela Salarial_CLT'!B:C,2,0),""),IFERROR(VLOOKUP(I17,'Tabela Salarial_PJ'!B:C,2,0),"")) -> 3105.14 | K17: =J17-H17 -> -546.86 | L17: =IF(K17<0,0,IF(K17>0,K17,IF(K17=0,0,""))) -> 0 | M17: =IF(F17="CLT",H17/(VLOOKUP(I17,'Tabela Salarial_CLT'!B:G,6,0)),H17/(VLOOKUP(I17,'Tabela Salarial_PJ'!B:G,6,0))) -> 0.94089034 | N17: =IF(F17="CLT",IFERROR(VLOOKUP(I17,'Tabela Salarial_CLT'!B:G,6,0),""),IFERROR(VLOOKUP(I17,'Tabela Salarial_PJ'!B:G,6,0),"")) -> 3881.43 | O17: =IF(F17="CLT",N17-H17,-(H17)+N17) -> 229.43 | P17: =IF(O17<0,0,if(O17>0,O17,if(O17=0,0,""))) -> 229.43 | Q17: =IF(F17="CLT",(VLOOKUP(I17,'Tabela Salarial_CLT'!B:K,10,0))-H17,(VLOOKUP(I17,'Tabela Salarial_PJ'!B:K,10,0))-H17) -> 1005.716
A18: 190 | B18: ASSISTENTE DE MARKETING | C18: Assistente Marketing | D18: Marketing | E18: Operacional | F18: CLT | G18: 220 | H18: 2919 | I18: =VLOOKUP(C18,'Estrutura Salarial'!B:F,5,0) -> 11 | J18: =IF(F18="CLT",IFERROR(VLOOKUP(I18,'Tabela Salarial_CLT'!B:C,2,0),""),IFERROR(VLOOKUP(I18,'Tabela Salarial_PJ'!B:C,2,0),"")) -> 2191.11 | K18: =J18-H18 -> -727.89 | L18: =IF(K18<0,0,IF(K18>0,K18,IF(K18=0,0,""))) -> 0 | M18: =IF(F18="CLT",H18/(VLOOKUP(I18,'Tabela Salarial_CLT'!B:G,6,0)),H18/(VLOOKUP(I18,'Tabela Salarial_PJ'!B:G,6,0))) -> 1.0657602 | N18: =IF(F18="CLT",IFERROR(VLOOKUP(I18,'Tabela Salarial_CLT'!B:G,6,0),""),IFERROR(VLOOKUP(I18,'Tabela Salarial_PJ'!B:G,6,0),"")) -> 2738.89 | O18: =IF(F18="CLT",N18-H18,-(H18)+N18) -> -180.11 | P18: =IF(O18<0,0,if(O18>0,O18,if(O18=0,0,""))) -> 0 | Q18: =IF(F18="CLT",(VLOOKUP(I18,'Tabela Salarial_CLT'!B:K,10,0))-H18,(VLOOKUP(I18,'Tabela Salarial_PJ'!B:K,10,0))-H18) -> 367.668
... A27: 191 | B27: AUXILIAR DE ENGENHARIA | C27: Auxiliar Engenharia | D27: Urbanismo | E27: Operacional | F27: CLT | G27: 220 | H27: 2560 | I27: =VLOOKUP(C27,'Estrutura Salarial'!B:F,5,0) -> 11 | J27: =IF(F27="CLT",IFERROR(VLOOKUP(I27,'Tabela Salarial_CLT'!B:C,2,0),""),IFERROR(VLOOKUP(I27,'Tabela Salarial_PJ'!B:C,2,0),"")) -> 2191.11 | K27: =J27-H27 -> -368.89 | L27: =IF(K27<0,0,IF(K27>0,K27,IF(K27=0,0,""))) -> 0 | M27: =IF(F27="CLT",H27/(VLOOKUP(I27,'Tabela Salarial_CLT'!B:G,6,0)),H27/(VLOOKUP(I27,'Tabela Salarial_PJ'!B:G,6,0))) -> 0.93468522 | N27: =IF(F27="CLT",IFERROR(VLOOKUP(I27,'Tabela Salarial_CLT'!B:G,6,0),""),IFERROR(VLOOKUP(I27,'Tabela Salarial_PJ'!B:G,6,0),"")) -> 2738.89 | O27: =IF(F27="CLT",N27-H27,-(H27)+N27) -> 178.89 | P27: =IF(O27<0,0,if(O27>0,O27,if(O27=0,0,""))) -> 178.89 | Q27: =IF(F27="CLT",(VLOOKUP(I27,'Tabela Salarial_CLT'!B:K,10,0))-H27,(VLOOKUP(I27,'Tabela Salarial_PJ'!B:K,10,0))-H27) -> 726.668
A28: PJ2 | B28: CONTROLER JURÍDICO | C28: Controller Jurídico | D28: Administrativo | E28: Tático | F28: PJ | G28: 220 | H28: 11339 | I28: =VLOOKUP(C28,'Estrutura Salarial'!B:F,5,0) -> 17 | J28: =IF(F28="CLT",IFERROR(VLOOKUP(I28,'Tabela Salarial_CLT'!B:C,2,0),""),IFERROR(VLOOKUP(I28,'Tabela Salarial_PJ'!B:C,2,0),"")) -> 10244.96 | K28: =J28-H28 -> -1094.04 | L28: =IF(K28<0,0,IF(K28>0,K28,IF(K28=0,0,""))) -> 0 | M28: =IF(F28="CLT",H28/(VLOOKUP(I28,'Tabela Salarial_CLT'!B:G,6,0)),H28/(VLOOKUP(I28,'Tabela Salarial_PJ'!B:G,6,0))) -> 0.88543015 | N28: =IF(F28="CLT",IFERROR(VLOOKUP(I28,'Tabela Salarial_CLT'!B:G,6,0),""),IFERROR(VLOOKUP(I28,'Tabela Salarial_PJ'!B:G,6,0),"")) -> 12806.205 | O28: =IF(F28="CLT",N28-H28,-(H28)+N28) -> 1467.205 | P28: =IF(O28<0,0,if(O28>0,O28,if(O28=0,0,""))) -> 1467.205 | Q28: =IF(F28="CLT",(VLOOKUP(I28,'Tabela Salarial_CLT'!B:K,10,0))-H28,(VLOOKUP(I28,'Tabela Salarial_PJ'!B:K,10,0))-H28) -> 4028.446
A29: PJ3 | B29: CONTROLLER GERAL | C29: Controller Geral | D29: Controladoria | E29: Tático | F29: PJ | G29: 220 | H29: 16000 | I29: =VLOOKUP(C29,'Estrutura Salarial'!B:F,5,0) -> 20 | J29: =IF(F29="CLT",IFERROR(VLOOKUP(I29,'Tabela Salarial_CLT'!B:C,2,0),""),IFERROR(VLOOKUP(I29,'Tabela Salarial_PJ'!B:C,2,0),"")) -> 17290.17 | K29: =J29-H29 -> 1290.17 | L29: =IF(K29<0,0,IF(K29>0,K29,IF(K29=0,0,""))) -> 1290.17 | M29: =IF(F29="CLT",H29/(VLOOKUP(I29,'Tabela Salarial_CLT'!B:G,6,0)),H29/(VLOOKUP(I29,'Tabela Salarial_PJ'!B:G,6,0))) -> 0.74030513 | N29: =IF(F29="CLT",IFERROR(VLOOKUP(I29,'Tabela Salarial_CLT'!B:G,6,0),""),IFERROR(VLOOKUP(I29,'Tabela Salarial_PJ'!B:G,6,0),"")) -> 21612.71 | O29: =IF(F29="CLT",N29-H29,-(H29)+N29) -> 5612.71 | P29: =IF(O29<0,0,if(O29>0,O29,if(O29=0,0,""))) -> 5612.71 | Q29: =IF(F29="CLT",(VLOOKUP(I29,'Tabela Salarial_CLT'!B:K,10,0))-H29,(VLOOKUP(I29,'Tabela Salarial_PJ'!B:K,10,0))-H29) -> 9935.252
A30: PJ4 | B30: CONTROLLER TÉCNICO | C30: Controller Técnico | D30: Controladoria | E30: Tático | F30: PJ | G30: 220 | H30: 12663.6 | I30: =VLOOKUP(C30,'Estrutura Salarial'!B:F,5,0) -> 18 | J30: =IF(F30="CLT",IFERROR(VLOOKUP(I30,'Tabela Salarial_CLT'!B:C,2,0),""),IFERROR(VLOOKUP(I30,'Tabela Salarial_PJ'!B:C,2,0),"")) -> 12105.78 | K30: =J30-H30 -> -557.82 | L30: =IF(K30<0,0,IF(K30>0,K30,IF(K30=0,0,""))) -> 0 | M30: =IF(F30="CLT",H30/(VLOOKUP(I30,'Tabela Salarial_CLT'!B:G,6,0)),H30/(VLOOKUP(I30,'Tabela Salarial_PJ'!B:G,6,0))) -> 0.83686317 | N30: =IF(F30="CLT",IFERROR(VLOOKUP(I30,'Tabela Salarial_CLT'!B:G,6,0),""),IFERROR(VLOOKUP(I30,'Tabela Salarial_PJ'!B:G,6,0),"")) -> 15132.223 | O30: =IF(F30="CLT",N30-H30,-(H30)+N30) -> 2468.6229 | P30: =IF(O30<0,0,if(O30>0,O30,if(O30=0,0,""))) -> 2468.6229 | Q30: =IF(F30="CLT",(VLOOKUP(I30,'Tabela Salarial_CLT'!B:K,10,0))-H30,(VLOOKUP(I30,'Tabela Salarial_PJ'!B:K,10,0))-H30) -> 5495.0675
A31: 1959 | B31: COORDENADOR DE DHO | C31: Coordenador DHO | D31: DHO | E31: Tático | F31: CLT | G31: 220 | H31: 7420 | I31: =VLOOKUP(C31,'Estrutura Salarial'!B:F,5,0) -> 19 | J31: =IF(F31="CLT",IFERROR(VLOOKUP(I31,'Tabela Salarial_CLT'!B:C,2,0),""),IFERROR(VLOOKUP(I31,'Tabela Salarial_PJ'!B:C,2,0),"")) -> 10116.17 | K31: =J31-H31 -> 2696.17 | L31: =IF(K31<0,0,IF(K31>0,K31,IF(K31=0,0,""))) -> 2696.17 | M31: =IF(F31="CLT",H31/(VLOOKUP(I31,'Tabela Salarial_CLT'!B:G,6,0)),H31/(VLOOKUP(I31,'Tabela Salarial_PJ'!B:G,6,0))) -> 0.58678345 | N31: =IF(F31="CLT",IFERROR(VLOOKUP(I31,'Tabela Salarial_CLT'!B:G,6,0),""),IFERROR(VLOOKUP(I31,'Tabela Salarial_PJ'!B:G,6,0),"")) -> 12645.21 | O31: =IF(F31="CLT",N31-H31,-(H31)+N31) -> 5225.21 | P31: =IF(O31<0,0,if(O31>0,O31,if(O31=0,0,""))) -> 5225.21 | Q31: =IF(F31="CLT",(VLOOKUP(I31,'Tabela Salarial_CLT'!B:K,10,0))-H31,(VLOOKUP(I31,'Tabela Salarial_PJ'!B:K,10,0))-H31) -> 7754.252
A32: 151 | B32: COORDENADOR DE LEGAIZAÇÃO ll | C32: Coordenador Legalização | D32: Legalização | E32: Tático | F32: CLT | G32: 220 | H32: 8647 | I32: =VLOOKUP(C32,'Estrutura Salarial'!B:F,5,0) -> 17 | J32: =IF(F32="CLT",IFERROR(VLOOKUP(I32,'Tabela Salarial_CLT'!B:C,2,0),""),IFERROR(VLOOKUP(I32,'Tabela Salarial_PJ'!B:C,2,0),"")) -> 6829.98 | K32: =J32-H32 -> -1817.02 | L32: =IF(K32<0,0,IF(K32>0,K32,IF(K32=0,0,""))) -> 0 | M32: =IF(F32="CLT",H32/(VLOOKUP(I32,'Tabela Salarial_CLT'!B:G,6,0)),H32/(VLOOKUP(I32,'Tabela Salarial_PJ'!B:G,6,0))) -> 1.0128293 | N32: =IF(F32="CLT",IFERROR(VLOOKUP(I32,'Tabela Salarial_CLT'!B:G,6,0),""),IFERROR(VLOOKUP(I32,'Tabela Salarial_PJ'!B:G,6,0),"")) -> 8537.47 | O32: =IF(F32="CLT",N32-H32,-(H32)+N32) -> -109.53 | P32: =IF(O32<0,0,if(O32>0,O32,if(O32=0,0,""))) -> 0 | Q32: =IF(F32="CLT",(VLOOKUP(I32,'Tabela Salarial_CLT'!B:K,10,0))-H32,(VLOOKUP(I32,'Tabela Salarial_PJ'!B:K,10,0))-H32) -> 1597.964
A33: 1911 | B33: COORDENADOR DE MARKETING II | C33: Coordenador Marketing | D33: Marketing | E33: Tático | F33: CLT | G33: 220 | H33: 8647 | I33: =VLOOKUP(C33,'Estrutura Salarial'!B:F,5,0) -> 17 | J33: =IF(F33="CLT",IFERROR(VLOOKUP(I33,'Tabela Salarial_CLT'!B:C,2,0),""),IFERROR(VLOOKUP(I33,'Tabela Salarial_PJ'!B:C,2,0),"")) -> 6829.98 | K33: =J33-H33 -> -1817.02 | L33: =IF(K33<0,0,IF(K33>0,K33,IF(K33=0,0,""))) -> 0 | M33: =IF(F33="CLT",H33/(VLOOKUP(I33,'Tabela Salarial_CLT'!B:G,6,0)),H33/(VLOOKUP(I33,'Tabela Salarial_PJ'!B:G,6,0))) -> 1.0128293 | N33: =IF(F33="CLT",IFERROR(VLOOKUP(I33,'Tabela Salarial_CLT'!B:G,6,0),""),IFERROR(VLOOKUP(I33,'Tabela Salarial_PJ'!B:G,6,0),"")) -> 8537.47 | O33: =IF(F33="CLT",N33-H33,-(H33)+N33) -> -109.53 | P33: =IF(O33<0,0,if(O33>0,O33,if(O33=0,0,""))) -> 0 | Q33: =IF(F33="CLT",(VLOOKUP(I33,'Tabela Salarial_CLT'!B:K,10,0))-H33,(VLOOKUP(I33,'Tabela Salarial_PJ'!B:K,10,0))-H33) -> 1597.964
A34: 1452 | B34: COORDENADOR DE OBRAS | C34: Mestre de Obras | D34: Edificação | E34: Operacional | F34: CLT | G34: 220 | H34: 8714 | I34: =VLOOKUP(C34,'Estrutura Salarial'!B:F,5,0) -> 19 | J34: =IF(F34="CLT",IFERROR(VLOOKUP(I34,'Tabela Salarial_CLT'!B:C,2,0),""),IFERROR(VLOOKUP(I34,'Tabela Salarial_PJ'!B:C,2,0),"")) -> 10116.17 | K34: =J34-H34 -> 1402.17 | L34: =IF(K34<0,0,IF(K34>0,K34,IF(K34=0,0,""))) -> 1402.17 | M34: =IF(F34="CLT",H34/(VLOOKUP(I34,'Tabela Salarial_CLT'!B:G,6,0)),H34/(VLOOKUP(I34,'Tabela Salarial_PJ'!B:G,6,0))) -> 0.68911469 | N34: =IF(F34="CLT",IFERROR(VLOOKUP(I34,'Tabela Salarial_CLT'!B:G,6,0),""),IFERROR(VLOOKUP(I34,'Tabela Salarial_PJ'!B:G,6,0),"")) -> 12645.21 | O34: =IF(F34="CLT",N34-H34,-(H34)+N34) -> 3931.21 | P34: =IF(O34<0,0,if(O34>0,O34,if(O34=0,0,""))) -> 3931.21 | Q34: =IF(F34="CLT",(VLOOKUP(I34,'Tabela Salarial_CLT'!B:K,10,0))-H34,(VLOOKUP(I34,'Tabela Salarial_PJ'!B:K,10,0))-H34) -> 6460.252
A35: PJ5 | B35: COORDENADOR DE SUPRIMENTOS | C35: Coordenador Suprimentos | D35: Suprimentos | E35: Tático | F35: PJ | G35: 220 | H35: 16000 | I35: =VLOOKUP(C35,'Estrutura Salarial'!B:F,5,0) -> 19 | J35: =IF(F35="CLT",IFERROR(VLOOKUP(I35,'Tabela Salarial_CLT'!B:C,2,0),""),IFERROR(VLOOKUP(I35,'Tabela Salarial_PJ'!B:C,2,0),"")) -> 14314.38 | K35: =J35-H35 -> -1685.62 | L35: =IF(K35<0,0,IF(K35>0,K35,IF(K35=0,0,""))) -> 0 | M35: =IF(F35="CLT",H35/(VLOOKUP(I35,'Tabela Salarial_CLT'!B:G,6,0)),H35/(VLOOKUP(I35,'Tabela Salarial_PJ'!B:G,6,0))) -> 0.89420583 | N35: =IF(F35="CLT",IFERROR(VLOOKUP(I35,'Tabela Salarial_CLT'!B:G,6,0),""),IFERROR(VLOOKUP(I35,'Tabela Salarial_PJ'!B:G,6,0),"")) -> 17892.972 | O35: =IF(F35="CLT",N35-H35,-(H35)+N35) -> 1892.9722 | P35: =IF(O35<0,0,if(O35>0,O35,if(O35=0,0,""))) -> 1892.9722 | Q35: =IF(F35="CLT",(VLOOKUP(I35,'Tabela Salarial_CLT'!B:K,10,0))-H35,(VLOOKUP(I35,'Tabela Salarial_PJ'!B:K,10,0))-H35) -> 5471.5666
A36: PJ6 | B36: COORDENADOR FINANCEIRO | C36: Coordenador Financeiro | D36: Financeiro | E36: Tático | F36: PJ | G36: 220 | H36: 12000 | I36: =VLOOKUP(C36,'Estrutura Salarial'!B:F,5,0) -> 19 | J36: =IF(F36="CLT",IFERROR(VLOOKUP(I36,'Tabela Salarial_CLT'!B:C,2,0),""),IFERROR(VLOOKUP(I36,'Tabela Salarial_PJ'!B:C,2,0),"")) -> 14314.38 | K36: =J36-H36 -> 2314.38 | L36: =IF(K36<0,0,IF(K36>0,K36,IF(K36=0,0,""))) -> 2314.38 | M36: =IF(F36="CLT",H36/(VLOOKUP(I36,'Tabela Salarial_CLT'!B:G,6,0)),H36/(VLOOKUP(I36,'Tabela Salarial_PJ'!B:G,6,0))) -> 0.67065437 | N36: =IF(F36="CLT",IFERROR(VLOOKUP(I36,'Tabela Salarial_CLT'!B:G,6,0),""),IFERROR(VLOOKUP(I36,'Tabela Salarial_PJ'!B:G,6,0),"")) -> 17892.972 | O36: =IF(F36="CLT",N36-H36,-(H36)+N36) -> 5892.9721 | P36: =IF(O36<0,0,if(O36>0,O36,if(O36=0,0,""))) -> 5892.9721 | Q36: =IF(F36="CLT",(VLOOKUP(I36,'Tabela Salarial_CLT'!B:K,10,0))-H36,(VLOOKUP(I36,'Tabela Salarial_PJ'!B:K,10,0))-H36) -> 9471.5666
A37: PJ7 | B37: DIRETOR | C37: Diretor | D37: Comercial | E37: Estratégico | F37: PJ | G37: 220 | H37: 58000 | I37: =VLOOKUP(C37,'Estrutura Salarial'!B:F,5,0) -> 28 | J37: =IF(F37="CLT",IFERROR(VLOOKUP(I37,'Tabela Salarial_CLT'!B:C,2,0),""),IFERROR(VLOOKUP(I37,'Tabela Salarial_PJ'!B:C,2,0),"")) -> 45764.06 | K37: =J37-H37 -> -12235.94 | L37: =IF(K37<0,0,IF(K37>0,K37,IF(K37=0,0,""))) -> 0 | M37: =IF(F37="CLT",H37/(VLOOKUP(I37,'Tabela Salarial_CLT'!B:G,6,0)),H37/(VLOOKUP(I37,'Tabela Salarial_PJ'!B:G,6,0))) -> 1.0138961 | N37: =IF(F37="CLT",IFERROR(VLOOKUP(I37,'Tabela Salarial_CLT'!B:G,6,0),""),IFERROR(VLOOKUP(I37,'Tabela Salarial_PJ'!B:G,6,0),"")) -> 57205.075 | O37: =IF(F37="CLT",N37-H37,-(H37)+N37) -> -794.9248 | P37: =IF(O37<0,0,if(O37>0,O37,if(O37=0,0,""))) -> 0 | Q37: =IF(F37="CLT",(VLOOKUP(I37,'Tabela Salarial_CLT'!B:K,10,0))-H37,(VLOOKUP(I37,'Tabela Salarial_PJ'!B:K,10,0))-H37) -> 10646.09
A38: 132 | B38: ENCARREGADO DE OBRAS | C38: Encarregado Loteamento | D38: Urbanismo | E38: Operacional | F38: CLT | G38: 220 | H38: 8461 | I38: =VLOOKUP(C38,'Estrutura Salarial'!B:F,5,0) -> 18 | J38: =IF(F38="CLT",IFERROR(VLOOKUP(I38,'Tabela Salarial_CLT'!B:C,2,0),""),IFERROR(VLOOKUP(I38,'Tabela Salarial_PJ'!B:C,2,0),"")) -> 8329.66 | K38: =J38-H38 -> -131.34 | L38: =IF(K38<0,0,IF(K38>0,K38,IF(K38=0,0,""))) -> 0 | M38: =IF(F38="CLT",H38/(VLOOKUP(I38,'Tabela Salarial_CLT'!B:G,6,0)),H38/(VLOOKUP(I38,'Tabela Salarial_PJ'!B:G,6,0))) -> 0.81261381 | N38: =IF(F38="CLT",IFERROR(VLOOKUP(I38,'Tabela Salarial_CLT'!B:G,6,0),""),IFERROR(VLOOKUP(I38,'Tabela Salarial_PJ'!B:G,6,0),"")) -> 10412.08 | O38: =IF(F38="CLT",N38-H38,-(H38)+N38) -> 1951.08 | P38: =IF(O38<0,0,if(O38>0,O38,if(O38=0,0,""))) -> 1951.08 | Q38: =IF(F38="CLT",(VLOOKUP(I38,'Tabela Salarial_CLT'!B:K,10,0))-H38,(VLOOKUP(I38,'Tabela Salarial_PJ'!B:K,10,0))-H38) -> 4033.496
A39: 182 | B39: ENCARREGADO DE OBRAS | C39: Encarregado Loteamento | D39: Urbanismo | E39: Operacional | F39: CLT | G39: 220 | H39: 11540 | I39: =VLOOKUP(C39,'Estrutura Salarial'!B:F,5,0) -> 18 | J39: =IF(F39="CLT",IFERROR(VLOOKUP(I39,'Tabela Salarial_CLT'!B:C,2,0),""),IFERROR(VLOOKUP(I39,'Tabela Salarial_PJ'!B:C,2,0),"")) -> 8329.66 | K39: =J39-H39 -> -3210.34 | L39: =IF(K39<0,0,IF(K39>0,K39,IF(K39=0,0,""))) -> 0 | M39: =IF(F39="CLT",H39/(VLOOKUP(I39,'Tabela Salarial_CLT'!B:G,6,0)),H39/(VLOOKUP(I39,'Tabela Salarial_PJ'!B:G,6,0))) -> 1.108328 | N39: =IF(F39="CLT",IFERROR(VLOOKUP(I39,'Tabela Salarial_CLT'!B:G,6,0),""),IFERROR(VLOOKUP(I39,'Tabela Salarial_PJ'!B:G,6,0),"")) -> 10412.08 | O39: =IF(F39="CLT",N39-H39,-(H39)+N39) -> -1127.92 | P39: =IF(O39<0,0,if(O39>0,O39,if(O39=0,0,""))) -> 0 | Q39: =IF(F39="CLT",(VLOOKUP(I39,'Tabela Salarial_CLT'!B:K,10,0))-H39,(VLOOKUP(I39,'Tabela Salarial_PJ'!B:K,10,0))-H39) -> 954.496
A40: 1351 | B40: ENCARREGADO OBRAS/MANUTENCAO | C40: Encarregado Obras / Manutenção | D40: Edificação | E40: Operacional | F40: CLT | G40: 220 | H40: 8714 | I40: =VLOOKUP(C40,'Estrutura Salarial'!B:F,5,0) -> 17 | J40: =IF(F40="CLT",IFERROR(VLOOKUP(I40,'Tabela Salarial_CLT'!B:C,2,0),""),IFERROR(VLOOKUP(I40,'Tabela Salarial_PJ'!B:C,2,0),"")) -> 6829.98 | K40: =J40-H40 -> -1884.02 | L40: =IF(K40<0,0,IF(K40>0,K40,IF(K40=0,0,""))) -> 0 | M40: =IF(F40="CLT",H40/(VLOOKUP(I40,'Tabela Salarial_CLT'!B:G,6,0)),H40/(VLOOKUP(I40,'Tabela Salarial_PJ'!B:G,6,0))) -> 1.0206771 | N40: =IF(F40="CLT",IFERROR(VLOOKUP(I40,'Tabela Salarial_CLT'!B:G,6,0),""),IFERROR(VLOOKUP(I40,'Tabela Salarial_PJ'!B:G,6,0),"")) -> 8537.47 | O40: =IF(F40="CLT",N40-H40,-(H40)+N40) -> -176.53 | P40: =IF(O40<0,0,if(O40>0,O40,if(O40=0,0,""))) -> 0 | Q40: =IF(F40="CLT",(VLOOKUP(I40,'Tabela Salarial_CLT'!B:K,10,0))-H40,(VLOOKUP(I40,'Tabela Salarial_PJ'!B:K,10,0))-H40) -> 1530.964
A41: PJ8 | B41: ENGENHEIRO JUNIOR DE URBANISMO | C41: Engenheiro Urbanismo Jr | D41: Urbanismo | E41: Operacional | F41: PJ | G41: 220 | H41: 8390 | I41: =VLOOKUP(C41,'Estrutura Salarial'!B:F,5,0) -> 17 | J41: =IF(F41="CLT",IFERROR(VLOOKUP(I41,'Tabela Salarial_CLT'!B:C,2,0),""),IFERROR(VLOOKUP(I41,'Tabela Salarial_PJ'!B:C,2,0),"")) -> 10244.96 | K41: =J41-H41 -> 1854.96 | L41: =IF(K41<0,0,IF(K41>0,K41,IF(K41=0,0,""))) -> 1854.96 | M41: =IF(F41="CLT",H41/(VLOOKUP(I41,'Tabela Salarial_CLT'!B:G,6,0)),H41/(VLOOKUP(I41,'Tabela Salarial_PJ'!B:G,6,0))) -> 0.65515116 | N41: =IF(F41="CLT",IFERROR(VLOOKUP(I41,'Tabela Salarial_CLT'!B:G,6,0),""),IFERROR(VLOOKUP(I41,'Tabela Salarial_PJ'!B:G,6,0),"")) -> 12806.205 | O41: =IF(F41="CLT",N41-H41,-(H41)+N41) -> 4416.205 | P41: =IF(O41<0,0,if(O41>0,O41,if(O41=0,0,""))) -> 4416.205 | Q41: =IF(F41="CLT",(VLOOKUP(I41,'Tabela Salarial_CLT'!B:K,10,0))-H41,(VLOOKUP(I41,'Tabela Salarial_PJ'!B:K,10,0))-H41) -> 6977.446
A42: PJ9 | B42: ENGENHEIRO SÊNIOR | C42: Engenheiro Sr | D42: Edificação | E42: Tático | F42: PJ | G42: 220 | H42: 19000 | I42: =VLOOKUP(C42,'Estrutura Salarial'!B:F,5,0) -> 19 | J42: =IF(F42="CLT",IFERROR(VLOOKUP(I42,'Tabela Salarial_CLT'!B:C,2,0),""),IFERROR(VLOOKUP(I42,'Tabela Salarial_PJ'!B:C,2,0),"")) -> 14314.38 | K42: =J42-H42 -> -4685.62 | L42: =IF(K42<0,0,IF(K42>0,K42,IF(K42=0,0,""))) -> 0 | M42: =IF(F42="CLT",H42/(VLOOKUP(I42,'Tabela Salarial_CLT'!B:G,6,0)),H42/(VLOOKUP(I42,'Tabela Salarial_PJ'!B:G,6,0))) -> 1.0618694 | N42: =IF(F42="CLT",IFERROR(VLOOKUP(I42,'Tabela Salarial_CLT'!B:G,6,0),""),IFERROR(VLOOKUP(I42,'Tabela Salarial_PJ'!B:G,6,0),"")) -> 17892.972 | O42: =IF(F42="CLT",N42-H42,-(H42)+N42) -> -1107.0278 | P42: =IF(O42<0,0,if(O42>0,O42,if(O42=0,0,""))) -> 0 | Q42: =IF(F42="CLT",(VLOOKUP(I42,'Tabela Salarial_CLT'!B:K,10,0))-H42,(VLOOKUP(I42,'Tabela Salarial_PJ'!B:K,10,0))-H42) -> 2471.5666
