Workbook

Sheet Folha de Pagamento
B1: Folha de Pagamento | G1: CNPJ da empresa: Referência da Folha de Pagamento: 09/2025 Quantidade de horas mensais usada: 160h Data de Construção: 06/10/2025
A3: Cod. do cargo | B3: Cod. do funcionário | C3: Cargo atual | D3: Novo Cargo | E3: Senioridade | F3: Nível Organizacional | G3: Área | H3: Carga Horária | I3: Salários | J3: Tipo de Contratação | K3: CBO | L3: Gênero | M3: Data de Admissão | N3: Observações
A4: 3 | B4: 15 | C4: Engenheiro de Software Full Stack | D4: Engenheiro de Software Full Stack Sr | E4: Sênior | F4: Tático | G4: DEV | H4: 160 | I4: 6458.4 | J4: CLT | K4: 81937 | L4: Masculino | M4: 45420
A5: 3 | B5: 50 | C5: Engenheiro de Software Full Stack | D5: Engenheiro de Software Full Stack Sr | E5: Sênior | F5: Tático | G5: DEV | H5: 160 | I5: 6458.4 | J5: CLT | K5: 81937 | L5: Masculino | M5: 45420
A6: 2 | B6: 14 | C6: Engenheiro de Software Full Stack | D6: Engenheiro de Software Full Stack Pl | E6: Pleno | F6: Operacional | G6: DEV | H6: 160 | I6: 4305.6 | J6: CLT | K6: 81937 | L6: Masculino | M6: 1/13/2025
A7: 2 | B7: 42 | C7: Engenheiro de Software Full Stack | D7: Engenheiro de Software Full Stack Pl | E7: Pleno | F7: Operacional | G7: DEV | H7: 160 | I7: 4305.6 | J7: CLT | K7: 81937 | L7: Feminino | M7: 45334
A8: 2 | B8: 36 | C8: Engenheiro de Software Full Stack | D8: Engenheiro de Software Full Stack Pl | E8: Pleno | F8: Operacional | G8: DEV | H8: 160 | I8: 4305.6 | J8: CLT | K8: 81937 | L8: Masculino | M8: 45809
A9: 2 | B9: 37 | C9: Engenheiro de Software Full Stack | D9: Engenheiro de Software Full Stack Pl | E9: Pleno | F9: Operacional | G9: DEV | H9: 160 | I9: 4305.6 | J9: CLT | K9: 81937 | L9: Masculino | M9: 45809
A10: 2 | B10: 38 | C10: Engenheiro de Software Full Stack | D10: Engenheiro de Software Full Stack Pl | E10: Pleno | F10: Operacional | G10: DEV | H10: 160 | I10: 4305.6 | J10: CLT | K10: 81937 | L10: Masculino | M10: 45635
A11: 1 | B11: 20 | C11: Engenheiro de Software Full Stack | D11: Engenheiro de Software Full Stack Jr | E11: Júnior | F11: Operacional | G11: DEV | H11: 160 | I11: 2489.18 | J11: CLT | K11: 81937 | L11: Masculino | M11: 45331
A12: 1 | B12: 54 | C12: Engenheiro de Software Full Stack | D12: Engenheiro de Software Full Stack Jr | E12: Júnior | F12: Operacional | G12: DEV | H12: 160 | I12: 2489.18 | J12: CLT | K12: 81937 | L12: Masculino | M12: 2/19/2024
A13: 1 | B13: 8 | C13: Engenheiro de Software Full Stack | D13: Engenheiro de Software Full Stack Jr | E13: Júnior | F13: Operacional | G13: DEV | H13: 160 | I13: 2489.18 | J13: CLT | K13: 81937 | L13: Masculino | M13: 1/13/2025
A14: 1 | B14: 41 | C14: Engenheiro de Software Full Stack | D14: Engenheiro de Software Full Stack Jr | E14: Júnior | F14: Operacional | G14: DEV | H14: 160 | I14: 2489.18 | J14: CLT | K14: 81937 | L14: Feminino | M14: 45809
A15: 1 | B15: 46 | C15: Engenheiro de Software Full Stack | D15: Engenheiro de Software Full Stack Jr | E15: Júnior | F15: Operacional | G15: DEV | H15: 160 | I15: 2489.18 | J15: CLT | K15: 81937 | L15: Masculino | M15: 1/13/2025
A16: 1 | B16: 40 | C16: Engenheiro de Software Full Stack | D16: Engenheiro de Software Full Stack Jr | E16: Júnior | F16: Operacional | G16: DEV | H16: 160 | I16: 2489.18 | J16: CLT | K16: 81937 | L16: Masculino | M16: 1/13/2025
A17: 1 | B17: 39 | C17: Engenheiro de Software Full Stack | D17: Engenheiro de Software Full Stack Jr | E17: Júnior | F17: Operacional | G17: DEV | H17: 160 | I17: 2489.18 | J17: CLT | K17: 81937 | L17: Masculino | M17: 45809
A18: 1 | B18: 19 | C18: Engenheiro de Software Full Stack | D18: Engenheiro de Software Full Stack Jr | E18: Júnior | F18: Operacional | G18: DEV | H18: 160 | I18: 2489.18 | J18: CLT | K18: 81937 | L18: Masculino | M18: 45421
A19: 1 | B19: 19 | C19: Engenheiro de Software Full Stack | D19: Engenheiro de Software Full Stack Jr | E19: Júnior | F19: Operacional | G19: DEV | H19: 160 | I19: 2489.18 | J19: CLT | K19: 81937 | L19: Masculino | M19: 45635
A20: 1 | B20: 21 | C20: Engenheiro de Software Full Stack | D20: Engenheiro de Software Full Stack Jr | E20: Júnior | F20: Operacional | G20: DEV | H20: 160 | I20: 2489.18 | J20: CLT | K20: 81937 | L20: Masculino | M20: 45809
A21: 1 | B21: 45 | C21: Engenheiro de Software Full Stack | D21: Engenheiro de Software Full Stack Jr | E21: Júnior | F21: Operacional | G21: DEV | H21: 160 | I21: 2489.18 | J21: CLT | K21: 81937 | L21: Masculino | M21: 45511
A22: 1 | B22: 13 | C22: Engenheiro de Software Full Stack | D22: Engenheiro de Software Full Stack Jr | E22: Júnior | F22: Operacional | G22: DEV | H22: 160 | I22: 2489.18 | J22: CLT | K22: 81937 | L22: Masculino | M22: 9/16/2024
A23: 1 | B23: 22 | C23: Engenheiro de Software Full Stack | D23: Engenheiro de Software Full Stack Jr | E23: Júnior | F23: Operacional | G23: DEV | H23: 160 | I23: 2489.18 | J23: CLT | K23: 81937 | L23: Feminino | M23: 44932
A24: 1 | B24: 1 | C24: Engenheiro de Software Full Stack | D24: Engenheiro de Software Full Stack Jr | E24: Júnior | F24: Operacional | G24: DEV | H24: 160 | I24: 2489.18 | J24: CLT | K24: 81937 | L24: Masculino | M24: 2/19/2024
A25: 1 | B25: 9 | C25: Engenheiro de Software Full Stack | D25: Engenheiro de Software Full Stack Jr | E25: Júnior | F25: Operacional | G25: DEV | H25: 160 | I25: 2489.18 | J25: CLT | K25: 81937 | L25: Masculino | M25: 44932
A26: 1 | B26: 2 | C26: Engenheiro de Software Full Stack | D26: Engenheiro de Software Full Stack Jr | E26: Júnior | F26: Operacional | G26: DEV | H26: 160 | I26: 2489.18 | J26: CLT | K26: 81937 | L26: Masculino | M26: 45809
A27: 1 | B27: 43 | C27: Engenheiro de Software Full Stack | D27: Engenheiro de Software Full Stack Jr | E27: Júnior | F27: Operacional | G27: DEV | H27: 160 | I27: 2489.18 | J27: CLT | K27: 81937 | L27: Masculino | M27: 45809
A28: 1 | B28: 44 | C28: Engenheiro de Software Full Stack | D28: Engenheiro de Software Full Stack Jr | E28: Júnior | F28: Operacional | G28: DEV | H28: 160 | I28: 2489.18 | J28: CLT | K28: 81937 | L28: Masculino | M28: 9/16/2024
A29: 1 | B29: 24 | C29: Engenheiro de Software Full Stack | D29: Engenheiro de Software Full Stack Jr | E29: Júnior | F29: Operacional | G29: DEV | H29: 160 | I29: 2489.18 | J29: CLT | K29: 81937 | L29: Masculino | M29: 44932
A30: 1 | B30: 4 | C30: Engenheiro de Software Full Stack | D30: Engenheiro de Software Full Stack Jr | E30: Júnior | F30: Operacional | G30: DEV | H30: 160 | I30: 2489.18 | J30: CLT | K30: 81937 | L30: Masculino | M30: 10/14/2024
A31: 1 | B31: 27 | C31: Engenheiro de Software Full Stack | D31: Engenheiro de Software Full Stack Jr | E31: Júnior | F31: Operacional | G31: DEV | H31: 160 | I31: 2489.18 | J31: CLT | K31: 81937 | L31: Feminino | M31: 44937
A32: 1 | B32: 381 | C32: Engenheiro de Software Full Stack | D32: Engenheiro de Software Full Stack Jr | E32: Júnior | F32: Operacional | G32: DEV | H32: 160 | I32: 2489.18 | J32: CLT | K32: 81937 | L32: Masculino | M32: 45628
A33: 1 | B33: 34 | C33: Engenheiro de Software Full Stack | D33: Engenheiro de Software Full Stack Jr | E33: Júnior | F33: Operacional | G33: DEV | H33: 160 | I33: 2489.18 | J33: CLT | K33: 81937 | L33: Masculino | M33: 45809
A34: 4 | B34: 33 | C34: Analista de Requisitos | E34: Júnior | F34: Operacional | G34: DEV | H34: 160 | I34: 2489.18 | J34: CLT | K34: 81937 | L34: Feminino | M34: 45607
A35: 4 | B35: 49 | C35: Analista de Requisitos | E35: Júnior | F35: Operacional | G35: DEV | H35: 160 | I35: 3229.2 | J35: CLT | K35: 81968 | L35: Masculino | M35: 45809
A36: 5 | B36: 3 | C36: Lider | E36: Sênior | F36: Estratégico | G36: DEV | H36: 160 | I36: 8611.2 | J36: CLT | K36: 464498 | L36: Masculino | M36: 45078

Sheet Jobmatch
A1: Jobmatch
A3: Cod. | B3: Cargos Empresa | C3: Área | D3: Nível Organizacional | E3: Cod. Pesquisa | F3: Cargos Pesquisa | G3: Senioridade | H3: Observações
A4: 1 | B4: Engenheiro de Software Full Stack Jr | C4: DEV | D4: Operacional | E4: 1 | F4: Desenvolvedor | G4: Júnior
A5: 2 | B5: Engenheiro de Software Full Stack Pl | C5: DEV | D5: Operacional | E5: 1 | F5: Desenvolvedor | G5: Pleno
A6: 3 | B6: Engenheiro de Software Full Stack Sr | C6: DEV | D6: Tático | E6: 1 | F6: Desenvolvedor | G6: Sênior
A7: 4 | B7: Analista de Requisitos | C7: DEV | D7: Operacional | E7: 796 | F7: Analista de Requisitos | G7: Júnior
A8: 5 | B8: Lider | C8: DEV | D8: Estratégico | E8: 1016 | F8: Líder Técnico | G8: Indiferente

Sheet Cálculos Comparativos
G1: DADOS PARA COMPARAÇÃO | L1: ='Informações Relevantes Cenários'!A1 -> Cenário 01: Pesquisa TI - Nacional | R1: ="% Distância da "&'Painel Geral'!B5 -> % Distância da Mediana | S1: Posicionamento | T1: ='Informações Relevantes Cenários'!C1 -> Cenário 02: Pesquisa TI - Corte por Santa Catarina | Z1: ="% Distância da "&'Painel Geral'!B5 -> % Distância da Mediana | AA1: Posicionamento
A3: Cod. | B3: Cargos Empresa | C3: Média Empresa | D3: Cod. Área | E3: Área | F3: Nível Organizacional | G3: Cod. Pesquisa | H3: Cargos Pesquisa | I3: Senioridade | J3: Código+Senioridade | K3: Qtd de Colab | L3: Menor Salário | M3: 1º Quartil | N3: Média | O3: Mediana | P3: 3º Quartil | Q3: Maior Salário | R3: C-01 | S3: C-01 (Posicionamento) | T3: Menor Salário | U3: 1º Quartil | V3: Média | W3: Mediana | X3: 3º Quartil | Y3: Maior Salário | Z3: C-02 | AA3: C-02 (Posicionamento)
A4: 1 | B4: =VLOOKUP(A4,Jobmatch!A:F,2,0) -> Engenheiro de Software Full Stack Jr | C4: =IFERROR(AVERAGEIF('Folha de Pagamento'!A:A,A4,'Folha de Pagamento'!I:I),"") -> 2489.18 | D4: 1 | E4: =VLOOKUP(A4,Jobmatch!A:G,3,0) -> DEV | F4: =VLOOKUP(A4,Jobmatch!A:H,4,0) -> Operacional | G4: =VLOOKUP(A4,Jobmatch!A:H,5,0) -> 1 | H4: =VLOOKUP(A4,Jobmatch!A:H,6,0) -> Desenvolvedor | I4: =VLOOKUP(A4,Jobmatch!A:H,7,0) -> Júnior | J4: =G4&I4 -> 1Júnior | K4: =COUNTIF('Folha de Pagamento'!A:A,A4) -> 23 | L4: =IFERROR(VLOOKUP(J4,'C-01'!$D:$L,4,0),"") -> 2030.9 | M4: =IFERROR(VLOOKUP(J4,'C-01'!$D:$L,5,0),"") -> 2706.62 | N4: =IFERROR(VLOOKUP(J4,'C-01'!$D:$L,6,0),"") -> 3370.79 | O4: =IFERROR(VLOOKUP(J4,'C-01'!$D:$L,7,0),"") -> 3379.04 | P4: =IFERROR(VLOOKUP(J4,'C-01'!$D:$L,8,0),"") -> 3870.49 | Q4: =IFERROR(VLOOKUP(J4,'C-01'!$D:$L,9,0),"") -> 5268.74 | R4: =IFS('Painel Geral'!$B$5="Mediana",IFERROR(IF(OR(C4="",O4=0,O4=""),"",($C4/$O4)),""),'Painel Geral'!$B$5="Menor Salário",IFERROR(IF(OR(C4="",O4=0,O4=""),"",($C4/$L4)),""),'Painel Geral'!$B$5="1º Quartil",IFERROR(IF(OR(C4="",O4=0,O4=""),"",($C4/$M4)),""), 'Painel Geral'!$B$5="Média",IFERROR(IF(OR(C4="",O4=0,O4=""),"",($C4/$N4)),""),'Painel Geral'!$B$5="3º Quartil",IFERROR(IF(OR(C4="",O4=0,O4=""),"",($C4/$P4)),""),'Painel Geral'!$B$5="Maior Salário",IFERROR(IF(OR(C4="",O4=0,O4=""),"",($C4/$Q4)),"")) -> 0.73665301 | S4: =IFS(OR(L4="",L4=0,C4="", C4=0),"",R4<=80%,"Muito Defasado",R4<=90%,"Defasado",R4<=100%,"Na Média",R4<=110%,"Competitivo",R4<=120%,"Muito Competitivo",R4>120%,"Agressivo") -> Muito Defasado | T4: =IFERROR(VLOOKUP($J4,'C-02'!$D:$L,4,0),"") -> 2468.17 | U4: =IFERROR(VLOOKUP($J4,'C-02'!$D:$L,5,0),"") -> 2944.09 | V4: =IFERROR(VLOOKUP($J4,'C-02'!$D:$L,6,0),"") -> 3642.17 | W4: =IFERROR(VLOOKUP($J4,'C-02'!$D:$L,7,0),"") -> 3493.9 | X4: =IFERROR(VLOOKUP($J4,'C-02'!$D:$L,8,0),"") -> 4224.13 | Y4: =IFERROR(VLOOKUP($J4,'C-02'!$D:$L,9,0),"") -> 5456.83 | Z4: =IFS('Painel Geral'!$B$5="Mediana",IFERROR(IF(OR(C4="",W4=0,W4=""),"",($C4/$W4)),""),'Painel Geral'!$B$5="Menor Salário",IFERROR(IF(OR(C4="",W4=0,W4=""),"",($C4/$T4)),""),'Painel Geral'!$B$5="1º Quartil",IFERROR(IF(OR(C4="",W4=0,W4=""),"",($C4/$U4)),""),'Painel Geral'!$B$5="Média",IFERROR(IF(OR(C4="",W4=0,W4=""),"",($C4/$V4)),""),'Painel Geral'!$B$5="3º Quartil",IFERROR(IF(OR(C4="",W4=0,W4=""),"",($C4/$X4)),""), 'Painel Geral'!$B$5="Maior Salário",IFERROR(IF(OR(C4="",W4=0,W4=""),"",($C4/$Y4)),"")) -> 0.71243596 | AA4: =IFS(OR(T4="",T4=0,C4="", C4=0),"",Z4<=80%,"Muito Defasado",Z4<=90%,"Defasado",Z4<=100%,"Na Média",Z4<=110%,"Competitivo",Z4<=120%,"Muito Competitivo",Z4>120%,"Agressivo") -> Muito Defasado
A5: 2 | B5: =VLOOKUP(A5,Jobmatch!A:F,2,0) -> Engenheiro de Software Full Stack Pl | C5: =IFERROR(AVERAGEIF('Folha de Pagamento'!A:A,A5,'Folha de Pagamento'!I:I),"") -> 4305.6 | D5: 1 | E5: =VLOOKUP(A5,Jobmatch!A:G,3,0) -> DEV | F5: =VLOOKUP(A5,Jobmatch!A:H,4,0) -> Operacional | G5: =VLOOKUP(A5,Jobmatch!A:H,5,0) -> 1 | H5: =VLOOKUP(A5,Jobmatch!A:H,6,0) -> Desenvolvedor | I5: =VLOOKUP(A5,Jobmatch!A:H,7,0) -> Pleno | J5: =G5&I5 -> 1Pleno | K5: =COUNTIF('Folha de Pagamento'!A:A,A5) -> 5 | L5: =IFERROR(VLOOKUP(J5,'C-01'!$D:$L,4,0),"") -> 3358.05 | M5: =IFERROR(VLOOKUP(J5,'C-01'!$D:$L,5,0),"") -> 4730.15 | N5: =IFERROR(VLOOKUP(J5,'C-01'!$D:$L,6,0),"") -> 5379.82 | O5: =IFERROR(VLOOKUP(J5,'C-01'!$D:$L,7,0),"") -> 5342.35 | P5: =IFERROR(VLOOKUP(J5,'C-01'!$D:$L,8,0),"") -> 5995.34 | Q5: =IFERROR(VLOOKUP(J5,'C-01'!$D:$L,9,0),"") -> 7790.91 | R5: =IFS('Painel Geral'!$B$5="Mediana",IFERROR(IF(OR(C5="",O5=0,O5=""),"",($C5/$O5)),""),'Painel Geral'!$B$5="Menor Salário",IFERROR(IF(OR(C5="",O5=0,O5=""),"",($C5/$L5)),""),'Painel Geral'!$B$5="1º Quartil",IFERROR(IF(OR(C5="",O5=0,O5=""),"",($C5/$M5)),""), 'Painel Geral'!$B$5="Média",IFERROR(IF(OR(C5="",O5=0,O5=""),"",($C5/$N5)),""),'Painel Geral'!$B$5="3º Quartil",IFERROR(IF(OR(C5="",O5=0,O5=""),"",($C5/$P5)),""),'Painel Geral'!$B$5="Maior Salário",IFERROR(IF(OR(C5="",O5=0,O5=""),"",($C5/$Q5)),"")) -> 0.80593746 | S5: =IFS(OR(L5="",L5=0,C5="", C5=0),"",R5<=80%,"Muito Defasado",R5<=90%,"Defasado",R5<=100%,"Na Média",R5<=110%,"Competitivo",R5<=120%,"Muito Competitivo",R5>120%,"Agressivo") -> Defasado | T5: =IFERROR(VLOOKUP($J5,'C-02'!$D:$L,4,0),"") -> 3480.14 | U5: =IFERROR(VLOOKUP($J5,'C-02'!$D:$L,5,0),"") -> 4665.99 | V5: =IFERROR(VLOOKUP($J5,'C-02'!$D:$L,6,0),"") -> 5399.83 | W5: =IFERROR(VLOOKUP($J5,'C-02'!$D:$L,7,0),"") -> 5248.63 | X5: =IFERROR(VLOOKUP($J5,'C-02'!$D:$L,8,0),"") -> 6311.23 | Y5: =IFERROR(VLOOKUP($J5,'C-02'!$D:$L,9,0),"") -> 7135.86 | Z5: =IFS('Painel Geral'!$B$5="Mediana",IFERROR(IF(OR(C5="",W5=0,W5=""),"",($C5/$W5)),""),'Painel Geral'!$B$5="Menor Salário",IFERROR(IF(OR(C5="",W5=0,W5=""),"",($C5/$T5)),""),'Painel Geral'!$B$5="1º Quartil",IFERROR(IF(OR(C5="",W5=0,W5=""),"",($C5/$U5)),""),'Painel Geral'!$B$5="Média",IFERROR(IF(OR(C5="",W5=0,W5=""),"",($C5/$V5)),""),'Painel Geral'!$B$5="3º Quartil",IFERROR(IF(OR(C5="",W5=0,W5=""),"",($C5/$X5)),""), 'Painel Geral'!$B$5="Maior Salário",IFERROR(IF(OR(C5="",W5=0,W5=""),"",($C5/$Y5)),"")) -> 0.82032835 | AA5: =IFS(OR(T5="",T5=0,C5="", C5=0),"",Z5<=80%,"Muito Defasado",Z5<=90%,"Defasado",Z5<=100%,"Na Média",Z5<=110%,"Competitivo",Z5<=120%,"Muito Competitivo",Z5>120%,"Agressivo") -> Defasado
A6: 3 | B6: =VLOOKUP(A6,Jobmatch!A:F,2,0) -> Engenheiro de Software Full Stack Sr | C6: =IFERROR(AVERAGEIF('Folha de Pagamento'!A:A,A6,'Folha de Pagamento'!I:I),"") -> 6458.4 | D6: 1 | E6: =VLOOKUP(A6,Jobmatch!A:G,3,0) -> DEV | F6: =VLOOKUP(A6,Jobmatch!A:H,4,0) -> Tático | G6: =VLOOKUP(A6,Jobmatch!A:H,5,0) -> 1 | H6: =VLOOKUP(A6,Jobmatch!A:H,6,0) -> Desenvolvedor | I6: =VLOOKUP(A6,Jobmatch!A:H,7,0) -> Sênior | J6: =G6&I6 -> 1Sênior | K6: =COUNTIF('Folha de Pagamento'!A:A,A6) -> 2 | L6: =IFERROR(VLOOKUP(J6,'C-01'!$D:$L,4,0),"") -> 5873.21 | M6: =IFERROR(VLOOKUP(J6,'C-01'!$D:$L,5,0),"") -> 7005.56 | N6: =IFERROR(VLOOKUP(J6,'C-01'!$D:$L,6,0),"") -> 8047.78 | O6: =IFERROR(VLOOKUP(J6,'C-01'!$D:$L,7,0),"") -> 7999.87 | P6: =IFERROR(VLOOKUP(J6,'C-01'!$D:$L,8,0),"") -> 9271.4 | Q6: =IFERROR(VLOOKUP(J6,'C-01'!$D:$L,9,0),"") -> 10095.14 | R6: =IFS('Painel Geral'!$B$5="Mediana",IFERROR(IF(OR(C6="",O6=0,O6=""),"",($C6/$O6)),""),'Painel Geral'!$B$5="Menor Salário",IFERROR(IF(OR(C6="",O6=0,O6=""),"",($C6/$L6)),""),'Painel Geral'!$B$5="1º Quartil",IFERROR(IF(OR(C6="",O6=0,O6=""),"",($C6/$M6)),""), 'Painel Geral'!$B$5="Média",IFERROR(IF(OR(C6="",O6=0,O6=""),"",($C6/$N6)),""),'Painel Geral'!$B$5="3º Quartil",IFERROR(IF(OR(C6="",O6=0,O6=""),"",($C6/$P6)),""),'Painel Geral'!$B$5="Maior Salário",IFERROR(IF(OR(C6="",O6=0,O6=""),"",($C6/$Q6)),"")) -> 0.80731312 | S6: =IFS(OR(L6="",L6=0,C6="", C6=0),"",R6<=80%,"Muito Defasado",R6<=90%,"Defasado",R6<=100%,"Na Média",R6<=110%,"Competitivo",R6<=120%,"Muito Competitivo",R6>120%,"Agressivo") -> Defasado | T6: =IFERROR(VLOOKUP($J6,'C-02'!$D:$L,4,0),"") -> 5928.64 | U6: =IFERROR(VLOOKUP($J6,'C-02'!$D:$L,5,0),"") -> 6791.87 | V6: =IFERROR(VLOOKUP($J6,'C-02'!$D:$L,6,0),"") -> 7984.54 | W6: =IFERROR(VLOOKUP($J6,'C-02'!$D:$L,7,0),"") -> 7851.14 | X6: =IFERROR(VLOOKUP($J6,'C-02'!$D:$L,8,0),"") -> 9534.06 | Y6: =IFERROR(VLOOKUP($J6,'C-02'!$D:$L,9,0),"") -> 9921.51 | Z6: =IFS('Painel Geral'!$B$5="Mediana",IFERROR(IF(OR(C6="",W6=0,W6=""),"",($C6/$W6)),""),'Painel Geral'!$B$5="Menor Salário",IFERROR(IF(OR(C6="",W6=0,W6=""),"",($C6/$T6)),""),'Painel Geral'!$B$5="1º Quartil",IFERROR(IF(OR(C6="",W6=0,W6=""),"",($C6/$U6)),""),'Painel Geral'!$B$5="Média",IFERROR(IF(OR(C6="",W6=0,W6=""),"",($C6/$V6)),""),'Painel Geral'!$B$5="3º Quartil",IFERROR(IF(OR(C6="",W6=0,W6=""),"",($C6/$X6)),""), 'Painel Geral'!$B$5="Maior Salário",IFERROR(IF(OR(C6="",W6=0,W6=""),"",($C6/$Y6)),"")) -> 0.82260665 | AA6: =IFS(OR(T6="",T6=0,C6="", C6=0),"",Z6<=80%,"Muito Defasado",Z6<=90%,"Defasado",Z6<=100%,"Na Média",Z6<=110%,"Competitivo",Z6<=120%,"Muito Competitivo",Z6>120%,"Agressivo") -> Defasado
A7: 4 | B7: =VLOOKUP(A7,Jobmatch!A:F,2,0) -> Analista de Requisitos | C7: =IFERROR(AVERAGEIF('Folha de Pagamento'!A:A,A7,'Folha de Pagamento'!I:I),"") -> 2859.19 | D7: 1 | E7: =VLOOKUP(A7,Jobmatch!A:G,3,0) -> DEV | F7: =VLOOKUP(A7,Jobmatch!A:H,4,0) -> Operacional | G7: =VLOOKUP(A7,Jobmatch!A:H,5,0) -> 796 | H7: =VLOOKUP(A7,Jobmatch!A:H,6,0) -> Analista de Requisitos | I7: =VLOOKUP(A7,Jobmatch!A:H,7,0) -> Júnior | J7: =G7&I7 -> 796Júnior | K7: =COUNTIF('Folha de Pagamento'!A:A,A7) -> 2 | L7: =IFERROR(VLOOKUP(J7,'C-01'!$D:$L,4,0),"") -> 2626.68 | M7: =IFERROR(VLOOKUP(J7,'C-01'!$D:$L,5,0),"") -> 3508.61 | N7: =IFERROR(VLOOKUP(J7,'C-01'!$D:$L,6,0),"") -> 4174.12 | O7: =IFERROR(VLOOKUP(J7,'C-01'!$D:$L,7,0),"") -> 3618.72 | P7: =IFERROR(VLOOKUP(J7,'C-01'!$D:$L,8,0),"") -> 5081.15 | Q7: =IFERROR(VLOOKUP(J7,'C-01'!$D:$L,9,0),"") -> 5977.75 | R7: =IFS('Painel Geral'!$B$5="Mediana",IFERROR(IF(OR(C7="",O7=0,O7=""),"",($C7/$O7)),""),'Painel Geral'!$B$5="Menor Salário",IFERROR(IF(OR(C7="",O7=0,O7=""),"",($C7/$L7)),""),'Painel Geral'!$B$5="1º Quartil",IFERROR(IF(OR(C7="",O7=0,O7=""),"",($C7/$M7)),""), 'Painel Geral'!$B$5="Média",IFERROR(IF(OR(C7="",O7=0,O7=""),"",($C7/$N7)),""),'Painel Geral'!$B$5="3º Quartil",IFERROR(IF(OR(C7="",O7=0,O7=""),"",($C7/$P7)),""),'Painel Geral'!$B$5="Maior Salário",IFERROR(IF(OR(C7="",O7=0,O7=""),"",($C7/$Q7)),"")) -> 0.79011087 | S7: =IFS(OR(L7="",L7=0,C7="", C7=0),"",R7<=80%,"Muito Defasado",R7<=90%,"Defasado",R7<=100%,"Na Média",R7<=110%,"Competitivo",R7<=120%,"Muito Competitivo",R7>120%,"Agressivo") -> Muito Defasado | T7: =IFERROR(VLOOKUP($J7,'C-02'!$D:$L,4,0),"") -> 0 | U7: =IFERROR(VLOOKUP($J7,'C-02'!$D:$L,5,0),"") -> 0 | V7: =IFERROR(VLOOKUP($J7,'C-02'!$D:$L,6,0),"") -> 0 | W7: =IFERROR(VLOOKUP($J7,'C-02'!$D:$L,7,0),"") -> 0 | X7: =IFERROR(VLOOKUP($J7,'C-02'!$D:$L,8,0),"") -> 0 | Y7: =IFERROR(VLOOKUP($J7,'C-02'!$D:$L,9,0),"") -> 0 | Z7: =IFS('Painel Geral'!$B$5="Mediana",IFERROR(IF(OR(C7="",W7=0,W7=""),"",($C7/$W7)),""),'Painel Geral'!$B$5="Menor Salário",IFERROR(IF(OR(C7="",W7=0,W7=""),"",($C7/$T7)),""),'Painel Geral'!$B$5="1º Quartil",IFERROR(IF(OR(C7="",W7=0,W7=""),"",($C7/$U7)),""),'Painel Geral'!$B$5="Média",IFERROR(IF(OR(C7="",W7=0,W7=""),"",($C7/$V7)),""),'Painel Geral'!$B$5="3º Quartil",IFERROR(IF(OR(C7="",W7=0,W7=""),"",($C7/$X7)),""), 'Painel Geral'!$B$5="Maior Salário",IFERROR(IF(OR(C7="",W7=0,W7=""),"",($C7/$Y7)),"")) | AA7: =IFS(OR(T7="",T7=0,C7="", C7=0),"",Z7<=80%,"Muito Defasado",Z7<=90%,"Defasado",Z7<=100%,"Na Média",Z7<=110%,"Competitivo",Z7<=120%,"Muito Competitivo",Z7>120%,"Agressivo")
A8: 5 | B8: =VLOOKUP(A8,Jobmatch!A:F,2,0) -> Lider | C8: =IFERROR(AVERAGEIF('Folha de Pagamento'!A:A,A8,'Folha de Pagamento'!I:I),"") -> 8611.2 | D8: 1 | E8: =VLOOKUP(A8,Jobmatch!A:G,3,0) -> DEV | F8: =VLOOKUP(A8,Jobmatch!A:H,4,0) -> Estratégico | G8: =VLOOKUP(A8,Jobmatch!A:H,5,0) -> 1016 | H8: =VLOOKUP(A8,Jobmatch!A:H,6,0) -> Líder Técnico | I8: =VLOOKUP(A8,Jobmatch!A:H,7,0) -> Indiferente | J8: =G8&I8 -> 1016Indiferente | K8: =COUNTIF('Folha de Pagamento'!A:A,A8) -> 1 | L8: =IFERROR(VLOOKUP(J8,'C-01'!$D:$L,4,0),"") -> 5639.53 | M8: =IFERROR(VLOOKUP(J8,'C-01'!$D:$L,5,0),"") -> 7452.03 | N8: =IFERROR(VLOOKUP(J8,'C-01'!$D:$L,6,0),"") -> 8919.44 | O8: =IFERROR(VLOOKUP(J8,'C-01'!$D:$L,7,0),"") -> 8929.22 | P8: =IFERROR(VLOOKUP(J8,'C-01'!$D:$L,8,0),"") -> 10057.47 | Q8: =IFERROR(VLOOKUP(J8,'C-01'!$D:$L,9,0),"") -> 12817.68 | R8: =IFS('Painel Geral'!$B$5="Mediana",IFERROR(IF(OR(C8="",O8=0,O8=""),"",($C8/$O8)),""),'Painel Geral'!$B$5="Menor Salário",IFERROR(IF(OR(C8="",O8=0,O8=""),"",($C8/$L8)),""),'Painel Geral'!$B$5="1º Quartil",IFERROR(IF(OR(C8="",O8=0,O8=""),"",($C8/$M8)),""), 'Painel Geral'!$B$5="Média",IFERROR(IF(OR(C8="",O8=0,O8=""),"",($C8/$N8)),""),'Painel Geral'!$B$5="3º Quartil",IFERROR(IF(OR(C8="",O8=0,O8=""),"",($C8/$P8)),""),'Painel Geral'!$B$5="Maior Salário",IFERROR(IF(OR(C8="",O8=0,O8=""),"",($C8/$Q8)),"")) -> 0.96438435 | S8: =IFS(OR(L8="",L8=0,C8="", C8=0),"",R8<=80%,"Muito Defasado",R8<=90%,"Defasado",R8<=100%,"Na Média",R8<=110%,"Competitivo",R8<=120%,"Muito Competitivo",R8>120%,"Agressivo") -> Na Média | T8: =IFERROR(VLOOKUP($J8,'C-02'!$D:$L,4,0),"") -> 5288.93 | U8: =IFERROR(VLOOKUP($J8,'C-02'!$D:$L,5,0),"") -> 7107.92 | V8: =IFERROR(VLOOKUP($J8,'C-02'!$D:$L,6,0),"") -> 8904.46 | W8: =IFERROR(VLOOKUP($J8,'C-02'!$D:$L,7,0),"") -> 9047.66 | X8: =IFERROR(VLOOKUP($J8,'C-02'!$D:$L,8,0),"") -> 10074.15 | Y8: =IFERROR(VLOOKUP($J8,'C-02'!$D:$L,9,0),"") -> 12817.68 | Z8: =IFS('Painel Geral'!$B$5="Mediana",IFERROR(IF(OR(C8="",W8=0,W8=""),"",($C8/$W8)),""),'Painel Geral'!$B$5="Menor Salário",IFERROR(IF(OR(C8="",W8=0,W8=""),"",($C8/$T8)),""),'Painel Geral'!$B$5="1º Quartil",IFERROR(IF(OR(C8="",W8=0,W8=""),"",($C8/$U8)),""),'Painel Geral'!$B$5="Média",IFERROR(IF(OR(C8="",W8=0,W8=""),"",($C8/$V8)),""),'Painel Geral'!$B$5="3º Quartil",IFERROR(IF(OR(C8="",W8=0,W8=""),"",($C8/$X8)),""), 'Painel Geral'!$B$5="Maior Salário",IFERROR(IF(OR(C8="",W8=0,W8=""),"",($C8/$Y8)),"")) -> 0.9517599 | AA8: =IFS(OR(T8="",T8=0,C8="", C8=0),"",Z8<=80%,"Muito Defasado",Z8<=90%,"Defasado",Z8<=100%,"Na Média",Z8<=110%,"Competitivo",Z8<=120%,"Muito Competitivo",Z8>120%,"Agressivo") -> Na Média

Sheet Painel Geral
B3: Posicionamento e Gráficos em Relação à: | F3: ="Legenda (em relação à "&B5&"):" -> Legenda (em relação à Mediana):
F4: ▇ | G4: <=80% | H4: Muito Defasado
B5: Mediana | F5: ▇ | G5: 80% - 90% | H5: Defasado
F6: ▇ | G6: 90% - 100% | H6: Na Média
F7: ▇ | G7: 100% - 110% | H7: Competitivo
F8: ▇ | G8: 110% - 120% | H8: Muito Competitivo
F9: ▇ | G9: >120% | H9: Agressivo
B12: Cenário 1 | F12: Cenário 2
D15: =D42 -> 5 | J15: =J42 -> 4
D17: cargos com amostra | J17: cargos com amostra
D24: =IF(SUM(C36:C38)>SUM(C39:C41),SUM(C36:C38),SUM(C39:C41)) -> 1 | J24: =IF(SUM(H36:H38)>SUM(H39:H41),SUM(H36:H38),SUM(H39:H41)) -> 1
D26: =IF(SUM(C36:C38)>SUM(C39:C41),"dos cargos abaixo "&IF(B5="Mediana","da ",IF(B5="Média","da ","do "))&B5,"dos cargos acima "&IF(B5="Mediana","da ",IF(B5="Média","da ","do "))&B5) -> dos cargos abaixo da Mediana | J26: =IF(SUM(H36:H38)>SUM(H39:H41),"dos cargos abaixo "&IF(B5="Mediana","da ",IF(B5="Média","da ","do "))&B5,"dos cargos acima "&IF(B5="Mediana","da ",IF(B5="Média","da ","do "))&B5) -> dos cargos abaixo da Mediana
B35: Posição | C35: Percentual | D35: Qtde de Cargos | F35: Posição | H35: Percentual | J35: Qtde de Cargos
B36: Muito Defasado | C36: =IFERROR(D36/$D$42,0) -> 0.4 | D36: =COUNTIF('Cálculos Comparativos'!S:S,$B36) -> 2 | F36: Muito Defasado | H36: =iferror(J36/J$42,0) -> 0.25 | J36: =COUNTIF('Cálculos Comparativos'!AA:AA,$F36) -> 1
B37: Defasado | C37: =IFERROR(D37/$D$42,0) -> 0.4 | D37: =COUNTIF('Cálculos Comparativos'!S:S,$B37) -> 2 | F37: Defasado | H37: =iferror(J37/J$42,0) -> 0.5 | J37: =COUNTIF('Cálculos Comparativos'!AA:AA,$F37) -> 2
B38: Na Média | C38: =IFERROR(D38/$D$42,0) -> 0.2 | D38: =COUNTIF('Cálculos Comparativos'!S:S,$B38) -> 1 | F38: Na Média | H38: =iferror(J38/J$42,0) -> 0.25 | J38: =COUNTIF('Cálculos Comparativos'!AA:AA,$F38) -> 1
B39: Competitivo | C39: =IFERROR(D39/$D$42,0) -> 0 | D39: =COUNTIF('Cálculos Comparativos'!S:S,$B39) -> 0 | F39: Competitivo | H39: =iferror(J39/J$42,0) -> 0 | J39: =COUNTIF('Cálculos Comparativos'!AA:AA,$F39) -> 0
B40: Muito Competitivo | C40: =IFERROR(D40/$D$42,0) -> 0 | D40: =COUNTIF('Cálculos Comparativos'!S:S,$B40) -> 0 | F40: Muito Competitivo | H40: =iferror(J40/J$42,0) -> 0 | J40: =COUNTIF('Cálculos Comparativos'!AA:AA,$F40) -> 0
B41: Agressivo | C41: =IFERROR(D41/$D$42,0) -> 0 | D41: =COUNTIF('Cálculos Comparativos'!S:S,$B41) -> 0 | F41: Agressivo | H41: =iferror(J41/J$42,0) -> 0 | J41: =COUNTIF('Cálculos Comparativos'!AA:AA,$F41) -> 0
B42: Total Geral | C42: =SUM(C36:C41) -> 1 | D42: =SUM(D36:D41) -> 5 | F42: Total Geral | H42: =SUM(H36:H41) -> 1 | J42: =SUM(J36:J41) -> 4
B45: ANÁLISE DE SALÁRIOS
B46: NÍVEIS ORGANIZACIONAIS
L48: =IF(SUM(C53:C55)>SUM(C56:C58),SUM(C53:C55),SUM(C56:C58)) -> 1 | M48: =IF(SUM(C53:C55)>SUM(C56:C58),"dos cargos abaixo "&IF(B5="Mediana","da ",IF(B5="Média","da ","do "))&B5,"dos cargos acima "&IF(B5="Mediana","da ",IF(B5="Média","da ","do "))&B5) -> dos cargos abaixo da Mediana
B49: Operacional
B52: Posição | C52: C1 | D52: C2
B53: Muito Defasado | C53: =IFERROR(COUNTIFS('Cálculos Comparativos'!F:F,$B$49,'Cálculos Comparativos'!S:S,$B53)/C$59, 0) -> 0.66666667 | D53: =IFERROR(COUNTIFS('Cálculos Comparativos'!F:F,$B$49,'Cálculos Comparativos'!AA:AA,$B53)/D$59, 0) -> 0.5 | L53: =IF(SUM(D53:D55)>SUM(D56:D58),SUM(D53:D55),SUM(D56:D58)) -> 1 | M53: =IF(SUM(D53:D55)>SUM(D56:D58),"dos cargos abaixo "&IF(B5="Mediana","da ",IF(B5="Média","da ","do "))&B5,"dos cargos acima "&IF(B5="Mediana","da ",IF(B5="Média","da ","do "))&B5) -> dos cargos abaixo da Mediana
B54: Defasado | C54: =IFERROR(COUNTIFS('Cálculos Comparativos'!F:F,$B$49,'Cálculos Comparativos'!S:S,$B54)/C$59, 0) -> 0.33333333 | D54: =IFERROR(COUNTIFS('Cálculos Comparativos'!F:F,$B$49,'Cálculos Comparativos'!AA:AA,$B54)/D$59, 0) -> 0.5
B55: Na Média | C55: =IFERROR(COUNTIFS('Cálculos Comparativos'!F:F,$B$49,'Cálculos Comparativos'!S:S,$B55)/C$59, 0) -> 0 | D55: =IFERROR(COUNTIFS('Cálculos Comparativos'!F:F,$B$49,'Cálculos Comparativos'!AA:AA,$B55)/D$59, 0) -> 0
B56: Competitivo | C56: =IFERROR(COUNTIFS('Cálculos Comparativos'!F:F,$B$49,'Cálculos Comparativos'!S:S,$B56)/C$59, 0) -> 0 | D56: =IFERROR(COUNTIFS('Cálculos Comparativos'!F:F,$B$49,'Cálculos Comparativos'!AA:AA,$B56)/D$59, 0) -> 0
B57: Muito Competitivo | C57: =IFERROR(COUNTIFS('Cálculos Comparativos'!F:F,$B$49,'Cálculos Comparativos'!S:S,$B57)/C$59, 0) -> 0 | D57: =IFERROR(COUNTIFS('Cálculos Comparativos'!F:F,$B$49,'Cálculos Comparativos'!AA:AA,$B57)/D$59, 0) -> 0
B58: Agressivo | C58: =IFERROR(COUNTIFS('Cálculos Comparativos'!F:F,$B$49,'Cálculos Comparativos'!S:S,$B58)/C$59, 0) -> 0 | D58: =IFERROR(COUNTIFS('Cálculos Comparativos'!F:F,$B$49,'Cálculos Comparativos'!AA:AA,$B58)/D$59, 0) -> 0
B59: Nº de Cargos Total | C59: =COUNTIFS('Cálculos Comparativos'!F:F,B49,'Cálculos Comparativos'!S:S,"?*") -> 3 | D59: =COUNTIFS('Cálculos Comparativos'!F:F, B49,'Cálculos Comparativos'!AA:AA,"?*") -> 2
B72: ="5 Maiores Salários acima "&IF(B5="Mediana","da ",IF(B5="Média","da ","do "))&B5 -> 5 Maiores Salários acima da Mediana
B74: Classificado pelo C-01 | E74: Cenário 1 | G74: Cenário 2
B75: Cargos Empresa | C75: Cargos Pesquisa | D75: Média empresa | E75: =$B$5 -> Mediana | F75: Posição | G75: =$B$5 -> Mediana | H75: Posição
A76: {=INDEX('Cálculos Comparativos'!A:A, MATCH(LARGE('Cálculos Comparativos'!R:R, ROW(A1)), 'Cálculos Comparativos'!R:R, 0))} -> 5 | B76: =iferror(VLOOKUP($A76,'Cálculos Comparativos'!$A:$AA,2,0),"") -> Lider | C76: =iferror(VLOOKUP($A76,'Cálculos Comparativos'!$A:$AA,8,0)&" "&if(VLOOKUP($A76,'Cálculos Comparativos'!$A:$AA,9,0)="Indiferente","",VLOOKUP($A76,'Cálculos Comparativos'!$A:$AA,9,0)),"") -> Líder Técnico | D76: =VLOOKUP(A76,'Cálculos Comparativos'!$A:$AA,3,0) -> 8611.2 | E76: =IFS($B$5="Mediana",VLOOKUP(A76,'Cálculos Comparativos'!A:AA,15,0),$B$5="Menor Salário",VLOOKUP(A76,'Cálculos Comparativos'!A:AA,12,0),$B$5="1º Quartil",VLOOKUP(A76,'Cálculos Comparativos'!A:AA,13,0),$B$5="Média",VLOOKUP(A76,'Cálculos Comparativos'!A:AA,14,0),$B$5="3º Quartil",VLOOKUP(A76,'Cálculos Comparativos'!A:AA,16,0),$B$5="Maior Salário",VLOOKUP(A76,'Cálculos Comparativos'!A:AA,17,0)) -> 8929.22 | F76: =VLOOKUP(A76,'Cálculos Comparativos'!$A:$AA,18,0) -> 0.96438435 | G76: =IFS($B$5="Mediana",VLOOKUP(A76,'Cálculos Comparativos'!A:AA,23,0),$B$5="Menor Salário",VLOOKUP(A76,'Cálculos Comparativos'!A:AA,20,0),$B$5="1º Quartil",VLOOKUP(A76,'Cálculos Comparativos'!A:AA,21,0),$B$5="Média",VLOOKUP(A76,'Cálculos Comparativos'!A:AA,22,0),$B$5="3º Quartil",VLOOKUP(A76,'Cálculos Comparativos'!A:AA,24,0),$B$5="Maior Salário",VLOOKUP(A76,'Cálculos Comparativos'!A:AA,25,0)) -> 9047.66 | H76: =VLOOKUP(A76,'Cálculos Comparativos'!$A:$AA,26,0) -> 0.9517599
A77: {=INDEX('Cálculos Comparativos'!A:A, MATCH(LARGE('Cálculos Comparativos'!R:R, ROW(A2)), 'Cálculos Comparativos'!R:R, 0))} -> 3 | B77: =iferror(VLOOKUP($A77,'Cálculos Comparativos'!$A:$AA,2,0),"") -> Engenheiro de Software Full Stack Sr | C77: =iferror(VLOOKUP($A77,'Cálculos Comparativos'!$A:$AA,8,0)&" "&if(VLOOKUP($A77,'Cálculos Comparativos'!$A:$AA,9,0)="Indiferente","",VLOOKUP($A77,'Cálculos Comparativos'!$A:$AA,9,0)),"") -> Desenvolvedor Sênior | D77: =VLOOKUP(A77,'Cálculos Comparativos'!$A:$AA,3,0) -> 6458.4 | E77: =IFS($B$5="Mediana",VLOOKUP(A77,'Cálculos Comparativos'!A:AA,15,0),$B$5="Menor Salário",VLOOKUP(A77,'Cálculos Comparativos'!A:AA,12,0),$B$5="1º Quartil",VLOOKUP(A77,'Cálculos Comparativos'!A:AA,13,0),$B$5="Média",VLOOKUP(A77,'Cálculos Comparativos'!A:AA,14,0),$B$5="3º Quartil",VLOOKUP(A77,'Cálculos Comparativos'!A:AA,16,0),$B$5="Maior Salário",VLOOKUP(A77,'Cálculos Comparativos'!A:AA,17,0)) -> 7999.87 | F77: =VLOOKUP(A77,'Cálculos Comparativos'!$A:$AA,18,0) -> 0.80731312 | G77: =IFS($B$5="Mediana",VLOOKUP(A77,'Cálculos Comparativos'!A:AA,23,0),$B$5="Menor Salário",VLOOKUP(A77,'Cálculos Comparativos'!A:AA,20,0),$B$5="1º Quartil",VLOOKUP(A77,'Cálculos Comparativos'!A:AA,21,0),$B$5="Média",VLOOKUP(A77,'Cálculos Comparativos'!A:AA,22,0),$B$5="3º Quartil",VLOOKUP(A77,'Cálculos Comparativos'!A:AA,24,0),$B$5="Maior Salário",VLOOKUP(A77,'Cálculos Comparativos'!A:AA,25,0)) -> 7851.14 | H77: =VLOOKUP(A77,'Cálculos Comparativos'!$A:$AA,26,0) -> 0.82260665
A78: {=INDEX('Cálculos Comparativos'!A:A, MATCH(LARGE('Cálculos Comparativos'!R:R, ROW(A3)), 'Cálculos Comparativos'!R:R, 0))} -> 2 | B78: =iferror(VLOOKUP($A78,'Cálculos Comparativos'!$A:$AA,2,0),"") -> Engenheiro de Software Full Stack Pl | C78: =iferror(VLOOKUP($A78,'Cálculos Comparativos'!$A:$AA,8,0)&" "&if(VLOOKUP($A78,'Cálculos Comparativos'!$A:$AA,9,0)="Indiferente","",VLOOKUP($A78,'Cálculos Comparativos'!$A:$AA,9,0)),"") -> Desenvolvedor Pleno | D78: =VLOOKUP(A78,'Cálculos Comparativos'!$A:$AA,3,0) -> 4305.6 | E78: =IFS($B$5="Mediana",VLOOKUP(A78,'Cálculos Comparativos'!A:AA,15,0),$B$5="Menor Salário",VLOOKUP(A78,'Cálculos Comparativos'!A:AA,12,0),$B$5="1º Quartil",VLOOKUP(A78,'Cálculos Comparativos'!A:AA,13,0),$B$5="Média",VLOOKUP(A78,'Cálculos Comparativos'!A:AA,14,0),$B$5="3º Quartil",VLOOKUP(A78,'Cálculos Comparativos'!A:AA,16,0),$B$5="Maior Salário",VLOOKUP(A78,'Cálculos Comparativos'!A:AA,17,0)) -> 5342.35 | F78: =VLOOKUP(A78,'Cálculos Comparativos'!$A:$AA,18,0) -> 0.80593746 | G78: =IFS($B$5="Mediana",VLOOKUP(A78,'Cálculos Comparativos'!A:AA,23,0),$B$5="Menor Salário",VLOOKUP(A78,'Cálculos Comparativos'!A:AA,20,0),$B$5="1º Quartil",VLOOKUP(A78,'Cálculos Comparativos'!A:AA,21,0),$B$5="Média",VLOOKUP(A78,'Cálculos Comparativos'!A:AA,22,0),$B$5="3º Quartil",VLOOKUP(A78,'Cálculos Comparativos'!A:AA,24,0),$B$5="Maior Salário",VLOOKUP(A78,'Cálculos Comparativos'!A:AA,25,0)) -> 5248.63 | H78: =VLOOKUP(A78,'Cálculos Comparativos'!$A:$AA,26,0) -> 0.82032835
A79: {=INDEX('Cálculos Comparativos'!A:A, MATCH(LARGE('Cálculos Comparativos'!R:R, ROW(A4)), 'Cálculos Comparativos'!R:R, 0))} -> 4 | B79: =iferror(VLOOKUP($A79,'Cálculos Comparativos'!$A:$AA,2,0),"") -> Analista de Requisitos | C79: =iferror(VLOOKUP($A79,'Cálculos Comparativos'!$A:$AA,8,0)&" "&if(VLOOKUP($A79,'Cálculos Comparativos'!$A:$AA,9,0)="Indiferente","",VLOOKUP($A79,'Cálculos Comparativos'!$A:$AA,9,0)),"") -> Analista de Requisitos Júnior | D79: =VLOOKUP(A79,'Cálculos Comparativos'!$A:$AA,3,0) -> 2859.19 | E79: =IFS($B$5="Mediana",VLOOKUP(A79,'Cálculos Comparativos'!A:AA,15,0),$B$5="Menor Salário",VLOOKUP(A79,'Cálculos Comparativos'!A:AA,12,0),$B$5="1º Quartil",VLOOKUP(A79,'Cálculos Comparativos'!A:AA,13,0),$B$5="Média",VLOOKUP(A79,'Cálculos Comparativos'!A:AA,14,0),$B$5="3º Quartil",VLOOKUP(A79,'Cálculos Comparativos'!A:AA,16,0),$B$5="Maior Salário",VLOOKUP(A79,'Cálculos Comparativos'!A:AA,17,0)) -> 3618.72 | F79: =VLOOKUP(A79,'Cálculos Comparativos'!$A:$AA,18,0) -> 0.79011087 | G79: =IFS($B$5="Mediana",VLOOKUP(A79,'Cálculos Comparativos'!A:AA,23,0),$B$5="Menor Salário",VLOOKUP(A79,'Cálculos Comparativos'!A:AA,20,0),$B$5="1º Quartil",VLOOKUP(A79,'Cálculos Comparativos'!A:AA,21,0),$B$5="Média",VLOOKUP(A79,'Cálculos Comparativos'!A:AA,22,0),$B$5="3º Quartil",VLOOKUP(A79,'Cálculos Comparativos'!A:AA,24,0),$B$5="Maior Salário",VLOOKUP(A79,'Cálculos Comparativos'!A:AA,25,0)) -> 0 | H79: =VLOOKUP(A79,'Cálculos Comparativos'!$A:$AA,26,0)
A80: {=INDEX('Cálculos Comparativos'!A:A, MATCH(LARGE('Cálculos Comparativos'!R:R, ROW(A5)), 'Cálculos Comparativos'!R:R, 0))} -> 1 | B80: =iferror(VLOOKUP($A80,'Cálculos Comparativos'!$A:$AA,2,0),"") -> Engenheiro de Software Full Stack Jr | C80: =iferror(VLOOKUP($A80,'Cálculos Comparativos'!$A:$AA,8,0)&" "&if(VLOOKUP($A80,'Cálculos Comparativos'!$A:$AA,9,0)="Indiferente","",VLOOKUP($A80,'Cálculos Comparativos'!$A:$AA,9,0)),"") -> Desenvolvedor Júnior | D80: =VLOOKUP(A80,'Cálculos Comparativos'!$A:$AA,3,0) -> 2489.18 | E80: =IFS($B$5="Mediana",VLOOKUP(A80,'Cálculos Comparativos'!A:AA,15,0),$B$5="Menor Salário",VLOOKUP(A80,'Cálculos Comparativos'!A:AA,12,0),$B$5="1º Quartil",VLOOKUP(A80,'Cálculos Comparativos'!A:AA,13,0),$B$5="Média",VLOOKUP(A80,'Cálculos Comparativos'!A:AA,14,0),$B$5="3º Quartil",VLOOKUP(A80,'Cálculos Comparativos'!A:AA,16,0),$B$5="Maior Salário",VLOOKUP(A80,'Cálculos Comparativos'!A:AA,17,0)) -> 3379.04 | F80: =VLOOKUP(A80,'Cálculos Comparativos'!$A:$AA,18,0) -> 0.73665301 | G80: =IFS($B$5="Mediana",VLOOKUP(A80,'Cálculos Comparativos'!A:AA,23,0),$B$5="Menor Salário",VLOOKUP(A80,'Cálculos Comparativos'!A:AA,20,0),$B$5="1º Quartil",VLOOKUP(A80,'Cálculos Comparativos'!A:AA,21,0),$B$5="Média",VLOOKUP(A80,'Cálculos Comparativos'!A:AA,22,0),$B$5="3º Quartil",VLOOKUP(A80,'Cálculos Comparativos'!A:AA,24,0),$B$5="Maior Salário",VLOOKUP(A80,'Cálculos Comparativos'!A:AA,25,0)) -> 3493.9 | H80: =VLOOKUP(A80,'Cálculos Comparativos'!$A:$AA,26,0) -> 0.71243596
...

Sheet Painel Áreas
E1: Cenário 1 | K1: Cenário 2 | P1: DEV | Q1: 1
B3: Posicionamento e Gráficos em Relação à:
E4: =$D$28 -> 5 | N4: =$F$28 -> 4
B5: ='Painel Geral'!$B$5 -> Mediana
E6: cargos com amostra | N6: cargos com amostra
B7: (Para alterar o dado de comparação use a aba Painel Geral)
B9: ANÁLISE DE
B10: COMPARATIVOS SALARIAIS
B11: POR ÁREAS | E11: =IF(SUM(C22:C24)>SUM(C25:C27),SUM(C22:C24),SUM(C25:C27)) -> 1 | N11: =IF(SUM(E22:E24)>SUM(E25:E27),SUM(E22:E24),SUM(E25:E27)) -> 1
B13: DEV | E13: =IF(SUM(C22:C24)>SUM(C25:C27),"dos cargos abaixo "&IF(B5="Mediana","da ",IF(B5="Média","da ","do "))&B5,"dos cargos acima "&IF(B5="Mediana","da ",IF(B5="Média","da ","do "))&B5) -> dos cargos abaixo da Mediana | N13: =IF(SUM(E22:E24)>SUM(E25:E27),"dos cargos abaixo "&IF(B5="Mediana","da ",IF(B5="Média","da ","do "))&B5,"dos cargos acima "&IF(B5="Mediana","da ",IF(B5="Média","da ","do "))&B5) -> dos cargos abaixo da Mediana
B15: =VLOOKUP(B13,P:Q,2,0) -> 1
A20: 2 | C20: Cenário 1 | E20: Cenário 2 | H20: Posição | I20: Percentual C-01 | J20: Percentual C-02
B21: Posição | C21: Percentual | D21: Qtd Cargos | E21: Percentual | F21: Qtd Cargos | H21: Muito Defasado | I21: =C22 -> 0.4 | J21: =E22 -> 0.25
B22: Muito Defasado | C22: =iferror(D22/D$28,0) -> 0.4 | D22: =COUNTIFS('Cálculos Comparativos'!S:S,$B22,'Cálculos Comparativos'!D:D,$B$15) -> 2 | E22: =iferror(F22/F$28,0) -> 0.25 | F22: =COUNTIFS('Cálculos Comparativos'!AA:AA,$B22,'Cálculos Comparativos'!D:D,$B$15) -> 1 | H22: Defasado | I22: =C23 -> 0.4 | J22: =E23 -> 0.5
B23: Defasado | C23: =iferror(D23/D$28,0) -> 0.4 | D23: =COUNTIFS('Cálculos Comparativos'!S:S,$B23,'Cálculos Comparativos'!D:D,$B$15) -> 2 | E23: =iferror(F23/F$28,0) -> 0.5 | F23: =COUNTIFS('Cálculos Comparativos'!AA:AA,$B23,'Cálculos Comparativos'!D:D,$B$15) -> 2 | H23: Na Média | I23: =C24 -> 0.2 | J23: =E24 -> 0.25
B24: Na Média | C24: =iferror(D24/D$28,0) -> 0.2 | D24: =COUNTIFS('Cálculos Comparativos'!S:S,$B24,'Cálculos Comparativos'!D:D,$B$15) -> 1 | E24: =iferror(F24/F$28,0) -> 0.25 | F24: =COUNTIFS('Cálculos Comparativos'!AA:AA,$B24,'Cálculos Comparativos'!D:D,$B$15) -> 1 | H24: Competitivo | I24: =C25 -> 0 | J24: =E25 -> 0
B25: Competitivo | C25: =iferror(D25/D$28,0) -> 0 | D25: =COUNTIFS('Cálculos Comparativos'!S:S,$B25,'Cálculos Comparativos'!D:D,$B$15) -> 0 | E25: =iferror(F25/F$28,0) -> 0 | F25: =COUNTIFS('Cálculos Comparativos'!AA:AA,$B25,'Cálculos Comparativos'!D:D,$B$15) -> 0 | H25: Muito Competitivo | I25: =C26 -> 0 | J25: =E26 -> 0
B26: Muito Competitivo | C26: =iferror(D26/D$28,0) -> 0 | D26: =COUNTIFS('Cálculos Comparativos'!S:S,$B26,'Cálculos Comparativos'!D:D,$B$15) -> 0 | E26: =iferror(F26/F$28,0) -> 0 | F26: =COUNTIFS('Cálculos Comparativos'!AA:AA,$B26,'Cálculos Comparativos'!D:D,$B$15) -> 0 | H26: Agressivo | I26: =C27 -> 0 | J26: =E27 -> 0
A27: 2 | B27: Agressivo | C27: =iferror(D27/D$28,0) -> 0 | D27: =COUNTIFS('Cálculos Comparativos'!S:S,$B27,'Cálculos Comparativos'!D:D,$B$15) -> 0 | E27: =iferror(F27/F$28,0) -> 0 | F27: =COUNTIFS('Cálculos Comparativos'!AA:AA,$B27,'Cálculos Comparativos'!D:D,$B$15) -> 0 | H27: Total Geral | I27: =SUM(I21:I26) -> 1 | J27: =SUM(J21:J26) -> 1
B28: Total Geral | C28: =SUM(C22:C27) -> 1 | D28: =SUM(D22:D27) -> 5 | E28: =SUM(E22:E27) -> 1 | F28: =SUM(F22:F27) -> 4
E30: Cenário 1 | H30: Cenário 2
B31: Cargos Empresa | C31: Cargos Pesquisa | D31: Média Empresa | E31: =B5 -> Mediana | F31: Posição | H31: =B5 -> Mediana | I31: Posição
A32: =IFERROR(__xludf.DUMMYFUNCTION("FILTER('Cálculos Comparativos'!A:A,'Cálculos Comparativos'!D:D=$B$15,'Cálculos Comparativos'!S:S<>"""")"),1.0) -> 1 | B32: =IFERROR(VLOOKUP($A32,'Cálculos Comparativos'!$A:$AA,2,0),"") -> Engenheiro de Software Full Stack Jr | C32: =IFERROR(VLOOKUP($A32,'Cálculos Comparativos'!$A:$AA,8,0)&" "&if(VLOOKUP($A32,'Cálculos Comparativos'!$A:$AA,9,0)="Indiferente","",VLOOKUP($A32,'Cálculos Comparativos'!$A:$AA,9,0)),"") -> Desenvolvedor Júnior | D32: =IFERROR(VLOOKUP(A32,'Cálculos Comparativos'!A:K,3,0),"") -> 2489.18 | E32: =IFERROR(IFS($B$5="Mediana",VLOOKUP(A32,'Cálculos Comparativos'!A:AA,15,0),$B$5="Menor Salário",VLOOKUP(A32,'Cálculos Comparativos'!A:AA,12,0),$B$5="1º Quartil",VLOOKUP(A32,'Cálculos Comparativos'!A:AA,13,0),$B$5="Média",VLOOKUP(A32,'Cálculos Comparativos'!A:AA,14,0),$B$5="3º Quartil",VLOOKUP(A32,'Cálculos Comparativos'!A:AA,16,0),$B$5="Maior Salário",VLOOKUP(A32,'Cálculos Comparativos'!A:AA,17,0)),"") -> 3379.04 | F32: =IFERROR(VLOOKUP($A32,'Cálculos Comparativos'!$A:$AA,18,0),"") -> 0.73665301 | G32: =IFERROR(VLOOKUP($A32,'Cálculos Comparativos'!$A:$AA,19,0),"") -> Muito Defasado | H32: =iferror(IFS($B$5="Mediana",VLOOKUP(A32,'Cálculos Comparativos'!A:AB,23,0),$B$5="Menor Salário",VLOOKUP(A32,'Cálculos Comparativos'!A:AB,20,0),$B$5="1º Quartil",VLOOKUP(A32,'Cálculos Comparativos'!A:AB,21,0),$B$5="Média",VLOOKUP(A32,'Cálculos Comparativos'!A:AB,22,0),$B$5="3º Quartil",VLOOKUP(O32,'Cálculos Comparativos'!S:AB,24,0),$B$5="Maior Salário",VLOOKUP(A32,'Cálculos Comparativos'!A:AB,25,0)),"") -> 3493.9 | I32: =iferror(VLOOKUP($A32,'Cálculos Comparativos'!$A:$AA,26,0),"") -> 0.71243596 | J32: =iferror(VLOOKUP($A32,'Cálculos Comparativos'!$A:$AA,27,0),"") -> Muito Defasado
A33: =IFERROR(__xludf.DUMMYFUNCTION("""COMPUTED_VALUE"""),2.0) -> 2 | B33: =IFERROR(VLOOKUP($A33,'Cálculos Comparativos'!$A:$AA,2,0),"") -> Engenheiro de Software Full Stack Pl | C33: =IFERROR(VLOOKUP($A33,'Cálculos Comparativos'!$A:$AA,8,0)&" "&if(VLOOKUP($A33,'Cálculos Comparativos'!$A:$AA,9,0)="Indiferente","",VLOOKUP($A33,'Cálculos Comparativos'!$A:$AA,9,0)),"") -> Desenvolvedor Pleno | D33: =IFERROR(VLOOKUP(A33,'Cálculos Comparativos'!A:K,3,0),"") -> 4305.6 | E33: =IFERROR(IFS($B$5="Mediana",VLOOKUP(A33,'Cálculos Comparativos'!A:AA,15,0),$B$5="Menor Salário",VLOOKUP(A33,'Cálculos Comparativos'!A:AA,12,0),$B$5="1º Quartil",VLOOKUP(A33,'Cálculos Comparativos'!A:AA,13,0),$B$5="Média",VLOOKUP(A33,'Cálculos Comparativos'!A:AA,14,0),$B$5="3º Quartil",VLOOKUP(A33,'Cálculos Comparativos'!A:AA,16,0),$B$5="Maior Salário",VLOOKUP(A33,'Cálculos Comparativos'!A:AA,17,0)),"") -> 5342.35 | F33: =IFERROR(VLOOKUP($A33,'Cálculos Comparativos'!$A:$AA,18,0),"") -> 0.80593746 | G33: =IFERROR(VLOOKUP($A33,'Cálculos Comparativos'!$A:$AA,19,0),"") -> Defasado | H33: =iferror(IFS($B$5="Mediana",VLOOKUP(A33,'Cálculos Comparativos'!A:AB,23,0),$B$5="Menor Salário",VLOOKUP(A33,'Cálculos Comparativos'!A:AB,20,0),$B$5="1º Quartil",VLOOKUP(A33,'Cálculos Comparativos'!A:AB,21,0),$B$5="Média",VLOOKUP(A33,'Cálculos Comparativos'!A:AB,22,0),$B$5="3º Quartil",VLOOKUP(O33,'Cálculos Comparativos'!S:AB,24,0),$B$5="Maior Salário",VLOOKUP(A33,'Cálculos Comparativos'!A:AB,25,0)),"") -> 5248.63 | I33: =iferror(VLOOKUP($A33,'Cálculos Comparativos'!$A:$AA,26,0),"") -> 0.82032835 | J33: =iferror(VLOOKUP($A33,'Cálculos Comparativos'!$A:$AA,27,0),"") -> Defasado
A34: =IFERROR(__xludf.DUMMYFUNCTION("""COMPUTED_VALUE"""),3.0) -> 3 | B34: =IFERROR(VLOOKUP($A34,'Cálculos Comparativos'!$A:$AA,2,0),"") -> Engenheiro de Software Full Stack Sr | C34: =IFERROR(VLOOKUP($A34,'Cálculos Comparativos'!$A:$AA,8,0)&" "&if(VLOOKUP($A34,'Cálculos Comparativos'!$A:$AA,9,0)="Indiferente","",VLOOKUP($A34,'Cálculos Comparativos'!$A:$AA,9,0)),"") -> Desenvolvedor Sênior | D34: =IFERROR(VLOOKUP(A34,'Cálculos Comparativos'!A:K,3,0),"") -> 6458.4 | E34: =IFERROR(IFS($B$5="Mediana",VLOOKUP(A34,'Cálculos Comparativos'!A:AA,15,0),$B$5="Menor Salário",VLOOKUP(A34,'Cálculos Comparativos'!A:AA,12,0),$B$5="1º Quartil",VLOOKUP(A34,'Cálculos Comparativos'!A:AA,13,0),$B$5="Média",VLOOKUP(A34,'Cálculos Comparativos'!A:AA,14,0),$B$5="3º Quartil",VLOOKUP(A34,'Cálculos Comparativos'!A:AA,16,0),$B$5="Maior Salário",VLOOKUP(A34,'Cálculos Comparativos'!A:AA,17,0)),"") -> 7999.87 | F34: =IFERROR(VLOOKUP($A34,'Cálculos Comparativos'!$A:$AA,18,0),"") -> 0.80731312 | G34: =IFERROR(VLOOKUP($A34,'Cálculos Comparativos'!$A:$AA,19,0),"") -> Defasado | H34: =iferror(IFS($B$5="Mediana",VLOOKUP(A34,'Cálculos Comparativos'!A:AB,23,0),$B$5="Menor Salário",VLOOKUP(A34,'Cálculos Comparativos'!A:AB,20,0),$B$5="1º Quartil",VLOOKUP(A34,'Cálculos Comparativos'!A:AB,21,0),$B$5="Média",VLOOKUP(A34,'Cálculos Comparativos'!A:AB,22,0),$B$5="3º Quartil",VLOOKUP(O34,'Cálculos Comparativos'!S:AB,24,0),$B$5="Maior Salário",VLOOKUP(A34,'Cálculos Comparativos'!A:AB,25,0)),"") -> 7851.14 | I34: =iferror(VLOOKUP($A34,'Cálculos Comparativos'!$A:$AA,26,0),"") -> 0.82260665 | J34: =iferror(VLOOKUP($A34,'Cálculos Comparativos'!$A:$AA,27,0),"") -> Defasado
A35: =IFERROR(__xludf.DUMMYFUNCTION("""COMPUTED_VALUE"""),4.0) -> 4 | B35: =IFERROR(VLOOKUP($A35,'Cálculos Comparativos'!$A:$AA,2,0),"") -> Analista de Requisitos | C35: =IFERROR(VLOOKUP($A35,'Cálculos Comparativos'!$A:$AA,8,0)&" "&if(VLOOKUP($A35,'Cálculos Comparativos'!$A:$AA,9,0)="Indiferente","",VLOOKUP($A35,'Cálculos Comparativos'!$A:$AA,9,0)),"") -> Analista de Requisitos Júnior | D35: =IFERROR(VLOOKUP(A35,'Cálculos Comparativos'!A:K,3,0),"") -> 2859.19 | E35: =IFERROR(IFS($B$5="Mediana",VLOOKUP(A35,'Cálculos Comparativos'!A:AA,15,0),$B$5="Menor Salário",VLOOKUP(A35,'Cálculos Comparativos'!A:AA,12,0),$B$5="1º Quartil",VLOOKUP(A35,'Cálculos Comparativos'!A:AA,13,0),$B$5="Média",VLOOKUP(A35,'Cálculos Comparativos'!A:AA,14,0),$B$5="3º Quartil",VLOOKUP(A35,'Cálculos Comparativos'!A:AA,16,0),$B$5="Maior Salário",VLOOKUP(A35,'Cálculos Comparativos'!A:AA,17,0)),"") -> 3618.72 | F35: =IFERROR(VLOOKUP($A35,'Cálculos Comparativos'!$A:$AA,18,0),"") -> 0.79011087 | G35: =IFERROR(VLOOKUP($A35,'Cálculos Comparativos'!$A:$AA,19,0),"") -> Muito Defasado | H35: =iferror(IFS($B$5="Mediana",VLOOKUP(A35,'Cálculos Comparativos'!A:AB,23,0),$B$5="Menor Salário",VLOOKUP(A35,'Cálculos Comparativos'!A:AB,20,0),$B$5="1º Quartil",VLOOKUP(A35,'Cálculos Comparativos'!A:AB,21,0),$B$5="Média",VLOOKUP(A35,'Cálculos Comparativos'!A:AB,22,0),$B$5="3º Quartil",VLOOKUP(O35,'Cálculos Comparativos'!S:AB,24,0),$B$5="Maior Salário",VLOOKUP(A35,'Cálculos Comparativos'!A:AB,25,0)),"") -> 0 | I35: =iferror(VLOOKUP($A35,'Cálculos Comparativos'!$A:$AA,26,0),"") | J35: =iferror(VLOOKUP($A35,'Cálculos Comparativos'!$A:$AA,27,0),"")
A36: =IFERROR(__xludf.DUMMYFUNCTION("""COMPUTED_VALUE"""),5.0) -> 5 | B36: =IFERROR(VLOOKUP($A36,'Cálculos Comparativos'!$A:$AA,2,0),"") -> Lider | C36: =IFERROR(VLOOKUP($A36,'Cálculos Comparativos'!$A:$AA,8,0)&" "&if(VLOOKUP($A36,'Cálculos Comparativos'!$A:$AA,9,0)="Indiferente","",VLOOKUP($A36,'Cálculos Comparativos'!$A:$AA,9,0)),"") -> Líder Técnico | D36: =IFERROR(VLOOKUP(A36,'Cálculos Comparativos'!A:K,3,0),"") -> 8611.2 | E36: =IFERROR(IFS($B$5="Mediana",VLOOKUP(A36,'Cálculos Comparativos'!A:AA,15,0),$B$5="Menor Salário",VLOOKUP(A36,'Cálculos Comparativos'!A:AA,12,0),$B$5="1º Quartil",VLOOKUP(A36,'Cálculos Comparativos'!A:AA,13,0),$B$5="Média",VLOOKUP(A36,'Cálculos Comparativos'!A:AA,14,0),$B$5="3º Quartil",VLOOKUP(A36,'Cálculos Comparativos'!A:AA,16,0),$B$5="Maior Salário",VLOOKUP(A36,'Cálculos Comparativos'!A:AA,17,0)),"") -> 8929.22 | F36: =IFERROR(VLOOKUP($A36,'Cálculos Comparativos'!$A:$AA,18,0),"") -> 0.96438435 | G36: =IFERROR(VLOOKUP($A36,'Cálculos Comparativos'!$A:$AA,19,0),"") -> Na Média | H36: =iferror(IFS($B$5="Mediana",VLOOKUP(A36,'Cálculos Comparativos'!A:AB,23,0),$B$5="Menor Salário",VLOOKUP(A36,'Cálculos Comparativos'!A:AB,20,0),$B$5="1º Quartil",VLOOKUP(A36,'Cálculos Comparativos'!A:AB,21,0),$B$5="Média",VLOOKUP(A36,'Cálculos Comparativos'!A:AB,22,0),$B$5="3º Quartil",VLOOKUP(O36,'Cálculos Comparativos'!S:AB,24,0),$B$5="Maior Salário",VLOOKUP(A36,'Cálculos Comparativos'!A:AB,25,0)),"") -> 9047.66 | I36: =iferror(VLOOKUP($A36,'Cálculos Comparativos'!$A:$AA,26,0),"") -> 0.9517599 | J36: =iferror(VLOOKUP($A36,'Cálculos Comparativos'!$A:$AA,27,0),"") -> Na Média
B65: Cód Cargo | C65: Cargo Empresa | F65: Muito Defasado | G65: Defasado | H65: Na Média | I65: Competitivo | J65: Muito Competitivo | K65: Agressivo
B66: =A32 -> 1 | C66: =IFERROR(VLOOKUP(B66,'Cálculos Comparativos'!A:B,2,0),"") -> Engenheiro de Software Full Stack Jr | D66: - C-01 | E66: =IF(C66="","",C66&" "&D66) -> Engenheiro de Software Full Stack Jr - C-01 | F66: =IF(E66="","",IFERROR(COUNTIFS('Comparativo por Funcionário'!A:A,B66,'Comparativo por Funcionário'!R:R,F$65),0)) -> 23 | G66: =IF(E66="","",IFERROR(COUNTIFS('Comparativo por Funcionário'!$A:$A,$B66,'Comparativo por Funcionário'!$R:$R,G$65),0)) -> 0 | H66: =IF(E66="","",IFERROR(COUNTIFS('Comparativo por Funcionário'!$A:$A,$B66,'Comparativo por Funcionário'!$R:$R,H$65),0)) -> 0 | I66: =IF(E66="","",IFERROR(COUNTIFS('Comparativo por Funcionário'!$A:$A,$B66,'Comparativo por Funcionário'!$R:$R,I$65),0)) -> 0 | J66: =IF(E66="","",IFERROR(COUNTIFS('Comparativo por Funcionário'!$A:$A,$B66,'Comparativo por Funcionário'!$R:$R,J$65),0)) -> 0 | K66: =IF(E66="","",IFERROR(COUNTIFS('Comparativo por Funcionário'!$A:$A,$B66,'Comparativo por Funcionário'!$R:$R,K$65),0)) -> 0
B67: =A32 -> 1 | C67: =IFERROR(VLOOKUP(B67,'Cálculos Comparativos'!A:B,2,0),"") -> Engenheiro de Software Full Stack Jr | D67: - C-02 | E67: =IF(C67="","",C67&" "&D67) -> Engenheiro de Software Full Stack Jr - C-02 | F67: =IF(E67="","",IFERROR(COUNTIFS('Comparativo por Funcionário'!A:A,B67,'Comparativo por Funcionário'!Z:Z,F$65),0)) -> 23 | G67: =IF(E67="","",IFERROR(COUNTIFS('Comparativo por Funcionário'!$A:$A,$B67,'Comparativo por Funcionário'!$Z:$Z,G$65),0)) -> 0 | H67: =IF(E67="","",IFERROR(COUNTIFS('Comparativo por Funcionário'!$A:$A,$B67,'Comparativo por Funcionário'!$Z:$Z,H$65),0)) -> 0 | I67: =IF(E67="","",IFERROR(COUNTIFS('Comparativo por Funcionário'!$A:$A,$B67,'Comparativo por Funcionário'!$Z:$Z,I$65),0)) -> 0 | J67: =IF(E67="","",IFERROR(COUNTIFS('Comparativo por Funcionário'!$A:$A,$B67,'Comparativo por Funcionário'!$Z:$Z,J$65),0)) -> 0 | K67: =IF(E67="","",IFERROR(COUNTIFS('Comparativo por Funcionário'!$A:$A,$B67,'Comparativo por Funcionário'!$Z:$Z,K$65),0)) -> 0
B68: =A33 -> 2 | C68: =IFERROR(VLOOKUP(B68,'Cálculos Comparativos'!A:B,2,0),"") -> Engenheiro de Software Full Stack Pl | D68: - C-01 | E68: =IF(C68="","",C68&" "&D68) -> Engenheiro de Software Full Stack Pl - C-01 | F68: =IF(E68="","",IFERROR(COUNTIFS('Comparativo por Funcionário'!A:A,B68,'Comparativo por Funcionário'!R:R,F$65),0)) -> 0 | G68: =IF(E68="","",IFERROR(COUNTIFS('Comparativo por Funcionário'!$A:$A,$B68,'Comparativo por Funcionário'!$R:$R,G$65),0)) -> 5 | H68: =IF(E68="","",IFERROR(COUNTIFS('Comparativo por Funcionário'!$A:$A,$B68,'Comparativo por Funcionário'!$R:$R,H$65),0)) -> 0 | I68: =IF(E68="","",IFERROR(COUNTIFS('Comparativo por Funcionário'!$A:$A,$B68,'Comparativo por Funcionário'!$R:$R,I$65),0)) -> 0 | J68: =IF(E68="","",IFERROR(COUNTIFS('Comparativo por Funcionário'!$A:$A,$B68,'Comparativo por Funcionário'!$R:$R,J$65),0)) -> 0 | K68: =IF(E68="","",IFERROR(COUNTIFS('Comparativo por Funcionário'!$A:$A,$B68,'Comparativo por Funcionário'!$R:$R,K$65),0)) -> 0
B69: =A33 -> 2 | C69: =IFERROR(VLOOKUP(B69,'Cálculos Comparativos'!A:B,2,0),"") -> Engenheiro de Software Full Stack Pl | D69: - C-02 | E69: =IF(C69="","",C69&" "&D69) -> Engenheiro de Software Full Stack Pl - C-02 | F69: =IF(E69="","",IFERROR(COUNTIFS('Comparativo por Funcionário'!A:A,B69,'Comparativo por Funcionário'!Z:Z,F$65),0)) -> 0 | G69: =IF(E69="","",IFERROR(COUNTIFS('Comparativo por Funcionário'!$A:$A,$B69,'Comparativo por Funcionário'!$Z:$Z,G$65),0)) -> 5 | H69: =IF(E69="","",IFERROR(COUNTIFS('Comparativo por Funcionário'!$A:$A,$B69,'Comparativo por Funcionário'!$Z:$Z,H$65),0)) -> 0 | I69: =IF(E69="","",IFERROR(COUNTIFS('Comparativo por Funcionário'!$A:$A,$B69,'Comparativo por Funcionário'!$Z:$Z,I$65),0)) -> 0 | J69: =IF(E69="","",IFERROR(COUNTIFS('Comparativo por Funcionário'!$A:$A,$B69,'Comparativo por Funcionário'!$Z:$Z,J$65),0)) -> 0 | K69: =IF(E69="","",IFERROR(COUNTIFS('Comparativo por Funcionário'!$A:$A,$B69,'Comparativo por Funcionário'!$Z:$Z,K$65),0)) -> 0
B70: =A34 -> 3 | C70: =IFERROR(VLOOKUP(B70,'Cálculos Comparativos'!A:B,2,0),"") -> Engenheiro de Software Full Stack Sr | D70: - C-01 | E70: =IF(C70="","",C70&" "&D70) -> Engenheiro de Software Full Stack Sr - C-01 | F70: =IF(E70="","",IFERROR(COUNTIFS('Comparativo por Funcionário'!A:A,B70,'Comparativo por Funcionário'!R:R,F$65),0)) -> 0 | G70: =IF(E70="","",IFERROR(COUNTIFS('Comparativo por Funcionário'!$A:$A,$B70,'Comparativo por Funcionário'!$R:$R,G$65),0)) -> 2 | H70: =IF(E70="","",IFERROR(COUNTIFS('Comparativo por Funcionário'!$A:$A,$B70,'Comparativo por Funcionário'!$R:$R,H$65),0)) -> 0 | I70: =IF(E70="","",IFERROR(COUNTIFS('Comparativo por Funcionário'!$A:$A,$B70,'Comparativo por Funcionário'!$R:$R,I$65),0)) -> 0 | J70: =IF(E70="","",IFERROR(COUNTIFS('Comparativo por Funcionário'!$A:$A,$B70,'Comparativo por Funcionário'!$R:$R,J$65),0)) -> 0 | K70: =IF(E70="","",IFERROR(COUNTIFS('Comparativo por Funcionário'!$A:$A,$B70,'Comparativo por Funcionário'!$R:$R,K$65),0)) -> 0
B71: =A34 -> 3 | C71: =IFERROR(VLOOKUP(B71,'Cálculos Comparativos'!A:B,2,0),"") -> Engenheiro de Software Full Stack Sr | D71: - C-02 | E71: =IF(C71="","",C71&" "&D71) -> Engenheiro de Software Full Stack Sr - C-02 | F71: =IF(E71="","",IFERROR(COUNTIFS('Comparativo por Funcionário'!A:A,B71,'Comparativo por Funcionário'!Z:Z,F$65),0)) -> 0 | G71: =IF(E71="","",IFERROR(COUNTIFS('Comparativo por Funcionário'!$A:$A,$B71,'Comparativo por Funcionário'!$Z:$Z,G$65),0)) -> 2 | H71: =IF(E71="","",IFERROR(COUNTIFS('Comparativo por Funcionário'!$A:$A,$B71,'Comparativo por Funcionário'!$Z:$Z,H$65),0)) -> 0 | I71: =IF(E71="","",IFERROR(COUNTIFS('Comparativo por Funcionário'!$A:$A,$B71,'Comparativo por Funcionário'!$Z:$Z,I$65),0)) -> 0 | J71: =IF(E71="","",IFERROR(COUNTIFS('Comparativo por Funcionário'!$A:$A,$B71,'Comparativo por Funcionário'!$Z:$Z,J$65),0)) -> 0 | K71: =IF(E71="","",IFERROR(COUNTIFS('Comparativo por Funcionário'!$A:$A,$B71,'Comparativo por Funcionário'!$Z:$Z,K$65),0)) -> 0
B72: =A35 -> 4 | C72: =IFERROR(VLOOKUP(B72,'Cálculos Comparativos'!A:B,2,0),"") -> Analista de Requisitos | D72: - C-01 | E72: =IF(C72="","",C72&" "&D72) -> Analista de Requisitos - C-01 | F72: =IF(E72="","",IFERROR(COUNTIFS('Comparativo por Funcionário'!A:A,B72,'Comparativo por Funcionário'!R:R,F$65),0)) -> 1 | G72: =IF(E72="","",IFERROR(COUNTIFS('Comparativo por Funcionário'!$A:$A,$B72,'Comparativo por Funcionário'!$R:$R,G$65),0)) -> 1 | H72: =IF(E72="","",IFERROR(COUNTIFS('Comparativo por Funcionário'!$A:$A,$B72,'Comparativo por Funcionário'!$R:$R,H$65),0)) -> 0 | I72: =IF(E72="","",IFERROR(COUNTIFS('Comparativo por Funcionário'!$A:$A,$B72,'Comparativo por Funcionário'!$R:$R,I$65),0)) -> 0 | J72: =IF(E72="","",IFERROR(COUNTIFS('Comparativo por Funcionário'!$A:$A,$B72,'Comparativo por Funcionário'!$R:$R,J$65),0)) -> 0 | K72: =IF(E72="","",IFERROR(COUNTIFS('Comparativo por Funcionário'!$A:$A,$B72,'Comparativo por Funcionário'!$R:$R,K$65),0)) -> 0
B73: =A35 -> 4 | C73: =IFERROR(VLOOKUP(B73,'Cálculos Comparativos'!A:B,2,0),"") -> Analista de Requisitos | D73: - C-02 | E73: =IF(C73="","",C73&" "&D73) -> Analista de Requisitos - C-02 | F73: =IF(E73="","",IFERROR(COUNTIFS('Comparativo por Funcionário'!A:A,B73,'Comparativo por Funcionário'!Z:Z,F$65),0)) -> 0 | G73: =IF(E73="","",IFERROR(COUNTIFS('Comparativo por Funcionário'!$A:$A,$B73,'Comparativo por Funcionário'!$Z:$Z,G$65),0)) -> 0 | H73: =IF(E73="","",IFERROR(COUNTIFS('Comparativo por Funcionário'!$A:$A,$B73,'Comparativo por Funcionário'!$Z:$Z,H$65),0)) -> 0 | I73: =IF(E73="","",IFERROR(COUNTIFS('Comparativo por Funcionário'!$A:$A,$B73,'Comparativo por Funcionário'!$Z:$Z,I$65),0)) -> 0 | J73: =IF(E73="","",IFERROR(COUNTIFS('Comparativo por Funcionário'!$A:$A,$B73,'Comparativo por Funcionário'!$Z:$Z,J$65),0)) -> 0 | K73: =IF(E73="","",IFERROR(COUNTIFS('Comparativo por Funcionário'!$A:$A,$B73,'Comparativo por Funcionário'!$Z:$Z,K$65),0)) -> 0
B74: =A36 -> 5 | C74: =IFERROR(VLOOKUP(B74,'Cálculos Comparativos'!A:B,2,0),"") -> Lider | D74: - C-01 | E74: =IF(C74="","",C74&" "&D74) -> Lider - C-01 | F74: =IF(E74="","",IFERROR(COUNTIFS('Comparativo por Funcionário'!A:A,B74,'Comparativo por Funcionário'!R:R,F$65),0)) -> 0 | G74: =IF(E74="","",IFERROR(COUNTIFS('Comparativo por Funcionário'!$A:$A,$B74,'Comparativo por Funcionário'!$R:$R,G$65),0)) -> 0 | H74: =IF(E74="","",IFERROR(COUNTIFS('Comparativo por Funcionário'!$A:$A,$B74,'Comparativo por Funcionário'!$R:$R,H$65),0)) -> 1 | I74: =IF(E74="","",IFERROR(COUNTIFS('Comparativo por Funcionário'!$A:$A,$B74,'Comparativo por Funcionário'!$R:$R,I$65),0)) -> 0 | J74: =IF(E74="","",IFERROR(COUNTIFS('Comparativo por Funcionário'!$A:$A,$B74,'Comparativo por Funcionário'!$R:$R,J$65),0)) -> 0 | K74: =IF(E74="","",IFERROR(COUNTIFS('Comparativo por Funcionário'!$A:$A,$B74,'Comparativo por Funcionário'!$R:$R,K$65),0)) -> 0
B75: =A36 -> 5 | C75: =IFERROR(VLOOKUP(B75,'Cálculos Comparativos'!A:B,2,0),"") -> Lider | D75: - C-02 | E75: =IF(C75="","",C75&" "&D75) -> Lider - C-02 | F75: =IF(E75="","",IFERROR(COUNTIFS('Comparativo por Funcionário'!A:A,B75,'Comparativo por Funcionário'!Z:Z,F$65),0)) -> 0 | G75: =IF(E75="","",IFERROR(COUNTIFS('Comparativo por Funcionário'!$A:$A,$B75,'Comparativo por Funcionário'!$Z:$Z,G$65),0)) -> 0 | H75: =IF(E75="","",IFERROR(COUNTIFS('Comparativo por Funcionário'!$A:$A,$B75,'Comparativo por Funcionário'!$Z:$Z,H$65),0)) -> 1 | I75: =IF(E75="","",IFERROR(COUNTIFS('Comparativo por Funcionário'!$A:$A,$B75,'Comparativo por Funcionário'!$Z:$Z,I$65),0)) -> 0 | J75: =IF(E75="","",IFERROR(COUNTIFS('Comparativo por Funcionário'!$A:$A,$B75,'Comparativo por Funcionário'!$Z:$Z,J$65),0)) -> 0 | K75: =IF(E75="","",IFERROR(COUNTIFS('Comparativo por Funcionário'!$A:$A,$B75,'Comparativo por Funcionário'!$Z:$Z,K$65),0)) -> 0

Sheet Informações Relevantes Cenários
A1: Cenário 01: Pesquisa TI - Nacional | C1: Cenário 02: Pesquisa TI - Corte por Santa Catarina
A2: Plooral Salary Research :: Remuneração Inteligente | C2: Plooral Salary Research :: Remuneração Inteligente
A4: 11º Pesquisa Salarial Nacional de Tecnologia - 2024 | C4: 11º Pesquisa Salarial Nacional de Tecnologia - 2024
A5: Período de Coleta: 11/07/2024 à 20/09/2024 | C5: Período de Coleta: 11/07/2024 à 20/09/2024
A6: Divulgação dos Resultados: 23/10/2024 | C6: Divulgação dos Resultados: 23/10/2024
A7: Carga Horária: 160 horas | C7: Carga Horária: 160 horas
A8: INPC Acumulado Aplicado: 4,94% | C8: INPC Acumulado Aplicado: 4,94%
A9: * O índice acumulado aplicado pode variar havendo diferentes coletas no escopo da pesquisa. | C9: * O índice acumulado aplicado pode variar havendo diferentes coletas no escopo da pesquisa.
A11: FILTROS UTILIZADOS | C11: FILTROS UTILIZADOS
A12: Segmentos de Negócio: Não Definido | C12: Segmentos de Negócio: Não Definido
A13: Áreas de Atuação: Não Definido | C13: Áreas de Atuação: Não Definido
A14: Formas de Contratação: CLT | C14: Formas de Contratação: CLT
... A23: © 2015-2025 Plooral Salary Research | C23: © 2015-2025 Plooral Salary Research

Sheet C-01
A1: Código do Cargo | B1: Nome do Cargo | C1: Senioridade | D1: Código do CargoSenioridade | E1: Dados Estatísticos - Empresas | F1: Dados Estatísticos - Salários | G1: Menor Salário | H1: 1o Quartil | I1: Média | J1: Mediana | K1: 3o Quartil | L1: Maior Salário
A2: 1 | B2: Desenvolvedor | C2: Indiferente | D2: =A2&C2 -> 1Indiferente | E2: 117 | F2: 2117 | G2: 2893.86 | H2: 3926.72 | I2: 5272.43 | J2: 5105.88 | K2: 6380.3 | L2: 8466.57
A3: 1 | B3: Desenvolvedor | C3: Júnior | D3: =A3&C3 -> 1Júnior | E3: 91 | F3: 883 | G3: 2030.9 | H3: 2706.62 | I3: 3370.79 | J3: 3379.04 | K3: 3870.49 | L3: 5268.74
A4: 1 | B4: Desenvolvedor | C4: Pleno | D4: =A4&C4 -> 1Pleno | E4: 84 | F4: 836 | G4: 3358.05 | H4: 4730.15 | I4: 5379.82 | J4: 5342.35 | K4: 5995.34 | L4: 7790.91
A5: 1 | B5: Desenvolvedor | C5: Sênior | D5: =A5&C5 -> 1Sênior | E5: 64 | F5: 613 | G5: 5873.21 | H5: 7005.56 | I5: 8047.78 | J5: 7999.87 | K5: 9271.4 | L5: 10095.14
A6: 1 | B6: Desenvolvedor | C6: Master | D6: =A6&C6 -> 1Master | E6: 2 | F6: 6 | G6: 0 | H6: 0 | I6: 0 | J6: 0 | K6: 0 | L6: 0
A7: 1 | B7: Desenvolvedor | C7: Especialista | D7: =A7&C7 -> 1Especialista | E7: 15 | F7: 40 | G7: 8294.38 | H7: 10078.94 | I7: 11458.76 | J7: 11626.1 | K7: 12714.48 | L7: 14476.68
A8: 1016 | B8: Líder Técnico | C8: Indiferente | D8: =A8&C8 -> 1016Indiferente | E8: 28 | F8: 71 | G8: 5639.53 | H8: 7452.03 | I8: 8919.44 | J8: 8929.22 | K8: 10057.47 | L8: 12817.68
A9: 1016 | B9: Líder Técnico | C9: Júnior | D9: =A9&C9 -> 1016Júnior | E9: 5 | F9: 6 | G9: 4848.58 | H9: 5725.38 | I9: 6258.83 | J9: 6038.19 | K9: 7160.54 | L9: 7472.24
A10: 1016 | B10: Líder Técnico | C10: Pleno | D10: =A10&C10 -> 1016Pleno | E10: 5 | F10: 14 | G10: 4960.76 | H10: 6756.91 | I10: 8222.66 | J10: 8364.84 | K10: 10040.79 | L10: 11026.42
A11: 1016 | B11: Líder Técnico | C11: Sênior | D11: =A11&C11 -> 1016Sênior | E11: 5 | F11: 9 | G11: 7250.34 | H11: 8906.82 | I11: 9300.57 | J11: 9082 | K11: 9530.31 | L11: 11415.69
A12: 1016 | B12: Líder Técnico | C12: Master | D12: =A12&C12 -> 1016Master | E12: 1 | F12: 5 | G12: 0 | H12: 0 | I12: 0 | J12: 0 | K12: 0 | L12: 0
